Workbook

Sheet Inputs
A1: Parameter | B1: Year | C1: Value | D1: Unit
A2: Standard Values
A3: Current Year | C3: =[1]Inputs!C4 -> 2024
A4: Inflation | C4: =[1]Inputs!C5 -> 0.02
A5: WACC | C5: =[1]Inputs!C6 -> 0.07
A6: USD to EUR | C6: =[1]Inputs!C7 -> 0.9
A7: Electricity
A8: LCOE | B8: 2024 | C8: =[1]Inputs!C9 -> 64 | D8: $/MWh
A9: LCOE | B9: 2050 | C9: =[1]Inputs!C10 -> 39 | D9: $/MWh
A10: Jet Fuel A-1 Characteristics
A11: Emissions Intensity | B11: 2024 | C11: =[1]Inputs!C12 -> 88.7 | D11: gCO2/MJ
A12: Emissions Intensity | B12: 2050 | C12: =[1]Inputs!C13 -> 88.7 | D12: gCO2/MJ
A13: Energy Density | C13: =[1]Inputs!C14 -> 43.2 | D13: MJ/kg
A14: Energy Density | C14: =[1]Inputs!C15 -> 34.6896 | D14: MJ/l
A15: Volumetric Density | C15: =[1]Inputs!C16 -> 0.803 | D15: kg/l
A16: Jet Fuel A-1 Price | B16: 2024 | C16: =[1]Inputs!C17 -> 0.8 | D16: $/l
A17: Scenario Specific Values
A18: Jet Fuel A-1 Price | B18: 2050 | C18: =[1]Inputs!C19 -> 0.8 | D18: $/l
A19: Reference
A20: Jet Fuel A-1 Price | B20: 2024 | C20: =[1]Inputs!C21 -> 0.32246154 | D20: $/l
A21: Jet Fuel A-1 Price | B21: 2050 | C21: =[1]Inputs!C22 -> 0.20923077 | D21: $/l
A22: EIA Reference
A23: Jet Fuel A-1 Price | B23: 2024 | C23: =[1]Inputs!C24 -> 1.0209014 | D23: $/l
A24: Jet Fuel A-1 Price | B24: 2050 | C24: =[1]Inputs!C25 -> 2.0095594 | D24: $/l
A25: EIA Low Oil Price Scenario
A26: Jet Fuel A-1 Price | B26: 2024 | C26: =[1]Inputs!C27 -> 0.48286833 | D26: $/l
A27: Jet Fuel A-1 Price | B27: 2050 | C27: =[1]Inputs!C28 -> 0.89646575 | D27: $/l
A28: EIA High Scenario
A29: Jet Fuel A-1 Price | B29: 2024 | C29: =[1]Inputs!C30 -> 1.8838713 | D29: $/l
A30: Jet Fuel A-1 Price | B30: 2050 | C30: =[1]Inputs!C31 -> 3.7893731 | D30: $/l
A31: Direct Air Capture
A32: LCOR | B32: 2024 | C32: =[1]Inputs!C33 -> 1282 | D32: $/tCO2
A33: LCOR | B33: 2050 | C33: 542 | D33: $/tCO2 | E33: TO BE UPDATED WITH 25 AND 75TH RANGE OF DAC INPUT COSTS? SAME AS FOR SYNFUELS
A34: CO2 Transport
A35: CO2 Transport Cost | B35: 2024 | C35: 25 | D35: $/tCO2 | E35: Dummy value for now
A36: CO2 Transport Cost | B36: 2050 | C36: 15 | D36: $/tCO2 | E36: Dummy value for now
A37: CO2 Storage
A38: CO2 Storage Cost | B38: 2024 | C38: 15 | D38: $/tCO2 | E38: Dummy value for now
A39: CO2 Storage Cost | B39: 2050 | C39: 10 | D39: $/tCO2 | E39: Dummy value for now
A40: NATURAL GAS
...

Sheet Study Parameters
A1: Key Parameters: Blue H₂ (SMR/ATR + CCS) + DAC
A2: Parameter | B2: min | C2: max | D2: Unit | E2: Source
A3: Hydrogen Cost (€2022/kg H₂) | B3: 1.7 | C3: 2.55 | D3: €2022/kg H₂ | E3: Frieden et al. (2024); 2050 SMR+CCS; Fig 5
A4: Hydrogen Cost ($/kg H₂) | B4: =(B3/Inputs!$C$6)*(1+Inputs!$C$4) -> 1.9266667 | C4: =(C3/Inputs!$C$6)*(1+Inputs!$C$4) -> 2.89 | D4: $2023/kg H₂ | E4: Frieden et al. (2024)
A5: Hydrogen Production Emissions (kg CO₂/kg H₂) | B5: 1 | C5: 2.7 | D5: kg CO₂/kg H₂ | E5: Katebah et al. (2022); 2.7: maximum carbon capture from the SMR plant using Option 1 is around 70% of the total CO2 emissions
A6: NG consumption Methane | B6: 3.4 | C6: 3.4 | D6: kg CH4/kg H2 | E6: Katebah et al. (2022)
A7: Methane GWP-100 potential (1 kg CH₄ = 36 kg CO₂e) | B7: 36 | C7: 36 | E7: https://www.epa.gov/ghgemissions/understanding-global-warming-potentials
A8: Methane Leakage Rate | B8: 0.0016 | C8: 0.01 | D8: % | E8: Katebah et al. (2022)
A9: Methane Leakage Contribution (kg CO₂e/kg H₂) | B9: =B6*B7*B8 -> 0.19584 | C9: =C6*C7*C8 -> 1.224 | D9: kg CO₂e/kg H₂
A10: Natural Gas Cost ($/GJ) | B10: =Inputs!C42 -> 5.6 | C10: =B10 -> 5.6 | D10: $/GJ | E10: In line with Sievert et al. (2024); NG price for 2050
A12: H₂ required per liter of synfuel | B12: =F12/I12 -> 0.3645576 | C12: 0.5 | D12: kg H₂/L fuel | E12: Argonne National Lab, Modelling of the Synfuel Production Process | F12: 1.38 | G12: kg/gallon of Ft fuel | H12: 1 gallon = | I12: 3.78541 | J12: liters | K12: Range from SAF meta-analysis
A13: CO₂ Required per Liter of Synfuel | B13: =F13/I13 -> 2.2613138 | C13: 3.5 | D13: kg CO₂/L fuel | E13: Argonne National Lab, Modelling of the Synfuel Production Process | F13: 8.56 | G13: kg/gallon of Ft fuel | H13: 1 gallon = | I13: 3.78541 | J13: liters | K13: Range from SAF meta-analysis
A16: Calculating Synfuel Emissions
A17: Syn-Fuel emissions (SMR+CCS) CO2 | B17: =(B5)*1000/Inputs!$C$44 -> 8.3333333 | C17: =(C5)*1000/Inputs!$C$44 -> 22.5 | D17: gCO2eq/MJ
A18: Syn-Fuel emissions (SMR+CCS) methane | B18: =(B9)*1000/Inputs!$C$44 -> 1.632 | C18: =(C9)*1000/Inputs!$C$44 -> 10.2 | D18: gCO2eq/MJ
A19: Total Syn-Fuel emissions (SMR+CCS) | B19: =SUM(B17:B18) -> 9.9653333 | C19: =SUM(C17:C18) -> 32.7 | D19: gCO2eq/MJ
A20: --> emissions to be abated via DACCS so that we have zero synfuel emissions
A22: Calculating DACCS needed to offset Synfuel Emissions
A23: Total Emissions (gCO₂eq/L synfuel) | B23: =B19*Inputs!$C$14 -> 345.69343 | C23: =C19*Inputs!$C$14 -> 1134.3499 | D23: gCO₂eq/L synfuel
A24: DACCS Requirement (kg CO₂/L synfuel) | B24: =B23/1000 -> 0.34569343 | C24: =C23/1000 -> 1.1343499 | D24: kg CO₂/L synfuel
A27: Calculating Synfuel Production costs
A28: Hydrogen cost per liter of synfuel | B28: ='Study Parameters'!B3*'Study Parameters'!B12 -> 0.61974793 | C28: ='Study Parameters'!C3*'Study Parameters'!C12 -> 1.275 | D28: $/l
A29: CO2 feedstock cost per liter of synfuel | B29: =(Inputs!$C$33/1000)*B13 -> 1.2256321 | C29: =(Inputs!$C$33/1000)*C13 -> 1.897 | D29: $/l
A30: Fischer-Tropsch and refining costs | B30: 0.3 | C30: 1.5 | D30: $/l | K30: Range from SAF meta-analysis
A31: DACCS cost to offset emissions | B31: =B24*((Inputs!$C$33+Inputs!$C$36+Inputs!$C$39)/1000) -> 0.19600817 | C31: =C24*((Inputs!$C$33+Inputs!$C$36+Inputs!$C$39)/1000) -> 0.6431764 | D31: $/l
A32: Synfuel (SMR+CCS+DACCS) production costs) | B32: =SUM(B28:B31) -> 2.3413882 | C32: =SUM(C28:C31) -> 5.3151764 | D32: $/l

Sheet Outputs
B2: 2050
B3: Parameter | C3: Unit | D3: Min | E3: Max | F3: Median
B4: Syn-Fuel cost | C4: $/l | D4: ='Study Parameters'!B32 -> 2.3413882 | E4: ='Study Parameters'!C32 -> 5.3151764
B5: Fossil Fuel cost | C5: $/l | D5: =Inputs!C18 -> 0.8 | E5: =D5 -> 0.8
B6: Syn-Fuel emissions (SMR+CCS+DACCS) | C6: gCO2eq/MJ | D6: 0 | E6: 0
B7: Fossil Fuel emissions | C7: gCO2eq/MJ | D7: =Inputs!C12 -> 88.7 | E7: =D7 -> 88.7
B8: CO2 Abated | C8: gCO2eq/MJ | D8: =D7-D6 -> 88.7 | E8: =E7-E6 -> 88.7
B9: CO2 Abated | C9: gCO2eq/l | D9: =D8*Inputs!$C$14 -> 3076.9675 | E9: =E8*Inputs!$C$14 -> 3076.9675
B10: Abatement cost blue hydrogen+DACCS synfuels | C10: $/tCO2 | D10: =(D4-D5) / D9 * 10^6 -> 500.94393 | E10: =(E4-E5) / E9 * 10^6 -> 1467.4111 | F10: =MEDIAN(D10:E10) -> 984.17753
B13: Abatement cost also needed for CO2e
B14: Conclusion: DACCS alone remains cheaper; why would you go for blue hydrogen + DACCS then; makes no sense
