Workbook

Sheet Intro
A1: This is a sheet for standardisation of inputs for the Meta Analysis of Abatement Costs from Alternative Fuel Pathways in Commercial Aviation

Sheet Steps

Sheet Inputs
A1: Scenario Selected | B1: Reference Oil Price | C1: Electricity and CO2 Price | D1: Reference
A2: Parameter | B2: Year | C2: Value | D2: Unit
A3: Standard Values
A4: Current Year | C4: 2024
A5: Inflation | C5: 0.02
A6: WACC | C6: 0.07
A7: USD to EUR | C7: 0.9
A8: Electricity
A9: LCOE | B9: 2024 | C9: {=_xlfn.IFS($D$1 = "Low Electricity and CO2", Electricity!F30, $D$1 = "Reference",'Standard Input Calculations'!E13, $D$1="High Electricity and CO2",Electricity!F34)} -> 64 | D9: $/MWh
A10: LCOE | B10: 2050 | C10: 39 | D10: $/MWh | E10: Vary this for electricity price scenarios
A11: Jet Fuel A-1 Characteristics
A12: Emissions Intensity | B12: 2024 | C12: ='Standard Input Calculations'!C63 -> 88.7 | D12: gCO2/MJ
A13: Emissions Intensity | B13: 2050 | C13: ='Standard Input Calculations'!D63 -> 88.7 | D13: gCO2/MJ
A14: Energy Density | C14: ='Standard Input Calculations'!C110 -> 43.2 | D14: MJ/kg
A15: Energy Density | C15: =C14*C16 -> 34.6896 | D15: MJ/l
A16: Volumetric Density | C16: ='Standard Input Calculations'!C111 -> 0.803 | D16: kg/l
A17: Jet Fuel A-1 Price | B17: 2024 | C17: ='Standard Input Calculations'!C73 -> 0.8 | D17: $/l
A18: Scenario Specific Values
A19: Jet Fuel A-1 Price | B19: 2050 | C19: 0.8 | D19: $/l | E19: Average fuel price across scenarios
A20: IEA Reference
A21: Jet Fuel A-1 Price | B21: 2024 | C21: ='Standard Input Calculations'!D103 -> 0.32246154 | D21: $/l
A22: Jet Fuel A-1 Price | B22: 2050 | C22: ='Standard Input Calculations'!E103 -> 0.20923077 | D22: $/l
A23: EIA Reference
A24: Jet Fuel A-1 Price | B24: 2024 | C24: ='Standard Input Calculations'!D104 -> 1.0209014 | D24: $/l
A25: Jet Fuel A-1 Price | B25: 2050 | C25: ='Standard Input Calculations'!E104 -> 2.0095594 | D25: $/l
A26: EIA Low Oil Price Scenario
A27: Jet Fuel A-1 Price | B27: 2024 | C27: ='Standard Input Calculations'!D106 -> 0.48286833 | D27: $/l
A28: Jet Fuel A-1 Price | B28: 2050 | C28: ='Standard Input Calculations'!E106 -> 0.89646575 | D28: $/l
A29: EIA High Scenario
A30: Jet Fuel A-1 Price | B30: 2024 | C30: ='Standard Input Calculations'!D105 -> 1.8838713 | D30: $/l
A31: Jet Fuel A-1 Price | B31: 2050 | C31: ='Standard Input Calculations'!E105 -> 3.7893731 | D31: $/l
A32: Direct Air Capture
A33: LCOR | B33: 2024 | C33: ='Standard Input Calculations'!C52 -> 440 | D33: $/tCO2 | E33: Modified as needed for Low CO2, median CO2, and high CO2 runs.
A34: LCOR | B34: 2050 | C34: ='Standard Input Calculations'!D52 -> 235 | D34: $/tCO2 | E34: Modified as needed for Low CO2, median CO2, and high CO2 runs.

Sheet Electricity
A1: Technology | B1: Scenario | C1: Period raw | D1: 2022 | E1: 2023 | F1: 2024 | G1: 2025 | H1: 2026 | I1: 2027 | J1: 2028 | K1: 2029 | L1: 2030 | M1: 2031 | N1: 2032 | O1: 2033 | P1: 2034 | Q1: 2035 | R1: 2036 | S1: 2037 | T1: 2038 | U1: 2039 | V1: 2040 | W1: 2041 | X1: 2042 | Y1: 2043 | Z1: 2044 | AA1: 2045 | AB1: 2046 | AC1: 2047 | AD1: 2048 | AE1: 2049 | AF1: 2050 | AG1: Source | AH1: Note | AI1: Link | AJ1: carbon_intensity | AK1: unit | AL1: Source
A2: PV tracking with storage | B2: LCOE $/MWh (avg) | C2: 2022 2H | D2: 111 | E2: 97 | F2: 84 | G2: 75 | H2: 68 | I2: 62 | J2: 58 | K2: 55 | L2: 53 | M2: 50 | N2: 48 | O2: 47 | P2: 45 | Q2: 44 | R2: 43 | S2: 43 | T2: 42 | U2: 41 | V2: 41 | W2: 41 | X2: 40 | Y2: 41 | Z2: 40 | AA2: 40 | AB2: 40 | AC2: 39 | AD2: 40 | AE2: 39 | AF2: 39 | AG2: BNEF LCOE - All Technologies - Unites States - LCOE Forecast 2022 | AH2: To be converted in $/GJ with conversion factor in Universal Inputs "conversion_electricity" OR just | AI2: https://www.bnef.com/flagships/lcoe | AJ2: =15.3/1000 -> 0.0153 | AK2: [t-CO2,eq GJ-1] | AL2: Young et al. (2023)
A3: CCGT | B3: LCOE $/GJ (low) | C3: 2022 2H | D3: 47 | E3: 48 | F3: 48 | G3: 48 | H3: 49 | I3: 49 | J3: 50 | K3: 51 | L3: 51 | M3: 52 | N3: 52 | O3: 53 | P3: 53 | Q3: 54 | R3: 54 | S3: 54 | T3: 55 | U3: 55 | V3: 56 | W3: 56 | X3: 56 | Y3: 56 | Z3: 57 | AA3: 57 | AB3: 57 | AC3: 57 | AD3: 57 | AE3: 57 | AF3: 57 | AG3: BNEF LCOE - All Technologies - Unites States - LCOE Forecast 2022 | AH3: To be converted in $/GJ with conversion factor in Universal Inputs "conversion_electricity" OR just | AI3: https://www.bnef.com/flagships/lcoe
A4: CCGT CCS | B4: LCOE $/MWh (low) | C4: 2022 2H | D4: 151 | E4: 141 | F4: 132 | G4: 121 | H4: 112 | I4: 102 | J4: 92 | K4: 82 | L4: 72 | M4: 73 | N4: 74 | O4: 74 | P4: 75 | Q4: 75 | R4: 76 | S4: 76 | T4: 77 | U4: 77 | V4: 77 | W4: 78 | X4: 78 | Y4: 79 | Z4: 79 | AA4: 79 | AB4: 79 | AC4: 79 | AD4: 79 | AE4: 79 | AF4: 79 | AG4: BNEF LCOE - All Technologies - Unites States - LCOE Forecast 2022 | AH4: To be converted in $/GJ with conversion factor in Universal Inputs "conversion_electricity" OR just | AI4: https://www.bnef.com/flagships/lcoe
A5: CCGT Hydrogen | B5: LCOE $/MWh (low) | C5: 2022 2H | D5: 152 | E5: 141 | F5: 130 | G5: 120 | H5: 112 | I5: 104 | J5: 98 | K5: 93 | L5: 89 | M5: 86 | N5: 83 | O5: 81 | P5: 78 | Q5: 76 | R5: 74 | S5: 72 | T5: 71 | U5: 70 | V5: 69 | W5: 68 | X5: 68 | Y5: 67 | Z5: 67 | AA5: 66 | AB5: 66 | AC5: 65 | AD5: 65 | AE5: 65 | AF5: 65 | AG5: BNEF LCOE - All Technologies - Unites States - LCOE Forecast 2022 | AH5: To be converted in $/GJ with conversion factor in Universal Inputs "conversion_electricity" OR just | AI5: https://www.bnef.com/flagships/lcoe
A6: Coal | B6: LCOE $/MWh (low) | C6: 2022 2H | D6: 68 | E6: 68 | F6: 68 | G6: 68 | H6: 68 | I6: 69 | J6: 70 | K6: 70 | L6: 71 | M6: 71 | N6: 72 | O6: 72 | P6: 73 | Q6: 73 | R6: 74 | S6: 74 | T6: 74 | U6: 75 | V6: 75 | W6: 76 | X6: 76 | Y6: 76 | Z6: 76 | AA6: 76 | AB6: 76 | AC6: 76 | AD6: 76 | AE6: 76 | AF6: 76 | AG6: BNEF LCOE - All Technologies - Unites States - LCOE Forecast 2022 | AH6: To be converted in $/GJ with conversion factor in Universal Inputs "conversion_electricity" OR just | AI6: https://www.bnef.com/flagships/lcoe
A7: Coal CCS | B7: LCOE $/MWh (low) | C7: 2022 2H | D7: 259 | E7: 246 | F7: 231 | G7: 212 | H7: 194 | I7: 175 | J7: 154 | K7: 133 | L7: 112 | M7: 113 | N7: 114 | O7: 115 | P7: 115 | Q7: 116 | R7: 117 | S7: 117 | T7: 118 | U7: 119 | V7: 119 | W7: 120 | X7: 120 | Y7: 120 | Z7: 120 | AA7: 120 | AB7: 120 | AC7: 120 | AD7: 120 | AE7: 120 | AF7: 120 | AG7: BNEF LCOE - All Technologies - Unites States - LCOE Forecast 2022 | AH7: To be converted in $/GJ with conversion factor in Universal Inputs "conversion_electricity" OR just | AI7: https://www.bnef.com/flagships/lcoe
A8: OCGT | B8: LCOE $/MWh (low) | C8: 2022 2H | D8: 96 | E8: 98 | F8: 99 | G8: 101 | H8: 102 | I8: 103 | J8: 104 | K8: 105 | L8: 106 | M8: 107 | N8: 108 | O8: 109 | P8: 109 | Q8: 110 | R8: 111 | S8: 112 | T8: 112 | U8: 113 | V8: 114 | W8: 114 | X8: 114 | Y8: 115 | Z8: 115 | AA8: 115 | AB8: 116 | AC8: 116 | AD8: 116 | AE8: 116 | AF8: 116 | AG8: BNEF LCOE - All Technologies - Unites States - LCOE Forecast 2022 | AH8: To be converted in $/GJ with conversion factor in Universal Inputs "conversion_electricity" OR just | AI8: https://www.bnef.com/flagships/lcoe
A9: OCGT CCS | B9: LCOE $/MWh (low) | C9: 2022 2H | D9: 455 | E9: 432 | F9: 401 | G9: 366 | H9: 330 | I9: 293 | J9: 255 | K9: 216 | L9: 176 | M9: 178 | N9: 179 | O9: 180 | P9: 181 | Q9: 182 | R9: 183 | S9: 184 | T9: 185 | U9: 186 | V9: 187 | W9: 188 | X9: 188 | Y9: 189 | Z9: 189 | AA9: 189 | AB9: 189 | AC9: 190 | AD9: 190 | AE9: 190 | AF9: 190 | AG9: BNEF LCOE - All Technologies - Unites States - LCOE Forecast 2022 | AH9: To be converted in $/GJ with conversion factor in Universal Inputs "conversion_electricity" OR just | AI9: https://www.bnef.com/flagships/lcoe
A10: OCGT Hydrogen | B10: LCOE $/MWh (low) | C10: 2022 2H | D10: 235 | E10: 224 | F10: 213 | G10: 202 | H10: 192 | I10: 184 | J10: 176 | K10: 170 | L10: 166 | M10: 161 | N10: 158 | O10: 154 | P10: 150 | Q10: 146 | R10: 142 | S10: 139 | T10: 137 | U10: 136 | V10: 134 | W10: 134 | X10: 133 | Y10: 132 | Z10: 131 | AA10: 131 | AB10: 130 | AC10: 130 | AD10: 130 | AE10: 129 | AF10: 129 | AG10: BNEF LCOE - All Technologies - Unites States - LCOE Forecast 2022 | AH10: To be converted in $/GJ with conversion factor in Universal Inputs "conversion_electricity" OR just | AI10: https://www.bnef.com/flagships/lcoe
A11: PV non-tracking | B11: LCOE $/MWh (low) | C11: 2022 2H | D11: 39 | E11: 35 | F11: 33 | G11: 29 | H11: 28 | I11: 27 | J11: 27 | K11: 25 | L11: 23 | M11: 21 | N11: 19 | O11: 19 | P11: 18 | Q11: 18 | R11: 17 | S11: 17 | T11: 16 | U11: 16 | V11: 16 | W11: 15 | X11: 15 | Y11: 15 | Z11: 14 | AA11: 14 | AB11: 14 | AC11: 14 | AD11: 13 | AE11: 13 | AF11: 13 | AG11: BNEF LCOE - All Technologies - Unites States - LCOE Forecast 2022 | AH11: To be converted in $/GJ with conversion factor in Universal Inputs "conversion_electricity" OR just | AI11: https://www.bnef.com/flagships/lcoe
A12: PV non-tracking with storage | B12: LCOE $/MWh (low) | C12: 2022 2H | D12: 58 | E12: 51 | F12: 47 | G12: 42 | H12: 40 | I12: 37 | J12: 36 | K12: 33 | L12: 31 | M12: 29 | N12: 27 | O12: 26 | P12: 26 | Q12: 25 | R12: 25 | S12: 24 | T12: 24 | U12: 23 | V12: 23 | W12: 22 | X12: 22 | Y12: 22 | Z12: 22 | AA12: 21 | AB12: 21 | AC12: 21 | AD12: 21 | AE12: 20 | AF12: 20 | AG12: BNEF LCOE - All Technologies - Unites States - LCOE Forecast 2022 | AH12: To be converted in $/GJ with conversion factor in Universal Inputs "conversion_electricity" OR just | AI12: https://www.bnef.com/flagships/lcoe
A13: PV tracking | B13: LCOE $/MWh (low) | C13: 2022 2H | D13: 34 | E13: 31 | F13: 28 | G13: 25 | H13: 25 | I13: 24 | J13: 23 | K13: 21 | L13: 20 | M13: 18 | N13: 17 | O13: 16 | P13: 16 | Q13: 15 | R13: 15 | S13: 15 | T13: 14 | U13: 14 | V13: 13 | W13: 13 | X13: 13 | Y13: 13 | Z13: 12 | AA13: 12 | AB13: 12 | AC13: 12 | AD13: 12 | AE13: 11 | AF13: 11 | AG13: BNEF LCOE - All Technologies - Unites States - LCOE Forecast 2022 | AH13: To be converted in $/GJ with conversion factor in Universal Inputs "conversion_electricity" OR just | AI13: https://www.bnef.com/flagships/lcoe
A14: PV tracking with storage | B14: LCOE $/MWh (low) | C14: 2022 2H | D14: 38.62069 | E14: 44 | F14: 40 | G14: 35 | H14: 34 | I14: 32 | J14: 30 | K14: 28 | L14: 26 | M14: 25 | N14: 23 | O14: 22 | P14: 22 | Q14: 21 | R14: 21 | S14: 20 | T14: 20 | U14: 20 | V14: 19 | W14: 19 | X14: 19 | Y14: 18 | Z14: 18 | AA14: 18 | AB14: 18 | AC14: 18 | AD14: 17 | AE14: 17 | AF14: 17 | AG14: BNEF LCOE - All Technologies - Unites States - LCOE Forecast 2022 | AH14: To be converted in $/GJ with conversion factor in Universal Inputs "conversion_electricity" OR just | AI14: https://www.bnef.com/flagships/lcoe | AJ14: =15.3/1000 -> 0.0153 | AK14: [t-CO2,eq GJ-1] | AL14: Young et al. (2023)
A15: Utility-scale battery (1h) | B15: LCOE $/MWh (low) | C15: 2022 2H | D15: 160 | E15: 136 | F15: 119 | G15: 106 | H15: 96 | I15: 88 | J15: 81 | K15: 78 | L15: 75 | M15: 71 | N15: 67 | O15: 65 | P15: 63 | Q15: 59 | R15: 58 | S15: 57 | T15: 56 | U15: 55 | V15: 54 | W15: 54 | X15: 54 | Y15: 54 | Z15: 54 | AA15: 54 | AB15: 54 | AC15: 54 | AD15: 54 | AE15: 54 | AF15: 54 | AG15: BNEF LCOE - All Technologies - Unites States - LCOE Forecast 2022 | AH15: To be converted in $/GJ with conversion factor in Universal Inputs "conversion_electricity" OR just | AI15: https://www.bnef.com/flagships/lcoe
A16: Utility-scale battery (4h) | B16: LCOE $/MWh (low) | C16: 2022 2H | D16: 123 | E16: 99 | F16: 83 | G16: 72 | H16: 63 | I16: 56 | J16: 50 | K16: 47 | L16: 45 | M16: 43 | N16: 41 | O16: 39 | P16: 38 | Q16: 36 | R16: 36 | S16: 35 | T16: 35 | U16: 34 | V16: 34 | W16: 34 | X16: 34 | Y16: 34 | Z16: 34 | AA16: 34 | AB16: 34 | AC16: 34 | AD16: 34 | AE16: 34 | AF16: 34 | AG16: BNEF LCOE - All Technologies - Unites States - LCOE Forecast 2022 | AH16: To be converted in $/GJ with conversion factor in Universal Inputs "conversion_electricity" OR just | AI16: https://www.bnef.com/flagships/lcoe
A17: Wind offshore | B17: LCOE $/MWh (low) | C17: 2022 2H | D17: 116 | E17: 107 | F17: 102 | G17: 97 | H17: 94 | I17: 91 | J17: 88 | K17: 86 | L17: 54 | M17: 53 | N17: 52 | O17: 51 | P17: 50 | Q17: 49 | R17: 48 | S17: 47 | T17: 46 | U17: 45 | V17: 44 | W17: 44 | X17: 43 | Y17: 43 | Z17: 42 | AA17: 42 | AB17: 41 | AC17: 40 | AD17: 40 | AE17: 40 | AF17: 40 | AG17: BNEF LCOE - All Technologies - Unites States - LCOE Forecast 2022 | AH17: To be converted in $/GJ with conversion factor in Universal Inputs "conversion_electricity" OR just | AI17: https://www.bnef.com/flagships/lcoe
A18: Wind onshore | B18: LCOE $/MWh (low) | C18: 2022 2H | D18: 33 | E18: 31 | F18: 29 | G18: 28 | H18: 27 | I18: 26 | J18: 25 | K18: 25 | L18: 24 | M18: 24 | N18: 23 | O18: 23 | P18: 22 | Q18: 22 | R18: 22 | S18: 21 | T18: 21 | U18: 21 | V18: 21 | W18: 20 | X18: 20 | Y18: 20 | Z18: 20 | AA18: 20 | AB18: 19 | AC18: 19 | AD18: 19 | AE18: 19 | AF18: 19 | AG18: BNEF LCOE - All Technologies - Unites States - LCOE Forecast 2022 | AH18: To be converted in $/GJ with conversion factor in Universal Inputs "conversion_electricity" OR just | AI18: https://www.bnef.com/flagships/lcoe
A19: Wind onshore with storage | B19: LCOE $/MWh (low) | C19: 2022 2H | D19: 49 | E19: 45 | F19: 42 | G19: 39 | H19: 37 | I19: 36 | J19: 35 | K19: 34 | L19: 33 | M19: 32 | N19: 31 | O19: 31 | P19: 30 | Q19: 30 | R19: 29 | S19: 29 | T19: 29 | U19: 28 | V19: 28 | W19: 28 | X19: 27 | Y19: 27 | Z19: 27 | AA19: 27 | AB19: 26 | AC19: 26 | AD19: 26 | AE19: 26 | AF19: 26 | AG19: BNEF LCOE - All Technologies - Unites States - LCOE Forecast 2022 | AH19: To be converted in $/GJ with conversion factor in Universal Inputs "conversion_electricity" OR just | AI19: https://www.bnef.com/flagships/lcoe | AJ19: =5.9/1000 -> 0.0059 | AK19: [t-CO2,eq GJ-1] | AL19: Young et al. (2023)
A20: CCGT | B20: LCOE $/MWh (high) | C20: 2022 2H | D20: 93 | E20: 91 | F20: 91 | G20: 90 | H20: 90 | I20: 91 | J20: 91 | K20: 92 | L20: 92 | M20: 93 | N20: 93 | O20: 94 | P20: 94 | Q20: 94 | R20: 95 | S20: 95 | T20: 95 | U20: 96 | V20: 96 | W20: 96 | X20: 96 | Y20: 97 | Z20: 97 | AA20: 97 | AB20: 97 | AC20: 97 | AD20: 97 | AE20: 97 | AF20: 97 | AG20: BNEF LCOE - All Technologies - Unites States - LCOE Forecast 2022 | AH20: To be converted in $/GJ with conversion factor in Universal Inputs "conversion_electricity" OR just | AI20: https://www.bnef.com/flagships/lcoe
A21: CCGT CCS | B21: LCOE $/MWh (high) | C21: 2022 2H | D21: 479 | E21: 435 | F21: 395 | G21: 351 | H21: 312 | I21: 274 | J21: 235 | K21: 196 | L21: 158 | M21: 158 | N21: 159 | O21: 159 | P21: 160 | Q21: 160 | R21: 161 | S21: 161 | T21: 161 | U21: 162 | V21: 162 | W21: 162 | X21: 162 | Y21: 163 | Z21: 163 | AA21: 163 | AB21: 163 | AC21: 163 | AD21: 163 | AE21: 163 | AF21: 163 | AG21: BNEF LCOE - All Technologies - Unites States - LCOE Forecast 2022 | AH21: To be converted in $/GJ with conversion factor in Universal Inputs "conversion_electricity" OR just | AI21: https://www.bnef.com/flagships/lcoe
A22: CCGT Hydrogen | B22: LCOE $/MWh (high) | C22: 2022 2H | D22: 214 | E22: 195 | F22: 181 | G22: 168 | H22: 160 | I22: 153 | J22: 147 | K22: 143 | L22: 139 | M22: 136 | N22: 133 | O22: 129 | P22: 126 | Q22: 122 | R22: 119 | S22: 117 | T22: 115 | U22: 113 | V22: 112 | W22: 111 | X22: 111 | Y22: 110 | Z22: 110 | AA22: 109 | AB22: 109 | AC22: 108 | AD22: 108 | AE22: 108 | AF22: 108 | AG22: BNEF LCOE - All Technologies - Unites States - LCOE Forecast 2022 | AH22: To be converted in $/GJ with conversion factor in Universal Inputs "conversion_electricity" OR just | AI22: https://www.bnef.com/flagships/lcoe
A23: Coal | B23: LCOE $/MWh (high) | C23: 2022 2H | D23: 158 | E23: 161 | F23: 164 | G23: 164 | H23: 167 | I23: 170 | J23: 172 | K23: 174 | L23: 176 | M23: 178 | N23: 180 | O23: 182 | P23: 183 | Q23: 185 | R23: 186 | S23: 188 | T23: 189 | U23: 190 | V23: 191 | W23: 192 | X23: 192 | Y23: 192 | Z23: 192 | AA23: 192 | AB23: 192 | AC23: 192 | AD23: 192 | AE23: 192 | AF23: 192 | AG23: BNEF LCOE - All Technologies - Unites States - LCOE Forecast 2022 | AH23: To be converted in $/GJ with conversion factor in Universal Inputs "conversion_electricity" OR just | AI23: https://www.bnef.com/flagships/lcoe
A24: Coal CCS | B24: LCOE $/MWh (high) | C24: 2022 2H | D24: 730 | E24: 699 | F24: 659 | G24: 600 | H24: 546 | I24: 488 | J24: 426 | K24: 361 | L24: 293 | M24: 297 | N24: 300 | O24: 303 | P24: 305 | Q24: 308 | R24: 310 | S24: 313 | T24: 315 | U24: 317 | V24: 319 | W24: 321 | X24: 321 | Y24: 321 | Z24: 321 | AA24: 321 | AB24: 321 | AC24: 321 | AD24: 321 | AE24: 321 | AF24: 321 | AG24: BNEF LCOE - All Technologies - Unites States - LCOE Forecast 2022 | AH24: To be converted in $/GJ with conversion factor in Universal Inputs "conversion_electricity" OR just | AI24: https://www.bnef.com/flagships/lcoe
A25: OCGT | B25: LCOE $/MWh (high) | C25: 2022 2H | D25: 223 | E25: 224 | F25: 225 | G25: 226 | H25: 227 | I25: 229 | J25: 230 | K25: 232 | L25: 233 | M25: 235 | N25: 236 | O25: 237 | P25: 238 | Q25: 239 | R25: 241 | S25: 242 | T25: 243 | U25: 244 | V25: 244 | W25: 245 | X25: 246 | Y25: 247 | Z25: 247 | AA25: 248 | AB25: 248 | AC25: 249 | AD25: 249 | AE25: 249 | AF25: 249 | AG25: BNEF LCOE - All Technologies - Unites States - LCOE Forecast 2022 | AH25: To be converted in $/GJ with conversion factor in Universal Inputs "conversion_electricity" OR just | AI25: https://www.bnef.com/flagships/lcoe
A26: OCGT CCS | B26: LCOE $/MWh (high) | C26: 2022 2H | D26: 1,148 | E26: 1,059 | F26: 964 | G26: 868 | H26: 772 | I26: 678 | J26: 584 | K26: 489 | L26: 395 | M26: 396 | N26: 398 | O26: 399 | P26: 401 | Q26: 402 | R26: 403 | S26: 404 | T26: 405 | U26: 407 | V26: 408 | W26: 409 | X26: 409 | Y26: 410 | Z26: 411 | AA26: 411 | AB26: 412 | AC26: 412 | AD26: 412 | AE26: 412 | AF26: 412 | AG26: BNEF LCOE - All Technologies - Unites States - LCOE Forecast 2022 | AH26: To be converted in $/GJ with conversion factor in Universal Inputs "conversion_electricity" OR just | AI26: https://www.bnef.com/flagships/lcoe
A27: OCGT Hydrogen | B27: LCOE $/MWh (high) | C27: 2022 2H | D27: 540 | E27: 506 | F27: 475 | G27: 447 | H27: 423 | I27: 403 | J27: 385 | K27: 371 | L27: 360 | M27: 350 | N27: 341 | O27: 332 | P27: 323 | Q27: 314 | R27: 306 | S27: 299 | T27: 295 | U27: 291 | V27: 288 | W27: 286 | X27: 284 | Y27: 283 | Z27: 281 | AA27: 280 | AB27: 279 | AC27: 278 | AD27: 278 | AE27: 277 | AF27: 277 | AG27: BNEF LCOE - All Technologies - Unites States - LCOE Forecast 2022 | AH27: To be converted in $/GJ with conversion factor in Universal Inputs "conversion_electricity" OR just | AI27: https://www.bnef.com/flagships/lcoe
A28: PV non-tracking | B28: LCOE $/MWh (high) | C28: 2022 2H | D28: 60 | E28: 53 | F28: 50 | G28: 45 | H28: 43 | I28: 42 | J28: 40 | K28: 38 | L28: 35 | M28: 32 | N28: 29 | O28: 28 | P28: 28 | Q28: 27 | R28: 26 | S28: 26 | T28: 25 | U28: 24 | V28: 24 | W28: 23 | X28: 23 | Y28: 22 | Z28: 22 | AA28: 21 | AB28: 21 | AC28: 21 | AD28: 20 | AE28: 20 | AF28: 20 | AG28: BNEF LCOE - All Technologies - Unites States - LCOE Forecast 2022 | AH28: To be converted in $/GJ with conversion factor in Universal Inputs "conversion_electricity" OR just | AI28: https://www.bnef.com/flagships/lcoe
A29: PV non-tracking with storage | B29: LCOE $/MWh (high) | C29: 2022 2H | D29: 188 | E29: 163 | F29: 146 | G29: 129 | H29: 119 | I29: 110 | J29: 103 | K29: 98 | L29: 93 | M29: 88 | N29: 83 | O29: 81 | P29: 79 | Q29: 76 | R29: 75 | S29: 74 | T29: 73 | U29: 71 | V29: 70 | W29: 70 | X29: 69 | Y29: 69 | Z29: 68 | AA29: 68 | AB29: 67 | AC29: 67 | AD29: 67 | AE29: 66 | AF29: 66 | AG29: BNEF LCOE - All Technologies - Unites States - LCOE Forecast 2022 | AH29: To be converted in $/GJ with conversion factor in Universal Inputs "conversion_electricity" OR just | AI29: https://www.bnef.com/flagships/lcoe
A30: PV tracking | B30: LCOE $/MWh (high) | C30: 2022 2H | D30: 53 | E30: 48 | F30: 44 | G30: 40 | H30: 39 | I30: 37 | J30: 36 | K30: 33 | L30: 31 | M30: 28 | N30: 26 | O30: 25 | P30: 25 | Q30: 24 | R30: 23 | S30: 23 | T30: 22 | U30: 22 | V30: 21 | W30: 21 | X30: 20 | Y30: 20 | Z30: 19 | AA30: 19 | AB30: 19 | AC30: 18 | AD30: 18 | AE30: 18 | AF30: 18 | AG30: BNEF LCOE - All Technologies - Unites States - LCOE Forecast 2022 | AH30: To be converted in $/GJ with conversion factor in Universal Inputs "conversion_electricity" OR just | AI30: https://www.bnef.com/flagships/lcoe
A31: PV tracking with storage | B31: LCOE $/MWh (high) | C31: 2022 2H | D31: 160 | E31: 141 | F31: 124 | G31: 110 | H31: 102 | I31: 94 | J31: 88 | K31: 83 | L31: 79 | M31: 75 | N31: 71 | O31: 69 | P31: 67 | Q31: 65 | R31: 64 | S31: 63 | T31: 62 | U31: 61 | V31: 60 | W31: 60 | X31: 59 | Y31: 59 | Z31: 58 | AA31: 58 | AB31: 58 | AC31: 57 | AD31: 57 | AE31: 56 | AF31: 56 | AG31: BNEF LCOE - All Technologies - Unites States - LCOE Forecast 2022 | AH31: To be converted in $/GJ with conversion factor in Universal Inputs "conversion_electricity" OR just | AI31: https://www.bnef.com/flagships/lcoe | AJ31: =15.3/1000 -> 0.0153 | AK31: [t-CO2,eq GJ-1] | AL31: Young et al. (2023)
A32: Utility-scale battery (1h) | B32: LCOE $/MWh (high) | C32: 2022 2H | D32: 287 | E32: 241 | F32: 209 | G32: 184 | H32: 165 | I32: 151 | J32: 139 | K32: 132 | L32: 127 | M32: 119 | N32: 112 | O32: 109 | P32: 106 | Q32: 98 | R32: 96 | S32: 94 | T32: 92 | U32: 90 | V32: 88 | W32: 88 | X32: 88 | Y32: 88 | Z32: 88 | AA32: 88 | AB32: 88 | AC32: 88 | AD32: 88 | AE32: 88 | AF32: 88 | AG32: BNEF LCOE - All Technologies - Unites States - LCOE Forecast 2022 | AH32: To be converted in $/GJ with conversion factor in Universal Inputs "conversion_electricity" OR just | AI32: https://www.bnef.com/flagships/lcoe
A33: Utility-scale battery (4h) | B33: LCOE $/MWh (high) | C33: 2022 2H | D33: 206 | E33: 172 | F33: 146 | G33: 127 | H33: 112 | I33: 100 | J33: 89 | K33: 85 | L33: 81 | M33: 77 | N33: 74 | O33: 71 | P33: 69 | Q33: 66 | R33: 65 | S33: 63 | T33: 62 | U33: 61 | V33: 60 | W33: 60 | X33: 60 | Y33: 60 | Z33: 60 | AA33: 60 | AB33: 60 | AC33: 60 | AD33: 60 | AE33: 60 | AF33: 60 | AG33: BNEF LCOE - All Technologies - Unites States - LCOE Forecast 2022 | AH33: To be converted in $/GJ with conversion factor in Universal Inputs "conversion_electricity" OR just | AI33: https://www.bnef.com/flagships/lcoe
A34: Wind offshore | B34: LCOE $/MWh (high) | C34: 2022 2H | D34: 150 | E34: 137 | F34: 130 | G34: 124 | H34: 120 | I34: 116 | J34: 113 | K34: 110 | L34: 90 | M34: 88 | N34: 86 | O34: 84 | P34: 82 | Q34: 81 | R34: 79 | S34: 77 | T34: 76 | U34: 74 | V34: 73 | W34: 71 | X34: 71 | Y34: 70 | Z34: 69 | AA34: 68 | AB34: 67 | AC34: 66 | AD34: 66 | AE34: 66 | AF34: 65 | AG34: BNEF LCOE - All Technologies - Unites States - LCOE Forecast 2022 | AH34: To be converted in $/GJ with conversion factor in Universal Inputs "conversion_electricity" OR just | AI34: https://www.bnef.com/flagships/lcoe
A35: Wind onshore | B35: LCOE $/MWh (high) | C35: 2022 2H | D35: 65 | E35: 60 | F35: 55 | G35: 52 | H35: 50 | I35: 48 | J35: 46 | K35: 45 | L35: 44 | M35: 42 | N35: 41 | O35: 41 | P35: 40 | Q35: 39 | R35: 39 | S35: 38 | T35: 38 | U35: 37 | V35: 36 | W35: 36 | X35: 36 | Y35: 35 | Z35: 35 | AA35: 34 | AB35: 34 | AC35: 34 | AD35: 33 | AE35: 33 | AF35: 33 | AG35: BNEF LCOE - All Technologies - Unites States - LCOE Forecast 2022 | AH35: To be converted in $/GJ with conversion factor in Universal Inputs "conversion_electricity" OR just | AI35: https://www.bnef.com/flagships/lcoe
A36: Wind onshore with storage | B36: LCOE $/MWh (high) | C36: 2022 2H | D36: 132 | E36: 114 | F36: 99 | G36: 89 | H36: 82 | I36: 77 | J36: 72 | K36: 69 | L36: 67 | M36: 64 | N36: 62 | O36: 61 | P36: 59 | Q36: 58 | R36: 57 | S36: 56 | T36: 55 | U36: 54 | V36: 53 | W36: 53 | X36: 52 | Y36: 52 | Z36: 51 | AA36: 51 | AB36: 50 | AC36: 50 | AD36: 49 | AE36: 49 | AF36: 48 | AG36: BNEF LCOE - All Technologies - Unites States - LCOE Forecast 2022 | AH36: To be converted in $/GJ with conversion factor in Universal Inputs "conversion_electricity" OR just | AI36: https://www.bnef.com/flagships/lcoe | AJ36: =5.9/1000 -> 0.0059 | AK36: [t-CO2,eq GJ-1] | AL36: Young et al. (2023)
A37: Nuclear | B37: LCOE $/MWh (low) | C37: 2022 2H | D37: 43.9 | AI37: Nuclear Energy Agency (NEA) - Projected Costs of Generating Electricity - 2020 Edition (oecd-nea.org) | AJ37: =1.9/1000 -> 0.0019 | AK37: [t-CO2,eq GJ-1] | AL37: p.59
A38: Nuclear | B38: LCOE $/MWh (high) | C38: 2022 2H | D38: 98.56 | AI38: Nuclear Energy Agency (NEA) - Projected Costs of Generating Electricity - 2020 Edition (oecd-nea.org) | AJ38: =1.9/1000 -> 0.0019 | AL38: p.59
A39: Geothermal | B39: LCOE $/MWh (low) | C39: 2022 2H | D39: 37 | AI39: Renewable Power Generation Costs in 2021 (irena.org) | AJ39: =18.9/1000 -> 0.0189 | AK39: [t-CO2,eq GJ-1] | AL39: Young et al. (2023) | AM39: In line with icelandic LCOE | AN39: Global weighted average
A40: Geothermal | B40: LCOE $/MWh (high) | C40: 2022 2H | D40: 98.879151 | AI40: Renewable Power Generation Costs in 2021 (irena.org) | AJ40: =18.9/1000 -> 0.0189

Sheet Standard Input Calculations
B2: LCOE cost assumption
B4: Source: | C4: BNEF LCOE Forecast 2022
B5: Year | C5: 2022 | D5: 2023 | E5: 2024 | F5: 2025 | G5: 2026 | H5: 2027 | I5: 2028 | J5: 2029 | K5: 2030 | L5: 2031 | M5: 2032 | N5: 2033 | O5: 2034 | P5: 2035 | Q5: 2036 | R5: 2037 | S5: 2038 | T5: 2039 | U5: 2040 | V5: 2041 | W5: 2042 | X5: 2043 | Y5: 2044 | Z5: 2045 | AA5: 2046 | AB5: 2047 | AC5: 2048 | AD5: 2049 | AE5: 2050 | AF5: -
B6: LCOE ($/MWh) | C6: 79 | D6: 70 | E6: 64 | F6: 55 | G6: 52 | H6: 48 | I6: 44 | J6: 42 | K6: 38 | L6: 39 | M6: 35 | N6: 34 | O6: 34 | P6: 33 | Q6: 33 | R6: 30 | S6: 32 | T6: 32 | U6: 31 | V6: 31 | W6: 31 | X6: 28 | Y6: 30 | Z6: 30 | AA6: 30 | AB6: 30 | AC6: 27 | AD6: 29 | AE6: 29
B7: LCOE (€/MWh) | C7: 84 | D7: 75 | E7: 68 | F7: 59 | G7: 55 | H7: 51 | I7: 47 | J7: 45 | K7: 40.53 | L7: 42 | M7: 37 | N7: 36 | O7: 36 | P7: 35 | Q7: 35 | R7: 32 | S7: 34 | T7: 34 | U7: 33 | V7: 33 | W7: 33 | X7: 30 | Y7: 32 | Z7: 32 | AA7: 32 | AB7: 32 | AC7: 29 | AD7: 31 | AE7: 31
B9: Possible sensitivities
B10: PV tracking with storage (high) - 12 battery hours - high
B11: LCOE ($/MWh) | C11: 374 | D11: 327 | E11: 284 | F11: 250 | G11: 228 | H11: 208 | I11: 192 | J11: 183 | K11: 175 | L11: 169 | M11: 161 | N11: 157 | O11: 151 | P11: 147 | Q11: 146 | R11: 143 | S11: 142 | T11: 139 | U11: 138 | V11: 138 | W11: 137 | X11: 137 | Y11: 136 | Z11: 136 | AA11: 136 | AB11: 135 | AC11: 135 | AD11: 132 | AE11: 132
B12: PV tracking with storage (low) - 12 battery hours - high
B13: LCOE ($/MWh) | C13: 79 | D13: 70 | E13: 64 | F13: 55 | G13: 52 | H13: 48 | I13: 44 | J13: 42 | K13: 38 | L13: 39 | M13: 35 | N13: 34 | O13: 34 | P13: 33 | Q13: 33 | R13: 30 | S13: 32 | T13: 32 | U13: 31 | V13: 31 | W13: 31 | X13: 28 | Y13: 30 | Z13: 30 | AA13: 30 | AB13: 30 | AC13: 27 | AD13: 29 | AE13: 29
B14: Wind Offshore
B15: LCOE ($/MWh) | C15: 116 | D15: 107 | E15: 102 | F15: 97 | G15: 94 | H15: 91 | I15: 88 | J15: 86 | K15: 54 | L15: 53 | M15: 52 | N15: 51 | O15: 50 | P15: 49 | Q15: 48 | R15: 47 | S15: 46 | T15: 45 | U15: 44 | V15: 44 | W15: 43 | X15: 43 | Y15: 42 | Z15: 42 | AA15: 41 | AB15: 40 | AC15: 40 | AD15: 40 | AE15: 40
B18: DAC cost assumption | F18: Source | G18: Note
F19: Sievert et. al. (2024) | G19: Multi Component learning curves are considered
C20: Solid Sorbent | D20: Liquid Solvent | E20: CaO ambient weathering
B21: Start Year | C21: 2024 | D21: 2024 | E21: 2024
B22: End Year | C22: 2050 | D22: 2050 | E22: 2050
B25: Year | C25: 2024 | D25: 2050
B27: Solid Sorbent
B28: Capacity (MtCO2/year) | C28: 0.004 | D28: 1000
B29: LCOR ($/tCO2) | C29: 1282 | D29: 374
B30: LCOR low ($/tCO2) | C30: 1180 | D30: 281
B31: LCOR high ($/tCO2) | C31: 1392 | D31: 579
B33: Liquid Solvent
B34: Capacity (MtCO2/year) | C34: 0.5 | D34: 1000
B35: LCOR ($/tCO2) | C35: 670 | D35: 341
B36: LCOR low ($/tCO2) | C36: 521 | D36: 226
B37: LCOR high ($/tCO2) | C37: 894 | D37: 544
B39: CaO ambient weathering
B40: Capacity (MtCO2/year) | C40: 0.001 | D40: 1000
B41: LCOR ($/tCO2) | C41: 2481 | D41: 371
B42: LCOR low ($/tCO2) | C42: 2153 | D42: 230
B43: LCOR high ($/tCO2) | C43: 2874 | D43: 835
B45: Average
B46: LCOR ($/tCO2) | C46: =AVERAGE(C29,C35,C41) -> 1477.6667 | D46: =AVERAGE(D29,D35,D41) -> 362
B47: LCOR low ($/tCO2) | C47: =AVERAGE(C30,C36,C42) -> 1284.6667 | D47: =AVERAGE(D30,D36,D42) -> 245.66667
B48: LCOR high ($/tCO2) | C48: =AVERAGE(C31,C37,C43) -> 1720 | D48: =AVERAGE(D31,D37,D43) -> 652.66667
B50: LCOR DACCS Meta-Analysis
B51: 0.25 | C51: 295 | D51: 142
B52: 0.5 | C52: 440 | D52: 235
...

Sheet Sensitivities
A1: Coupling of CO2 and Electricity
A2: CO2 Price | B2: Electricity Price
A3: 406 | B3: 79
A4: 358 | B4: 29
A6: Slope | B6: =(A3-A4)/(B3-B4) -> 0.96 | C6: $/t per $/kWh
A9: Electricity Price Range
B10: 2024 | C10: 2050
A11: High | B11: 116 | C11: 40 | D11: Wind Offshore
A12: Low | B12: 64 | C12: 29
A14: CO2 Price Range
B15: 2024 | C15: 2050
A16: High | B16: 1477 | C16: 362
A17: Low | B17: 1284 | C17: 246 | D17: Lower bounds of multi component experience curves

Sheet Notes for Study Parameters
A2: Parameter | B2: Note | C2: Source
A3: Lifetime | B3: If lifetime is not explicitly mentioned, lifetime of Fischer-Tropsch unit or heliostat is considered | C3: FT reactor/heliostat is a critical component
A4: Energy Density of Sustainable Fuel | B4: Energy Density is assumed to be 43.2 MJ/kg if not provided | C4: https://www.energy.gov/sites/prod/files/2020/09/f78/beto-sust-aviation-fuel-sep-2020.pdf
A5: Volumetric Density of Sustainable Fuel | B5: Considered to be 0.76 kg/l if not mentioned | C5: https://www.qcintel.com/biofuels/assessment/sustainable-aviation-fuel-fob-ara-premium-SAFARP.html
A6: Electrolyser | B6: Efficiency assumed to be 85% for PEM. Energy requirement of 40kWh/kg H2 | C6: https://www.enapter.com/kb_post/how-much-hydrogen-can-be-produced-by-enapters-electrolyser-and-how-long-does-it-take-to-fill-a-500-l-tank/ https://www.ise.fraunhofer.de/content/dam/ise/de/documents/publications/studies/cost-forecast-for-low-temperature-electrolysis.pdf
A7: Synthetic Fuel Emissions | B7: If not provided, assumed to be a 70% reduction (minimum under EU Renewable Energy Directive (RED) | C7: https://www.ecac-ceac.org/images/activities/environment/ECAC_Guidance_on_SAF_DGs_endorsed_HighRes.pdf

Sheet Studies current & future cost
A1: Reference | B1: Included | C1: Year of Assumptions in Study | D1: DOI | E1: Pathway | F1: Pathway Detail | G1: Year of Cost | H1: Study Scenario | I1: Baseline | J1: LCOE Harmonized | K1: CO2 Cost Harmonized | L1: Fully Harmonized | M1: Electricity | N1: CO2 | O1: CAPEX | P1: Other OPEX | Q1: Study Type | R1: Plant Location | S1: Production
A2: Albrecht et. al. | C2: 2016 | D2: https://doi.org/10.1016/j.energy.2019.116511 | E2: e-Fuels | F2: Fischer Tropsch | G2: 2024 | H2: Reference | I2: =([1]Outputs!$C$10) * ((1+Inputs!$C$5) ^ (G2-C2)) -> 642.2967 | J2: =([1]Outputs!$D$10) * ((1+Inputs!$C$5) ^ (G2-C2)) -> 768.83261 | K2: =([1]Outputs!$E$10) * ((1+Inputs!$C$5) ^ (G2-C2)) -> 2386.5585 | L2: =([1]Outputs!$F$10) * ((1+Inputs!$C$5) ^ (G2-C2)) -> 2466.5878 | Q2: Industrial | R2: Europe | S2: 1.4477822e+08 | T2: This study has a detailed breakdown but considers a scenario where electricity is an output, leading to lower overall costs.
A3: Bachorz et. al | C3: 2024 | D3: https://www.researchsquare.com/article/rs-4241841/v1 | E3: e-Fuels | F3: Methanol | G3: 2024 | H3: Reference | I3: =[2]Outputs!$C$10 -> 2404.7475 | J3: =[2]Outputs!$D$10 -> 2435.2346 | K3: =[2]Outputs!$E$10 -> 1644.4988 | L3: =[2]Outputs!$F$10 -> 1623.8464 | M3: ='[2]Cost Breakdown'!$B$9 -> 0.091683397 | N3: ='[2]Cost Breakdown'!$B$8 -> 0.37268475 | O3: ='[2]Cost Breakdown'!$B$10 -> 0.51503063 | P3: ='[2]Cost Breakdown'!$B$11 -> 0.020601225 | Q3: Academic | R3: Europe | S3: - | T3: Due to a high WACC assumption (~11%, final wacc correction leads to lower cost)
A4: Brazzola et al. | C4: 2024 | E4: e-Fuels | F4: Fischer Tropsch | H4: Reference | Q4: Academic | R4: Worldwide | S4: -
A5: Dietrich et. al. | C5: 2018 | D5: https://doi.org/10.1016/j.biombioe.2017.07.006 | E5: e-Fuels | F5: Fischer Tropsch | G5: 2024 | H5: Reference | I5: =[3]Outputs!$C$10 -> 1144.7871 | J5: =[3]Outputs!$D$10 -> 706.66811 | K5: =[3]Outputs!$E$10 -> 2210.7958 | L5: =[3]Outputs!$F$10 -> 2210.7958 | M5: ='[3]Received Data'!$N$9 -> 0.11002479 | N5: ='[3]Received Data'!$N$8 -> 0.32309926 | O5: ='[3]Received Data'!$N$10 -> 0.51966602 | P5: ='[3]Received Data'!$N$11 -> 0.04720993 | Q5: Academic | R5: Europe
A6: Falter et. al. | C6: 2020 | D6: https://doi.org/10.1039/d0se00179a | E6: Solar Fuels | F6: Fischer Tropsch | G6: 2024 | H6: Reference | I6: =[4]Outputs!$C$10 * (1+Inputs!C5) ^ ('Standardization Results'!F40-'Standardization Results'!B40) -> 2029.869 | J6: =[4]Outputs!$D$10 * (1+Inputs!C5) ^ ('Standardization Results'!F40-'Standardization Results'!B40) -> 2086.9789 | K6: =[4]Outputs!$E$10 * (1+Inputs!C5) ^ ('Standardization Results'!F40-'Standardization Results'!B40) -> 8021.9643 | L6: =[4]Outputs!$F$10 * (1+Inputs!C5) ^ ('Standardization Results'!F40-'Standardization Results'!B40) -> 7995.8085 | Q6: Academic | R6: MENA | S6: 45872966 | T6: Most assumptions based on previous study
A7: Falter et. al. | C7: 2015 | D7: https://doi.org/10.1021/acs.est.5b03515 | E7: Solar Fuels | F7: Fischer Tropsch | G7: 2024 | H7: Reference | I7: =[5]Outputs!$J$10* (1+Inputs!C5) ^ ('Standardization Results'!F41-'Standardization Results'!B41) -> 471.65912 | J7: =[5]Outputs!$K$10* (1+Inputs!C5) ^ ('Standardization Results'!F41-'Standardization Results'!B41) -> 496.13588 | K7: =[5]Outputs!$L$10* (1+Inputs!C5) ^ ('Standardization Results'!F41-'Standardization Results'!B41) -> 4670.6876 | L7: =[5]Outputs!$M$10* (1+Inputs!C5) ^ ('Standardization Results'!F41-'Standardization Results'!B41) -> 5006.9118 | Q7: Academic | R7: MENA | S7: 58035000
A8: Falter et. al. | C8: 2015 | D8: https://doi.org/10.1021/acs.est.5b03515 | E8: Solar Fuels | F8: Fischer Tropsch | G8: 2024 | H8: Reference | I8: =[5]Outputs!$C$10* (1+Inputs!C5) ^ ('Standardization Results'!F42-'Standardization Results'!B42) -> 667.86758 | J8: =[5]Outputs!$D$10* (1+Inputs!C5) ^ ('Standardization Results'!F42-'Standardization Results'!B42) -> 692.34434 | K8: =[5]Outputs!$E$10* (1+Inputs!C5) ^ ('Standardization Results'!F42-'Standardization Results'!B42) -> 4866.896 | L8: =[5]Outputs!$F$10* (1+Inputs!C5) ^ ('Standardization Results'!F42-'Standardization Results'!B42) -> 5216.4445 | M8: ='[5]Cost Breakdowns'!$B$10 -> 0.058359447 | N8: ='[5]Cost Breakdowns'!$B$9 -> 0.66723593 | O8: ='[5]Cost Breakdowns'!$B$11 -> 0.10459443 | P8: ='[5]Cost Breakdowns'!$B$12 -> 0.1698102 | Q8: Academic | R8: MENA | S8: 58035000 | T8: Initial assumptions are very optimistic (by author's admission), Production is high. Overall process efficiency is 5% according to the author
A9: Gray et al. | C9: 2024 | D9: https://doi.org/10.1016/j.rser.2024.114552 | E9: e-Fuels | F9: Fischer Tropsch | G9: 2024 | H9: Reference DAC Deployment | I9: =[6]Outputs!$J$10 -> 2727.5773 | J9: =[6]Outputs!$K$10 -> 2805.9552 | K9: =[6]Outputs!$L$10 -> 1478.0572 | L9: =[6]Outputs!$M$10 -> 1555.9594 | M9: ='[6]LCOF WACC Corrected'!$J$9 -> 0.36289802 | N9: ='[6]LCOF WACC Corrected'!$J$8 -> 0.35987238 | O9: ='[6]LCOF WACC Corrected'!$J$10 -> 0.18908765 | P9: ='[6]LCOF WACC Corrected'!$J$11 -> 0.088141946 | Q9: Academic | R9: Europe | S9: 39140034
A10: Gray et al. | B10: y | C10: 2024 | D10: https://doi.org/10.1016/j.rser.2024.114552 | E10: e-Fuels | F10: Fischer Tropsch | G10: 2050 | H10: High DAC Deployment | I10: =[6]Outputs!$C$10 -> 1053.0157 | J10: =[6]Outputs!$D$10 -> 1131.3935 | K10: =[6]Outputs!$E$10 -> 1207.0426 | L10: =[6]Outputs!$F$10 -> 1284.9449 | M10: ='[6]LCOF WACC Corrected'!$M$9 -> 0.43600143 | N10: ='[6]LCOF WACC Corrected'!$M$8 -> 0.23092291 | O10: ='[6]LCOF WACC Corrected'!$M$10 -> 0.22717811 | P10: ='[6]LCOF WACC Corrected'!$M$11 -> 0.10589756 | Q10: Academic | R10: Europe | S10: 39140034 | T10: This scenario assumes a decline in CO2 cost but not CAPEX
A11: Marchese et.al. | C11: 2021 | D11: https://doi.org/10.1016/j.jcou.2021.101487 | E11: e-Fuels | F11: Fischer Tropsch | G11: 2024 | H11: C.4 | I11: =[7]Outputs!$X$10* (1+Inputs!$C$5) ^ (G11-C11) -> 1458.3489 | J11: =[7]Outputs!$Y$10* (1+Inputs!$C$5) ^ (G11-C11) -> 751.42719 | K11: =[7]Outputs!$Z$10* (1+Inputs!$C$5)^ (G11-C11) -> 898.0069 | L11: =[7]Outputs!$AA$10* (1+Inputs!$C$5) ^ (G11-C11) -> 883.12721 | Q11: Academic | R11: Europe | S11: 69000000
A12: Marchese et.al. | C12: 2021 | D12: https://doi.org/10.1016/j.jcou.2021.101487 | E12: e-Fuels | F12: Fischer Tropsch | G12: 2024 | H12: C.1 | I12: =[7]Outputs!$C$10 * (1+Inputs!$C$5) ^ (G12-C12) -> 1892.3064 | J12: =[7]Outputs!$D$10* (1+Inputs!$C$5) ^ (G12-C12) -> 1097.7096 | K12: =[7]Outputs!$E$10* (1+Inputs!$C$5) ^ (G12-C12) -> 1157.1299 | L12: =[7]Outputs!$F$10* (1+Inputs!$C$5) ^ (G12-C12) -> 1141.2526 | M12: ='[7]Cost Breakdown'!$B$10 -> 0.27085063 | N12: ='[7]Cost Breakdown'!$B$9 -> 0.1799626 | O12: ='[7]Cost Breakdown'!$B$11 -> 0.30397259 | P12: ='[7]Cost Breakdown'!$B$12 -> 0.24521419 | Q12: Academic | R12: Europe | S12: 87000000
A13: Marchese et.al. | C13: 2021 | D13: https://doi.org/10.1016/j.jcou.2021.101487 | E13: e-Fuels | F13: Fischer Tropsch | G13: 2024 | H13: C.5 | I13: =[7]Outputs!$AE$10* (1+Inputs!$C$5) ^ (G13-C13) -> 1730.5108 | J13: =[7]Outputs!$AF$10* (1+Inputs!$C$5) ^ (G13-C13) -> 823.96436 | K13: =[7]Outputs!$AG$10* (1+Inputs!$C$5) ^ (G13-C13) -> 997.36187 | L13: =[7]Outputs!$AH$10* (1+Inputs!$C$5) ^ (G13-C13) -> 980.42742 | Q13: Academic | R13: Europe | S13: 68000000
A14: Marchese et.al. | C14: 2021 | D14: https://doi.org/10.1016/j.jcou.2021.101487 | E14: e-Fuels | F14: Fischer Tropsch | G14: 2024 | H14: C.3 | I14: =[7]Outputs!$Q$10* (1+Inputs!$C$5) ^ (G14-C14) -> 2708.6121 | J14: =[7]Outputs!$R$10* (1+Inputs!$C$5) ^(G14-C14) -> 1804.7169 | K14: =[7]Outputs!$S$10* (1+Inputs!$C$5) ^ (G14-C14) -> 1941.7692 | L14: =[7]Outputs!$T$10* (1+Inputs!$C$5) ^ (G14-C14) -> 1919.3136 | Q14: Academic | R14: Europe | S14: 48000000
A15: Marchese et.al. | C15: 2021 | D15: https://doi.org/10.1016/j.jcou.2021.101487 | E15: e-Fuels | F15: Fischer Tropsch | G15: 2024 | H15: C.2 | I15: =[7]Outputs!$J$10* 1.02 ^ (G15-C15) -> 2761.7003 | J15: =[7]Outputs!$K$10* 1.02 ^ (G15-C15) -> 1368.7085 | K15: =[7]Outputs!$L$10* 1.02 ^ (G15-C15) -> 1562.0729 | L15: =[7]Outputs!$M$10* 1.02 ^ (G15-C15) -> 1533.3503 | Q15: Academic | R15: Europe | S15: 35000000
A16: Marchese et.al. | B16: y | C16: 2021 | D16: https://doi.org/10.1016/j.jcou.2021.101487 | E16: e-Fuels | F16: Fischer Tropsch | G16: 2050 | H16: C.1 | I16: =[7]Outputs!$C$21* (1+Inputs!$C$5) ^ (G16-C16) -> 597.79762 | J16: =[7]Outputs!$D$21* (1+Inputs!$C$5) ^ (G16-C16) -> 297.6618 | K16: =[7]Outputs!$E$21* (1+Inputs!$C$5) ^ (G16-C16) -> 507.83267 | L16: =[7]Outputs!$F$21* (1+Inputs!$C$5) ^ (G16-C16) -> 497.82439 | M16: ='[7]Cost Breakdown'!$B$22 -> 0.28830506 | N16: ='[7]Cost Breakdown'!$B$21 -> 0.1573409 | O16: ='[7]Cost Breakdown'!$B$23 -> 0.15294257 | P16: ='[7]Cost Breakdown'!$B$24 -> 0.40141147 | Q16: Academic | R16: Europe | S16: 87000000
A17: Marchese et.al. | B17: y | C17: 2021 | D17: https://doi.org/10.1016/j.jcou.2021.101487 | E17: e-Fuels | F17: Fischer Tropsch | G17: 2050 | H17: C.2 | I17: =[7]Outputs!$J$21* (1+Inputs!$C$5) ^ (G17-C17) -> 1954.9193 | J17: =[7]Outputs!$K$21* (1+Inputs!$C$5) ^ (G17-C17) -> 1438.7117 | K17: =[7]Outputs!$L$21* (1+Inputs!$C$5) ^ (G17-C17) -> 1976.4189 | L17: =[7]Outputs!$M$21* (1+Inputs!$C$5) ^ (G17-C17) -> 1958.4433 | Q17: Academic | R17: Europe | S17: 35000000
A18: Marchese et.al. | B18: y | C18: 2021 | D18: https://doi.org/10.1016/j.jcou.2021.101487 | E18: e-Fuels | F18: Fischer Tropsch | G18: 2050 | H18: C.3 | I18: =[7]Outputs!$Q$21* (1+Inputs!$C$5) ^ (G18-C18) -> 1692.7913 | J18: =[7]Outputs!$R$21 * (1+Inputs!$C$5) ^ (G16-C16) -> 1109.928 | K18: =[7]Outputs!$S$21* (1+Inputs!$C$5) ^ (G16-C16) -> 1500.6866 | L18: =[7]Outputs!$T$21* (1+Inputs!$C$5) ^ (G16-C16) -> 1487.0626 | Q18: Academic | R18: Europe | S18: 48000000
A19: Marchese et.al. | B19: y | C19: 2021 | D19: https://doi.org/10.1016/j.jcou.2021.101487 | E19: e-Fuels | F19: Fischer Tropsch | G19: 2050 | H19: C.4 | I19: =[7]Outputs!$X$21* (1+Inputs!$C$5) ^ (G19-C19) -> 310.7968 | J19: =[7]Outputs!$Y$21* (1+Inputs!$C$5) ^ (G19-C19) -> 31.763718 | K19: =[7]Outputs!$Z$21* (1+Inputs!$C$5) ^(G19-C19) -> 320.74468 | L19: =[7]Outputs!$AA$21* (1+Inputs!$C$5) ^ (G19-C19) -> 310.75429 | Q19: Academic | R19: Europe | S19: 69000000
A20: Marchese et.al. | B20: y | C20: 2021 | D20: https://doi.org/10.1016/j.jcou.2021.101487 | E20: e-Fuels | F20: Fischer Tropsch | G20: 2050 | H20: C.5 | I20: =[7]Outputs!$AE$21* (1+Inputs!$C$5) ^ (G20-C20) -> 628.73238 | J20: =[7]Outputs!$AF$21* (1+Inputs!$C$5) ^ (G20-C20) -> 270.87595 | K20: =[7]Outputs!$AG$21* (1+Inputs!$C$5) ^ (G20-C20) -> 572.36067 | L20: =[7]Outputs!$AH$21* (1+Inputs!$C$5) ^ (G20-C20) -> 561.98413 | Q20: Academic | R20: Europe | S20: 68000000
A21: Martin et. al. | C21: 2023 | D21: https://www.sciencedirect.com/science/article/pii/S136403212300494X?via%3Dihub | E21: e-Fuels | F21: Fischer Tropsch | G21: 2024 | H21: Reference | I21: =[8]Outputs!$C$10 * (1+Inputs!C5) ^ ('Standardization Results'!F19-'Standardization Results'!B19) -> 1999.3691 | J21: =[8]Outputs!$D$10* (1+Inputs!C5) ^ ('Standardization Results'!F19-'Standardization Results'!B19) -> 1980.3771 | K21: =[8]Outputs!$E$10* (1+Inputs!C5) ^ ('Standardization Results'!F19-'Standardization Results'!B19) -> 1827.4016 | L21: =[8]Outputs!$F$10* (1+Inputs!C5) ^ ('Standardization Results'!F19-'Standardization Results'!B19) -> 1832.9217 | Q21: Academic | R21: Europe | S21: -
A22: Martin et. al. | B22: y | C22: 2023 | D22: https://www.sciencedirect.com/science/article/pii/S136403212300494X?via%3Dihub | E22: e-Fuels | F22: Fischer Tropsch | G22: 2050 | H22: Reference | I22: =[8]Outputs!$J$10 * (1+Inputs!C5) ^ ('Standardization Results'!F22-'Standardization Results'!B22) -> 209.51492 | J22: =[8]Outputs!$K$10* (1+Inputs!C5) ^ ('Standardization Results'!F22-'Standardization Results'!B22) -> 196.72581 | K22: =[8]Outputs!$L$10* (1+Inputs!C5) ^ ('Standardization Results'!F22-'Standardization Results'!B22) -> 384.1995 | L22: =[8]Outputs!$M$10* (1+Inputs!C5) ^ ('Standardization Results'!F22-'Standardization Results'!B22) -> 385.78482 | Q22: Academic | R22: Europe | S22: -
A23: Meurer et al. | C23: 2024 | D23: https://doi.org/10.1039/D3SE01156A | E23: e-Fuels | F23: Fischer Tropsch | G23: 2024 | H23: Reference | I23: =[9]Outputs!$C$10 -> 1678.5512 | J23: =[9]Outputs!$D$10 -> 1330.6142 | K23: =[9]Outputs!$E$10 -> 2039.9518 | L23: =[9]Outputs!$F$10 -> 2004.6361 | Q23: Academic | R23: Europe | S23: 3650000
A24: Moretti et al. | C24: 2023 | D24: https://doi.org/10.1016/j.scitotenv.2023.166005 | E24: Solar Fuels | F24: Fischer Tropsch | G24: 2024 | H24: Reference | I24: =[10]Outputs!$C$10 -> 838.68815 | J24: =[10]Outputs!$D$10 -> 793.08716 | K24: =[10]Outputs!$E$10 -> 549.23622 | L24: =[10]Outputs!$F$10 -> 614.21669 | M24: ='[10]MFSP WACC Corrected'!$B$39 -> -0.11475881 | N24: ='[10]MFSP WACC Corrected'!$B$40 -> 0.39312614 | O24: ='[10]MFSP WACC Corrected'!$B$38 -> 0.44920104 | P24: ='[10]MFSP WACC Corrected'!$B$41 -> 0.27243164 | Q24: Industrial | R24: MENA | S24: 31354838 | T24: High CO2 cost assumed, hence there is less effect, High Production levels lead to lower costs due to scale and cheaper labour in MENA
A25: Moretti et al. | B25: y | C25: 2023 | D25: https://doi.org/10.1016/j.scitotenv.2023.166005 | E25: Solar Fuels | F25: Fischer Tropsch | G25: 2050 | H25: Reference | I25: =[10]Outputs!$J$10 * (1+Inputs!$C$5) ^ (G25-C25) -> 982.3514 | J25: =[10]Outputs!$K$10 * (1+Inputs!$C$5) ^ (G25-C25) -> 982.36403 | K25: =[10]Outputs!$L$10 * (1+Inputs!$C$5) ^ (G25-C25) -> 976.94296 | L25: =[10]Outputs!$M$10 * (1+Inputs!$C$5) ^ (G25-C25) -> 1076.4346 | M25: ='[10]MFSP WACC Corrected'!$B$53 -> -3.6841458e-05 | N25: ='[10]MFSP WACC Corrected'!$B$54 -> 0.4089253 | O25: ='[10]MFSP WACC Corrected'!$B$52 -> 0.41554006 | P25: ='[10]MFSP WACC Corrected'!$B$55 -> 0.17557148 | Q25: Industrial | R25: MENA | S25: 31354838
A26: Moretti et al. | B26: y | C26: 2023 | D26: https://doi.org/10.1016/j.scitotenv.2023.166005 | E26: Solar Fuels | F26: Fischer Tropsch | G26: 2050 | H26: Optimistic | I26: =[10]Outputs!$Q$10 * (1+Inputs!$C$5) ^ ('Standardization Results'!F18-'Standardization Results'!B18) -> 858.71366 | J26: =[10]Outputs!$R$10* (1+Inputs!$C$5) ^ ('Standardization Results'!F18-'Standardization Results'!B18) -> 858.72679 | K26: =[10]Outputs!$S$10* (1+Inputs!$C$5) ^ ('Standardization Results'!F18-'Standardization Results'!B18) -> 853.08671 | L26: =[10]Outputs!$T$10* (1+Inputs!$C$5) ^ ('Standardization Results'!F18-'Standardization Results'!B18) -> 929.58904 | Q26: Industrial | R26: MENA | S26: 31354838
A27: Peacock et. al. | C27: 2024 | E27: e-Fuels | F27: Fischer Tropsch | G27: 2024 | H27: SOEC, Nuclear + Renewables | I27: =[11]Outputs!$Q$10 -> 2681.2488 | J27: =[11]Outputs!$R$10 -> 2495.6577 | K27: =[11]Outputs!$S$10 -> 2013.7955 | L27: =[11]Outputs!$T$10 -> 1988.4544 | Q27: Academic | R27: United Kingdom | S27: 157410000
A28: Peacock et. al. | C28: 2024 | E28: e-Fuels | F28: Fischer Tropsch | G28: 2024 | H28: PEM, Nuclear | I28: =[11]Outputs!$C$10 -> 3266.1214 | J28: =[11]Outputs!$D$10 -> 2576.9841 | K28: =[11]Outputs!$E$10 -> 1969.1598 | L28: =[11]Outputs!$F$10 -> 1947.4925 | Q28: Academic | R28: United Kingdom | S28: 157410000 | T28: Large scale production but high electrolyser costs and multiple replacements considered (missing from most other studies)
A29: Peacock et. al. | B29: y | C29: 2024 | E29: e-Fuels | F29: Fischer Tropsch | G29: 2050 | H29: PEM, Nuclear | I29: =[11]Outputs!$C$22 * (1+Inputs!$C$5) ^ ('Standardization Results'!F36-'Standardization Results'!B36) -> 1120.7136 | J29: =[11]Outputs!$D$22* (1+Inputs!$C$5) ^ ('Standardization Results'!F36-'Standardization Results'!B36) -> 983.41616 | K29: =[11]Outputs!$E$22* (1+Inputs!$C$5) ^ ('Standardization Results'!F36-'Standardization Results'!B36) -> 1214.6327 | L29: =[11]Outputs!$F$22* (1+Inputs!$C$5) ^ ('Standardization Results'!F36-'Standardization Results'!B36) -> 1197.7597 | Q29: Academic | R29: United Kingdom | S29: 157410000
A30: Peacock et. al. | B30: y | C30: 2024 | E30: e-Fuels | F30: Fischer Tropsch | G30: 2050 | H30: PEM, Nuclear + Renewables | I30: =[11]Outputs!$J$22* (1+Inputs!$C$5) ^ ('Standardization Results'!F37-'Standardization Results'!B37) -> 952.97687 | J30: =[11]Outputs!$K$22* (1+Inputs!$C$5) ^ ('Standardization Results'!F37-'Standardization Results'!B37) -> 964.92098 | K30: =[11]Outputs!$L$22* (1+Inputs!$C$5) ^ ('Standardization Results'!F37-'Standardization Results'!B37) -> 1151.5013 | L30: =[11]Outputs!$M$22* (1+Inputs!$C$5) ^ ('Standardization Results'!F37-'Standardization Results'!B37) -> 1134.6284 | M30: ='[11]Cost Breakdowns'!$B$22 -> 0.40154651 | N30: ='[11]Cost Breakdowns'!$B$21 -> 0.31639384 | O30: ='[11]Cost Breakdowns'!$B$23 -> 0.092223342 | P30: ='[11]Cost Breakdowns'!$B$24 -> 0.1898363 | Q30: Academic | R30: United Kingdom | S30: 157410000
A31: Peacock et. al. | B31: y | C31: 2024 | E31: e-Fuels | F31: Fischer Tropsch | G31: 2050 | H31: SOEC, Nuclear + Renewables | I31: =[11]Outputs!$Q$22 * (1+Inputs!$C$5) ^ ('Standardization Results'!F38-'Standardization Results'!B38) -> 1383.9118 | J31: =[11]Outputs!$R$22* (1+Inputs!$C$5) ^ ('Standardization Results'!F38-'Standardization Results'!B38) -> 1400.7491 | K31: =[11]Outputs!$S$22* (1+Inputs!$C$5) ^ ('Standardization Results'!F38-'Standardization Results'!B38) -> 1708.5223 | L31: =[11]Outputs!$T$22* (1+Inputs!$C$5) ^ ('Standardization Results'!F38-'Standardization Results'!B38) -> 1681.9374 | Q31: Academic | R31: United Kingdom | S31: 157410000
A32: Peacock et. al. | C32: 2024 | E32: e-Fuels | F32: Fischer Tropsch | G32: 2024 | H32: PEM, Nuclear + Renewables | I32: =[11]Outputs!$J$10 -> 2797.4452 | J32: =[11]Outputs!$K$10 -> 2548.3625 | K32: =[11]Outputs!$L$10 -> 2081.0539 | L32: =[11]Outputs!$M$10 -> 2059.3865 | M32: ='[11]Cost Breakdowns'!$B$10 -> 0.36579718 | N32: ='[11]Cost Breakdowns'!$B$9 -> 0.39350094 | O32: ='[11]Cost Breakdowns'!$B$11 -> 0.079277064 | P32: ='[11]Cost Breakdowns'!$B$12 -> 0.16142482 | Q32: Academic | R32: United Kingdom | S32: 157410000
A33: Peters et. al. | C33: 2022 | D33: https://doi.org/10.3390/pr10040699 | E33: e-Fuels | F33: Fischer Tropsch | G33: 2024 | H33: Baseline | I33: =[12]Outputs!$C$10 * (1+Inputs!C5) ^ ('Standardization Results'!F33-'Standardization Results'!B33) -> 642.42374 | J33: =[12]Outputs!$D$10* (1+Inputs!C5) ^ ('Standardization Results'!F33-'Standardization Results'!B33) -> 1011.8769 | K33: =[12]Outputs!$E$10 * (1+Inputs!C5) ^ ('Standardization Results'!F33-'Standardization Results'!B33) -> 3588.7386 | L33: =[12]Outputs!$F$10* (1+Inputs!C5) ^ ('Standardization Results'!F33-'Standardization Results'!B33) -> 3626.2481 | M33: ='[12]Cost of Manufacturing Models'!$F$10 -> 0.066800203 | N33: ='[12]Cost of Manufacturing Models'!$F$9 -> 0.46591807 | O33: ='[12]Cost of Manufacturing Models'!$F$11 -> 0.43493529 | P33: ='[12]Cost of Manufacturing Models'!$F$12 -> 0.032346433 | Q33: Academic | R33: Europe | S33: 208032000 | T33: Low intial electricity and CO2 price assumption lead to lower costs
A34: Rojas-Michaga et. al. | C34: 2023 | D34: https://www.sciencedirect.com/science/article/pii/S0196890423007732?via%3Dihub#s0005 | E34: e-Fuels | F34: Fischer Tropsch | G34: 2024 | H34: Reference | I34: =[13]Outputs!$C$10 * (1+Inputs!C5) ^ ('Standardization Results'!F30-'Standardization Results'!B30) -> 2879.4702 | J34: =[13]Outputs!$D$10 * (1+Inputs!C5) ^ ('Standardization Results'!F30-'Standardization Results'!B30) -> 2389.2886 | K34: =[13]Outputs!$E$10 * (1+Inputs!C5) ^ ('Standardization Results'!F20-'Standardization Results'!B20) -> 5490.9741 | L34: =[13]Outputs!$F$10 * (1+Inputs!C5) ^ ('Standardization Results'!F30-'Standardization Results'!B30) -> 5101.9877 | M34: ='[13]MJSP WACC Corrected'!$B$20 -> 0.28620653 | N34: ='[13]MJSP WACC Corrected'!$B$19 -> 0.47089021 | O34: ='[13]MJSP WACC Corrected'!$B$21 -> 0.025500914 | P34: ='[13]MJSP WACC Corrected'!$B$22 -> 0.21740235 | Q34: Academic | R34: United Kingdom | S34: 25105853 | T34: Very detailed study, we should note that this study considers a wide variety of costs that will be practically applicable (e.g. labour, overhead, catalyst, by-product sales etc.)
A35: Saad et al. | C35: 2024 | D35: https://doi.org/10.1021/acs.est.4c01578 | E35: e-Fuels | F35: Methanol | G35: 2024 | H35: CO2ER | I35: =[14]Outputs!$C$10 -> 6201.6747 | J35: =[14]Outputs!$D$10 -> 3818.5621 | K35: =[14]Outputs!$E$10 -> 3865.4181 | L35: =[14]Outputs!$F$10 -> 3949.4052 | M35: ='[14]Cost Breakdown'!$B$10 -> 0.18840662 | N35: ='[14]Cost Breakdown'!$B$9 -> 0.68456138 | O35: ='[14]Cost Breakdown'!$B$11 -> 0.11897367 | P35: ='[14]Cost Breakdown'!$B$12 -> 0.008058336 | Q35: Academic | R35: Europe | S35: 1250000000 | T35: LCA accounting methodology means that the emissions abated are low, therefore cost is high
A36: Saad et al. | C36: 2024 | D36: https://doi.org/10.1021/acs.est.4c01578 | E36: e-Fuels | F36: Methanol | G36: 2024 | H36: CO2HY | I36: =[14]Outputs!$J$10 -> 5186.3474 | J36: =[14]Outputs!$K$10 -> 3438.5193 | K36: =[14]Outputs!$L$10 -> 5951.2257 | L36: =[14]Outputs!$M$10 -> 6013.8338 | M36: ='[14]Cost Breakdown'!$B$22 -> 0.1011943 | N36: ='[14]Cost Breakdown'!$B$21 -> 0.61193523 | O36: ='[14]Cost Breakdown'!$B$23 -> 0.2723405 | P36: ='[14]Cost Breakdown'!$B$24 -> 0.014529965 | Q36: Academic | R36: Europe | S36: 1250000000
A37: Schmidt et. al. | B37: y | C37: 2024 | D37: https://onlinelibrary.wiley.com/doi/full/10.1002/cite.201700129?saml_referrer https://www.concawe.eu/wp-content/uploads/Rpt_24-4-1.pdf | E37: e-Fuels | F37: Fischer Tropsch | G37: 2050 | H37: EU-North | I37: =[15]Outputs!$C$21*((1+Inputs!$C$5)^($G$9-Inputs!$C$4)) -> 832.71053 | J37: =[15]Outputs!$D$21*((1+Inputs!$C$5)^($G$9-Inputs!$C$4)) -> 712.36778 | K37: =[15]Outputs!$E$21*((1+Inputs!$C$5)^($G$9-Inputs!$C$4)) -> 795.36025 | L37: =[15]Outputs!$F$21*((1+Inputs!$C$5)^($G$9-Inputs!$C$4)) -> 719.69502 | M37: ='[15]Cost Breakdown'!$B$22 -> 0.45315744 | N37: ='[15]Cost Breakdown'!$B$21 -> 0.31792431 | O37: ='[15]Cost Breakdown'!$B$23 -> 0.188823 | P37: ='[15]Cost Breakdown'!$B$24 -> 0.04009525 | Q37: Industrial | R37: Europe | S37: 1000000
A38: Schmidt et. al. | B38: y | C38: 2024 | D38: https://onlinelibrary.wiley.com/doi/full/10.1002/cite.201700129?saml_referrer https://www.concawe.eu/wp-content/uploads/Rpt_24-4-1.pdf | E38: e-Fuels | F38: Fischer Tropsch | G38: 2050 | H38: EU-Central | I38: =[15]Outputs!$J$21*((1+Inputs!$C$5)^($G$10-Inputs!$C$4)) -> 1651.2877 | J38: =[15]Outputs!$K$21*((1+Inputs!$C$5)^($G$10-Inputs!$C$4)) -> 1201.2151 | K38: =[15]Outputs!$L$21*((1+Inputs!$C$5)^($G$10-Inputs!$C$4)) -> 1340.0962 | L38: =[15]Outputs!$M$21*((1+Inputs!$C$5)^($G$10-Inputs!$C$4)) -> 1212.3243 | Q38: Industrial | R38: Europe | S38: 1000000
A39: Schmidt et. al. | B39: y | C39: 2024 | D39: https://onlinelibrary.wiley.com/doi/full/10.1002/cite.201700129?saml_referrer https://www.concawe.eu/wp-content/uploads/Rpt_24-4-1.pdf | E39: e-Fuels | F39: Fischer Tropsch | G39: 2050 | H39: EU-South | I39: =[15]Outputs!$Q$21*((1+Inputs!$C$5)^($G$9-Inputs!$C$4)) -> 832.16394 | J39: =[15]Outputs!$R$21*((1+Inputs!$C$5)^($G$9-Inputs!$C$4)) -> 711.82119 | K39: =[15]Outputs!$S$21*((1+Inputs!$C$5)^($G$9-Inputs!$C$4)) -> 794.81366 | L39: =[15]Outputs!$T$21*((1+Inputs!$C$5)^($G$9-Inputs!$C$4)) -> 719.3307 | Q39: Industrial | R39: Europe | S39: 1000000
A40: Schmidt et. al. | C40: 2024 | D40: https://onlinelibrary.wiley.com/doi/full/10.1002/cite.201700129?saml_referrer https://www.concawe.eu/wp-content/uploads/Rpt_24-4-1.pdf | E40: e-Fuels | F40: Fischer Tropsch | G40: 2024 | H40: EU-Central | I40: =[15]Outputs!$J$10*((1+Inputs!$C$5)^(G40-C40)) -> 1309.1064 | J40: =[15]Outputs!$K$10*((1+Inputs!$C$5)^(G40-C40)) -> 1104.4865 | K40: =[15]Outputs!$L$10*((1+Inputs!$C$5)^(G40-C40)) -> 1387.9542 | L40: =[15]Outputs!$M$10*((1+Inputs!$C$5)^(G40-C40)) -> 1287.5803 | Q40: Industrial | R40: Europe | S40: 1000000
...

Sheet Study Parameters
I1: Costs | M1: Input Values
A2: Reference | B2: Included? | C2: Year | D2: DOI | E2: Pathway | F2: Pathway Detail | G2: Timeline | H2: Learning Rates | I2: Cost Type | J2: Cost Range Short Term | K2: Cost Range 2050 | L2: Unit | M2: WACC / Discount Rate | N2: Electricity Price Range (EUR/MWh) | O2: Electricty Price Source | P2: Battery Storage | Q2: H2/H2O Source | R2: co-SOEC route? | S2: Electrolyser Cost Range (EUR/kW) | T2: H2 Price (EUR/kg) | U2: H2 Price Source | V2: H2 Storage | W2: CO2 Price Range ($/tCO2) | X2: CO2 Price Source | Y2: CO2 Storage | Z2: CO2 consumption (kg/kg fuel) | AA2: Fuel Emissions Intensity (gCO2/MJ) | AB2: Fossil Fuel Price (EUR/l) | AC2: Annual Production | AD2: Unit | AE2: Project Lifetime (Years) | AF2: LCA Methdology | AG2: Notes | AH2: Harmonization Status
A3: Seymour et al. | B3: Yes | C3: 2024 | D3: https://doi.org/10.1039/D3SE00978E | E3: e-Fuels | F3: Fischer Tropsch | G3: 2020-2050 | H3: Yes | I3: Abatement Cost | J3: 1500-1550 | K3: 450-890 | L3: EUR/tCO2 | M3: 0.05 | N3: 20-130 | O3: Eurostat Harmonised Indices of Consumer Prices, HICP | P3: Yes | Q3: PEM, Solid Oxide | R3: No | S3: 358-1084 | T3: - | U3: IEA G20 Hydrogen Report: Assumptions , International energy agency technical report, 2019 | V3: Yes | W3: 199-730 | X3: Fasihi et. al. (2019) (https://www.sciencedirect.com/science/article/pii/S0959652619307772?via%3Dihub) | Y3: Yes | Z3: 3.6 | AA3: 11 | AB3: 0.81 | AC3: 1018750 | AD3: litres | AE3: 30 | AF3: PSI, R.Sacchi | AH3: Fully Completed
A4: Meurer et al. | B4: Yes | C4: 2024 | D4: https://doi.org/10.1039/D3SE01156A | E4: e-Fuels | F4: Fischer Tropsch | G4: 2024-2050 | H4: Yes | I4: Production Cost | J4: 3.2-6.15 | K4: 1.5-2.75 | L4: EUR/l | M4: 0.15 | N4: 50-100 | O4: No Source, assumed | Q4: Solid Oxide | R4: Yes | S4: - | T4: - | U4: T. Smolinka , N. Wiebe , P. Sterchele and A. Palzer , Studie IndWEDe: Industrialisierung der Wasserelektrolyse in Deutschland: Chancen und Herausforderungen für nachhaltigen Wasserstoff für Verkehr, Strom und Wärme , NOW GmbH, 2018 | W4: 54-268 | X4: Fasihi et. al. (2019) (https://www.sciencedirect.com/science/article/pii/S0959652619307772?via%3Dihub) | AA4: - | AB4: - | AC4: 10000 | AD4: litres | AE4: 20 | AF4: GWP (24 parameters) | AH4: Meeting set for 11.07
A5: Martin et. al. | B5: Yes | C5: 2023 | D5: https://doi.org/10.1016/j.rser.2023.113637 | E5: e-Fuels | F5: Fischer Tropsch | G5: 2023-2050 | H5: Yes | I5: Levelised Cost | J5: 3.2-4.6 | K5: 1.1-1.4 | L5: EUR/l | M5: 0.06 | N5: 27.5-31 | O5: Fraunhofer (https://publica.fraunhofer.de/entities/publication/306f4a97-e39e-4570-887d-e4ba8ccd6605/details) | Q5: PEM | R5: No | S5: 330-1100 | T5: - | U5: T. Smolinka , N. Wiebe , P. Sterchele and A. Palzer , Studie IndWEDe: Industrialisierung der Wasserelektrolyse in Deutschland: Chancen und Herausforderungen für nachhaltigen Wasserstoff für Verkehr, Strom und Wärme , NOW GmbH, 2018 | W5: 90-600 | X5: Fasihi et. al. (2019) (https://www.sciencedirect.com/science/article/pii/S0959652619307772?via%3Dihub) | Z5: Not available | AA5: - | AB5: 0.28-0.52 | AC5: - | AE5: 25 | AH5: Fully Completed
A6: Schmidt et. al. | B6: Yes | C6: 2024 | D6: https://www.concawe.eu/wp-content/uploads/Rpt_24-4-1.pdf | E6: e-Fuels | F6: Fischer Tropsch | G6: 2018-2050 | H6: No | I6: Production Cost | J6: 3.1-4.2 | K6: 1.35-1.84 | L6: EUR/l | M6: 0.04 | N6: 66-100 | O6: No Source, assumed | P6: Yes | Q6: Alkaline, PEM | R6: No | S6: 600-1400 | T6: - | U6: https://www.osti.gov/biblio/1214980/ https://www.clean-hydrogen.europa.eu/system/files/2014-09/study%2520electrolyser_0-Logos_0_0.pdf | W6: Ground Up DAC modelling | X6: Climeworks plant, Hinwil, 2017 | AA6: 20 | AB6: - | AC6: - | AE6: - | AH6: Fully Completed
A7: Falter et. al. | B7: Yes | C7: 2015 | D7: https://doi.org/10.1021/acs.est.5b03515 | E7: Solar Fuels | F7: Fischer Tropsch | G7: 2015 | H7: No | I7: Production Cost | J7: 1.28-2.43 | K7: - | L7: EUR/l | M7: 0.06 | N7: 60 | O7: Assumed | P7: No | Q7: Desalination | R7: No | S7: Not Applicable | T7: - | U7: Not Applicable | V7: No | W7: 100 | X7: Assumed | Y7: No | Z7: 6 | AA7: 15 | AB7: - | AC7: 58035000 | AD7: litres | AE7: 25 | AH7: Fully Completed
A8: Staples et. al. | B8: Yes | C8: 2021 | D8: https://doi.org/10.1021/acs.est.0c07674 | E8: e-Fuels | F8: Fischer Tropsch | G8: 2021-2050 | H8: Yes | I8: Production Cost | J8: 2.66-3.11 | K8: 1.82-2.45 | L8: EUR/l | M8: 0.06 | N8: 45-55 | O8: https://www.eia.gov/outlooks/archive/aeo19/ | Q8: PEM, Solid Oxide | R8: No | S8: 920 | T8: - | U8: Albrecht 2020 (https://www.sciencedirect.com/science/article/pii/S0016236116312248?via%3Dihub) | W8: 94-232 | X8: Keith et al. (2018) https://www.cell.com/joule/fulltext/S2542-4351(18)30225-3?_returnURL=https%3A%2F%2Flinkinghub.elsevier.com%2Fretrieve%2Fpii%2FS2542435118302253%3Fshowall%3Dtrue | AA8: 27 | AB8: - | AC8: 58035000 | AD8: litres | AE8: 20 | AF8: GWP, excludes material flows | AH8: Partially Completed, CO2 missing
A9: Moretti et al. | B9: Yes | C9: 2023 | D9: https://doi.org/10.1016/j.scitotenv.2023.166005 | E9: Solar Fuels | F9: Fischer Tropsch | G9: 2023-2050 | H9: Yes | I9: Production Cost | J9: 2.5-3.2 | K9: 0.7-1.62 | L9: EUR/l | M9: 0.065 | N9: 50 | O9: Assumed | P9: No | Q9: Water | R9: No | S9: Not Applicable | T9: - | U9: Not Applicable | W9: 100-730 | X9: Sinha 2019 https://aiche.onlinelibrary.wiley.com/doi/10.1002/aic.16607 Climeworks, 2017 | Z9: 3 | AA9: 17.6 | AB9: - | AC9: 60000 | AD9: litres | AE9: 25 | AF9: Well-to-Wake assessment | AH9: Fully Completed
