Workbook

Sheet Intro
A1: This is a sheet for standardisation of inputs for the Meta Analysis of Net Removed Cost from Direct Air Capture Transport and Storage

Sheet Steps

Sheet Inputs
A1: Scenario Selected | B1: Reference Oil Price | C1: Electricity and CO2 Price | D1: Reference
A2: Parameter | B2: Year | C2: Value | D2: Unit
A3: Standard Values
A4: Current Year | C4: 2024
A5: Inflation | C5: =Inflation!C22 / 100 -> 0.024532829
A6: WACC | C6: 0.07
A7: USD to EUR | C7: =1/AVERAGE(USD_EUR!B11:B211) -> 0.8187011
A8: Electricity
A9: LCOE | B9: 2024 | C9: {=_xlfn.IFS($D$1 = "Low Electricity and CO2", 'Energy_Carbon intensity'!F30, $D$1 = "Reference",'Standard Input Calculations'!E13, $D$1="High Electricity and CO2",'Energy_Carbon intensity'!F34)} -> 64 | D9: $/MWh | E9: (these are not Sievert et al. Values - where do they come from?)
A10: LCOE | B10: 2050 | C10: 11 | D10: $/MWh | E10: Vary this for electricity price scenarios
A11: LCOH waste heat/combined heat and power | B11: 2024 | C11: 14.47 | D11: $/GJ | E11: See Standardization "Carbon intensity" tab
A12: LCOH waste heat/combined heat and power | B12: 2050 | C12: 10 | D12: $/GJ | E12: See Standardization "Carbon intensity" tab
A13: LCOH waste heat/combined heat and power | B13: 2024 | C13: =C11*$C$29 -> 52.092 | D13: $/MWh
A14: LCOH waste heat/combined heat and power | B14: 2050 | C14: =C12*$C$29 -> 36 | D14: $/MWh
A15: LCOH natural gas | B15: 2024 | C15: 5.49 | D15: $/GJ | E15: See Standardization "Carbon intensity" tab
A16: LCOH natural gas | B16: 2050 | C16: 5.8 | D16: $/GJ | E16: See Standardization "Carbon intensity" tab
A17: LCOH natural gas | B17: 2024 | C17: =C15*C29 -> 19.764 | D17: $/MWh
A18: LCOH natural gas | B18: 2050 | C18: =C16*C29 -> 20.88 | D18: $/MWh
A19: Carbon intensity NG | C19: 0.0176 | D19: tCO2/GJ | E19: See Standardization "Carbon intensity" tab
A20: Carbon intensity electricity (solar PV w/ tracking | C20: 0.0153 | D20: tCO2/GJ | E20: See Standardization "Carbon intensity" tab
A21: Carbon intensity waste heat | C21: =8.43333333333333/1000 -> 0.0084333333 | D21: tCO2/GJ | E21: See Standardization "Carbon intensity" tab
A22: CO2 Transport
A23: CO2 Transport Cost | B23: 2024 | C23: 25 | D23: $/tCO2 | E23: Dummy value for now
A24: CO2 Transport Cost | B24: 2050 | C24: 15 | D24: $/tCO2 | E24: Dummy value for now
A25: CO2 Storage
A26: CO2 Storage Cost | B26: 2024 | C26: 15 | D26: $/tCO2 | E26: Dummy value for now
A27: CO2 Storage Cost | B27: 2050 | C27: 10 | D27: $/tCO2 | E27: Dummy value for now
A29: 1 MWh = 3.6 GJ | C29: 3.6 | E29: conversion factor

Sheet Energy_Carbon intensity
A1: Technology | B1: Scenario | C1: Period raw | D1: 2022 | E1: 2023 | F1: 2024 | G1: 2025 | H1: 2026 | I1: 2027 | J1: 2028 | K1: 2029 | L1: 2030 | M1: 2031 | N1: 2032 | O1: 2033 | P1: 2034 | Q1: 2035 | R1: 2036 | S1: 2037 | T1: 2038 | U1: 2039 | V1: 2040 | W1: 2041 | X1: 2042 | Y1: 2043 | Z1: 2044 | AA1: 2045 | AB1: 2046 | AC1: 2047 | AD1: 2048 | AE1: 2049 | AF1: 2050 | AG1: Source | AH1: Note | AI1: Link | AJ1: carbon_intensity | AK1: unit | AL1: Source
A2: PV tracking with storage | B2: LCOE $/MWh (avg) | C2: 2022 2H | D2: 111 | E2: 97 | F2: 84 | G2: 75 | H2: 68 | I2: 62 | J2: 58 | K2: 55 | L2: 53 | M2: 50 | N2: 48 | O2: 47 | P2: 45 | Q2: 44 | R2: 43 | S2: 43 | T2: 42 | U2: 41 | V2: 41 | W2: 41 | X2: 40 | Y2: 41 | Z2: 40 | AA2: 40 | AB2: 40 | AC2: 39 | AD2: 40 | AE2: 39 | AF2: 39 | AG2: BNEF LCOE - All Technologies - Unites States - LCOE Forecast 2022 | AH2: To be converted in $/GJ with conversion factor in Universal Inputs "conversion_electricity" OR just | AI2: https://www.bnef.com/flagships/lcoe | AJ2: =15.3/1000 -> 0.0153 | AK2: [t-CO2,eq GJ-1] | AL2: Young et al. (2023)
A3: CCGT | B3: LCOE $/GJ (low) | C3: 2022 2H | D3: 47 | E3: 48 | F3: 48 | G3: 48 | H3: 49 | I3: 49 | J3: 50 | K3: 51 | L3: 51 | M3: 52 | N3: 52 | O3: 53 | P3: 53 | Q3: 54 | R3: 54 | S3: 54 | T3: 55 | U3: 55 | V3: 56 | W3: 56 | X3: 56 | Y3: 56 | Z3: 57 | AA3: 57 | AB3: 57 | AC3: 57 | AD3: 57 | AE3: 57 | AF3: 57 | AG3: BNEF LCOE - All Technologies - Unites States - LCOE Forecast 2022 | AH3: To be converted in $/GJ with conversion factor in Universal Inputs "conversion_electricity" OR just | AI3: https://www.bnef.com/flagships/lcoe
A4: CCGT CCS | B4: LCOE $/MWh (low) | C4: 2022 2H | D4: 151 | E4: 141 | F4: 132 | G4: 121 | H4: 112 | I4: 102 | J4: 92 | K4: 82 | L4: 72 | M4: 73 | N4: 74 | O4: 74 | P4: 75 | Q4: 75 | R4: 76 | S4: 76 | T4: 77 | U4: 77 | V4: 77 | W4: 78 | X4: 78 | Y4: 79 | Z4: 79 | AA4: 79 | AB4: 79 | AC4: 79 | AD4: 79 | AE4: 79 | AF4: 79 | AG4: BNEF LCOE - All Technologies - Unites States - LCOE Forecast 2022 | AH4: To be converted in $/GJ with conversion factor in Universal Inputs "conversion_electricity" OR just | AI4: https://www.bnef.com/flagships/lcoe
A5: CCGT Hydrogen | B5: LCOE $/MWh (low) | C5: 2022 2H | D5: 152 | E5: 141 | F5: 130 | G5: 120 | H5: 112 | I5: 104 | J5: 98 | K5: 93 | L5: 89 | M5: 86 | N5: 83 | O5: 81 | P5: 78 | Q5: 76 | R5: 74 | S5: 72 | T5: 71 | U5: 70 | V5: 69 | W5: 68 | X5: 68 | Y5: 67 | Z5: 67 | AA5: 66 | AB5: 66 | AC5: 65 | AD5: 65 | AE5: 65 | AF5: 65 | AG5: BNEF LCOE - All Technologies - Unites States - LCOE Forecast 2022 | AH5: To be converted in $/GJ with conversion factor in Universal Inputs "conversion_electricity" OR just | AI5: https://www.bnef.com/flagships/lcoe
A6: Coal | B6: LCOE $/MWh (low) | C6: 2022 2H | D6: 68 | E6: 68 | F6: 68 | G6: 68 | H6: 68 | I6: 69 | J6: 70 | K6: 70 | L6: 71 | M6: 71 | N6: 72 | O6: 72 | P6: 73 | Q6: 73 | R6: 74 | S6: 74 | T6: 74 | U6: 75 | V6: 75 | W6: 76 | X6: 76 | Y6: 76 | Z6: 76 | AA6: 76 | AB6: 76 | AC6: 76 | AD6: 76 | AE6: 76 | AF6: 76 | AG6: BNEF LCOE - All Technologies - Unites States - LCOE Forecast 2022 | AH6: To be converted in $/GJ with conversion factor in Universal Inputs "conversion_electricity" OR just | AI6: https://www.bnef.com/flagships/lcoe
A7: Coal CCS | B7: LCOE $/MWh (low) | C7: 2022 2H | D7: 259 | E7: 246 | F7: 231 | G7: 212 | H7: 194 | I7: 175 | J7: 154 | K7: 133 | L7: 112 | M7: 113 | N7: 114 | O7: 115 | P7: 115 | Q7: 116 | R7: 117 | S7: 117 | T7: 118 | U7: 119 | V7: 119 | W7: 120 | X7: 120 | Y7: 120 | Z7: 120 | AA7: 120 | AB7: 120 | AC7: 120 | AD7: 120 | AE7: 120 | AF7: 120 | AG7: BNEF LCOE - All Technologies - Unites States - LCOE Forecast 2022 | AH7: To be converted in $/GJ with conversion factor in Universal Inputs "conversion_electricity" OR just | AI7: https://www.bnef.com/flagships/lcoe
A8: OCGT | B8: LCOE $/MWh (low) | C8: 2022 2H | D8: 96 | E8: 98 | F8: 99 | G8: 101 | H8: 102 | I8: 103 | J8: 104 | K8: 105 | L8: 106 | M8: 107 | N8: 108 | O8: 109 | P8: 109 | Q8: 110 | R8: 111 | S8: 112 | T8: 112 | U8: 113 | V8: 114 | W8: 114 | X8: 114 | Y8: 115 | Z8: 115 | AA8: 115 | AB8: 116 | AC8: 116 | AD8: 116 | AE8: 116 | AF8: 116 | AG8: BNEF LCOE - All Technologies - Unites States - LCOE Forecast 2022 | AH8: To be converted in $/GJ with conversion factor in Universal Inputs "conversion_electricity" OR just | AI8: https://www.bnef.com/flagships/lcoe
A9: OCGT CCS | B9: LCOE $/MWh (low) | C9: 2022 2H | D9: 455 | E9: 432 | F9: 401 | G9: 366 | H9: 330 | I9: 293 | J9: 255 | K9: 216 | L9: 176 | M9: 178 | N9: 179 | O9: 180 | P9: 181 | Q9: 182 | R9: 183 | S9: 184 | T9: 185 | U9: 186 | V9: 187 | W9: 188 | X9: 188 | Y9: 189 | Z9: 189 | AA9: 189 | AB9: 189 | AC9: 190 | AD9: 190 | AE9: 190 | AF9: 190 | AG9: BNEF LCOE - All Technologies - Unites States - LCOE Forecast 2022 | AH9: To be converted in $/GJ with conversion factor in Universal Inputs "conversion_electricity" OR just | AI9: https://www.bnef.com/flagships/lcoe
A10: OCGT Hydrogen | B10: LCOE $/MWh (low) | C10: 2022 2H | D10: 235 | E10: 224 | F10: 213 | G10: 202 | H10: 192 | I10: 184 | J10: 176 | K10: 170 | L10: 166 | M10: 161 | N10: 158 | O10: 154 | P10: 150 | Q10: 146 | R10: 142 | S10: 139 | T10: 137 | U10: 136 | V10: 134 | W10: 134 | X10: 133 | Y10: 132 | Z10: 131 | AA10: 131 | AB10: 130 | AC10: 130 | AD10: 130 | AE10: 129 | AF10: 129 | AG10: BNEF LCOE - All Technologies - Unites States - LCOE Forecast 2022 | AH10: To be converted in $/GJ with conversion factor in Universal Inputs "conversion_electricity" OR just | AI10: https://www.bnef.com/flagships/lcoe
A11: PV non-tracking | B11: LCOE $/MWh (low) | C11: 2022 2H | D11: 39 | E11: 35 | F11: 33 | G11: 29 | H11: 28 | I11: 27 | J11: 27 | K11: 25 | L11: 23 | M11: 21 | N11: 19 | O11: 19 | P11: 18 | Q11: 18 | R11: 17 | S11: 17 | T11: 16 | U11: 16 | V11: 16 | W11: 15 | X11: 15 | Y11: 15 | Z11: 14 | AA11: 14 | AB11: 14 | AC11: 14 | AD11: 13 | AE11: 13 | AF11: 13 | AG11: BNEF LCOE - All Technologies - Unites States - LCOE Forecast 2022 | AH11: To be converted in $/GJ with conversion factor in Universal Inputs "conversion_electricity" OR just | AI11: https://www.bnef.com/flagships/lcoe
A12: PV non-tracking with storage | B12: LCOE $/MWh (low) | C12: 2022 2H | D12: 58 | E12: 51 | F12: 47 | G12: 42 | H12: 40 | I12: 37 | J12: 36 | K12: 33 | L12: 31 | M12: 29 | N12: 27 | O12: 26 | P12: 26 | Q12: 25 | R12: 25 | S12: 24 | T12: 24 | U12: 23 | V12: 23 | W12: 22 | X12: 22 | Y12: 22 | Z12: 22 | AA12: 21 | AB12: 21 | AC12: 21 | AD12: 21 | AE12: 20 | AF12: 20 | AG12: BNEF LCOE - All Technologies - Unites States - LCOE Forecast 2022 | AH12: To be converted in $/GJ with conversion factor in Universal Inputs "conversion_electricity" OR just | AI12: https://www.bnef.com/flagships/lcoe
A13: PV tracking | B13: LCOE $/MWh (low) | C13: 2022 2H | D13: 34 | E13: 31 | F13: 28 | G13: 25 | H13: 25 | I13: 24 | J13: 23 | K13: 21 | L13: 20 | M13: 18 | N13: 17 | O13: 16 | P13: 16 | Q13: 15 | R13: 15 | S13: 15 | T13: 14 | U13: 14 | V13: 13 | W13: 13 | X13: 13 | Y13: 13 | Z13: 12 | AA13: 12 | AB13: 12 | AC13: 12 | AD13: 12 | AE13: 11 | AF13: 11 | AG13: BNEF LCOE - All Technologies - Unites States - LCOE Forecast 2022 | AH13: To be converted in $/GJ with conversion factor in Universal Inputs "conversion_electricity" OR just | AI13: https://www.bnef.com/flagships/lcoe
A14: PV tracking with storage | B14: LCOE $/MWh (low) | C14: 2022 2H | D14: 38.62069 | E14: 44 | F14: 40 | G14: 35 | H14: 34 | I14: 32 | J14: 30 | K14: 28 | L14: 26 | M14: 25 | N14: 23 | O14: 22 | P14: 22 | Q14: 21 | R14: 21 | S14: 20 | T14: 20 | U14: 20 | V14: 19 | W14: 19 | X14: 19 | Y14: 18 | Z14: 18 | AA14: 18 | AB14: 18 | AC14: 18 | AD14: 17 | AE14: 17 | AF14: 17 | AG14: BNEF LCOE - All Technologies - Unites States - LCOE Forecast 2022 | AH14: To be converted in $/GJ with conversion factor in Universal Inputs "conversion_electricity" OR just | AI14: https://www.bnef.com/flagships/lcoe | AJ14: =15.3/1000 -> 0.0153 | AK14: [t-CO2,eq GJ-1] | AL14: Young et al. (2023)
A15: Utility-scale battery (1h) | B15: LCOE $/MWh (low) | C15: 2022 2H | D15: 160 | E15: 136 | F15: 119 | G15: 106 | H15: 96 | I15: 88 | J15: 81 | K15: 78 | L15: 75 | M15: 71 | N15: 67 | O15: 65 | P15: 63 | Q15: 59 | R15: 58 | S15: 57 | T15: 56 | U15: 55 | V15: 54 | W15: 54 | X15: 54 | Y15: 54 | Z15: 54 | AA15: 54 | AB15: 54 | AC15: 54 | AD15: 54 | AE15: 54 | AF15: 54 | AG15: BNEF LCOE - All Technologies - Unites States - LCOE Forecast 2022 | AH15: To be converted in $/GJ with conversion factor in Universal Inputs "conversion_electricity" OR just | AI15: https://www.bnef.com/flagships/lcoe
A16: Utility-scale battery (4h) | B16: LCOE $/MWh (low) | C16: 2022 2H | D16: 123 | E16: 99 | F16: 83 | G16: 72 | H16: 63 | I16: 56 | J16: 50 | K16: 47 | L16: 45 | M16: 43 | N16: 41 | O16: 39 | P16: 38 | Q16: 36 | R16: 36 | S16: 35 | T16: 35 | U16: 34 | V16: 34 | W16: 34 | X16: 34 | Y16: 34 | Z16: 34 | AA16: 34 | AB16: 34 | AC16: 34 | AD16: 34 | AE16: 34 | AF16: 34 | AG16: BNEF LCOE - All Technologies - Unites States - LCOE Forecast 2022 | AH16: To be converted in $/GJ with conversion factor in Universal Inputs "conversion_electricity" OR just | AI16: https://www.bnef.com/flagships/lcoe
A17: Wind offshore | B17: LCOE $/MWh (low) | C17: 2022 2H | D17: 116 | E17: 107 | F17: 102 | G17: 97 | H17: 94 | I17: 91 | J17: 88 | K17: 86 | L17: 54 | M17: 53 | N17: 52 | O17: 51 | P17: 50 | Q17: 49 | R17: 48 | S17: 47 | T17: 46 | U17: 45 | V17: 44 | W17: 44 | X17: 43 | Y17: 43 | Z17: 42 | AA17: 42 | AB17: 41 | AC17: 40 | AD17: 40 | AE17: 40 | AF17: 40 | AG17: BNEF LCOE - All Technologies - Unites States - LCOE Forecast 2022 | AH17: To be converted in $/GJ with conversion factor in Universal Inputs "conversion_electricity" OR just | AI17: https://www.bnef.com/flagships/lcoe
A18: Wind onshore | B18: LCOE $/MWh (low) | C18: 2022 2H | D18: 33 | E18: 31 | F18: 29 | G18: 28 | H18: 27 | I18: 26 | J18: 25 | K18: 25 | L18: 24 | M18: 24 | N18: 23 | O18: 23 | P18: 22 | Q18: 22 | R18: 22 | S18: 21 | T18: 21 | U18: 21 | V18: 21 | W18: 20 | X18: 20 | Y18: 20 | Z18: 20 | AA18: 20 | AB18: 19 | AC18: 19 | AD18: 19 | AE18: 19 | AF18: 19 | AG18: BNEF LCOE - All Technologies - Unites States - LCOE Forecast 2022 | AH18: To be converted in $/GJ with conversion factor in Universal Inputs "conversion_electricity" OR just | AI18: https://www.bnef.com/flagships/lcoe
A19: Wind onshore with storage | B19: LCOE $/MWh (low) | C19: 2022 2H | D19: 49 | E19: 45 | F19: 42 | G19: 39 | H19: 37 | I19: 36 | J19: 35 | K19: 34 | L19: 33 | M19: 32 | N19: 31 | O19: 31 | P19: 30 | Q19: 30 | R19: 29 | S19: 29 | T19: 29 | U19: 28 | V19: 28 | W19: 28 | X19: 27 | Y19: 27 | Z19: 27 | AA19: 27 | AB19: 26 | AC19: 26 | AD19: 26 | AE19: 26 | AF19: 26 | AG19: BNEF LCOE - All Technologies - Unites States - LCOE Forecast 2022 | AH19: To be converted in $/GJ with conversion factor in Universal Inputs "conversion_electricity" OR just | AI19: https://www.bnef.com/flagships/lcoe | AJ19: =5.9/1000 -> 0.0059 | AK19: [t-CO2,eq GJ-1] | AL19: Young et al. (2023)
A20: CCGT | B20: LCOE $/MWh (high) | C20: 2022 2H | D20: 93 | E20: 91 | F20: 91 | G20: 90 | H20: 90 | I20: 91 | J20: 91 | K20: 92 | L20: 92 | M20: 93 | N20: 93 | O20: 94 | P20: 94 | Q20: 94 | R20: 95 | S20: 95 | T20: 95 | U20: 96 | V20: 96 | W20: 96 | X20: 96 | Y20: 97 | Z20: 97 | AA20: 97 | AB20: 97 | AC20: 97 | AD20: 97 | AE20: 97 | AF20: 97 | AG20: BNEF LCOE - All Technologies - Unites States - LCOE Forecast 2022 | AH20: To be converted in $/GJ with conversion factor in Universal Inputs "conversion_electricity" OR just | AI20: https://www.bnef.com/flagships/lcoe
A21: CCGT CCS | B21: LCOE $/MWh (high) | C21: 2022 2H | D21: 479 | E21: 435 | F21: 395 | G21: 351 | H21: 312 | I21: 274 | J21: 235 | K21: 196 | L21: 158 | M21: 158 | N21: 159 | O21: 159 | P21: 160 | Q21: 160 | R21: 161 | S21: 161 | T21: 161 | U21: 162 | V21: 162 | W21: 162 | X21: 162 | Y21: 163 | Z21: 163 | AA21: 163 | AB21: 163 | AC21: 163 | AD21: 163 | AE21: 163 | AF21: 163 | AG21: BNEF LCOE - All Technologies - Unites States - LCOE Forecast 2022 | AH21: To be converted in $/GJ with conversion factor in Universal Inputs "conversion_electricity" OR just | AI21: https://www.bnef.com/flagships/lcoe
A22: CCGT Hydrogen | B22: LCOE $/MWh (high) | C22: 2022 2H | D22: 214 | E22: 195 | F22: 181 | G22: 168 | H22: 160 | I22: 153 | J22: 147 | K22: 143 | L22: 139 | M22: 136 | N22: 133 | O22: 129 | P22: 126 | Q22: 122 | R22: 119 | S22: 117 | T22: 115 | U22: 113 | V22: 112 | W22: 111 | X22: 111 | Y22: 110 | Z22: 110 | AA22: 109 | AB22: 109 | AC22: 108 | AD22: 108 | AE22: 108 | AF22: 108 | AG22: BNEF LCOE - All Technologies - Unites States - LCOE Forecast 2022 | AH22: To be converted in $/GJ with conversion factor in Universal Inputs "conversion_electricity" OR just | AI22: https://www.bnef.com/flagships/lcoe
A23: Coal | B23: LCOE $/MWh (high) | C23: 2022 2H | D23: 158 | E23: 161 | F23: 164 | G23: 164 | H23: 167 | I23: 170 | J23: 172 | K23: 174 | L23: 176 | M23: 178 | N23: 180 | O23: 182 | P23: 183 | Q23: 185 | R23: 186 | S23: 188 | T23: 189 | U23: 190 | V23: 191 | W23: 192 | X23: 192 | Y23: 192 | Z23: 192 | AA23: 192 | AB23: 192 | AC23: 192 | AD23: 192 | AE23: 192 | AF23: 192 | AG23: BNEF LCOE - All Technologies - Unites States - LCOE Forecast 2022 | AH23: To be converted in $/GJ with conversion factor in Universal Inputs "conversion_electricity" OR just | AI23: https://www.bnef.com/flagships/lcoe
A24: Coal CCS | B24: LCOE $/MWh (high) | C24: 2022 2H | D24: 730 | E24: 699 | F24: 659 | G24: 600 | H24: 546 | I24: 488 | J24: 426 | K24: 361 | L24: 293 | M24: 297 | N24: 300 | O24: 303 | P24: 305 | Q24: 308 | R24: 310 | S24: 313 | T24: 315 | U24: 317 | V24: 319 | W24: 321 | X24: 321 | Y24: 321 | Z24: 321 | AA24: 321 | AB24: 321 | AC24: 321 | AD24: 321 | AE24: 321 | AF24: 321 | AG24: BNEF LCOE - All Technologies - Unites States - LCOE Forecast 2022 | AH24: To be converted in $/GJ with conversion factor in Universal Inputs "conversion_electricity" OR just | AI24: https://www.bnef.com/flagships/lcoe
A25: OCGT | B25: LCOE $/MWh (high) | C25: 2022 2H | D25: 223 | E25: 224 | F25: 225 | G25: 226 | H25: 227 | I25: 229 | J25: 230 | K25: 232 | L25: 233 | M25: 235 | N25: 236 | O25: 237 | P25: 238 | Q25: 239 | R25: 241 | S25: 242 | T25: 243 | U25: 244 | V25: 244 | W25: 245 | X25: 246 | Y25: 247 | Z25: 247 | AA25: 248 | AB25: 248 | AC25: 249 | AD25: 249 | AE25: 249 | AF25: 249 | AG25: BNEF LCOE - All Technologies - Unites States - LCOE Forecast 2022 | AH25: To be converted in $/GJ with conversion factor in Universal Inputs "conversion_electricity" OR just | AI25: https://www.bnef.com/flagships/lcoe
A26: OCGT CCS | B26: LCOE $/MWh (high) | C26: 2022 2H | D26: 1,148 | E26: 1,059 | F26: 964 | G26: 868 | H26: 772 | I26: 678 | J26: 584 | K26: 489 | L26: 395 | M26: 396 | N26: 398 | O26: 399 | P26: 401 | Q26: 402 | R26: 403 | S26: 404 | T26: 405 | U26: 407 | V26: 408 | W26: 409 | X26: 409 | Y26: 410 | Z26: 411 | AA26: 411 | AB26: 412 | AC26: 412 | AD26: 412 | AE26: 412 | AF26: 412 | AG26: BNEF LCOE - All Technologies - Unites States - LCOE Forecast 2022 | AH26: To be converted in $/GJ with conversion factor in Universal Inputs "conversion_electricity" OR just | AI26: https://www.bnef.com/flagships/lcoe
A27: OCGT Hydrogen | B27: LCOE $/MWh (high) | C27: 2022 2H | D27: 540 | E27: 506 | F27: 475 | G27: 447 | H27: 423 | I27: 403 | J27: 385 | K27: 371 | L27: 360 | M27: 350 | N27: 341 | O27: 332 | P27: 323 | Q27: 314 | R27: 306 | S27: 299 | T27: 295 | U27: 291 | V27: 288 | W27: 286 | X27: 284 | Y27: 283 | Z27: 281 | AA27: 280 | AB27: 279 | AC27: 278 | AD27: 278 | AE27: 277 | AF27: 277 | AG27: BNEF LCOE - All Technologies - Unites States - LCOE Forecast 2022 | AH27: To be converted in $/GJ with conversion factor in Universal Inputs "conversion_electricity" OR just | AI27: https://www.bnef.com/flagships/lcoe
A28: PV non-tracking | B28: LCOE $/MWh (high) | C28: 2022 2H | D28: 60 | E28: 53 | F28: 50 | G28: 45 | H28: 43 | I28: 42 | J28: 40 | K28: 38 | L28: 35 | M28: 32 | N28: 29 | O28: 28 | P28: 28 | Q28: 27 | R28: 26 | S28: 26 | T28: 25 | U28: 24 | V28: 24 | W28: 23 | X28: 23 | Y28: 22 | Z28: 22 | AA28: 21 | AB28: 21 | AC28: 21 | AD28: 20 | AE28: 20 | AF28: 20 | AG28: BNEF LCOE - All Technologies - Unites States - LCOE Forecast 2022 | AH28: To be converted in $/GJ with conversion factor in Universal Inputs "conversion_electricity" OR just | AI28: https://www.bnef.com/flagships/lcoe
A29: PV non-tracking with storage | B29: LCOE $/MWh (high) | C29: 2022 2H | D29: 188 | E29: 163 | F29: 146 | G29: 129 | H29: 119 | I29: 110 | J29: 103 | K29: 98 | L29: 93 | M29: 88 | N29: 83 | O29: 81 | P29: 79 | Q29: 76 | R29: 75 | S29: 74 | T29: 73 | U29: 71 | V29: 70 | W29: 70 | X29: 69 | Y29: 69 | Z29: 68 | AA29: 68 | AB29: 67 | AC29: 67 | AD29: 67 | AE29: 66 | AF29: 66 | AG29: BNEF LCOE - All Technologies - Unites States - LCOE Forecast 2022 | AH29: To be converted in $/GJ with conversion factor in Universal Inputs "conversion_electricity" OR just | AI29: https://www.bnef.com/flagships/lcoe
A30: PV tracking | B30: LCOE $/MWh (high) | C30: 2022 2H | D30: 53 | E30: 48 | F30: 44 | G30: 40 | H30: 39 | I30: 37 | J30: 36 | K30: 33 | L30: 31 | M30: 28 | N30: 26 | O30: 25 | P30: 25 | Q30: 24 | R30: 23 | S30: 23 | T30: 22 | U30: 22 | V30: 21 | W30: 21 | X30: 20 | Y30: 20 | Z30: 19 | AA30: 19 | AB30: 19 | AC30: 18 | AD30: 18 | AE30: 18 | AF30: 18 | AG30: BNEF LCOE - All Technologies - Unites States - LCOE Forecast 2022 | AH30: To be converted in $/GJ with conversion factor in Universal Inputs "conversion_electricity" OR just | AI30: https://www.bnef.com/flagships/lcoe
A31: PV tracking with storage | B31: LCOE $/MWh (high) | C31: 2022 2H | D31: 160 | E31: 141 | F31: 124 | G31: 110 | H31: 102 | I31: 94 | J31: 88 | K31: 83 | L31: 79 | M31: 75 | N31: 71 | O31: 69 | P31: 67 | Q31: 65 | R31: 64 | S31: 63 | T31: 62 | U31: 61 | V31: 60 | W31: 60 | X31: 59 | Y31: 59 | Z31: 58 | AA31: 58 | AB31: 58 | AC31: 57 | AD31: 57 | AE31: 56 | AF31: 56 | AG31: BNEF LCOE - All Technologies - Unites States - LCOE Forecast 2022 | AH31: To be converted in $/GJ with conversion factor in Universal Inputs "conversion_electricity" OR just | AI31: https://www.bnef.com/flagships/lcoe | AJ31: =15.3/1000 -> 0.0153 | AK31: [t-CO2,eq GJ-1] | AL31: Young et al. (2023)
A32: Utility-scale battery (1h) | B32: LCOE $/MWh (high) | C32: 2022 2H | D32: 287 | E32: 241 | F32: 209 | G32: 184 | H32: 165 | I32: 151 | J32: 139 | K32: 132 | L32: 127 | M32: 119 | N32: 112 | O32: 109 | P32: 106 | Q32: 98 | R32: 96 | S32: 94 | T32: 92 | U32: 90 | V32: 88 | W32: 88 | X32: 88 | Y32: 88 | Z32: 88 | AA32: 88 | AB32: 88 | AC32: 88 | AD32: 88 | AE32: 88 | AF32: 88 | AG32: BNEF LCOE - All Technologies - Unites States - LCOE Forecast 2022 | AH32: To be converted in $/GJ with conversion factor in Universal Inputs "conversion_electricity" OR just | AI32: https://www.bnef.com/flagships/lcoe
A33: Utility-scale battery (4h) | B33: LCOE $/MWh (high) | C33: 2022 2H | D33: 206 | E33: 172 | F33: 146 | G33: 127 | H33: 112 | I33: 100 | J33: 89 | K33: 85 | L33: 81 | M33: 77 | N33: 74 | O33: 71 | P33: 69 | Q33: 66 | R33: 65 | S33: 63 | T33: 62 | U33: 61 | V33: 60 | W33: 60 | X33: 60 | Y33: 60 | Z33: 60 | AA33: 60 | AB33: 60 | AC33: 60 | AD33: 60 | AE33: 60 | AF33: 60 | AG33: BNEF LCOE - All Technologies - Unites States - LCOE Forecast 2022 | AH33: To be converted in $/GJ with conversion factor in Universal Inputs "conversion_electricity" OR just | AI33: https://www.bnef.com/flagships/lcoe
A34: Wind offshore | B34: LCOE $/MWh (high) | C34: 2022 2H | D34: 150 | E34: 137 | F34: 130 | G34: 124 | H34: 120 | I34: 116 | J34: 113 | K34: 110 | L34: 90 | M34: 88 | N34: 86 | O34: 84 | P34: 82 | Q34: 81 | R34: 79 | S34: 77 | T34: 76 | U34: 74 | V34: 73 | W34: 71 | X34: 71 | Y34: 70 | Z34: 69 | AA34: 68 | AB34: 67 | AC34: 66 | AD34: 66 | AE34: 66 | AF34: 65 | AG34: BNEF LCOE - All Technologies - Unites States - LCOE Forecast 2022 | AH34: To be converted in $/GJ with conversion factor in Universal Inputs "conversion_electricity" OR just | AI34: https://www.bnef.com/flagships/lcoe
A35: Wind onshore | B35: LCOE $/MWh (high) | C35: 2022 2H | D35: 65 | E35: 60 | F35: 55 | G35: 52 | H35: 50 | I35: 48 | J35: 46 | K35: 45 | L35: 44 | M35: 42 | N35: 41 | O35: 41 | P35: 40 | Q35: 39 | R35: 39 | S35: 38 | T35: 38 | U35: 37 | V35: 36 | W35: 36 | X35: 36 | Y35: 35 | Z35: 35 | AA35: 34 | AB35: 34 | AC35: 34 | AD35: 33 | AE35: 33 | AF35: 33 | AG35: BNEF LCOE - All Technologies - Unites States - LCOE Forecast 2022 | AH35: To be converted in $/GJ with conversion factor in Universal Inputs "conversion_electricity" OR just | AI35: https://www.bnef.com/flagships/lcoe
A36: Wind onshore with storage | B36: LCOE $/MWh (high) | C36: 2022 2H | D36: 132 | E36: 114 | F36: 99 | G36: 89 | H36: 82 | I36: 77 | J36: 72 | K36: 69 | L36: 67 | M36: 64 | N36: 62 | O36: 61 | P36: 59 | Q36: 58 | R36: 57 | S36: 56 | T36: 55 | U36: 54 | V36: 53 | W36: 53 | X36: 52 | Y36: 52 | Z36: 51 | AA36: 51 | AB36: 50 | AC36: 50 | AD36: 49 | AE36: 49 | AF36: 48 | AG36: BNEF LCOE - All Technologies - Unites States - LCOE Forecast 2022 | AH36: To be converted in $/GJ with conversion factor in Universal Inputs "conversion_electricity" OR just | AI36: https://www.bnef.com/flagships/lcoe | AJ36: =5.9/1000 -> 0.0059 | AK36: [t-CO2,eq GJ-1] | AL36: Young et al. (2023)
A37: Nuclear | B37: LCOE $/MWh (low) | C37: 2022 2H | D37: 43.9 | AI37: Nuclear Energy Agency (NEA) - Projected Costs of Generating Electricity - 2020 Edition (oecd-nea.org) | AJ37: =1.9/1000 -> 0.0019 | AK37: [t-CO2,eq GJ-1] | AL37: p.59
A38: Nuclear | B38: LCOE $/MWh (high) | C38: 2022 2H | D38: 98.56 | AI38: Nuclear Energy Agency (NEA) - Projected Costs of Generating Electricity - 2020 Edition (oecd-nea.org) | AJ38: =1.9/1000 -> 0.0019 | AL38: p.59
A39: Geothermal | B39: LCOE $/MWh (low) | C39: 2022 2H | D39: 37 | AI39: Renewable Power Generation Costs in 2021 (irena.org) | AJ39: =18.9/1000 -> 0.0189 | AK39: [t-CO2,eq GJ-1] | AL39: Young et al. (2023) | AM39: In line with icelandic LCOE | AN39: Global weighted average
A40: Geothermal | B40: LCOE $/MWh (high) | C40: 2022 2H | D40: 98.879151 | AI40: Renewable Power Generation Costs in 2021 (irena.org) | AJ40: =18.9/1000 -> 0.0189
...

Sheet Standard Input Calculations
B2: LCOE cost assumption
B4: Source: | C4: BNEF LCOE Forecast 2022
B5: Year | C5: 2022 | D5: 2023 | E5: 2024 | F5: 2025 | G5: 2026 | H5: 2027 | I5: 2028 | J5: 2029 | K5: 2030 | L5: 2031 | M5: 2032 | N5: 2033 | O5: 2034 | P5: 2035 | Q5: 2036 | R5: 2037 | S5: 2038 | T5: 2039 | U5: 2040 | V5: 2041 | W5: 2042 | X5: 2043 | Y5: 2044 | Z5: 2045 | AA5: 2046 | AB5: 2047 | AC5: 2048 | AD5: 2049 | AE5: 2050 | AF5: -
B6: LCOE ($/MWh) | C6: 79 | D6: 70 | E6: 64 | F6: 55 | G6: 52 | H6: 48 | I6: 44 | J6: 42 | K6: 38 | L6: 39 | M6: 35 | N6: 34 | O6: 34 | P6: 33 | Q6: 33 | R6: 30 | S6: 32 | T6: 32 | U6: 31 | V6: 31 | W6: 31 | X6: 28 | Y6: 30 | Z6: 30 | AA6: 30 | AB6: 30 | AC6: 27 | AD6: 29 | AE6: 29
B7: LCOE (€/MWh) | C7: 84 | D7: 75 | E7: 68 | F7: 59 | G7: 55 | H7: 51 | I7: 47 | J7: 45 | K7: 40.53 | L7: 42 | M7: 37 | N7: 36 | O7: 36 | P7: 35 | Q7: 35 | R7: 32 | S7: 34 | T7: 34 | U7: 33 | V7: 33 | W7: 33 | X7: 30 | Y7: 32 | Z7: 32 | AA7: 32 | AB7: 32 | AC7: 29 | AD7: 31 | AE7: 31
B9: Possible sensitivities
B10: PV tracking with storage (high) - 12 battery hours - high
B11: LCOE ($/MWh) | C11: 374 | D11: 327 | E11: 284 | F11: 250 | G11: 228 | H11: 208 | I11: 192 | J11: 183 | K11: 175 | L11: 169 | M11: 161 | N11: 157 | O11: 151 | P11: 147 | Q11: 146 | R11: 143 | S11: 142 | T11: 139 | U11: 138 | V11: 138 | W11: 137 | X11: 137 | Y11: 136 | Z11: 136 | AA11: 136 | AB11: 135 | AC11: 135 | AD11: 132 | AE11: 132
B12: PV tracking with storage (low) - 12 battery hours - high
B13: LCOE ($/MWh) | C13: 79 | D13: 70 | E13: 64 | F13: 55 | G13: 52 | H13: 48 | I13: 44 | J13: 42 | K13: 38 | L13: 39 | M13: 35 | N13: 34 | O13: 34 | P13: 33 | Q13: 33 | R13: 30 | S13: 32 | T13: 32 | U13: 31 | V13: 31 | W13: 31 | X13: 28 | Y13: 30 | Z13: 30 | AA13: 30 | AB13: 30 | AC13: 27 | AD13: 29 | AE13: 29
B14: Wind Offshore
B15: LCOE ($/MWh) | C15: 116 | D15: 107 | E15: 102 | F15: 97 | G15: 94 | H15: 91 | I15: 88 | J15: 86 | K15: 54 | L15: 53 | M15: 52 | N15: 51 | O15: 50 | P15: 49 | Q15: 48 | R15: 47 | S15: 46 | T15: 45 | U15: 44 | V15: 44 | W15: 43 | X15: 43 | Y15: 42 | Z15: 42 | AA15: 41 | AB15: 40 | AC15: 40 | AD15: 40 | AE15: 40
B18: Discount rate
G20: Source
B21: Discount rate | C21: 0.07 | G21: Average across all studies considered (Multiple sources)

Sheet Sensitivities
A1: Coupling of CO2 and Electricity
A2: CO2 Price | B2: Electricity Price
A3: 406 | B3: 79
A4: 358 | B4: 29
A6: Slope | B6: =(A3-A4)/(B3-B4) -> 0.96 | C6: $/t per $/kWh
A9: Electricity Price Range
B10: 2024 | C10: 2050
A11: High | B11: 116 | C11: 40 | D11: Wind Offshore
A12: Low | B12: 64 | C12: 29
A14: CO2 Price Range
B15: 2024 | C15: 2050
A16: High | B16: 1477 | C16: 362
A17: Low | B17: 1284 | C17: 246 | D17: Lower bounds of multi component experience curves

Sheet Notes for Study Parameters
A2: Parameter | B2: Note | C2: Source

Sheet Study Selection Step 1
A1: Included? | B1: Title | C1: Journal | D1: Authors | E1: Year of Publication | F1: DOI | G1: Abstract | H1: First Read | I1: Second Read | J1: Cost Type | K1: Timeline | L1: Plant size | M1: Scale | N1: DAC Technology | O1: Year of Assumptions in Study | P1: Electricity Sources | Q1: Method | R1: Frequently Referenced? | S1: Sensitive Parameters | T1: Sensitive parameters CAPEX | U1: Sensitive parameters OPEX | V1: Sensitivity Analysis | W1: Sensitivity for current or future costs | X1: Main Cost Drivers | Y1: CAPEX Driver | Z1: OPEX Driver
A2: y | B2: Young et al. 2023 | C2: One Earth | D2: John Young 1 , Noah McQueen 2 , Charithea Charalambous 1 , Spyros Foteinis 1 , Olivia Hawrot 1 , Manuel Ojeda 1 , Hélène Pilorgé 2 , John Andresen 1 , Peter Psarras 2 , Phil Renforth 1 , Susana Garcia 1 , Mijndert van der Spek 1 3 | E2: 2023 | F2: 10.1016/j.oneear.2023.06.004 | H2: Relevant | L2: Initial plant size | M2: Initial plant | N2: Liquid solvent | O2: 2022 | P2: nuclear energy | Q2: Techno-economic modeling | S2: Capacity factor, Bare erected cost, Materials scaling | T2: Capacity factor | U2: Heat demand | V2: Tornado Chart | W2: current
A3: y | B3: Young et al. 2023 | C3: One Earth | D3: John Young 1 , Noah McQueen 2 , Charithea Charalambous 1 , Spyros Foteinis 1 , Olivia Hawrot 1 , Manuel Ojeda 1 , Hélène Pilorgé 2 , John Andresen 1 , Peter Psarras 2 , Phil Renforth 1 , Susana Garcia 1 , Mijndert van der Spek 1 3 | E3: 2023 | F3: 10.1016/j.oneear.2023.06.004 | H3: Relevant | L3: Initial plant size | M3: Initial plant | N3: Solid sorbent | O3: 2022 | P3: nuclear energy, heat pump | Q3: Techno-economic modeling | S3: Capacity factor, Bare erected cost, Materials scaling | T3: Capacity factor | U3: Electricity price | V3: Tornado Chart | W3: current
A4: y | B4: Young et al. 2023 | C4: One Earth | D4: John Young 1 , Noah McQueen 2 , Charithea Charalambous 1 , Spyros Foteinis 1 , Olivia Hawrot 1 , Manuel Ojeda 1 , Hélène Pilorgé 2 , John Andresen 1 , Peter Psarras 2 , Phil Renforth 1 , Susana Garcia 1 , Mijndert van der Spek 1 3 | E4: 2023 | F4: 10.1016/j.oneear.2023.06.004 | H4: Relevant | L4: Initial plant size | M4: Initial plant | N4: Liquid solvent with electrochemical regeneration | O4: 2022 | P4: nuclear energy | Q4: Techno-economic modeling | S4: Electricity demand, Electricity price, Bare erected cost | T4: Bare erected cost | U4: Electricity requirement, Electricity price | V4: Tornado Chart
A5: y | B5: Young et al. 2023 | C5: One Earth | D5: John Young 1 , Noah McQueen 2 , Charithea Charalambous 1 , Spyros Foteinis 1 , Olivia Hawrot 1 , Manuel Ojeda 1 , Hélène Pilorgé 2 , John Andresen 1 , Peter Psarras 2 , Phil Renforth 1 , Susana Garcia 1 , Mijndert van der Spek 1 3 | E5: 2023 | F5: 10.1016/j.oneear.2023.06.004 | H5: Relevant | L5: Initial plant size | M5: Initial plant | N5: Ambient weathering | O5: 2022 | P5: nuclear energy | Q5: Techno-economic modeling | S5: Bare erected cost, Capacity factor, MgCO3 price | T5: Bare erected cost | U5: MgCO3 price, heat demand | V5: Tornado Chart
A6: y | B6: Young et al. 2023 | C6: One Earth | D6: John Young 1 , Noah McQueen 2 , Charithea Charalambous 1 , Spyros Foteinis 1 , Olivia Hawrot 1 , Manuel Ojeda 1 , Hélène Pilorgé 2 , John Andresen 1 , Peter Psarras 2 , Phil Renforth 1 , Susana Garcia 1 , Mijndert van der Spek 1 3 | E6: 2023 | F6: 10.1016/j.oneear.2023.06.004 | H6: Relevant | L6: 1 Gt CO2/year | M6: Cost projection | N6: Liquid solvent | O6: 2050 | P6: nuclear energy | Q6: Techno-economic modeling | S6: Learning rate, Bare erected cost, Materials scaling | T6: Learning rate | U6: Electricity price | V6: Tornado Chart
A7: y | B7: Young et al. 2023 | C7: One Earth | D7: John Young 1 , Noah McQueen 2 , Charithea Charalambous 1 , Spyros Foteinis 1 , Olivia Hawrot 1 , Manuel Ojeda 1 , Hélène Pilorgé 2 , John Andresen 1 , Peter Psarras 2 , Phil Renforth 1 , Susana Garcia 1 , Mijndert van der Spek 1 3 | E7: 2023 | F7: 10.1016/j.oneear.2023.06.004 | H7: Relevant | L7: 1 Gt CO2/year | M7: Cost projection | N7: Solid sorbent | O7: 2050 | P7: nuclear energy, heat pump | Q7: Techno-economic modeling | S7: Learning rate, Electricity price, Variable OPEX learning rate | T7: Learning rate | U7: COP heat pump, heat demand | V7: Tornado Chart
A8: y | B8: Young et al. 2023 | C8: One Earth | D8: John Young 1 , Noah McQueen 2 , Charithea Charalambous 1 , Spyros Foteinis 1 , Olivia Hawrot 1 , Manuel Ojeda 1 , Hélène Pilorgé 2 , John Andresen 1 , Peter Psarras 2 , Phil Renforth 1 , Susana Garcia 1 , Mijndert van der Spek 1 3 | E8: 2023 | F8: 10.1016/j.oneear.2023.06.004 | H8: Relevant | L8: 1 Gt CO2/year | M8: Cost projection | N8: Liquid solvent with electrochemical regeneration | O8: 2050 | P8: nuclear energy | Q8: Techno-economic modeling | S8: Electricity demand, Electricity price, Variable OPEX learning rate | T8: Learning rate | U8: Electricity demand, electricity price | V8: Tornado Chart
A9: y | B9: Young et al. 2023 | C9: One Earth | D9: John Young 1 , Noah McQueen 2 , Charithea Charalambous 1 , Spyros Foteinis 1 , Olivia Hawrot 1 , Manuel Ojeda 1 , Hélène Pilorgé 2 , John Andresen 1 , Peter Psarras 2 , Phil Renforth 1 , Susana Garcia 1 , Mijndert van der Spek 1 3 | E9: 2023 | F9: 10.1016/j.oneear.2023.06.004 | H9: Relevant | L9: 1 Gt CO2/year | M9: Cost projection | N9: Ambient weathering | O9: 2050 | P9: nuclear energy | Q9: Techno-economic modeling | S9: Learning rate, Bare erected cost, Capacity factor | T9: Learning rate | U9: MgCO3 price, heat demand | V9: Tornado Chart
A10: y | B10: Sievert et al. 2024 | C10: Joule | D10: Sievert, Schmidt, Steffen | E10: 2024 | F10: 10.1016/j.joule.2024.02.005 | H10: Relevant | L10: Initial plant size | M10: Initial plant | N10: Liquid solvent | O10: 2022 | P10: Solar PV with tracking US | Q10: Techno-economic modeling | S10: Capacity factor, WACC, Plant lifetime | T10: Capacity factor | U10: Heat demand | V10: Tornado Chart
A11: y | B11: Sievert et al. 2024 | C11: Joule | D11: Sievert, Schmidt, Steffen | E11: 2024 | F11: 10.1016/j.joule.2024.02.005 | H11: Relevant | L11: 1 Gt CO2/year | M11: Cost projection | N11: Liquid solvent | O11: 2050 | P11: Solar PV with tracking US | Q11: Techno-economic modeling | S11: Capacity factor, WACC, Plant lifetime | T11: Capacity factor | U11: Heat demand | V11: Tornado Chart
A12: y | B12: Sievert et al. 2024 | C12: Joule | D12: Sievert, Schmidt, Steffen | E12: 2024 | F12: 10.1016/j.joule.2024.02.005 | H12: Relevant | L12: Initial plant size | M12: Initial plant | N12: Solid sorbent | O12: 2022 | P12: Solar PV with tracking US | Q12: Techno-economic modeling | S12: Capacity factor, WACC, Plant lifetime | T12: Capacity factor | U12: COP heat pump, Heat demand | V12: Tornado Chart
A13: y | B13: Sievert et al. 2024 | C13: Joule | D13: Sievert, Schmidt, Steffen | E13: 2024 | F13: 10.1016/j.joule.2024.02.005 | H13: Relevant | L13: 1 Gt CO2/year | M13: Cost projection | N13: Solid sorbent | O13: 2050 | P13: Solar PV with tracking US | Q13: Techno-economic modeling | S13: Capacity factor, WACC, learning rate OPEX | T13: Capacity factor | U13: Water requirement and cost | V13: Tornado Chart
A14: y | B14: Sievert et al. 2024 | C14: Joule | D14: Sievert, Schmidt, Steffen | E14: 2024 | F14: 10.1016/j.joule.2024.02.005 | H14: Relevant | L14: Initial plant size | M14: Initial plant | N14: Ambient weathering | O14: 2022 | P14: Solar PV with tracking US | Q14: Techno-economic modeling | S14: Capacity factor, WACC, Calciner CAPEX | T14: Capacity factor, discount rate, Calciner CAPEX | U14: Electricity demand | V14: Tornado Chart
A15: y | B15: Sievert et al. 2024 | C15: Joule | D15: Sievert, Schmidt, Steffen | E15: 2024 | F15: 10.1016/j.joule.2024.02.005 | H15: Relevant | L15: 1 Gt CO2/year | M15: Cost projection | N15: Ambient weathering | O15: 2050 | P15: Solar PV with tracking US | Q15: Techno-economic modeling | S15: Capacity factor, Learning rate system, WACC | T15: Capacity factor, learning rate system | U15: Electricity demand | V15: Tornado Chart
A16: y | B16: McQueen et al. 2020a | C16: Environmental Science & Technology | D16: Noah McQueenPeter PsarrasHélène PilorgéSimona LiguoriJiajun HeMengyao YuanCaleb M. WoodallKourosh KianLara PierpointJacob JurewiczJ. Matthew LucasRory JacobsonNoah DeichJennifer Wilcox* | E16: 2020 | F16: 10.1021/acs.est.0c00476 | H16: Relevant | L16: 100kt CO2/year | M16: Initial plant | N16: Solid sorbent | O16: 2022 | P16: nuclear energy | Q16: Techno-economic modeling | S16: / | V16: no sensitivity analysis | X16: Contactor CAPEX, Electricity, Steam | Y16: Contactor CAPEX | Z16: Electricity demand
A17: y | B17: Sendi et al. 2022 | C17: One Earth | D17: Marwan Sendi 1 2 , Mai Bui 2 3 , Niall Mac Dowell 2 3 , Paul Fennell 1 4 | E17: 2022 | F17: 10.1016/j.oneear.2022.09.003 | H17: Relevant | L17: 1Mt CO2/year | M17: Cost projection | N17: Solid sorbent | O17: 2022 | P17: Solar PV | Q17: Techno-economic modeling | S17: / | V17: no sensitivity analysis | X17: Contactor CAPEX, Steam, Electricity | Y17: Contactor CAPEX | Z17: Electricity demand
A18: y | B18: Fasihi et al. 2019 | C18: Journal of Cleaner Production | D18: Mahdi Fasihi , Olga Efimova , Christian Breyer | E18: 2019 | F18: 10.1016/j.jclepro.2019.03.086 | H18: Relevant | M18: Initial plant | N18: Liquid solvent | S18: WACC, DAC capex, Electricity demand | T18: WACC, DAC capex | U18: Electricity demand | V18: Sensitivity with just one parameter being varied
A19: y | B19: Fasihi et al. 2019 | C19: Journal of Cleaner Production | D19: Mahdi Fasihi , Olga Efimova , Christian Breyer | E19: 2019 | F19: 10.1016/j.jclepro.2019.03.086 | H19: Relevant | M19: Initial plant | N19: Solid sorbent | S19: WACC, DAC capex, heat demand | T19: WACC, DAC capex | U19: heat demand | V19: Sensitivity with just one parameter being varied
A20: y | B20: Mazzotti et al. 2013 | C20: Climatic Change | D20: Marco Mazzotti, Renato Baciocchi, Michael J. Desmond & Robert H. Socolow | E20: 2013 | F20: 10.1007/s10584-012-0679-y | H20: Relevant | M20: Initial plant | N20: Liquid solvent | S20: / | V20: no sensitivity analysis
A21: y | B21: Zeman 2014 | C21: Environmental Science & Technology | D21: Zeman | E21: 2014 | F21: 10.1021/es502887y | H21: Relevant | M21: Initial plant | N21: Liquid solvent | S21: / | V21: no sensitivity analysis
A22: y | B22: Prats-Salvado et al. 2024 | C22: Environmental Science & Technology | D22: Enric Prats-Salvado*Nipun JagtapNathalie MonnerieChristian Sattler | E22: 2024 | F22: 10.1021/acs.est.3c08269 | H22: Relevant | M22: Initial plant | N22: Liquid solvent | S22: / | V22: no sensitivity analysis
A23: y | B23: Prats-Salvado et al. 2024 | C23: Environmental Science & Technology | D23: Enric Prats-Salvado*Nipun JagtapNathalie MonnerieChristian Sattler | E23: 2024 | F23: 10.1021/acs.est.3c08269 | H23: Relevant | M23: Initial plant | N23: Liquid solvent | S23: / | V23: no sensitivity analysis
A24: y | B24: Terlouw et al. 2024 | C24: Environmental Science & Technology | D24: Tom TerlouwDaniel PokrasViola Becattini*Marco Mazzotti* | E24: 2024 | F24: 10.1021/acs.est.3c10041 | H24: Relevant | M24: Initial plant | N24: Solid sorbent | S24: CAPEX scaling factor, Capacity factor, CAPEX | T24: CAPEX scaling factor, Capacity factor | U24: Electricity demand, Electricity grid emission factor | V24: Tornado Chart
A25: y | B25: McQueen et al. 2021 | C25: Frontiers in Climate | D25: \nNoah McQueenNoah McQueen1Michael J. DesmondMichael J. Desmond2Robert H. SocolowRobert H. Socolow3Peter PsarrasPeter Psarras1Jennifer Wilcox Jennifer Wilcox1* | E25: 2021 | F25: 10.3389/fclim.2020.618644 | H25: Relevant | L25: 1Mt CO2/year | M25: Initial plant | N25: Liquid solvent | O25: 2021 | Q25: Techno-economic modeling | S25: Lifetime, WACC, natural gas price | T25: Lifetime, WACC | U25: Heat price | V25: Sensitivity with just one parameter being varied
A26: y | B26: Datta et al. 2023 | C26: Environmental Science & Technology | D26: Aparajita DattaRamanan Krishnamoorti* | E26: 2023 | F26: 10.1021/acs.est.2c05194 | H26: Relevant | M26: Initial plant | N26: Solid sorbent | S26: / | V26: no sensitivity analysis
A27: y | B27: Datta et al. 2023 | C27: Environmental Science & Technology | D27: Aparajita DattaRamanan Krishnamoorti* | E27: 2023 | F27: 10.1021/acs.est.2c05194 | H27: Relevant | M27: Initial plant | N27: Membrane-based m-DAC | S27: / | V27: no sensitivity analysis
A28: y | B28: Sinha et al. 2019 | C28: Sustainable Energy: Process Systems Engineering | D28: Anshuman Sinha, Matthew J. Realff | E28: 2019 | F28: 10.1002/aic.16607 | H28: Relevant | N28: Solid sorbent | S28: /
A29: y | B29: Simon et al. 2011 | C29: Energy Procedia | D29: A.J. Simon , Naluahi B. Kaahaaina , S. Julio Friedmann , Roger D. Aines | E29: 2011 | F29: 10.1016/j.egypro.2011.02.196 | H29: Relevant | M29: Initial plant | N29: Generic (Solid sorbent referenced) | S29: / | V29: no sensitivity analysis
A30: n | B30: Fuhrman et al. 2021 | C30: Environmental Research letters | D30: Jay Fuhrman1,2, Andres Clarens2, Katherine Calvin1, Scott C Doney3, James A Edmonds1, Patrick O'Rourke1, Pralit Patel1, Shreekar Pradhan2, William Shobe4 and Haewon McJeon5,1 | E30: 2021 | F30: 10.1088/1748-9326/ac2db0 | H30: Relevant | I30: Not relevant | L30: IAM integration and DAC modeling not clear; IAM study; exclusion criterion | S30: /
A31: y | B31: Küng et al. 2023 | C31: Energy & Environmental Science | D31: Lukas Küng, ORCID logo ‡a Silvan Aeschlimann, ORCID logo ‡b Charithea Charalambous, ORCID logo ab Fergus McIlwaine, ORCID logo a John Young, ORCID logo a Noah Shannon,b Karen Strassel, ORCID logo c Cara Nichole Maesano,b Rudy Kahsar, ORCID logo b Daniel Pike,b Mijndert van der Spek ORCID logo a and Susana Garcia ORCID logo | E31: 2023 | F31: 10.1039/d3ee01008b | H31: Relevant | M31: Initial plant | N31: Liquid solvent | S31: / | V31: no sensitivity analysis
A32: y | B32: Küng et al. 2023 | C32: Energy & Environmental Science | D32: Lukas Küng, ORCID logo ‡a Silvan Aeschlimann, ORCID logo ‡b Charithea Charalambous, ORCID logo ab Fergus McIlwaine, ORCID logo a John Young, ORCID logo a Noah Shannon,b Karen Strassel, ORCID logo c Cara Nichole Maesano,b Rudy Kahsar, ORCID logo b Daniel Pike,b Mijndert van der Spek ORCID logo a and Susana Garcia ORCID logo | E32: 2023 | F32: 10.1039/d3ee01008b | H32: Relevant | M32: Initial plant | N32: Solid sorbent | S32: / | V32: no sensitivity analysis
A33: y | B33: Mostafa et al. 2022 | C33: Carbon Capture Science & Technology | D33: Mahmoud Mostafa a b , Cristina Antonicelli c , Christopher Varela d e , Diego Barletta c , Edwin Zondervan b | E33: 2022 | F33: 10.1016/j.ccst.2022.100060 | H33: Relevant | M33: Initial plant | N33: Liquid solvent | S33: / | V33: no sensitivity analysis
A34: y | B34: Keith et al. 2018 | C34: Joule | D34: David W. Keith 1 2 3 4, Geoffrey Holmes 3, David St. Angelo 3, Kenton Heidel 3 | E34: 2018 | F34: 10.1016/j.joule.2018.05.006 | H34: Relevant | M34: Initial plant | N34: Liquid solvent | S34: / | V34: no sensitivity analysis
A35: y | B35: Gray et al. 2024 | C35: Renewable and Sustainable Energy Reviews | D35: Nathan Gray a b , Richard O'Shea a b , Beatrice Smyth c , Piet N.L. Lens d , Jerry D. Murphy a b | E35: 2024 | F35: 10.1016/j.rser.2024.114552 | H35: Relevant | M35: Initial plant | N35: Solid sorbent | O35: 2023 | P35: Norwegian Grid | Q35: Techno-economic modeling | S35: Capacity factor, DAC CAPEX, WACC | T35: Capacity factor | U35: Electricity price | V35: Capacity Factor
A36: y | B36: Rosen et al. 2024 | C36: Energy & Fuels | D36: Natalie RosenAndreas WelterMartin SchwanklNicolas PlumeréJúnior StaudtJakob Burger* | E36: 2024 | F36: 10.1021/acs.energyfuels.4c02202 | H36: Relevant | M36: Initial plant | N36: Liquid solvent | S36: / | V36: no sensitivity analysis
A37: y | B37: Rosen et al. 2024 | C37: Energy & Fuels | D37: Natalie RosenAndreas WelterMartin SchwanklNicolas PlumeréJúnior StaudtJakob Burger* | E37: 2024 | F37: 10.1021/acs.energyfuels.4c02202 | H37: Relevant | M37: Initial plant | N37: Liquid solvent with electrochemical regeneration | S37: / | V37: no sensitivity analysis
A38: y | B38: Rosen et al. 2024 | C38: Energy & Fuels | D38: Natalie RosenAndreas WelterMartin SchwanklNicolas PlumeréJúnior StaudtJakob Burger* | E38: 2024 | F38: 10.1021/acs.energyfuels.4c02202 | H38: Relevant | M38: Initial plant | N38: Solid sorbent | S38: / | V38: no sensitivity analysis
A39: y | B39: Rosen et al. 2024 | C39: Energy & Fuels | D39: Natalie RosenAndreas WelterMartin SchwanklNicolas PlumeréJúnior StaudtJakob Burger* | E39: 2024 | F39: 10.1021/acs.energyfuels.4c02202 | H39: Relevant | M39: Initial plant | N39: Electro-swing adsorption (ESA) | S39: / | V39: no sensitivity analysis
A40: y | B40: Sabatino et al. 2020 | C40: Industrial & Engineering Chemistry Research | D40: Francesco SabatinoMayank MehtaAlexa GrimmMatteo GazzaniFausto GallucciGert Jan KramerMartin van Sint Annaland* | E40: 2020 | F40: 10.1021/acs.iecr.9b05641 | H40: Relevant | S40: /
...

Sheet Studies current &future cost
A1: Reference | B1: Included? | C1: Harmonized by | D1: Type of literature | E1: DOI | F1: DAC Technology | G1: Technology Detail | H1: Timeline | I1: Plant Capacity (Mt CO2/year) | K1: Note for future projection
A2: Young et al. 2023 | B2: y | C2: YD/KS | D2: Journal article | E2: 10.1016/j.oneear.2023.06.004 | F2: Liquid solvent | G2: KOH absorption paired with regeneration via Ca looping | H2: 2022-2100 | I2: 0.98
A3: Young et al. 2023 | B3: y | C3: YD/KS | D3: Journal article | E3: 10.1016/j.oneear.2023.06.004 | F3: Solid sorbent | G3: Solid sorbent DAC using temperature vacuum swing adsorption | H3: 2022-2100 | I3: =46000/10^6 -> 0.046
A4: Young et al. 2023 | B4: y | C4: YD/KS | D4: Journal article | E4: 10.1016/j.oneear.2023.06.004 | F4: Liquid solvent with electrochemical regeneration | G4: Liquid solvent with electrochemical regeneration | H4: 2022-2100 | I4: =960/10^6 -> 0.00096
A5: Young et al. 2023 | B5: y | C5: YD/KS | D5: Journal article | E5: 10.1016/j.oneear.2023.06.004 | F5: Ambient weathering | G5: MgO ambient weathering with regeneration via calcination | H5: 2022-2100 | I5: =1100000/10^6 -> 1.1
A6: Sievert et al. 2024 | B6: y | C6: KS | D6: Journal article | E6: 10.1016/j.joule.2024.02.005 | F6: Liquid solvent | G6: KOH absorption paired with regeneration via Ca looping | H6: 2023-2050 | I6: =500000/10^6 -> 0.5
A7: Sievert et al. 2024 | B7: y | C7: KS | D7: Journal article | E7: 10.1016/j.joule.2024.02.005 | F7: Solid sorbent | G7: Solid sorbent DAC using temperature vacuum swing adsorption | H7: 2023-2050 | I7: =4000/10^6 -> 0.004
A8: Sievert et al. 2024 | B8: y | C8: KS | D8: Journal article | E8: 10.1016/j.joule.2024.02.005 | F8: Ambient weathering | G8: CaO ambient weathering with regeneration via calcination | H8: 2023-2050 | I8: =1000/10^6 -> 0.001
A9: McQueen et al. 2020a | B9: no | C9: YD | D9: Journal article | E9: 10.1021/acs.est.0c00476 | F9: Solid sorbent | G9: Solid sorbent | H9: 2023 | I9: 0.1 | K9: None of key words listed in context of future costs
A10: Sendi et al. 2022 | B10: no | C10: YD | D10: Journal article | E10: 10.1016/j.oneear.2022.09.003 | F10: Solid sorbent | G10: Solid sorbent | H10: 2022 | I10: n/a | K10: None of key words listed in context of future costs | L10: They discuss land use and elec req for 10 Gt CO2/year but they seem to model current costs
A11: Fasihi et al. 2019 | B11: y | C11: KS | D11: Journal article | E11: 10.1016/j.jclepro.2019.03.086 | F11: Liquid solvent | G11: Liquid solvent | H11: 2020-2050 | I11: 1
A12: Fasihi et al. 2019 | B12: y | C12: KS | D12: Journal article | E12: 10.1016/j.jclepro.2019.03.086 | F12: Solid sorbent | G12: Solid sorbent | H12: 2020-2050 | I12: 0.36
A13: Mazzotti et al. 2013 | B13: no | C13: KS | D13: Journal article | E13: 10.1007/s10584-012-0679-y | F13: Liquid solvent | G13: KOH absorption paired with regeneration via Ca looping | H13: 2008/2009 | I13: 1
A14: Zeman 2014 | B14: no | C14: KS | D14: Journal article | E14: 10.1021/es502887y | F14: Liquid solvent | G14: KOH absorption paired with regeneration via Ca looping | H14: 2008/2009 | I14: 1 | AL14: For data points before standardization, adjust Zeman 2014 values for other energy sources to 2023$
A15: Prats-Salvado et al. 2024 | B15: no | C15: KS | D15: Journal article | E15: 10.1021/acs.est.3c08269 | F15: Liquid solvent | G15: Solar thermal powered liquid solvent | H15: 2022 | I15: 1
A16: Prats-Salvado et al. 2024 | B16: no | C16: KS | D16: Journal article | E16: 10.1021/acs.est.3c08269 | F16: Liquid solvent | G16: Conventional: KOH absorption paired with regeneration via Ca looping | H16: 2022 | I16: 1.48
A17: Terlouw et al. 2024 | B17: no | C17: KS | D17: Journal article | E17: 10.1021/acs.est.3c10041 | F17: Solid sorbent | G17: Temperature-vacuum swing adsorption (TVSA) | H17: 2023 | I17: 1
A18: McQueen et al. 2021 | B18: no | C18: YD | D18: Journal article | E18: 10.3389/fclim.2020.618644 | F18: Liquid solvent | H18: 2020 | I18: 1
A19: Datta et al. 2023 | B19: no | C19: KS | D19: Journal article | E19: 10.1021/acs.est.2c05194 | F19: Solid sorbent | G19: Temperature swing adsorption-based DAC | H19: 2023 | I19: =1000/10^6 -> 0.001 | K19: None of key words listed in context of future costs
A20: Datta et al. 2023 | B20: no | C20: KS | D20: Journal article | E20: 10.1021/acs.est.2c05194 | F20: Membrane-based m-DAC | G20: Membrane-based DAC | H20: 2023 | I20: =1000/10^6 -> 0.001
A21: Sinha et al. 2019 | B21: no | D21: Journal article | E21: 10.1002/aic.16607 | F21: Solid sorbent
A22: Simon et al. 2011 | B22: no | C22: YD | D22: Journal article | E22: 10.1016/j.egypro.2011.02.196 | F22: Generic (Solid sorbent referenced) | G22: Generic | H22: 2011 | I22: 1 | K22: None of key words listed in context of future costs | L22: Also kicked out because data is outdated (2011)
A23: Küng et al. 2023 | B23: no | C23: YD | D23: Journal article | E23: 10.1039/d3ee01008b | F23: Liquid solvent | G23: Liquid solvent | H23: 2023 | I23: 1 | K23: Only FOAK and discussion that learning is needed
A24: Küng et al. 2023 | B24: no | C24: YD | D24: Journal article | E24: 10.1039/d3ee01008b | F24: Solid sorbent | G24: Solid sorbent | H24: 2023 | I24: Variable | K24: Only FOAK and discussion that learning is needed
A25: Mostafa et al. 2022 | B25: no | D25: Journal article | E25: 10.1016/j.ccst.2022.100060 | F25: Liquid solvent | G25: NaOH absorption DAC process paired with regeneration via Ca looping | K25: Borderline; Plant capacity: 6.3 million; because of grid emissions only 3.5 Mt CO2/year removed; "large-scale" in title
A26: Keith et al. 2018 | B26: y | C26: KS | D26: Journal article | E26: 10.1016/j.joule.2018.05.006 | F26: Liquid solvent | G26: KOH absorption paired with regeneration via Ca looping | H26: 2016 and Nth kind | I26: 1
A27: Gray et al. 2024 | B27: no | C27: YD | D27: Journal article | E27: 10.1016/j.rser.2024.114552 | F27: Solid sorbent | G27: Solid sorbent | H27: 2024 | I27: 1 | K27: Model first large-scale plant; not 2050 projection
A28: Rosen et al. 2024 | C28: YD | D28: Journal article | E28: 10.1021/acs.energyfuels.4c02202 | F28: Liquid solvent | G28: Absorption with regeneration via chemical looping (ACL) as described by Keith et al.13 (TRL 7) | H28: 2023
A29: Rosen et al. 2024 | C29: YD | D29: Journal article | E29: 10.1021/acs.energyfuels.4c02202 | F29: Liquid solvent with electrochemical regeneration | G29: Absorption with electrochemical regeneration (AEC); carbonate regeneration using a bipolar membrane described by Iizuka et al.53 (TRL 2−3) | H29: 2023
A30: Rosen et al. 2024 | C30: YD | D30: Journal article | E30: 10.1021/acs.energyfuels.4c02202 | F30: Solid sorbent | G30: Temperature-vacuum-swing adsorption (TVSA) with the Wurzbacher et al.69 (TRL 8) | H30: 2023
A31: Rosen et al. 2024 | C31: YD | D31: Journal article | E31: 10.1021/acs.energyfuels.4c02202 | F31: Electro-swing adsorption (ESA) | G31: Electro-swing adsorption (ESA) as described by Voskian and Hatton35 (TRL 1) | H31: 2023
A32: Sabatino et al. 2020 | B32: no | D32: Journal article | E32: 10.1021/acs.iecr.9b05641
A33: McQueen et al. 2020c | B33: no | C33: YD | D33: Journal article | E33: 10.1038/s41467-020-16510-3 | F33: Ambient Weathering | G33: MgO based | H33: 2020 | I33: 64-180 | K33: 64-180 Mt CO2/year removal is huge but no current and future
A34: Lee et al. 2023 | B34: no | C34: KS | D34: Journal article | E34: 10.1016/j.joule.2023.05.016 | F34: Solid sorbent | G34: Solid sorbent DAC via electrically driven temperature swing adsorption (ETSA) | H34: 2023 | I34: unclear
A35: Abanades et al. 2023 | B35: no | C35: YD | D35: Journal article | E35: 10.1016/j.xcrp.2023.101339 | F35: Solid sorbent | G35: CaCO3 based | H35: 2023 | I35: 1
A36: Abanades et al. 2020 | B36: no | C36: YD | D36: Journal article | E36: 10.1039/d0se00094a | F36: Ambient weathering | G36: CaCO3 based | H36: 2020 | I36: 1
A37: Ragipani et al. 2022 | B37: no | C37: YD | D37: Journal article | E37: 10.1021/acssuschemeng.1c07867 | F37: Liquid solvent | H37: 2022 | I37: 0.008
A38: Sinha et al. 2017 | B38: no | D38: Journal article | E38: 10.1021/acs.iecr.6b03887
A39: Pett-Ridge et al. 2024 | B39: y | C39: YD | D39: Report | E39: Roads to Removal – Options for carbon dioxide removal in the US (roads2removal.org) | F39: Solid sorbent | G39: Solid sorbent | H39: 2025-2050 | I39: =1000/10^6 -> 0.001
A40: Pett-Ridge et al. 2024 | B40: y | C40: YD | D40: Report | E40: Roads to Removal – Options for carbon dioxide removal in the US (roads2removal.org) | F40: Liquid solvent | G40: KOH absorption paired with regeneration via Ca looping | H40: 2025-2050 | I40: 1
...

Sheet Study Parameters
A1: Reference | B1: Included? | C1: Harmonized by | D1: Type of literature | E1: DOI | F1: DAC Technology | G1: Technology Detail | H1: Timeline | I1: Year Currency | J1: CAPEX Learning Rates (Capital Cost) | K1: OPEX Learning Rates | L1: Cost Type | M1: Cost Range Short Term | N1: Cost Range 2030 | O1: Cost Range 2050 | P1: Unit | Q1: Plant Capacity (Mt CO2/year) | R1: WACC / Discount Rate | S1: Electricity Price Range (EUR/MWh) | T1: Electricity Price Source | U1: Heat Price Range | V1: Heat Price Source | W1: Full load hours | X1: Capacity Factor | Y1: Plant Lifetime [y] | Z1: CO2 Transport and Storage | AA1: Transport cost | AB1: Storage cost | AC1: LCA Methdology | AD1: Data taken from | AE1: Sensitivity Analysis | AF1: Notes | AG1: Harmonization Status | AH1: Net removed cost harmonized | AI1: Request sent to author | AJ1: Answer? | AK1: To do
A2: Young et al. 2023 | B2: y | C2: YD/KS | D2: Journal article | E2: 10.1016/j.oneear.2023.06.004 | F2: Liquid solvent | G2: KOH absorption paired with regeneration via Ca looping | H2: 2022-2100 | I2: 2019 USD | J2: 5-15 | K2: n/a | L2: Net removed cost | M2: 300 - 550 | N2: n/a | O2: 150 - 220 | P2: USD/tCO2 | Q2: 0.98 | R2: 7.5 - 12.5% | S2: 11 - 300 $/MWh | T2: Multiple sources dependent on geographic location | U2: 3 - 114 $/GJ | V2: Prices are based on source (Natural Gas, Geothermal, Solar) and Location | W2: 8,000 (LT) - 8,760 (HT) | X2: 0.9 | Y2: 25 | Z2: Included in net removed cost | AA2: 12.4$/tCO2 | AB2: incl. In transport | AC2: No LCA | AD2: Keith et al. (2018) | AF2: The data for ACL is used from Keith et al.,¹³ AEC from Sabatino et al.,⁵⁴ MgO looping from McQueen et al.,⁶⁸ and the data for TVSA is calculated within their work.⁵¹ | AG2: Completed | AH2: Completed | AI2: 45548 | AK2: Convert to $2023 and connect to master sheet
A3: Young et al. 2023 | B3: y | C3: YD/KS | D3: Journal article | E3: 10.1016/j.oneear.2023.06.004 | F3: Solid sorbent | G3: Solid sorbent DAC using temperature vacuum swing adsorption | H3: 2022-2100 | I3: 2019 USD | J3: 10-19 | K3: n/a | L3: Net removed cost | M3: 1,600 - 2,500 | N3: n/a | O3: 500 - 1,100 | P3: USD/tCO2 | Q3: =46000/10^6 -> 0.046 | R3: 7.5 - 12.5% | S3: 11 - 300 $/MWh | T3: Multiple sources dependent on geographic location | U3: 3 - 114 $/GJ | V3: Prices are based on source (Natural Gas, Geothermal, Solar) and Location | W3: 8,000 (LT) - 8,760 (HT) | X3: 0.9 | Y3: 25 | Z3: Included in net removed cost | AA3: 12.4$/tCO2 | AB3: incl. In transport | AD3: Own modeling | AF3: The data for ACL is used from Keith et al.,¹³ AEC from Sabatino et al.,⁵⁴ MgO looping from McQueen et al.,⁶⁸ and the data for TVSA is calculated within their work.⁵¹ | AG3: Completed | AH3: Completed
A4: Young et al. 2023 | B4: y | C4: YD/KS | D4: Journal article | E4: 10.1016/j.oneear.2023.06.004 | F4: Liquid solvent with electrochemical regeneration | G4: Liquid solvent with electrochemical regeneration | H4: 2022-2100 | I4: 2019 USD | J4: 10-18 | K4: n/a | L4: Net removed cost | M4: 900 - 2,100 | N4: n/a | O4: 200 - 350 | P4: USD/tCO2 | Q4: =960/10^6 -> 0.00096 | R4: 7.5 - 12.5% | S4: 11 - 300 $/MWh | T4: Multiple sources dependent on geographic location | U4: 3 - 114 $/GJ | V4: Prices are based on source (Natural Gas, Geothermal, Solar) and Location | W4: 8,000 (LT) - 8,760 (HT) | X4: 0.9 | Y4: 25 | Z4: Included in net removed cost | AA4: 12.4$/tCO2 | AB4: incl. In transport | AD4: Sabatino et al. 2020 | AF4: The data for ACL is used from Keith et al.,¹³ AEC from Sabatino et al.,⁵⁴ MgO looping from McQueen et al.,⁶⁸ and the data for TVSA is calculated within their work.⁵¹ | AG4: Completed | AH4: Completed
A5: Young et al. 2023 | B5: y | C5: YD/KS | D5: Journal article | E5: 10.1016/j.oneear.2023.06.004 | F5: Ambient weathering | G5: MgO ambient weathering with regeneration via calcination | H5: 2022-2100 | I5: 2019 USD | J5: 5-15 | K5: n/a | L5: Net removed cost | M5: 400 - 500 | N5: n/a | O5: 180 - 250 | P5: USD/tCO2 | Q5: =1100000/10^6 -> 1.1 | R5: 7.5 - 12.5% | S5: 11 - 300 $/MWh | T5: Multiple sources dependent on geographic location | U5: 3 - 114 $/GJ | V5: Prices are based on source (Natural Gas, Geothermal, Solar) and Location | W5: 8,000 (LT) - 8,760 (HT) | X5: 0.9 | Y5: 25 | Z5: Included in net removed cost | AA5: $1.0-4.8/tCO2/km | AB5: incl. In transport | AD5: McQueen et al. (2020c) | AF5: The data for ACL is used from Keith et al.,¹³ AEC from Sabatino et al.,⁵⁴ MgO looping from McQueen et al.,⁶⁸ and the data for TVSA is calculated within their work.⁵¹ | AG5: Completed | AH5: Completed
A6: Sievert et al. 2024 | B6: y | C6: KS | D6: Journal article | E6: 10.1016/j.joule.2024.02.005 | F6: Liquid solvent | G6: KOH absorption paired with regeneration via Ca looping | H6: 2023-2050 | I6: 2022 USD | J6: 8 | K6: 8 | L6: Net removed cost | M6: 521–894 | N6: n/a | O6: 226–544 | P6: USD/tCO2 | Q6: =500000/10^6 -> 0.5 | R6: 0.07 | S6: 39 $/MWh | T6: tracking solar PV with storage | U6: (B) 5.6 $/GJ | V6: natural gas | W6: 8760 | X6: 0.5-0.9 | Y6: 25 | Z6: Included in net removed cost | AA6: $5-12/tCO2 | AB6: $9.74-23.20/tCO2 | AD6: Keith et al. (2018) | AG6: My study | AH6: Completed | AK6: Convert to $2023 and connect to master sheet
A7: Sievert et al. 2024 | B7: y | C7: KS | D7: Journal article | E7: 10.1016/j.joule.2024.02.005 | F7: Solid sorbent | G7: Solid sorbent DAC using temperature vacuum swing adsorption | H7: 2023-2050 | I7: 2022 USD | J7: 12 | K7: 12 | L7: Net removed cost | M7: 1180–1392 | N7: n/a | O7: 281–579 | P7: USD/tCO2 | Q7: =4000/10^6 -> 0.004 | R7: 0.07 | S7: 39 $/MWh | T7: tracking solar PV with storage | U7: (B) 5.6 $/GJ | V7: n/a | W7: 8760 | X7: 0.75-0.9 | Y7: 25 | Z7: Included in net removed cost | AA7: $5-12/tCO2 | AB7: $9.74-23.20/tCO2 | AD7: Young et al. (2023) | AG7: My study | AH7: Completed | AK7: Convert to $2023 and connect to master sheet
A8: Sievert et al. 2024 | B8: y | C8: KS | D8: Journal article | E8: 10.1016/j.joule.2024.02.005 | F8: Ambient weathering | G8: CaO ambient weathering with regeneration via calcination | H8: 2023-2050 | I8: 2022 USD | J8: 14 | K8: 14 | L8: Net removed cost | M8: 2153–2874 | N8: n/a | O8: 230–835 | P8: USD/tCO2 | Q8: =1000/10^6 -> 0.001 | R8: 0.07 | S8: 39 $/MWh | T8: tracking solar PV with storage | U8: (B) 5.6 $/GJ | V8: n/a | W8: 8760 | X8: 0.5-0.9 | Y8: 25 | Z8: Included in net removed cost | AA8: $5-12/tCO2 | AB8: $9.74-23.20/tCO2 | AD8: McQueen et al. (2020c); only partially | AG8: My study | AH8: Completed | AK8: Convert to $2023 and connect to master sheet
