Workbook

Sheet Inputs
A1: Parameter | B1: Year | C1: Value | D1: Unit
A2: Standard Values
A3: Current Year | C3: 2024
A4: Inflation | C4: =[1]Inputs!C5 -> 0.02
A5: WACC | C5: =[1]Inputs!C6 -> 0.07
A6: USD to EUR | C6: =[1]Inputs!C7 -> 0.9
A7: Electricity
A8: LCOE | B8: 2024 | C8: =[1]Inputs!C9 -> 64 | D8: $/MWh
A9: LCOE | B9: 2050 | C9: =[1]Inputs!C10 -> 11 | D9: $/MWh
A10: Jet Fuel A-1 Characteristics
A11: Emissions Intensity | B11: 2024 | C11: =[1]Inputs!C12 -> 88.7 | D11: gCO2/MJ
A12: Emissions Intensity | B12: 2050 | C12: =[1]Inputs!C13 -> 88.7 | D12: gCO2/MJ
A13: Energy Density | C13: =[1]Inputs!C14 -> 43.2 | D13: MJ/kg
A14: Energy Density | C14: =[1]Inputs!C15 -> 34.6896 | D14: MJ/l
A15: Volumetric Density | C15: =[1]Inputs!C16 -> 0.803 | D15: kg/l
A16: Jet Fuel A-1 Price | B16: 2024 | C16: =[1]Inputs!C17 -> 0.8 | D16: $/l
A17: Scenario Specific Values
A18: Jet Fuel A-1 Price | B18: 2050 | C18: =[1]Inputs!C19 -> 1.7 | D18: $/l
A19: IEA Reference
A20: Jet Fuel A-1 Price | B20: 2024 | C20: =[1]Inputs!C21 -> 0.32246154 | D20: $/l
A21: Jet Fuel A-1 Price | B21: 2050 | C21: =[1]Inputs!C22 -> 0.20923077 | D21: $/l
A22: EIA Reference
A23: Jet Fuel A-1 Price | B23: 2024 | C23: =[1]Inputs!C24 -> 1.0209014 | D23: $/l
A24: Jet Fuel A-1 Price | B24: 2050 | C24: =[1]Inputs!C25 -> 2.0095594 | D24: $/l
A25: EIA Low Oil Price Scenario
A26: Jet Fuel A-1 Price | B26: 2024 | C26: =[1]Inputs!C27 -> 0.48286833 | D26: $/l
A27: Jet Fuel A-1 Price | B27: 2050 | C27: =[1]Inputs!C28 -> 0.89646575 | D27: $/l
A28: EIA High Scenario
A29: Jet Fuel A-1 Price | B29: 2024 | C29: =[1]Inputs!C30 -> 1.8838713 | D29: $/l
A30: Jet Fuel A-1 Price | B30: 2050 | C30: =[1]Inputs!C31 -> 3.7893731 | D30: $/l
A31: Direct Air Capture
A32: LCOR | B32: 2024 | C32: =[1]Inputs!C33 -> 1371 | D32: $/tCO2
A33: LCOR | B33: 2050 | C33: =[1]Inputs!C34 -> 523 | D33: $/tCO2

Sheet Study Parameters
A1: Key Parameters
A2: Parameter | B2: Year | C2: Value | D2: Source | E2: Note
A3: Plant Lifetime (years) | B3: Both | C3: 25 | D3: Marchese et. al.
A4: Discount Rate | B4: Both | C4: 0.075 | D4: Marchese et. al. | E4: Medium risk discount rate considered as low risk is 0%
A6: Plant Parameters
A7: Parameter | B7: Year | C7: Value | D7: Unit | E7: Source | F7: Note
A8: Annual Full Load Hours | B8: Both | C8: 8000 | D8: h | E8: Marchese et. al.
A10: Process Parameters
A11: Parameter | B11: Year | C11: Value | D11: Unit | E11: Source | F11: Note
A12: Fuel Production C.1 | B12: Both | C12: 8.7 | D12: t/h | E12: Marchese et. al.
A13: Fuel Production C.2 | B13: Both | C13: 3.5 | D13: t/h | E13: Marchese et. al.
A14: Fuel Production C.3 | B14: Both | C14: 4.8 | D14: t/h | E14: Marchese et. al.
A15: Fuel Production C.4 | B15: Both | C15: 6.9 | D15: t/h | E15: Marchese et. al.
A16: Fuel Production C.5 | B16: Both | C16: 6.8 | D16: t/h | E16: Marchese et. al.
A17: H2 Consumption | B17: Both
A18: CO2 Consumption | B18: Both | C18: 27 | D18: t/h | E18: Marchese et. al.
A19: Annual CO2 Consumption | B19: Both | C19: =C18*C8 -> 216000 | D19: t | F19: Calculated
A20: DAC Electricity Consumption | B20: Both | C20: 694 | D20: kWh/t | E20: Fasihi et. al. 2019, Table 2 | F20: K2CO3 process is considered as it is modelled here
A21: Annual DAC Electricity Consumption | B21: Both | C21: =(C20*C19) / 10^3 -> 149904 | D21: MWh
A22: Annual Process Electricity Consumption C.1 | B22: Both | C22: =SUM('Cost Components'!B23:B29) * 10^6 / SUM('Study Parameters'!C30:C35) / 4 -> 2384886.1 | D22: MWh
A23: Annual Process Electricity Consumption C.2 | B23: Both | C23: =SUM('Cost Components'!C23:C29) * 10^6/ SUM('Study Parameters'!C30:C35) / 4 -> 1650148.4 | D23: MWh
A24: Annual Process Electricity Consumption C.3 | B24: Both | C24: =SUM('Cost Components'!D23:D29) * 10^6 / SUM('Study Parameters'!C30:C35) / 3 -> 2555280.2 | D24: MWh
A25: Annual Process Electricity Consumption C.4 | B25: Both | C25: =SUM('Cost Components'!E23:E29) * 10^6 / SUM('Study Parameters'!C30:C35) / 4 -> 1758471.6 | D25: MWh
A26: Annual Process Electricity Consumption C.5 | B26: Both | C26: =SUM('Cost Components'!F23:F29) * 10^6 / SUM('Study Parameters'!C30:C35) / 4 -> 2222533.5 | D26: MWh
A28: External Costs
A29: Parameter | B29: Year | C29: Value | D29: Unit | E29: Source | F29: Note
A30: Electricity Price: Hydropower | B30: 2021 | C30: 41.05 | D30: €/MWh | E30: Marchese et. al.
A31: Electricity Price: Onshore Wind | B31: 2021 | C31: 59.39 | D31: €/MWh | E31: Marchese et. al.
A32: Electricity Price: Geothermal | B32: 2021 | C32: 63.76 | D32: €/MWh | E32: Marchese et. al.
A33: Electricity Price: Offshore Wind | B33: 2021 | C33: 100.44 | D33: €/MWh | E33: Marchese et. al.
A34: Electricity Price: CSP | B34: 2021 | C34: 158.95 | D34: €/MWh | E34: Marchese et. al.
A35: Electricity Price: Baseload (Wind + Solar) | B35: 2021 | C35: 210 | D35: €/MWh | E35: Marchese et. al.
A36: Electricity Price: Baseload | B36: 2050
A38: Fuel Characteristics
A39: Parameter | B39: Year | C39: Value | D39: Unit | E39: Source | F39: Note
A40: GHG Emissions | B40: Both | C40: 0 | D40: gCO2/MJ | E40: Marchese et. al. | F40: Process is considered to be carbon neutral with embedded CO2 captured via DAC

Sheet Cost Components
A1: 2021 | L1: 2050
A2: CAPEX | L2: CAPEX
A3: Component | B3: C.1 | C3: C.2 | D3: C.3 | E3: C.4 | F3: C.5 | G3: Unit | H3: Source | I3: Note | L3: Component | M3: C.1 | N3: C.2 | O3: C.3 | P3: C.4 | Q3: C.5 | R3: Unit | S3: Source | T3: Note
A4: Electrolysis | B4: 330 | C4: 283 | D4: 310 | E4: 261 | F4: 337 | G4: M€ | H4: Marchese et. al. Supplementary Information Table S.6 | L4: Other CAPEX | M4: =M12-M5 -> 428.2 | N4: =N12-N5 -> 309.4 | O4: =O12-O5 -> 321.6 | P4: =P12-P5 -> 339 | Q4: =Q12-Q5 -> 347 | R4: M€ | S4: Marchese et. al. Supplementary Information Table S.6
A5: DAC | B5: 734 | C5: 698 | D5: 707 | E5: 595 | F5: 535 | G5: M€ | H5: Marchese et. al. Supplementary Information Table S.6 | L5: DAC | M5: =B5 * 0.2 -> 146.8 | N5: =C5 * 0.2 -> 139.6 | O5: =D5 * 0.2 -> 141.4 | P5: =E5 * 0.2 -> 119 | Q5: =F5 * 0.2 -> 107 | R5: M€ | S5: Marchese et. al. Supplementary Information Table S.6
A6: Thermal Integration | B6: 416 | C6: 355 | D6: 347 | E6: 305 | F6: 306 | G6: M€ | H6: Marchese et. al. Supplementary Information Table S.6
A7: RWGS | B7: 115 | C7: 75 | D7: 82 | E7: 79 | F7: 96 | G7: M€ | H7: Marchese et. al. Supplementary Information Table S.6
A8: FT | B8: 223 | C8: 86 | D8: 118 | E8: 164 | F8: 169 | G8: M€ | H8: Marchese et. al. Supplementary Information Table S.6
A9: Total Syngas Compression | B9: 32 | C9: 15 | D9: 18 | E9: 22 | F9: 24 | G9: M€ | H9: Marchese et. al. Supplementary Information Table S.6
A10: Distillation | B10: 14.76 | C10: 7.8 | D10: 9.03 | E10: 9.62 | F10: 11.46 | G10: M€ | H10: Marchese et. al. Supplementary Information Table S.6
A11: Afterburn Combustor | B11: 6 | C11: 5.5 | D11: 3 | E11: 4.3 | F11: 4.2 | G11: M€ | H11: Marchese et. al. Supplementary Information Table S.6
A12: Total CAPEX | B12: =SUM(B4:B11) -> 1870.76 | C12: =SUM(C4:C11) -> 1525.3 | D12: =SUM(D4:D11) -> 1594.03 | E12: =SUM(E4:E11) -> 1439.92 | F12: =SUM(F4:F11) -> 1482.66 | G12: M€ | H12: Marchese et. al. Supplementary Information Table S.6 | L12: Total CAPEX | M12: 575 | N12: 449 | O12: 463 | P12: 458 | Q12: 454 | R12: M€ | S12: Marchese et. al. Supplementary Information Table S.6
A14: OPEX | L14: OPEX
A15: Component | B15: C.1 | C15: C.2 | D15: C.3 | E15: C.4 | F15: C.5 | G15: Unit | H15: Source | I15: Note | L15: Component | M15: C.1 | N15: C.2 | O15: C.3 | P15: C.4 | Q15: C.5 | R15: Unit | S15: Source | T15: Note
A16: Electrolysis | B16: 51.8 | C16: 26.2 | D16: 26.5 | E16: 22.4 | F16: 20.2 | G16: M€/year | H16: Marchese et. al. Supplementary Information Table S.7 | L16: Electricity | M16: =(60 * 'Study Parameters'!$C$22) / 10^6 -> 143.09317 | N16: =(60 * 'Study Parameters'!$C$23) / 10^6 -> 99.008902 | O16: =(60 * 'Study Parameters'!$C$24) / 10^6 -> 153.31681 | P16: =(60 * 'Study Parameters'!$C$25) / 10^6 -> 105.50829 | Q16: =(60 * 'Study Parameters'!$C$26) / 10^6 -> 133.35201 | R16: M€/year | S16: Marchese et. al. Supplementary Information Table S.7
A17: DAC | B17: 12.6 | C17: 10.7 | D17: 10.5 | E17: 9.2 | F17: 9.2 | G17: M€/year | H17: Marchese et. al. Supplementary Information Table S.7 | L17: DAC | M17: =B17/B5*M5 -> 2.52 | N17: =C17/C5*N5 -> 2.14 | O17: =D17/D5*O5 -> 2.1 | P17: =E17/E5*P5 -> 1.84 | Q17: =F17/F5*Q5 -> 1.84 | R17: M€/year | S17: Marchese et. al. Supplementary Information Table S.7
A18: Thermal Integration | B18: 13.6 | C18: 11.6 | D18: 12.8 | E18: 10.7 | F18: 13.9 | G18: M€/year | H18: Marchese et. al. Supplementary Information Table S.7 | L18: Other OPEX | M18: 129.5 | N18: 101.8 | O18: 104.6 | P18: 89 | Q18: 100 | R18: M€/year | S18: Marchese et. al. Supplementary Information Table S.7
A19: RWGS | B19: 9.7 | C19: 7.3 | D19: 7.8 | E19: 7.2 | F19: 7.8 | G19: M€/year | H19: Marchese et. al. Supplementary Information Table S.7
A20: FT | B20: 41.8 | C20: 46 | D20: 47 | E20: 39.5 | F20: 48.9 | G20: M€/year | H20: Marchese et. al. Supplementary Information Table S.7
A21: Total OPEX (non electric) | B21: =SUM(B16:B20) -> 129.5 | C21: =SUM(C16:C20) -> 101.8 | D21: =SUM(D16:D20) -> 104.6 | E21: =SUM(E16:E20) -> 89 | F21: =SUM(F16:F20) -> 100 | G21: M€/year | L21: Total OPEX (including electricity) | M21: =SUM(M16:M18) -> 275.11317 | N21: =SUM(N16:N18) -> 202.9489 | O21: =SUM(O16:O18) -> 260.01681 | P21: =SUM(P16:P18) -> 196.34829 | Q21: =SUM(Q16:Q18) -> 235.19201 | R21: M€/year
A22: Electricity
A23: Hydropower | B23: 364.92 | C23: 252.5 | D23: 293.2 | E23: 269.1 | F23: 340.1 | G23: M€/year | H23: Marchese et. al. Supplementary Information Table S.7
A24: Onshore Wind | B24: 411.51 | C24: 284.73 | D24: 330.7 | E24: 303.4 | F24: 383.5 | G24: M€/year | H24: Marchese et. al. Supplementary Information Table S.7
A25: PV | B25: 527.98 | C25: 365.32 | D25: 424.3 | E25: 389.3 | F25: 492 | G25: M€/year | H25: Marchese et. al. Supplementary Information Table S.7
A26: Geothermal | B26: 566.8 | C26: 392.18 | D26: 455.5 | E26: 417.9 | F26: 528.2 | G26: M€/year | H26: Marchese et. al. Supplementary Information Table S.7
A27: Offshore Wind | B27: 892.9 | C27: 617.81 | D27: 717.5 | E27: 658.4 | F27: 832.1 | G27: M€/year | H27: Marchese et. al. Supplementary Information Table S.7
A28: CSP | B28: 1413.11 | C28: 977.76 | D28: 1135.6 | E28: 1041.9 | F28: 1316.9 | G28: M€/year | H28: Marchese et. al. Supplementary Information Table S.7
A29: Baseload (Solar + Wind) | B29: 1866.94 | C29: 1291.77 | D29: 1500.2 | E29: 1376.6 | F29: 1739.9 | G29: M€/year | H29: Marchese et. al. Supplementary Information Table S.7
A31: Revenues | L31: Revenues
A32: Component | B32: C.1 | C32: C.2 | D32: C.3 | E32: C.4 | F32: C.5 | G32: Unit | H32: Source | I32: Note | L32: Component | M32: C.1 | N32: C.2 | O32: C.3 | P32: C.4 | Q32: C.5 | R32: Unit | S32: Source | T32: Note
A33: O2 Sale | B33: 28.5 | C33: 56.5 | D33: 45 | E33: 52.6 | F33: 62 | G33: M€/year | H33: Marchese et. al. Supplementary Information Table S.7
A34: FT C5-C11 | B34: 12.1 | C34: 37.1 | D34: 15.5 | E34: 21.6 | F34: 30.8 | G34: M€/year | H34: Marchese et. al. Supplementary Information Table S.7
A35: FT C11-C20 | B35: 16.2 | C35: 56.3 | D35: 20.5 | E35: 29 | F35: 42.4 | G35: M€/year | H35: Marchese et. al. Supplementary Information Table S.7
A36: Total Revenue | B36: =SUM(B33:B35) -> 56.8 | C36: =SUM(C33:C35) -> 149.9 | D36: =SUM(D33:D35) -> 81 | E36: =SUM(E33:E35) -> 103.2 | F36: =SUM(F33:F35) -> 135.2 | G36: M€/year | L36: Total Revenue | M36: 149.9 | N36: 81 | O36: 103.2 | P36: 135.2 | Q36: 133.7 | R36: M€/year
A38: 2021 Corrected | L38: 2050 Corrected
A39: Component | B39: C.1 | C39: C.2 | D39: C.3 | E39: C.4 | F39: C.5 | G39: Unit | L39: Component | M39: C.1 | N39: C.2 | O39: C.3 | P39: C.4 | Q39: C.5 | R39: Unit
A40: Electricity | B40: =(('Study Parameters'!C22-'Study Parameters'!C21) * Inputs!$C$8) / 10^6 -> 143.03886 | C40: =(('Study Parameters'!C23-'Study Parameters'!C21) * Inputs!$C$8) / 10^6 -> 96.015639 | D40: =(('Study Parameters'!C24-'Study Parameters'!C21) * Inputs!$C$8) / 10^6 -> 153.94408 | E40: =(('Study Parameters'!C25-'Study Parameters'!E21) * Inputs!$C$8) / 10^6 -> 112.54218 | F40: =(('Study Parameters'!C26-'Study Parameters'!F21) * Inputs!$C$8) / 10^6 -> 142.24214 | G40: M€/year | L40: Electricity | M40: =(Inputs!$C$9* 'Study Parameters'!$C$22) / 10^6 -> 26.233747 | N40: =(Inputs!C9 * 'Study Parameters'!$C$23) / 10^6 -> 18.151632 | O40: =(Inputs!C9 * 'Study Parameters'!$C$24) / 10^6 -> 28.108083 | P40: =(Inputs!C9 * 'Study Parameters'!$C$25) / 10^6 -> 19.343187 | Q40: =(Inputs!C9 * 'Study Parameters'!$C$26) / 10^6 -> 24.447868 | R40: M€/year
A41: CO2 Cost | B41: =(Inputs!$C$32*'Study Parameters'!$C$19) / 10^6 -> 296.136 | C41: =(Inputs!$C$32*'Study Parameters'!$C$19) / 10^6 -> 296.136 | D41: =(Inputs!$C$32*'Study Parameters'!$C$19) / 10^6 -> 296.136 | E41: =(Inputs!$C$32*'Study Parameters'!$C$19) / 10^6 -> 296.136 | F41: =(Inputs!$C$32*'Study Parameters'!$C$19) / 10^6 -> 296.136 | G41: M€/year | L41: Total OPEX (including electricity) | M41: =M21-M16+M40 -> 158.25375 | N41: =N21-N16+N40 -> 122.09163 | O41: =O21-O16+O40 -> 134.80808 | P41: =P21-P16+P40 -> 110.18319 | Q41: =Q21-Q16+Q40 -> 126.28787 | R41: M€/year
A42: CO2 Corrected CAPEX | B42: =B12-B5 -> 1136.76 | C42: =C12-C5 -> 827.3 | D42: =D12-D5 -> 887.03 | E42: =E12-E5 -> 844.92 | F42: =F12-F5 -> 947.66 | G42: M€ | L42: CO2 Cost | M42: =('Study Parameters'!$C$19*Inputs!$C$33) / 10^6 -> 112.968 | N42: =('Study Parameters'!$C$19*Inputs!$C$33) / 10^6 -> 112.968 | O42: =('Study Parameters'!$C$19*Inputs!$C$33) / 10^6 -> 112.968 | P42: =('Study Parameters'!$C$19*Inputs!$C$33) / 10^6 -> 112.968 | Q42: =('Study Parameters'!$C$19*Inputs!$C$33) / 10^6 -> 112.968 | R42: M€/year
A43: CO2 Corrected OPEX (non electric) | B43: =B21-B17 -> 116.9 | C43: =C21-C17 -> 91.1 | D43: =D21-D17 -> 94.1 | E43: =E21-E17 -> 79.8 | F43: =F21-F17 -> 90.8 | G43: M€/year | L43: CO2 Corrected CAPEX | M43: =M4 -> 428.2 | N43: =N4 -> 309.4 | O43: =O4 -> 321.6 | P43: =P4 -> 339 | Q43: =Q4 -> 347 | R43: M€
...

Sheet Production Cost Baseline
A1: 2021
A2: Year | B2: 0 | C2: 1 | D2: 2 | E2: 3 | F2: 4 | G2: 5 | H2: 6 | I2: 7 | J2: 8 | K2: 9 | L2: 10 | M2: 11 | N2: 12 | O2: 13 | P2: 14 | Q2: 15 | R2: 16 | S2: 17 | T2: 18 | U2: 19 | V2: 20 | W2: 21 | X2: 22 | Y2: 23 | Z2: 24 | AA2: 25
A3: C.1 Hydropower
A4: Cost (€) | B4: ='Cost Components'!$B$12 * 10^6 -> 1870760000 | C4: =('Cost Components'!$B$21 + 'Cost Components'!$B$23) * 10^6 -> 494420000 | D4: =('Cost Components'!$B$21 + 'Cost Components'!$B$23) * 10^6 -> 494420000 | E4: =('Cost Components'!$B$21 + 'Cost Components'!$B$23) * 10^6 -> 494420000 | F4: =('Cost Components'!$B$21 + 'Cost Components'!$B$23) * 10^6 -> 494420000 | G4: =('Cost Components'!$B$21 + 'Cost Components'!$B$23) * 10^6 -> 494420000 | H4: =('Cost Components'!$B$21 + 'Cost Components'!$B$23) * 10^6 -> 494420000 | I4: =('Cost Components'!$B$21 + 'Cost Components'!$B$23) * 10^6 -> 494420000 | J4: =('Cost Components'!$B$21 + 'Cost Components'!$B$23) * 10^6 -> 494420000 | ... AA4: =('Cost Components'!$B$21 + 'Cost Components'!$B$23) * 10^6 -> 494420000
A5: Revenue (€) | B5: 0 | C5: ='Cost Components'!$B$36*10^6 -> 56800000 | D5: ='Cost Components'!$B$36*10^6 -> 56800000 | E5: ='Cost Components'!$B$36*10^6 -> 56800000 | F5: ='Cost Components'!$B$36*10^6 -> 56800000 | G5: ='Cost Components'!$B$36*10^6 -> 56800000 | H5: ='Cost Components'!$B$36*10^6 -> 56800000 | I5: ='Cost Components'!$B$36*10^6 -> 56800000 | J5: ='Cost Components'!$B$36*10^6 -> 56800000 | ... AA5: ='Cost Components'!$B$36*10^6 -> 56800000
A6: Free Cash Flow (€) | B6: =B4-B5 -> 1870760000 | C6: =C4-C5 -> 437620000 | D6: =D4-D5 -> 437620000 | E6: =E4-E5 -> 437620000 | F6: =F4-F5 -> 437620000 | G6: =G4-G5 -> 437620000 | H6: =H4-H5 -> 437620000 | I6: =I4-I5 -> 437620000 | ... AA6: =AA4-AA5 -> 437620000
A7: Discounted Cash Flow (€) | B7: =B6/(1+'Study Parameters'!$C$4) ^'Production Cost Baseline'!B$2 -> 1870760000 | C7: =C6/(1+'Study Parameters'!$C$4) ^'Production Cost Baseline'!C$2 -> 4.0708837e+08 | D7: =D6/(1+'Study Parameters'!$C$4) ^'Production Cost Baseline'!D$2 -> 3.7868686e+08 | E7: =E6/(1+'Study Parameters'!$C$4) ^'Production Cost Baseline'!E$2 -> 3.5226684e+08 | F7: =F6/(1+'Study Parameters'!$C$4) ^'Production Cost Baseline'!F$2 -> 3.2769009e+08 | G7: =G6/(1+'Study Parameters'!$C$4) ^'Production Cost Baseline'!G$2 -> 3.0482799e+08 | H7: =H6/(1+'Study Parameters'!$C$4) ^'Production Cost Baseline'!H$2 -> 2.8356092e+08 | I7: =I6/(1+'Study Parameters'!$C$4) ^'Production Cost Baseline'!I$2 -> 2.637776e+08 | ... AA7: =AA6/(1+'Study Parameters'!$C$4) ^'Production Cost Baseline'!AA$2 -> 71760516
A8: Fuel Production (kg) | B8: 0 | C8: ='Study Parameters'!$C$12*'Study Parameters'!$C$8 * 10^3 -> 69600000 | D8: ='Study Parameters'!$C$12*'Study Parameters'!$C$8 * 10^3 -> 69600000 | E8: ='Study Parameters'!$C$12*'Study Parameters'!$C$8 * 10^3 -> 69600000 | F8: ='Study Parameters'!$C$12*'Study Parameters'!$C$8 * 10^3 -> 69600000 | G8: ='Study Parameters'!$C$12*'Study Parameters'!$C$8 * 10^3 -> 69600000 | H8: ='Study Parameters'!$C$12*'Study Parameters'!$C$8 * 10^3 -> 69600000 | I8: ='Study Parameters'!$C$12*'Study Parameters'!$C$8 * 10^3 -> 69600000 | J8: ='Study Parameters'!$C$12*'Study Parameters'!$C$8 * 10^3 -> 69600000 | ... AA8: ='Study Parameters'!$C$12*'Study Parameters'!$C$8 * 10^3 -> 69600000
A9: Discounted Fuel Production (kg) | B9: 0 | C9: =C8/(1+'Study Parameters'!$C$4) ^'Production Cost Baseline'!C$2 -> 64744186 | D9: =D8/(1+'Study Parameters'!$C$4) ^'Production Cost Baseline'!D$2 -> 60227150 | E9: =E8/(1+'Study Parameters'!$C$4) ^'Production Cost Baseline'!E$2 -> 56025256 | F9: =F8/(1+'Study Parameters'!$C$4) ^'Production Cost Baseline'!F$2 -> 52116517 | G9: =G8/(1+'Study Parameters'!$C$4) ^'Production Cost Baseline'!G$2 -> 48480481 | H9: =H8/(1+'Study Parameters'!$C$4) ^'Production Cost Baseline'!H$2 -> 45098122 | I9: =I8/(1+'Study Parameters'!$C$4) ^'Production Cost Baseline'!I$2 -> 41951741 | J9: =J8/(1+'Study Parameters'!$C$4) ^'Production Cost Baseline'!J$2 -> 39024875 | ... AA9: =AA8/(1+'Study Parameters'!$C$4) ^'Production Cost Baseline'!AA$2 -> 11412943
A11: Production Cost of Fuel (€/kg) | B11: =SUM(B7:AA7) / SUM(C9:AA9) -> 8.6989531
A12: Production Cost of Fuel (€/l) | B12: =B11 * Inputs!$C$15 -> 6.9852593
A14: C.1 Baseload
A15: Cost (€) | B15: ='Cost Components'!$B$12 * 10^6 -> 1870760000 | C15: =('Cost Components'!$B$21 + 'Cost Components'!$B$29) * 10^6 -> 1996440000 | D15: =('Cost Components'!$B$21 + 'Cost Components'!$B$29) * 10^6 -> 1996440000 | E15: =('Cost Components'!$B$21 + 'Cost Components'!$B$29) * 10^6 -> 1996440000 | F15: =('Cost Components'!$B$21 + 'Cost Components'!$B$29) * 10^6 -> 1996440000 | G15: =('Cost Components'!$B$21 + 'Cost Components'!$B$29) * 10^6 -> 1996440000 | H15: =('Cost Components'!$B$21 + 'Cost Components'!$B$29) * 10^6 -> 1996440000 | I15: =('Cost Components'!$B$21 + 'Cost Components'!$B$29) * 10^6 -> 1996440000 | J15: =('Cost Components'!$B$21 + 'Cost Components'!$B$29) * 10^6 -> 1996440000 | ... AA15: =('Cost Components'!$B$21 + 'Cost Components'!$B$29) * 10^6 -> 1996440000
A16: Revenue (€) | B16: 0 | C16: ='Cost Components'!$B$36*10^6 -> 56800000 | D16: ='Cost Components'!$B$36*10^6 -> 56800000 | E16: ='Cost Components'!$B$36*10^6 -> 56800000 | F16: ='Cost Components'!$B$36*10^6 -> 56800000 | G16: ='Cost Components'!$B$36*10^6 -> 56800000 | H16: ='Cost Components'!$B$36*10^6 -> 56800000 | I16: ='Cost Components'!$B$36*10^6 -> 56800000 | J16: ='Cost Components'!$B$36*10^6 -> 56800000 | ... AA16: ='Cost Components'!$B$36*10^6 -> 56800000
A17: Free Cash Flow (€) | B17: =B15-B16 -> 1870760000 | C17: =C15-C16 -> 1939640000 | D17: =D15-D16 -> 1939640000 | E17: =E15-E16 -> 1939640000 | F17: =F15-F16 -> 1939640000 | G17: =G15-G16 -> 1939640000 | H17: =H15-H16 -> 1939640000 | I17: =I15-I16 -> 1939640000 | ... AA17: =AA15-AA16 -> 1939640000
A18: Discounted Cash Flow (€) | B18: =B17/(1+'Study Parameters'!$C$4) ^'Production Cost Baseline'!B$2 -> 1870760000 | C18: =C17/(1+'Study Parameters'!$C$4) ^'Production Cost Baseline'!C$2 -> 1.8043163e+09 | D18: =D17/(1+'Study Parameters'!$C$4) ^'Production Cost Baseline'!D$2 -> 1.6784337e+09 | E18: =E17/(1+'Study Parameters'!$C$4) ^'Production Cost Baseline'!E$2 -> 1.5613337e+09 | F18: =F17/(1+'Study Parameters'!$C$4) ^'Production Cost Baseline'!F$2 -> 1.4524035e+09 | G18: =G17/(1+'Study Parameters'!$C$4) ^'Production Cost Baseline'!G$2 -> 1.351073e+09 | H18: =H17/(1+'Study Parameters'!$C$4) ^'Production Cost Baseline'!H$2 -> 1.2568121e+09 | I18: =I17/(1+'Study Parameters'!$C$4) ^'Production Cost Baseline'!I$2 -> 1.1691275e+09 | ... AA18: =AA17/(1+'Study Parameters'!$C$4) ^'Production Cost Baseline'!AA$2 -> 3.1806034e+08
A19: Fuel Production (kg) | B19: 0 | C19: ='Study Parameters'!$C$12*'Study Parameters'!$C$8 * 10^3 -> 69600000 | D19: ='Study Parameters'!$C$12*'Study Parameters'!$C$8 * 10^3 -> 69600000 | E19: ='Study Parameters'!$C$12*'Study Parameters'!$C$8 * 10^3 -> 69600000 | F19: ='Study Parameters'!$C$12*'Study Parameters'!$C$8 * 10^3 -> 69600000 | G19: ='Study Parameters'!$C$12*'Study Parameters'!$C$8 * 10^3 -> 69600000 | H19: ='Study Parameters'!$C$12*'Study Parameters'!$C$8 * 10^3 -> 69600000 | I19: ='Study Parameters'!$C$12*'Study Parameters'!$C$8 * 10^3 -> 69600000 | J19: ='Study Parameters'!$C$12*'Study Parameters'!$C$8 * 10^3 -> 69600000 | ... AA19: ='Study Parameters'!$C$12*'Study Parameters'!$C$8 * 10^3 -> 69600000
A20: Discounted Fuel Production (kg) | B20: 0 | C20: =C19/(1+'Study Parameters'!$C$4) ^'Production Cost Baseline'!C$2 -> 64744186 | D20: =D19/(1+'Study Parameters'!$C$4) ^'Production Cost Baseline'!D$2 -> 60227150 | E20: =E19/(1+'Study Parameters'!$C$4) ^'Production Cost Baseline'!E$2 -> 56025256 | F20: =F19/(1+'Study Parameters'!$C$4) ^'Production Cost Baseline'!F$2 -> 52116517 | G20: =G19/(1+'Study Parameters'!$C$4) ^'Production Cost Baseline'!G$2 -> 48480481 | H20: =H19/(1+'Study Parameters'!$C$4) ^'Production Cost Baseline'!H$2 -> 45098122 | I20: =I19/(1+'Study Parameters'!$C$4) ^'Production Cost Baseline'!I$2 -> 41951741 | J20: =J19/(1+'Study Parameters'!$C$4) ^'Production Cost Baseline'!J$2 -> 39024875 | ... AA20: =AA19/(1+'Study Parameters'!$C$4) ^'Production Cost Baseline'!AA$2 -> 11412943
A22: Production Cost of Fuel (€/kg) | B22: =SUM(B18:AA18) / SUM(C20:AA20) -> 30.2797
A23: Production Cost of Fuel (€/l) | B23: =B22 * Inputs!$C$15 -> 24.314599
A25: C.2 Hydropower
A26: Cost (€) | B26: ='Cost Components'!$C$12 * 10^6 -> 1525300000 | C26: =('Cost Components'!$C$21 + 'Cost Components'!$C$23) * 10^6 -> 354300000 | D26: =('Cost Components'!$C$21 + 'Cost Components'!$C$23) * 10^6 -> 354300000 | E26: =('Cost Components'!$C$21 + 'Cost Components'!$C$23) * 10^6 -> 354300000 | F26: =('Cost Components'!$C$21 + 'Cost Components'!$C$23) * 10^6 -> 354300000 | G26: =('Cost Components'!$C$21 + 'Cost Components'!$C$23) * 10^6 -> 354300000 | H26: =('Cost Components'!$C$21 + 'Cost Components'!$C$23) * 10^6 -> 354300000 | I26: =('Cost Components'!$C$21 + 'Cost Components'!$C$23) * 10^6 -> 354300000 | J26: =('Cost Components'!$C$21 + 'Cost Components'!$C$23) * 10^6 -> 354300000 | ... AA26: =('Cost Components'!$C$21 + 'Cost Components'!$C$23) * 10^6 -> 354300000
A27: Revenue (€) | B27: 0 | C27: ='Cost Components'!$C$36*10^6 -> 1.499e+08 | D27: ='Cost Components'!$C$36*10^6 -> 1.499e+08 | E27: ='Cost Components'!$C$36*10^6 -> 1.499e+08 | F27: ='Cost Components'!$C$36*10^6 -> 1.499e+08 | G27: ='Cost Components'!$C$36*10^6 -> 1.499e+08 | H27: ='Cost Components'!$C$36*10^6 -> 1.499e+08 | I27: ='Cost Components'!$C$36*10^6 -> 1.499e+08 | J27: ='Cost Components'!$C$36*10^6 -> 1.499e+08 | ... AA27: ='Cost Components'!$C$36*10^6 -> 1.499e+08
A28: Free Cash Flow (€) | B28: =B26-B27 -> 1525300000 | C28: =C26-C27 -> 2.044e+08 | D28: =D26-D27 -> 2.044e+08 | E28: =E26-E27 -> 2.044e+08 | F28: =F26-F27 -> 2.044e+08 | G28: =G26-G27 -> 2.044e+08 | H28: =H26-H27 -> 2.044e+08 | I28: =I26-I27 -> 2.044e+08 | ... AA28: =AA26-AA27 -> 2.044e+08
A29: Discounted Cash Flow (€) | B29: =B28/(1+'Study Parameters'!$C$4) ^'Production Cost Baseline'!B$2 -> 1525300000 | C29: =C28/(1+'Study Parameters'!$C$4) ^'Production Cost Baseline'!C$2 -> 1.9013953e+08 | D29: =D28/(1+'Study Parameters'!$C$4) ^'Production Cost Baseline'!D$2 -> 1.7687399e+08 | E29: =E28/(1+'Study Parameters'!$C$4) ^'Production Cost Baseline'!E$2 -> 1.6453394e+08 | F29: =F28/(1+'Study Parameters'!$C$4) ^'Production Cost Baseline'!F$2 -> 1.5305483e+08 | G29: =G28/(1+'Study Parameters'!$C$4) ^'Production Cost Baseline'!G$2 -> 1.4237658e+08 | H29: =H28/(1+'Study Parameters'!$C$4) ^'Production Cost Baseline'!H$2 -> 1.3244333e+08 | I29: =I28/(1+'Study Parameters'!$C$4) ^'Production Cost Baseline'!I$2 -> 1.232031e+08 | ... AA29: =AA28/(1+'Study Parameters'!$C$4) ^'Production Cost Baseline'!AA$2 -> 33517320
A30: Fuel Production (kg) | B30: 0 | C30: ='Study Parameters'!$C$13*'Study Parameters'!$C$8 * 10^3 -> 28000000 | D30: ='Study Parameters'!$C$13*'Study Parameters'!$C$8 * 10^3 -> 28000000 | E30: ='Study Parameters'!$C$13*'Study Parameters'!$C$8 * 10^3 -> 28000000 | F30: ='Study Parameters'!$C$13*'Study Parameters'!$C$8 * 10^3 -> 28000000 | G30: ='Study Parameters'!$C$13*'Study Parameters'!$C$8 * 10^3 -> 28000000 | H30: ='Study Parameters'!$C$13*'Study Parameters'!$C$8 * 10^3 -> 28000000 | I30: ='Study Parameters'!$C$13*'Study Parameters'!$C$8 * 10^3 -> 28000000 | J30: ='Study Parameters'!$C$13*'Study Parameters'!$C$8 * 10^3 -> 28000000 | ... AA30: ='Study Parameters'!$C$13*'Study Parameters'!$C$8 * 10^3 -> 28000000
A31: Discounted Fuel Production (kg) | B31: 0 | C31: =C30/(1+'Study Parameters'!$C$4) ^'Production Cost Baseline'!C$2 -> 26046512 | D31: =D30/(1+'Study Parameters'!$C$4) ^'Production Cost Baseline'!D$2 -> 24229313 | E31: =E30/(1+'Study Parameters'!$C$4) ^'Production Cost Baseline'!E$2 -> 22538896 | F31: =F30/(1+'Study Parameters'!$C$4) ^'Production Cost Baseline'!F$2 -> 20966415 | G31: =G30/(1+'Study Parameters'!$C$4) ^'Production Cost Baseline'!G$2 -> 19503642 | H31: =H30/(1+'Study Parameters'!$C$4) ^'Production Cost Baseline'!H$2 -> 18142923 | I31: =I30/(1+'Study Parameters'!$C$4) ^'Production Cost Baseline'!I$2 -> 16877137 | J31: =J30/(1+'Study Parameters'!$C$4) ^'Production Cost Baseline'!J$2 -> 15699663 | ... AA31: =AA30/(1+'Study Parameters'!$C$4) ^'Production Cost Baseline'!AA$2 -> 4591413.7
A33: Production Cost of Fuel (€/kg) | B33: =SUM(B29:AA29) / SUM(C31:AA31) -> 12.186989
A34: Production Cost of Fuel (€/l) | B34: =B33 * Inputs!$C$15 -> 9.786152
A36: C.2 Baseload
A37: Cost (€) | B37: ='Cost Components'!$C$12 * 10^6 -> 1525300000 | C37: =('Cost Components'!$C$21 + 'Cost Components'!$C$29) * 10^6 -> 1393570000 | D37: =('Cost Components'!$C$21 + 'Cost Components'!$C$29) * 10^6 -> 1393570000 | E37: =('Cost Components'!$C$21 + 'Cost Components'!$C$29) * 10^6 -> 1393570000 | F37: =('Cost Components'!$C$21 + 'Cost Components'!$C$29) * 10^6 -> 1393570000 | G37: =('Cost Components'!$C$21 + 'Cost Components'!$C$29) * 10^6 -> 1393570000 | H37: =('Cost Components'!$C$21 + 'Cost Components'!$C$29) * 10^6 -> 1393570000 | I37: =('Cost Components'!$C$21 + 'Cost Components'!$C$29) * 10^6 -> 1393570000 | J37: =('Cost Components'!$C$21 + 'Cost Components'!$C$29) * 10^6 -> 1393570000 | ... AA37: =('Cost Components'!$C$21 + 'Cost Components'!$C$29) * 10^6 -> 1393570000
A38: Revenue (€) | B38: 0 | C38: ='Cost Components'!$C$36*10^6 -> 1.499e+08 | D38: ='Cost Components'!$C$36*10^6 -> 1.499e+08 | E38: ='Cost Components'!$C$36*10^6 -> 1.499e+08 | F38: ='Cost Components'!$C$36*10^6 -> 1.499e+08 | G38: ='Cost Components'!$C$36*10^6 -> 1.499e+08 | H38: ='Cost Components'!$C$36*10^6 -> 1.499e+08 | I38: ='Cost Components'!$C$36*10^6 -> 1.499e+08 | J38: ='Cost Components'!$C$36*10^6 -> 1.499e+08 | ... AA38: ='Cost Components'!$C$36*10^6 -> 1.499e+08
A39: Free Cash Flow (€) | B39: =B37-B38 -> 1525300000 | C39: =C37-C38 -> 1243670000 | D39: =D37-D38 -> 1243670000 | E39: =E37-E38 -> 1243670000 | F39: =F37-F38 -> 1243670000 | G39: =G37-G38 -> 1243670000 | H39: =H37-H38 -> 1243670000 | I39: =I37-I38 -> 1243670000 | ... AA39: =AA37-AA38 -> 1243670000
A40: Discounted Cash Flow (€) | B40: =B39/(1+'Study Parameters'!$C$4) ^'Production Cost Baseline'!B$2 -> 1525300000 | C40: =C39/(1+'Study Parameters'!$C$4) ^'Production Cost Baseline'!C$2 -> 1.1569023e+09 | D40: =D39/(1+'Study Parameters'!$C$4) ^'Production Cost Baseline'!D$2 -> 1.0761882e+09 | E40: =E39/(1+'Study Parameters'!$C$4) ^'Production Cost Baseline'!E$2 -> 1.0011053e+09 | F40: =F39/(1+'Study Parameters'!$C$4) ^'Production Cost Baseline'!F$2 -> 9.3126075e+08 | G40: =G39/(1+'Study Parameters'!$C$4) ^'Production Cost Baseline'!G$2 -> 8.6628907e+08 | H40: =H39/(1+'Study Parameters'!$C$4) ^'Production Cost Baseline'!H$2 -> 8.058503e+08 | I40: =I39/(1+'Study Parameters'!$C$4) ^'Production Cost Baseline'!I$2 -> 7.4962819e+08 | ... AA40: =AA39/(1+'Study Parameters'!$C$4) ^'Production Cost Baseline'!AA$2 -> 2.0393584e+08
A41: Fuel Production (kg) | B41: 0 | C41: ='Study Parameters'!$C$13*'Study Parameters'!$C$8 * 10^3 -> 28000000 | D41: ='Study Parameters'!$C$13*'Study Parameters'!$C$8 * 10^3 -> 28000000 | E41: ='Study Parameters'!$C$13*'Study Parameters'!$C$8 * 10^3 -> 28000000 | F41: ='Study Parameters'!$C$13*'Study Parameters'!$C$8 * 10^3 -> 28000000 | G41: ='Study Parameters'!$C$13*'Study Parameters'!$C$8 * 10^3 -> 28000000 | H41: ='Study Parameters'!$C$13*'Study Parameters'!$C$8 * 10^3 -> 28000000 | I41: ='Study Parameters'!$C$13*'Study Parameters'!$C$8 * 10^3 -> 28000000 | J41: ='Study Parameters'!$C$13*'Study Parameters'!$C$8 * 10^3 -> 28000000 | ... AA41: ='Study Parameters'!$C$13*'Study Parameters'!$C$8 * 10^3 -> 28000000
A42: Discounted Fuel Production (kg) | B42: 0 | C42: =C41/(1+'Study Parameters'!$C$4) ^'Production Cost Baseline'!C$2 -> 26046512 | D42: =D41/(1+'Study Parameters'!$C$4) ^'Production Cost Baseline'!D$2 -> 24229313 | E42: =E41/(1+'Study Parameters'!$C$4) ^'Production Cost Baseline'!E$2 -> 22538896 | F42: =F41/(1+'Study Parameters'!$C$4) ^'Production Cost Baseline'!F$2 -> 20966415 | G42: =G41/(1+'Study Parameters'!$C$4) ^'Production Cost Baseline'!G$2 -> 19503642 | H42: =H41/(1+'Study Parameters'!$C$4) ^'Production Cost Baseline'!H$2 -> 18142923 | I42: =I41/(1+'Study Parameters'!$C$4) ^'Production Cost Baseline'!I$2 -> 16877137 | J42: =J41/(1+'Study Parameters'!$C$4) ^'Production Cost Baseline'!J$2 -> 15699663 | ... AA42: =AA41/(1+'Study Parameters'!$C$4) ^'Production Cost Baseline'!AA$2 -> 4591413.7
A44: Production Cost of Fuel (€/kg) | B44: =SUM(B40:AA40) / SUM(C42:AA42) -> 49.303775
A45: Production Cost of Fuel (€/l) | B45: =B44 * Inputs!$C$15 -> 39.590931
A47: C.3 Hydropower
A48: Cost (€) | B48: ='Cost Components'!$D$12 * 10^6 -> 1594030000 | C48: =('Cost Components'!$D$21 + 'Cost Components'!$D$23) * 10^6 -> 3.978e+08 | D48: =('Cost Components'!$D$21 + 'Cost Components'!$D$23) * 10^6 -> 3.978e+08 | E48: =('Cost Components'!$D$21 + 'Cost Components'!$D$23) * 10^6 -> 3.978e+08 | F48: =('Cost Components'!$D$21 + 'Cost Components'!$D$23) * 10^6 -> 3.978e+08 | G48: =('Cost Components'!$D$21 + 'Cost Components'!$D$23) * 10^6 -> 3.978e+08 | H48: =('Cost Components'!$D$21 + 'Cost Components'!$D$23) * 10^6 -> 3.978e+08 | I48: =('Cost Components'!$D$21 + 'Cost Components'!$D$23) * 10^6 -> 3.978e+08 | J48: =('Cost Components'!$D$21 + 'Cost Components'!$D$23) * 10^6 -> 3.978e+08 | ... AA48: =('Cost Components'!$D$21 + 'Cost Components'!$D$23) * 10^6 -> 3.978e+08
...

Sheet LCOE Corrected Production Cost 
A1: 2021
A2: Year | B2: 0 | C2: 1 | D2: 2 | E2: 3 | F2: 4 | G2: 5 | H2: 6 | I2: 7 | J2: 8 | K2: 9 | L2: 10 | M2: 11 | N2: 12 | O2: 13 | P2: 14 | Q2: 15 | R2: 16 | S2: 17 | T2: 18 | U2: 19 | V2: 20 | W2: 21 | X2: 22 | Y2: 23 | Z2: 24 | AA2: 25
A3: C.1 Baseload
A4: Cost (€) | B4: ='Cost Components'!$B$12 * 10^6 -> 1870760000 | C4: =('Cost Components'!$B$21 + 'Cost Components'!$B$40) * 10^6 -> 2.7253886e+08 | D4: =('Cost Components'!$B$21 + 'Cost Components'!$B$40) * 10^6 -> 2.7253886e+08 | E4: =('Cost Components'!$B$21 + 'Cost Components'!$B$40) * 10^6 -> 2.7253886e+08 | F4: =('Cost Components'!$B$21 + 'Cost Components'!$B$40) * 10^6 -> 2.7253886e+08 | G4: =('Cost Components'!$B$21 + 'Cost Components'!$B$40) * 10^6 -> 2.7253886e+08 | H4: =('Cost Components'!$B$21 + 'Cost Components'!$B$40) * 10^6 -> 2.7253886e+08 | I4: =('Cost Components'!$B$21 + 'Cost Components'!$B$40) * 10^6 -> 2.7253886e+08 | J4: =('Cost Components'!$B$21 + 'Cost Components'!$B$40) * 10^6 -> 2.7253886e+08 | ... AA4: =('Cost Components'!$B$21 + 'Cost Components'!$B$40) * 10^6 -> 2.7253886e+08
A5: Revenue (€) | B5: 0 | C5: ='Cost Components'!$B$36*10^6 -> 56800000 | D5: ='Cost Components'!$B$36*10^6 -> 56800000 | E5: ='Cost Components'!$B$36*10^6 -> 56800000 | F5: ='Cost Components'!$B$36*10^6 -> 56800000 | G5: ='Cost Components'!$B$36*10^6 -> 56800000 | H5: ='Cost Components'!$B$36*10^6 -> 56800000 | I5: ='Cost Components'!$B$36*10^6 -> 56800000 | J5: ='Cost Components'!$B$36*10^6 -> 56800000 | ... AA5: ='Cost Components'!$B$36*10^6 -> 56800000
A6: Free Cash Flow (€) | B6: =B4-B5 -> 1870760000 | C6: =C4-C5 -> 2.1573886e+08 | D6: =D4-D5 -> 2.1573886e+08 | E6: =E4-E5 -> 2.1573886e+08 | F6: =F4-F5 -> 2.1573886e+08 | G6: =G4-G5 -> 2.1573886e+08 | H6: =H4-H5 -> 2.1573886e+08 | I6: =I4-I5 -> 2.1573886e+08 | ... AA6: =AA4-AA5 -> 2.1573886e+08
A7: Discounted Cash Flow (€) | B7: =B6/(1+'Study Parameters'!$C$4) ^'Production Cost Baseline'!B$2 -> 1870760000 | C7: =C6/(1+'Study Parameters'!$C$4) ^'Production Cost Baseline'!C$2 -> 2.0068731e+08 | D7: =D6/(1+'Study Parameters'!$C$4) ^'Production Cost Baseline'!D$2 -> 1.8668587e+08 | E7: =E6/(1+'Study Parameters'!$C$4) ^'Production Cost Baseline'!E$2 -> 1.7366127e+08 | F7: =F6/(1+'Study Parameters'!$C$4) ^'Production Cost Baseline'!F$2 -> 1.6154537e+08 | G7: =G6/(1+'Study Parameters'!$C$4) ^'Production Cost Baseline'!G$2 -> 1.5027476e+08 | H7: =H6/(1+'Study Parameters'!$C$4) ^'Production Cost Baseline'!H$2 -> 1.3979048e+08 | I7: =I6/(1+'Study Parameters'!$C$4) ^'Production Cost Baseline'!I$2 -> 1.3003765e+08 | ... AA7: =AA6/(1+'Study Parameters'!$C$4) ^'Production Cost Baseline'!AA$2 -> 35376655
A8: Fuel Production (kg) | B8: 0 | C8: ='Study Parameters'!$C$12*'Study Parameters'!$C$8 * 10^3 -> 69600000 | D8: ='Study Parameters'!$C$12*'Study Parameters'!$C$8 * 10^3 -> 69600000 | E8: ='Study Parameters'!$C$12*'Study Parameters'!$C$8 * 10^3 -> 69600000 | F8: ='Study Parameters'!$C$12*'Study Parameters'!$C$8 * 10^3 -> 69600000 | G8: ='Study Parameters'!$C$12*'Study Parameters'!$C$8 * 10^3 -> 69600000 | H8: ='Study Parameters'!$C$12*'Study Parameters'!$C$8 * 10^3 -> 69600000 | I8: ='Study Parameters'!$C$12*'Study Parameters'!$C$8 * 10^3 -> 69600000 | J8: ='Study Parameters'!$C$12*'Study Parameters'!$C$8 * 10^3 -> 69600000 | ... AA8: ='Study Parameters'!$C$12*'Study Parameters'!$C$8 * 10^3 -> 69600000
A9: Discounted Fuel Production (kg) | B9: 0 | C9: =C8/(1+'Study Parameters'!$C$4) ^'Production Cost Baseline'!C$2 -> 64744186 | D9: =D8/(1+'Study Parameters'!$C$4) ^'Production Cost Baseline'!D$2 -> 60227150 | E9: =E8/(1+'Study Parameters'!$C$4) ^'Production Cost Baseline'!E$2 -> 56025256 | F9: =F8/(1+'Study Parameters'!$C$4) ^'Production Cost Baseline'!F$2 -> 52116517 | G9: =G8/(1+'Study Parameters'!$C$4) ^'Production Cost Baseline'!G$2 -> 48480481 | H9: =H8/(1+'Study Parameters'!$C$4) ^'Production Cost Baseline'!H$2 -> 45098122 | I9: =I8/(1+'Study Parameters'!$C$4) ^'Production Cost Baseline'!I$2 -> 41951741 | J9: =J8/(1+'Study Parameters'!$C$4) ^'Production Cost Baseline'!J$2 -> 39024875 | ... AA9: =AA8/(1+'Study Parameters'!$C$4) ^'Production Cost Baseline'!AA$2 -> 11412943
A11: Production Cost of Fuel (€/kg) | B11: =SUM(B7:AA7) / SUM(C9:AA9) -> 5.5110056
A12: Production Cost of Fuel (€/l) | B12: =B11 * Inputs!$C$15 -> 4.4253375
A14: C.2 Baseload
A15: Cost (€) | B15: ='Cost Components'!$C$12 * 10^6 -> 1525300000 | C15: =('Cost Components'!$C$21 + 'Cost Components'!$C$40) * 10^6 -> 1.9781564e+08 | D15: =('Cost Components'!$C$21 + 'Cost Components'!$C$40) * 10^6 -> 1.9781564e+08 | E15: =('Cost Components'!$C$21 + 'Cost Components'!$C$40) * 10^6 -> 1.9781564e+08 | F15: =('Cost Components'!$C$21 + 'Cost Components'!$C$40) * 10^6 -> 1.9781564e+08 | G15: =('Cost Components'!$C$21 + 'Cost Components'!$C$40) * 10^6 -> 1.9781564e+08 | H15: =('Cost Components'!$C$21 + 'Cost Components'!$C$40) * 10^6 -> 1.9781564e+08 | I15: =('Cost Components'!$C$21 + 'Cost Components'!$C$40) * 10^6 -> 1.9781564e+08 | J15: =('Cost Components'!$C$21 + 'Cost Components'!$C$40) * 10^6 -> 1.9781564e+08 | ... AA15: =('Cost Components'!$C$21 + 'Cost Components'!$C$40) * 10^6 -> 1.9781564e+08
A16: Revenue (€) | B16: 0 | C16: ='Cost Components'!$C$36*10^6 -> 1.499e+08 | D16: ='Cost Components'!$C$36*10^6 -> 1.499e+08 | E16: ='Cost Components'!$C$36*10^6 -> 1.499e+08 | F16: ='Cost Components'!$C$36*10^6 -> 1.499e+08 | G16: ='Cost Components'!$C$36*10^6 -> 1.499e+08 | H16: ='Cost Components'!$C$36*10^6 -> 1.499e+08 | I16: ='Cost Components'!$C$36*10^6 -> 1.499e+08 | J16: ='Cost Components'!$C$36*10^6 -> 1.499e+08 | ... AA16: ='Cost Components'!$C$36*10^6 -> 1.499e+08
A17: Free Cash Flow (€) | B17: =B15-B16 -> 1525300000 | C17: =C15-C16 -> 47915639 | D17: =D15-D16 -> 47915639 | E17: =E15-E16 -> 47915639 | F17: =F15-F16 -> 47915639 | G17: =G15-G16 -> 47915639 | H17: =H15-H16 -> 47915639 | I17: =I15-I16 -> 47915639 | ... AA17: =AA15-AA16 -> 47915639
A18: Discounted Cash Flow (€) | B18: =B17/(1+'Study Parameters'!$C$4) ^'Production Cost Baseline'!B$2 -> 1525300000 | C18: =C17/(1+'Study Parameters'!$C$4) ^'Production Cost Baseline'!C$2 -> 44572688 | D18: =D17/(1+'Study Parameters'!$C$4) ^'Production Cost Baseline'!D$2 -> 41462965 | E18: =E17/(1+'Study Parameters'!$C$4) ^'Production Cost Baseline'!E$2 -> 38570200 | F18: =F17/(1+'Study Parameters'!$C$4) ^'Production Cost Baseline'!F$2 -> 35879256 | G18: =G17/(1+'Study Parameters'!$C$4) ^'Production Cost Baseline'!G$2 -> 33376052 | H18: =H17/(1+'Study Parameters'!$C$4) ^'Production Cost Baseline'!H$2 -> 31047490 | I18: =I17/(1+'Study Parameters'!$C$4) ^'Production Cost Baseline'!I$2 -> 28881386 | ... AA18: =AA17/(1+'Study Parameters'!$C$4) ^'Production Cost Baseline'!AA$2 -> 7857161.5
A19: Fuel Production (kg) | B19: 0 | C19: ='Study Parameters'!$C$13*'Study Parameters'!$C$8 * 10^3 -> 28000000 | D19: ='Study Parameters'!$C$13*'Study Parameters'!$C$8 * 10^3 -> 28000000 | E19: ='Study Parameters'!$C$13*'Study Parameters'!$C$8 * 10^3 -> 28000000 | F19: ='Study Parameters'!$C$13*'Study Parameters'!$C$8 * 10^3 -> 28000000 | G19: ='Study Parameters'!$C$13*'Study Parameters'!$C$8 * 10^3 -> 28000000 | H19: ='Study Parameters'!$C$13*'Study Parameters'!$C$8 * 10^3 -> 28000000 | I19: ='Study Parameters'!$C$13*'Study Parameters'!$C$8 * 10^3 -> 28000000 | J19: ='Study Parameters'!$C$13*'Study Parameters'!$C$8 * 10^3 -> 28000000 | ... AA19: ='Study Parameters'!$C$13*'Study Parameters'!$C$8 * 10^3 -> 28000000
A20: Discounted Fuel Production (kg) | B20: 0 | C20: =C19/(1+'Study Parameters'!$C$4) ^'Production Cost Baseline'!C$2 -> 26046512 | D20: =D19/(1+'Study Parameters'!$C$4) ^'Production Cost Baseline'!D$2 -> 24229313 | E20: =E19/(1+'Study Parameters'!$C$4) ^'Production Cost Baseline'!E$2 -> 22538896 | F20: =F19/(1+'Study Parameters'!$C$4) ^'Production Cost Baseline'!F$2 -> 20966415 | G20: =G19/(1+'Study Parameters'!$C$4) ^'Production Cost Baseline'!G$2 -> 19503642 | H20: =H19/(1+'Study Parameters'!$C$4) ^'Production Cost Baseline'!H$2 -> 18142923 | I20: =I19/(1+'Study Parameters'!$C$4) ^'Production Cost Baseline'!I$2 -> 16877137 | J20: =J19/(1+'Study Parameters'!$C$4) ^'Production Cost Baseline'!J$2 -> 15699663 | ... AA20: =AA19/(1+'Study Parameters'!$C$4) ^'Production Cost Baseline'!AA$2 -> 4591413.7
A22: Production Cost of Fuel (€/kg) | B22: =SUM(B18:AA18) / SUM(C20:AA20) -> 6.5982617
A23: Production Cost of Fuel (€/l) | B23: =B22 * Inputs!$C$15 -> 5.2984041
A25: C.3 Baseload
A26: Cost (€) | B26: ='Cost Components'!$D$12 * 10^6 -> 1594030000 | C26: =('Cost Components'!$D$21 + 'Cost Components'!$D$40) * 10^6 -> 2.5854408e+08 | D26: =('Cost Components'!$D$21 + 'Cost Components'!$D$40) * 10^6 -> 2.5854408e+08 | E26: =('Cost Components'!$D$21 + 'Cost Components'!$D$40) * 10^6 -> 2.5854408e+08 | F26: =('Cost Components'!$D$21 + 'Cost Components'!$D$40) * 10^6 -> 2.5854408e+08 | G26: =('Cost Components'!$D$21 + 'Cost Components'!$D$40) * 10^6 -> 2.5854408e+08 | H26: =('Cost Components'!$D$21 + 'Cost Components'!$D$40) * 10^6 -> 2.5854408e+08 | I26: =('Cost Components'!$D$21 + 'Cost Components'!$D$40) * 10^6 -> 2.5854408e+08 | J26: =('Cost Components'!$D$21 + 'Cost Components'!$D$40) * 10^6 -> 2.5854408e+08 | ... AA26: =('Cost Components'!$D$21 + 'Cost Components'!$D$40) * 10^6 -> 2.5854408e+08
A27: Revenue (€) | B27: 0 | C27: ='Cost Components'!$D$36*10^6 -> 81000000 | D27: ='Cost Components'!$D$36*10^6 -> 81000000 | E27: ='Cost Components'!$D$36*10^6 -> 81000000 | F27: ='Cost Components'!$D$36*10^6 -> 81000000 | G27: ='Cost Components'!$D$36*10^6 -> 81000000 | H27: ='Cost Components'!$D$36*10^6 -> 81000000 | I27: ='Cost Components'!$D$36*10^6 -> 81000000 | J27: ='Cost Components'!$D$36*10^6 -> 81000000 | ... AA27: ='Cost Components'!$D$36*10^6 -> 81000000
A28: Free Cash Flow (€) | B28: =B26-B27 -> 1594030000 | C28: =C26-C27 -> 1.7754408e+08 | D28: =D26-D27 -> 1.7754408e+08 | E28: =E26-E27 -> 1.7754408e+08 | F28: =F26-F27 -> 1.7754408e+08 | G28: =G26-G27 -> 1.7754408e+08 | H28: =H26-H27 -> 1.7754408e+08 | I28: =I26-I27 -> 1.7754408e+08 | ... AA28: =AA26-AA27 -> 1.7754408e+08
A29: Discounted Cash Flow (€) | B29: =B28/(1+'Study Parameters'!$C$4) ^'Production Cost Baseline'!B$2 -> 1594030000 | C29: =C28/(1+'Study Parameters'!$C$4) ^'Production Cost Baseline'!C$2 -> 1.6515728e+08 | D29: =D28/(1+'Study Parameters'!$C$4) ^'Production Cost Baseline'!D$2 -> 1.5363468e+08 | E29: =E28/(1+'Study Parameters'!$C$4) ^'Production Cost Baseline'!E$2 -> 1.4291598e+08 | F29: =F28/(1+'Study Parameters'!$C$4) ^'Production Cost Baseline'!F$2 -> 1.329451e+08 | G29: =G28/(1+'Study Parameters'!$C$4) ^'Production Cost Baseline'!G$2 -> 1.2366986e+08 | H29: =H28/(1+'Study Parameters'!$C$4) ^'Production Cost Baseline'!H$2 -> 1.1504173e+08 | I29: =I28/(1+'Study Parameters'!$C$4) ^'Production Cost Baseline'!I$2 -> 1.0701556e+08 | ... AA29: =AA28/(1+'Study Parameters'!$C$4) ^'Production Cost Baseline'!AA$2 -> 29113511
A30: Fuel Production (kg) | B30: 0 | C30: ='Study Parameters'!$C$14*'Study Parameters'!$C$8 * 10^3 -> 38400000 | D30: ='Study Parameters'!$C$14*'Study Parameters'!$C$8 * 10^3 -> 38400000 | E30: ='Study Parameters'!$C$14*'Study Parameters'!$C$8 * 10^3 -> 38400000 | F30: ='Study Parameters'!$C$14*'Study Parameters'!$C$8 * 10^3 -> 38400000 | G30: ='Study Parameters'!$C$14*'Study Parameters'!$C$8 * 10^3 -> 38400000 | H30: ='Study Parameters'!$C$14*'Study Parameters'!$C$8 * 10^3 -> 38400000 | I30: ='Study Parameters'!$C$14*'Study Parameters'!$C$8 * 10^3 -> 38400000 | J30: ='Study Parameters'!$C$14*'Study Parameters'!$C$8 * 10^3 -> 38400000 | ... AA30: ='Study Parameters'!$C$14*'Study Parameters'!$C$8 * 10^3 -> 38400000
A31: Discounted Fuel Production (kg) | B31: 0 | C31: =C30/(1+'Study Parameters'!$C$4) ^'Production Cost Baseline'!C$2 -> 35720930 | D31: =D30/(1+'Study Parameters'!$C$4) ^'Production Cost Baseline'!D$2 -> 33228772 | E31: =E30/(1+'Study Parameters'!$C$4) ^'Production Cost Baseline'!E$2 -> 30910486 | F31: =F30/(1+'Study Parameters'!$C$4) ^'Production Cost Baseline'!F$2 -> 28753940 | G31: =G30/(1+'Study Parameters'!$C$4) ^'Production Cost Baseline'!G$2 -> 26747851 | H31: =H30/(1+'Study Parameters'!$C$4) ^'Production Cost Baseline'!H$2 -> 24881722 | I31: =I30/(1+'Study Parameters'!$C$4) ^'Production Cost Baseline'!I$2 -> 23145788 | J31: =J30/(1+'Study Parameters'!$C$4) ^'Production Cost Baseline'!J$2 -> 21530966 | ... AA31: =AA30/(1+'Study Parameters'!$C$4) ^'Production Cost Baseline'!AA$2 -> 6296795.9
A33: Production Cost of Fuel (€/kg) | B33: =SUM(B29:AA29) / SUM(C31:AA31) -> 8.3475412
A34: Production Cost of Fuel (€/l) | B34: =B33 * Inputs!$C$15 -> 6.7030756
A36: C.4 Baseload
A37: Cost (€) | B37: ='Cost Components'!$E$12 * 10^6 -> 1.43992e+09 | C37: =('Cost Components'!$E$21 + 'Cost Components'!$E$40) * 10^6 -> 2.0154218e+08 | D37: =('Cost Components'!$E$21 + 'Cost Components'!$E$40) * 10^6 -> 2.0154218e+08 | E37: =('Cost Components'!$E$21 + 'Cost Components'!$E$40) * 10^6 -> 2.0154218e+08 | F37: =('Cost Components'!$E$21 + 'Cost Components'!$E$40) * 10^6 -> 2.0154218e+08 | G37: =('Cost Components'!$E$21 + 'Cost Components'!$E$40) * 10^6 -> 2.0154218e+08 | H37: =('Cost Components'!$E$21 + 'Cost Components'!$E$40) * 10^6 -> 2.0154218e+08 | I37: =('Cost Components'!$E$21 + 'Cost Components'!$E$40) * 10^6 -> 2.0154218e+08 | J37: =('Cost Components'!$E$21 + 'Cost Components'!$E$40) * 10^6 -> 2.0154218e+08 | ... AA37: =('Cost Components'!$E$21 + 'Cost Components'!$E$40) * 10^6 -> 2.0154218e+08
A38: Revenue (€) | B38: 0 | C38: ='Cost Components'!$E$36*10^6 -> 103200000 | D38: ='Cost Components'!$E$36*10^6 -> 103200000 | E38: ='Cost Components'!$E$36*10^6 -> 103200000 | F38: ='Cost Components'!$E$36*10^6 -> 103200000 | G38: ='Cost Components'!$E$36*10^6 -> 103200000 | H38: ='Cost Components'!$E$36*10^6 -> 103200000 | I38: ='Cost Components'!$E$36*10^6 -> 103200000 | J38: ='Cost Components'!$E$36*10^6 -> 103200000 | ... AA38: ='Cost Components'!$E$36*10^6 -> 103200000
A39: Free Cash Flow (€) | B39: =B37-B38 -> 1.43992e+09 | C39: =C37-C38 -> 98342180 | D39: =D37-D38 -> 98342180 | E39: =E37-E38 -> 98342180 | F39: =F37-F38 -> 98342180 | G39: =G37-G38 -> 98342180 | H39: =H37-H38 -> 98342180 | I39: =I37-I38 -> 98342180 | ... AA39: =AA37-AA38 -> 98342180
A40: Discounted Cash Flow (€) | B40: =B39/(1+'Study Parameters'!$C$4) ^'Production Cost Baseline'!B$2 -> 1.43992e+09 | C40: =C39/(1+'Study Parameters'!$C$4) ^'Production Cost Baseline'!C$2 -> 91481098 | D40: =D39/(1+'Study Parameters'!$C$4) ^'Production Cost Baseline'!D$2 -> 85098696 | E40: =E39/(1+'Study Parameters'!$C$4) ^'Production Cost Baseline'!E$2 -> 79161577 | F40: =F39/(1+'Study Parameters'!$C$4) ^'Production Cost Baseline'!F$2 -> 73638677 | G40: =G39/(1+'Study Parameters'!$C$4) ^'Production Cost Baseline'!G$2 -> 68501095 | H40: =H39/(1+'Study Parameters'!$C$4) ^'Production Cost Baseline'!H$2 -> 63721948 | I40: =I39/(1+'Study Parameters'!$C$4) ^'Production Cost Baseline'!I$2 -> 59276231 | ... AA40: =AA39/(1+'Study Parameters'!$C$4) ^'Production Cost Baseline'!AA$2 -> 16126058
A41: Fuel Production (kg) | B41: 0 | C41: ='Study Parameters'!$C$15*'Study Parameters'!$C$8 * 10^3 -> 55200000 | D41: ='Study Parameters'!$C$15*'Study Parameters'!$C$8 * 10^3 -> 55200000 | E41: ='Study Parameters'!$C$15*'Study Parameters'!$C$8 * 10^3 -> 55200000 | F41: ='Study Parameters'!$C$15*'Study Parameters'!$C$8 * 10^3 -> 55200000 | G41: ='Study Parameters'!$C$15*'Study Parameters'!$C$8 * 10^3 -> 55200000 | H41: ='Study Parameters'!$C$15*'Study Parameters'!$C$8 * 10^3 -> 55200000 | I41: ='Study Parameters'!$C$15*'Study Parameters'!$C$8 * 10^3 -> 55200000 | J41: ='Study Parameters'!$C$15*'Study Parameters'!$C$8 * 10^3 -> 55200000 | ... AA41: ='Study Parameters'!$C$15*'Study Parameters'!$C$8 * 10^3 -> 55200000
A42: Discounted Fuel Production (kg) | B42: 0 | C42: =C41/(1+'Study Parameters'!$C$4) ^'Production Cost Baseline'!C$2 -> 51348837 | D42: =D41/(1+'Study Parameters'!$C$4) ^'Production Cost Baseline'!D$2 -> 47766360 | E42: =E41/(1+'Study Parameters'!$C$4) ^'Production Cost Baseline'!E$2 -> 44433823 | F42: =F41/(1+'Study Parameters'!$C$4) ^'Production Cost Baseline'!F$2 -> 41333789 | G42: =G41/(1+'Study Parameters'!$C$4) ^'Production Cost Baseline'!G$2 -> 38450037 | H42: =H41/(1+'Study Parameters'!$C$4) ^'Production Cost Baseline'!H$2 -> 35767476 | I42: =I41/(1+'Study Parameters'!$C$4) ^'Production Cost Baseline'!I$2 -> 33272071 | J42: =J41/(1+'Study Parameters'!$C$4) ^'Production Cost Baseline'!J$2 -> 30950763 | ... AA42: =AA41/(1+'Study Parameters'!$C$4) ^'Production Cost Baseline'!AA$2 -> 9051644.1
A44: Production Cost of Fuel (€/kg) | B44: =SUM(B40:AA40) / SUM(C42:AA42) -> 4.1217096
A45: Production Cost of Fuel (€/l) | B45: =B44 * Inputs!$C$15 -> 3.3097328
A47: C.5 Baseload
A48: Cost (€) | B48: ='Cost Components'!$F$12 * 10^6 -> 1482660000 | C48: =('Cost Components'!$F$21 + 'Cost Components'!$F$40) * 10^6 -> 2.4224214e+08 | D48: =('Cost Components'!$F$21 + 'Cost Components'!$F$40) * 10^6 -> 2.4224214e+08 | E48: =('Cost Components'!$F$21 + 'Cost Components'!$F$40) * 10^6 -> 2.4224214e+08 | F48: =('Cost Components'!$F$21 + 'Cost Components'!$F$40) * 10^6 -> 2.4224214e+08 | G48: =('Cost Components'!$F$21 + 'Cost Components'!$F$40) * 10^6 -> 2.4224214e+08 | H48: =('Cost Components'!$F$21 + 'Cost Components'!$F$40) * 10^6 -> 2.4224214e+08 | I48: =('Cost Components'!$F$21 + 'Cost Components'!$F$40) * 10^6 -> 2.4224214e+08 | J48: =('Cost Components'!$F$21 + 'Cost Components'!$F$40) * 10^6 -> 2.4224214e+08 | ... AA48: =('Cost Components'!$F$21 + 'Cost Components'!$F$40) * 10^6 -> 2.4224214e+08
...

Sheet CO2 Corrected Production Cost
A1: 2021
A2: Year | B2: 0 | C2: 1 | D2: 2 | E2: 3 | F2: 4 | G2: 5 | H2: 6 | I2: 7 | J2: 8 | K2: 9 | L2: 10 | M2: 11 | N2: 12 | O2: 13 | P2: 14 | Q2: 15 | R2: 16 | S2: 17 | T2: 18 | U2: 19 | V2: 20 | W2: 21 | X2: 22 | Y2: 23 | Z2: 24 | AA2: 25
A3: C.1 Baseload
A4: Cost (€) | B4: ='Cost Components'!$B$42 * 10^6 -> 1136760000 | C4: =('Cost Components'!$B$43 + 'Cost Components'!$B$40 + 'Cost Components'!$B$41) * 10^6 -> 5.5607486e+08 | D4: =('Cost Components'!$B$43 + 'Cost Components'!$B$40 + 'Cost Components'!$B$41) * 10^6 -> 5.5607486e+08 | E4: =('Cost Components'!$B$43 + 'Cost Components'!$B$40 + 'Cost Components'!$B$41) * 10^6 -> 5.5607486e+08 | F4: =('Cost Components'!$B$43 + 'Cost Components'!$B$40 + 'Cost Components'!$B$41) * 10^6 -> 5.5607486e+08 | G4: =('Cost Components'!$B$43 + 'Cost Components'!$B$40 + 'Cost Components'!$B$41) * 10^6 -> 5.5607486e+08 | H4: =('Cost Components'!$B$43 + 'Cost Components'!$B$40 + 'Cost Components'!$B$41) * 10^6 -> 5.5607486e+08 | I4: =('Cost Components'!$B$43 + 'Cost Components'!$B$40 + 'Cost Components'!$B$41) * 10^6 -> 5.5607486e+08 | J4: =('Cost Components'!$B$43 + 'Cost Components'!$B$40 + 'Cost Components'!$B$41) * 10^6 -> 5.5607486e+08 | ... AA4: =('Cost Components'!$B$43 + 'Cost Components'!$B$40 + 'Cost Components'!$B$41) * 10^6 -> 5.5607486e+08
A5: Revenue (€) | B5: 0 | C5: ='Cost Components'!$B$36*10^6 -> 56800000 | D5: ='Cost Components'!$B$36*10^6 -> 56800000 | E5: ='Cost Components'!$B$36*10^6 -> 56800000 | F5: ='Cost Components'!$B$36*10^6 -> 56800000 | G5: ='Cost Components'!$B$36*10^6 -> 56800000 | H5: ='Cost Components'!$B$36*10^6 -> 56800000 | I5: ='Cost Components'!$B$36*10^6 -> 56800000 | J5: ='Cost Components'!$B$36*10^6 -> 56800000 | ... AA5: ='Cost Components'!$B$36*10^6 -> 56800000
A6: Free Cash Flow (€) | B6: =B4-B5 -> 1136760000 | C6: =C4-C5 -> 4.9927486e+08 | D6: =D4-D5 -> 4.9927486e+08 | E6: =E4-E5 -> 4.9927486e+08 | F6: =F4-F5 -> 4.9927486e+08 | G6: =G4-G5 -> 4.9927486e+08 | H6: =H4-H5 -> 4.9927486e+08 | I6: =I4-I5 -> 4.9927486e+08 | ... AA6: =AA4-AA5 -> 4.9927486e+08
A7: Discounted Cash Flow (€) | B7: =B6/(1+'Study Parameters'!$C$4) ^'Production Cost Baseline'!B$2 -> 1136760000 | C7: =C6/(1+'Study Parameters'!$C$4) ^'Production Cost Baseline'!C$2 -> 4.6444173e+08 | D7: =D6/(1+'Study Parameters'!$C$4) ^'Production Cost Baseline'!D$2 -> 4.3203882e+08 | E7: =E6/(1+'Study Parameters'!$C$4) ^'Production Cost Baseline'!E$2 -> 4.0189657e+08 | F7: =F6/(1+'Study Parameters'!$C$4) ^'Production Cost Baseline'!F$2 -> 3.7385728e+08 | G7: =G6/(1+'Study Parameters'!$C$4) ^'Production Cost Baseline'!G$2 -> 3.4777421e+08 | H7: =H6/(1+'Study Parameters'!$C$4) ^'Production Cost Baseline'!H$2 -> 3.2351089e+08 | I7: =I6/(1+'Study Parameters'!$C$4) ^'Production Cost Baseline'!I$2 -> 3.0094037e+08 | ... AA7: =AA6/(1+'Study Parameters'!$C$4) ^'Production Cost Baseline'!AA$2 -> 81870622
A8: Fuel Production (kg) | B8: 0 | C8: ='Study Parameters'!$C$12*'Study Parameters'!$C$8 * 10^3 -> 69600000 | D8: ='Study Parameters'!$C$12*'Study Parameters'!$C$8 * 10^3 -> 69600000 | E8: ='Study Parameters'!$C$12*'Study Parameters'!$C$8 * 10^3 -> 69600000 | F8: ='Study Parameters'!$C$12*'Study Parameters'!$C$8 * 10^3 -> 69600000 | G8: ='Study Parameters'!$C$12*'Study Parameters'!$C$8 * 10^3 -> 69600000 | H8: ='Study Parameters'!$C$12*'Study Parameters'!$C$8 * 10^3 -> 69600000 | I8: ='Study Parameters'!$C$12*'Study Parameters'!$C$8 * 10^3 -> 69600000 | J8: ='Study Parameters'!$C$12*'Study Parameters'!$C$8 * 10^3 -> 69600000 | ... AA8: ='Study Parameters'!$C$12*'Study Parameters'!$C$8 * 10^3 -> 69600000
A9: Discounted Fuel Production (kg) | B9: 0 | C9: =C8/(1+'Study Parameters'!$C$4) ^'Production Cost Baseline'!C$2 -> 64744186 | D9: =D8/(1+'Study Parameters'!$C$4) ^'Production Cost Baseline'!D$2 -> 60227150 | E9: =E8/(1+'Study Parameters'!$C$4) ^'Production Cost Baseline'!E$2 -> 56025256 | F9: =F8/(1+'Study Parameters'!$C$4) ^'Production Cost Baseline'!F$2 -> 52116517 | G9: =G8/(1+'Study Parameters'!$C$4) ^'Production Cost Baseline'!G$2 -> 48480481 | H9: =H8/(1+'Study Parameters'!$C$4) ^'Production Cost Baseline'!H$2 -> 45098122 | I9: =I8/(1+'Study Parameters'!$C$4) ^'Production Cost Baseline'!I$2 -> 41951741 | J9: =J8/(1+'Study Parameters'!$C$4) ^'Production Cost Baseline'!J$2 -> 39024875 | ... AA9: =AA8/(1+'Study Parameters'!$C$4) ^'Production Cost Baseline'!AA$2 -> 11412943
A11: Production Cost of Fuel (€/kg) | B11: =SUM(B7:AA7) / SUM(C9:AA9) -> 8.6387121
A12: Production Cost of Fuel (€/l) | B12: =B11 * Inputs!$C$15 -> 6.9368858
A14: C.2 Baseload
A15: Cost (€) | B15: ='Cost Components'!$C$42 * 10^6 -> 827300000 | C15: =('Cost Components'!$C$43 + 'Cost Components'!$C$40 + 'Cost Components'!$C$41) * 10^6 -> 4.8325164e+08 | D15: =('Cost Components'!$C$43 + 'Cost Components'!$C$40 + 'Cost Components'!$C$41) * 10^6 -> 4.8325164e+08 | E15: =('Cost Components'!$C$43 + 'Cost Components'!$C$40 + 'Cost Components'!$C$41) * 10^6 -> 4.8325164e+08 | F15: =('Cost Components'!$C$43 + 'Cost Components'!$C$40 + 'Cost Components'!$C$41) * 10^6 -> 4.8325164e+08 | G15: =('Cost Components'!$C$43 + 'Cost Components'!$C$40 + 'Cost Components'!$C$41) * 10^6 -> 4.8325164e+08 | H15: =('Cost Components'!$C$43 + 'Cost Components'!$C$40 + 'Cost Components'!$C$41) * 10^6 -> 4.8325164e+08 | I15: =('Cost Components'!$C$43 + 'Cost Components'!$C$40 + 'Cost Components'!$C$41) * 10^6 -> 4.8325164e+08 | J15: =('Cost Components'!$C$43 + 'Cost Components'!$C$40 + 'Cost Components'!$C$41) * 10^6 -> 4.8325164e+08 | ... AA15: =('Cost Components'!$C$43 + 'Cost Components'!$C$40 + 'Cost Components'!$C$41) * 10^6 -> 4.8325164e+08
A16: Revenue (€) | B16: 0 | C16: ='Cost Components'!$C$36*10^6 -> 1.499e+08 | D16: ='Cost Components'!$C$36*10^6 -> 1.499e+08 | E16: ='Cost Components'!$C$36*10^6 -> 1.499e+08 | F16: ='Cost Components'!$C$36*10^6 -> 1.499e+08 | G16: ='Cost Components'!$C$36*10^6 -> 1.499e+08 | H16: ='Cost Components'!$C$36*10^6 -> 1.499e+08 | I16: ='Cost Components'!$C$36*10^6 -> 1.499e+08 | J16: ='Cost Components'!$C$36*10^6 -> 1.499e+08 | ... AA16: ='Cost Components'!$C$36*10^6 -> 1.499e+08
A17: Free Cash Flow (€) | B17: =B15-B16 -> 827300000 | C17: =C15-C16 -> 3.3335164e+08 | D17: =D15-D16 -> 3.3335164e+08 | E17: =E15-E16 -> 3.3335164e+08 | F17: =F15-F16 -> 3.3335164e+08 | G17: =G15-G16 -> 3.3335164e+08 | H17: =H15-H16 -> 3.3335164e+08 | I17: =I15-I16 -> 3.3335164e+08 | ... AA17: =AA15-AA16 -> 3.3335164e+08
A18: Discounted Cash Flow (€) | B18: =B17/(1+'Study Parameters'!$C$4) ^'Production Cost Baseline'!B$2 -> 827300000 | C18: =C17/(1+'Study Parameters'!$C$4) ^'Production Cost Baseline'!C$2 -> 3.1009455e+08 | D18: =D17/(1+'Study Parameters'!$C$4) ^'Production Cost Baseline'!D$2 -> 2.8846004e+08 | E18: =E17/(1+'Study Parameters'!$C$4) ^'Production Cost Baseline'!E$2 -> 2.6833493e+08 | F18: =F17/(1+'Study Parameters'!$C$4) ^'Production Cost Baseline'!F$2 -> 2.4961388e+08 | G18: =G17/(1+'Study Parameters'!$C$4) ^'Production Cost Baseline'!G$2 -> 2.3219896e+08 | H18: =H17/(1+'Study Parameters'!$C$4) ^'Production Cost Baseline'!H$2 -> 2.1599903e+08 | I18: =I17/(1+'Study Parameters'!$C$4) ^'Production Cost Baseline'!I$2 -> 2.0092933e+08 | ... AA18: =AA17/(1+'Study Parameters'!$C$4) ^'Production Cost Baseline'!AA$2 -> 54662689
A19: Fuel Production (kg) | B19: 0 | C19: ='Study Parameters'!$C$13*'Study Parameters'!$C$8 * 10^3 -> 28000000 | D19: ='Study Parameters'!$C$13*'Study Parameters'!$C$8 * 10^3 -> 28000000 | E19: ='Study Parameters'!$C$13*'Study Parameters'!$C$8 * 10^3 -> 28000000 | F19: ='Study Parameters'!$C$13*'Study Parameters'!$C$8 * 10^3 -> 28000000 | G19: ='Study Parameters'!$C$13*'Study Parameters'!$C$8 * 10^3 -> 28000000 | H19: ='Study Parameters'!$C$13*'Study Parameters'!$C$8 * 10^3 -> 28000000 | I19: ='Study Parameters'!$C$13*'Study Parameters'!$C$8 * 10^3 -> 28000000 | J19: ='Study Parameters'!$C$13*'Study Parameters'!$C$8 * 10^3 -> 28000000 | ... AA19: ='Study Parameters'!$C$13*'Study Parameters'!$C$8 * 10^3 -> 28000000
A20: Discounted Fuel Production (kg) | B20: 0 | C20: =C19/(1+'Study Parameters'!$C$4) ^'Production Cost Baseline'!C$2 -> 26046512 | D20: =D19/(1+'Study Parameters'!$C$4) ^'Production Cost Baseline'!D$2 -> 24229313 | E20: =E19/(1+'Study Parameters'!$C$4) ^'Production Cost Baseline'!E$2 -> 22538896 | F20: =F19/(1+'Study Parameters'!$C$4) ^'Production Cost Baseline'!F$2 -> 20966415 | G20: =G19/(1+'Study Parameters'!$C$4) ^'Production Cost Baseline'!G$2 -> 19503642 | H20: =H19/(1+'Study Parameters'!$C$4) ^'Production Cost Baseline'!H$2 -> 18142923 | I20: =I19/(1+'Study Parameters'!$C$4) ^'Production Cost Baseline'!I$2 -> 16877137 | J20: =J19/(1+'Study Parameters'!$C$4) ^'Production Cost Baseline'!J$2 -> 15699663 | ... AA20: =AA19/(1+'Study Parameters'!$C$4) ^'Production Cost Baseline'!AA$2 -> 4591413.7
A22: Production Cost of Fuel (€/kg) | B22: =SUM(B18:AA18) / SUM(C20:AA20) -> 14.556046
A23: Production Cost of Fuel (€/l) | B23: =B22 * Inputs!$C$15 -> 11.688505
A25: C.3 Baseload
A26: Cost (€) | B26: ='Cost Components'!$D$42 * 10^6 -> 887030000 | C26: =('Cost Components'!$D$43 + 'Cost Components'!$D$40 + 'Cost Components'!$D$41) * 10^6 -> 5.4418008e+08 | D26: =('Cost Components'!$D$43 + 'Cost Components'!$D$40 + 'Cost Components'!$D$41) * 10^6 -> 5.4418008e+08 | E26: =('Cost Components'!$D$43 + 'Cost Components'!$D$40 + 'Cost Components'!$D$41) * 10^6 -> 5.4418008e+08 | F26: =('Cost Components'!$D$43 + 'Cost Components'!$D$40 + 'Cost Components'!$D$41) * 10^6 -> 5.4418008e+08 | G26: =('Cost Components'!$D$43 + 'Cost Components'!$D$40 + 'Cost Components'!$D$41) * 10^6 -> 5.4418008e+08 | H26: =('Cost Components'!$D$43 + 'Cost Components'!$D$40 + 'Cost Components'!$D$41) * 10^6 -> 5.4418008e+08 | I26: =('Cost Components'!$D$43 + 'Cost Components'!$D$40 + 'Cost Components'!$D$41) * 10^6 -> 5.4418008e+08 | J26: =('Cost Components'!$D$43 + 'Cost Components'!$D$40 + 'Cost Components'!$D$41) * 10^6 -> 5.4418008e+08 | ... AA26: =('Cost Components'!$D$43 + 'Cost Components'!$D$40 + 'Cost Components'!$D$41) * 10^6 -> 5.4418008e+08
A27: Revenue (€) | B27: 0 | C27: ='Cost Components'!$D$36*10^6 -> 81000000 | D27: ='Cost Components'!$D$36*10^6 -> 81000000 | E27: ='Cost Components'!$D$36*10^6 -> 81000000 | F27: ='Cost Components'!$D$36*10^6 -> 81000000 | G27: ='Cost Components'!$D$36*10^6 -> 81000000 | H27: ='Cost Components'!$D$36*10^6 -> 81000000 | I27: ='Cost Components'!$D$36*10^6 -> 81000000 | J27: ='Cost Components'!$D$36*10^6 -> 81000000 | ... AA27: ='Cost Components'!$D$36*10^6 -> 81000000
A28: Free Cash Flow (€) | B28: =B26-B27 -> 887030000 | C28: =C26-C27 -> 4.6318008e+08 | D28: =D26-D27 -> 4.6318008e+08 | E28: =E26-E27 -> 4.6318008e+08 | F28: =F26-F27 -> 4.6318008e+08 | G28: =G26-G27 -> 4.6318008e+08 | H28: =H26-H27 -> 4.6318008e+08 | I28: =I26-I27 -> 4.6318008e+08 | ... AA28: =AA26-AA27 -> 4.6318008e+08
