Workbook

Sheet Inputs
A1: Parameter | B1: Year | C1: Value | D1: Unit
A2: Standard Values
A3: Current Year | C3: =[1]Inputs!C4 -> 2024
A4: Inflation | C4: =[1]Inputs!C5 -> 0.02
A5: WACC | C5: =[1]Inputs!C6 -> 0.07
A6: USD to EUR | C6: =[1]Inputs!C7 -> 0.9
A7: Electricity
A8: LCOE | B8: 2024 | C8: =[1]Inputs!C9 -> 64 | D8: $/MWh
A9: LCOE | B9: 2050 | C9: =[1]Inputs!C10 -> 11 | D9: $/MWh
A10: Jet Fuel A-1 Characteristics
A11: Emissions Intensity | B11: 2024 | C11: =[1]Inputs!C12 -> 88.7 | D11: gCO2/MJ
A12: Emissions Intensity | B12: 2050 | C12: =[1]Inputs!C13 -> 88.7 | D12: gCO2/MJ
A13: Energy Density | C13: =[1]Inputs!C14 -> 43.2 | D13: MJ/kg
A14: Energy Density | C14: =[1]Inputs!C15 -> 34.6896 | D14: MJ/l
A15: Volumetric Density | C15: =[1]Inputs!C16 -> 0.803 | D15: kg/l
A16: Jet Fuel A-1 Price | B16: 2024 | C16: =[1]Inputs!C17 -> 0.8 | D16: $/l
A17: Scenario Specific Values
A18: Jet Fuel A-1 Price | B18: 2050 | C18: =[1]Inputs!C19 -> 0.8 | D18: $/l
A19: IEA Reference
A20: Jet Fuel A-1 Price | B20: 2024 | C20: =[1]Inputs!C21 -> 0.32246154 | D20: $/l
A21: Jet Fuel A-1 Price | B21: 2050 | C21: =[1]Inputs!C22 -> 0.20923077 | D21: $/l
A22: EIA Reference
A23: Jet Fuel A-1 Price | B23: 2024 | C23: =[1]Inputs!C24 -> 1.0209014 | D23: $/l
A24: Jet Fuel A-1 Price | B24: 2050 | C24: =[1]Inputs!C25 -> 2.0095594 | D24: $/l
A25: EIA Low Oil Price Scenario
A26: Jet Fuel A-1 Price | B26: 2024 | C26: =[1]Inputs!C27 -> 0.48286833 | D26: $/l
A27: Jet Fuel A-1 Price | B27: 2050 | C27: =[1]Inputs!C28 -> 0.89646575 | D27: $/l
A28: EIA High Scenario
A29: Jet Fuel A-1 Price | B29: 2024 | C29: =[1]Inputs!C30 -> 1.8838713 | D29: $/l
A30: Jet Fuel A-1 Price | B30: 2050 | C30: =[1]Inputs!C31 -> 3.7893731 | D30: $/l
A31: Direct Air Capture
A32: LCOR | B32: 2024 | C32: =[1]Inputs!C33 -> 1282 | D32: $/tCO2
A33: LCOR | B33: 2050 | C33: =[1]Inputs!C34 -> 480 | D33: $/tCO2

Sheet Base LCOF
A1: WACC_source | B1: 0.06 | C1: 0.06 | D1: 0.06 | E1: 0.06 | F1: 0.06 | G1: 0.06 | H1: 0.06 | I1: 0.06 | J1: 0.06 | K1: -
A2: WACC_alternative | B2: 0.06 | C2: 0.06 | D2: 0.06 | E2: 0.06 | F2: 0.06 | G2: 0.06 | H2: 0.06 | I2: 0.06 | J2: 0.06 | K2: -
A3: LCOE_alternative | B3: 9.3710341 | C3: 5.2586511 | D3: 2.969201 | E3: 5.9593963 | F3: 3.6109404 | G3: 2.969201 | H3: 4.7585019 | I3: 3.330479 | J3: 2.969201 | K3: ct/kWh
B4: 11.1 | C4: 11.1 | D4: 11.1 | E4: 7.5 | F4: 7.5 | G4: 7.5 | H4: 3.9 | I4: 3.9 | J4: 3.9 | L4: Note: this is the standard LCOE curve
A5: DAC_source | B5: 460 | C5: 460 | D5: 460 | E5: 135 | F5: 135 | G5: 135 | H5: 80 | I5: 80 | J5: 80 | K5: €/tCO2
A6: DAC_alternative | B6: 460 | C6: 460 | D6: 460 | E6: 135 | F6: 135 | G6: 135 | H6: 80 | I6: 80 | J6: 80 | K6: €/tCO2 | L6: Average between SS and LS DAC
B7: 731.19867 | C7: 731.19867 | D7: 731.19867 | E7: 449.5681 | F7: 449.5681 | G7: 449.5681 | H7: 298.29332 | I7: 298.29332 | J7: 298.29332 | L7: Note: this is modelled DAC cost
A8: Levelized cost of electricity [ct/kWh]
B10: 2020 | E10: 2035 | H10: 2050
B11: Offshore | C11: Onshore | D11: Hydro | E11: Offshore | F11: Onshore | G11: Hydro | H11: Offshore | I11: Onshore | J11: Hydro | N11: 2020 Offshore | O11: 2020 Onshore
A12: Capex generation | B12: 5.6892159 | C12: 4.0867761 | D12: 2.1299153 | E12: 3.5557599 | F12: 2.8062529 | G12: 2.1299153 | H12: 2.9335019 | I12: 2.5882915 | J12: 2.1299153 | K12: ct/kWh | M12: CAPEX | N12: 3200 | O12: 1500
A13: Opex generation | B13: 2.1818182 | C13: 1.171875 | D13: 0.83928571 | E13: 1.3636364 | F13: 0.8046875 | G13: 0.83928571 | H13: 1.125 | I13: 0.7421875 | J13: 0.83928571 | K13: ct/kWh | M13: Loadhours | N13: 4400 | O13: 3200
A14: Offshore grid fee | B14: 1.5 | C14: 0 | D14: 0 | E14: 1.04 | F14: 0 | G14: 0 | H14: 0.7 | I14: 0 | J14: 0 | K14: ct/kWh | M14: UCRF | N14: =B23 -> 0.078226718 | O14: =C23 -> 0.087184557
M15: Annualized CAPEX | N15: =N12*N14/N13 -> 0.056892159 | O15: =O12*O14/O13 -> 0.040867761 | P15: €/kWh
A16: BC | B16: 1.377431 | C16: 0.80426429 | D16: 0.37115013 | E16: 1.3238642 | F16: 1.1857743 | G16: 0.37115013 | H16: 1.292708 | I16: 1.020797 | J16: 0.37115013 | K16: ct/kWh | N16: =N15*100 -> 5.6892159 | O16: =O15*100 -> 4.0867761 | P16: ct/kWh
A17: WC | B17: 1.4414975 | C17: 0.91149953 | D17: 0.49486684 | E17: 1.3602703 | F17: 1.3812724 | G17: 0.49486684 | H17: 1.352834 | I17: 1.1569032 | J17: 0.49486684 | K17: ct/kWh
A19: LCOE | B19: =SUM(B12:B14) -> 9.3710341 | C19: =SUM(C12:C14) -> 5.2586511 | D19: =SUM(D12:D14) -> 2.969201 | E19: =SUM(E12:E14) -> 5.9593963 | F19: =SUM(F12:F14) -> 3.6109404 | G19: =SUM(G12:G14) -> 2.969201 | H19: =SUM(H12:H14) -> 4.7585019 | I19: =SUM(I12:I14) -> 3.330479 | J19: =SUM(J12:J14) -> 2.969201 | K19: ct/kWh
A20: LCOE | B20: =B19*10 -> 93.710341 | C20: =C19*10 -> 52.586511 | D20: =D19*10 -> 29.69201 | E20: =E19*10 -> 59.593963 | F20: =F19*10 -> 36.109404 | G20: =G19*10 -> 29.69201 | H20: =H19*10 -> 47.585019 | I20: =I19*10 -> 33.30479 | J20: =J19*10 -> 29.69201 | K20: €/MWh
A22: Lifetime | B22: 25 | C22: 20 | D22: 50 | E22: 25 | F22: 20 | G22: 50 | H22: 25 | I22: 20 | J22: 50 | K22: years | M22: WACC
A23: UCRF | B23: =(B$1*(1+B$1)^B22)/((1+B$1)^B22-1) -> 0.078226718 | C23: =(C$1*(1+C$1)^C22)/((1+C$1)^C22-1) -> 0.087184557 | D23: =(D$1*(1+D$1)^D22)/((1+D$1)^D22-1) -> 0.063444286 | E23: =(E$1*(1+E$1)^E22)/((1+E$1)^E22-1) -> 0.078226718 | F23: =(F$1*(1+F$1)^F22)/((1+F$1)^F22-1) -> 0.087184557 | G23: =(G$1*(1+G$1)^G22)/((1+G$1)^G22-1) -> 0.063444286 | H23: =(H$1*(1+H$1)^H22)/((1+H$1)^H22-1) -> 0.078226718 | I23: =(I$1*(1+I$1)^I22)/((1+I$1)^I22-1) -> 0.087184557 | J23: =(J$1*(1+J$1)^J22)/((1+J$1)^J22-1) -> 0.063444286 | K23: - | M23: WACC
A25: UCRF_alternative | B25: =(B$2*(1+B$2)^B22)/((1+B$2)^B22-1) -> 0.078226718 | C25: =(C$2*(1+C$2)^C22)/((1+C$2)^C22-1) -> 0.087184557 | D25: =(D$2*(1+D$2)^D22)/((1+D$2)^D22-1) -> 0.063444286 | E25: =(E$2*(1+E$2)^E22)/((1+E$2)^E22-1) -> 0.078226718 | F25: =(F$2*(1+F$2)^F22)/((1+F$2)^F22-1) -> 0.087184557 | G25: =(G$2*(1+G$2)^G22)/((1+G$2)^G22-1) -> 0.063444286 | H25: =(H$2*(1+H$2)^H22)/((1+H$2)^H22-1) -> 0.078226718 | I25: =(I$2*(1+I$2)^I22)/((1+I$2)^I22-1) -> 0.087184557 | J25: =(J$2*(1+J$2)^J22)/((1+J$2)^J22-1) -> 0.063444286 | K25: - | M25: WACC
A26: Capex generation_alternative | B26: =B12/B23*B25 -> 5.6892159 | C26: =C12/C23*C25 -> 4.0867761 | D26: =D12/D23*D25 -> 2.1299153 | E26: =E12/E23*E25 -> 3.5557599 | F26: =F12/F23*F25 -> 2.8062529 | G26: =G12/G23*G25 -> 2.1299153 | H26: =H12/H23*H25 -> 2.9335019 | I26: =I12/I23*I25 -> 2.5882915 | J26: =J12/J23*J25 -> 2.1299153 | K26: ct/kWh | M26: WACC
A27: LCOE_alternative | B27: =B19-B12+B26 -> 9.3710341 | C27: =C19-C12+C26 -> 5.2586511 | D27: =D19-D12+D26 -> 2.969201 | E27: =E19-E12+E26 -> 5.9593963 | F27: =F19-F12+F26 -> 3.6109404 | G27: =G19-G12+G26 -> 2.969201 | H27: =H19-H12+H26 -> 4.7585019 | I27: =I19-I12+I26 -> 3.330479 | J27: =J19-J12+J26 -> 2.969201 | K27: ct/kWh
A29: Levelized cost of hydrogen [ct/kWh]
B31: 2020 | E31: 2035 | H31: 2050
B32: Offshore | C32: Onshore | D32: Hydro | E32: Offshore | F32: Onshore | G32: Hydro | H32: Offshore | I32: Onshore | J32: Hydro
A33: Capex electrolysis | B33: 3.0462118 | C33: 4.1885412 | D33: 1.9147617 | E33: 1.3931149 | F33: 1.915533 | G33: 0.87567222 | H33: 0.81260441 | I33: 1.1173311 | J33: 0.51077992 | K33: ct/kWh
A34: Opex electrolysis | B34: 1.1682243 | C34: 1.6063084 | D34: 0.73431242 | E34: 0.53426052 | F34: 0.73460821 | G34: 0.3358209 | H34: 0.31163435 | I34: 0.42849723 | J34: 0.19588445 | K34: ct/kWh
A35: Electricity cost | B35: 14.596626 | C35: 8.1910453 | D35: 4.6249237 | E35: 8.8946213 | F35: 5.3894633 | G35: 4.4316433 | H35: 6.5907229 | I35: 4.6128518 | J35: 4.1124668 | K35: ct/kWh
A36: Storage cost | B36: 2.9792732 | C36: 2.9792732 | D36: 2.9792732 | E36: 2.3792732 | F36: 2.3792732 | G36: 2.3792732 | H36: 1.9792732 | I36: 1.9792732 | J36: 1.9792732 | K36: ct/kWh
A37: Liquefaction cost | B37: 3.7938486 | C37: 3.7938486 | D37: 3.7938486 | E37: 2.1404261 | F37: 2.1404261 | G37: 2.1404261 | H37: 1.4308452 | I37: 1.4308452 | J37: 1.4308452 | K37: ct/kWh
A38: Distribution cost | B38: 0.225 | C38: 0.225 | D38: 0.225 | E38: 0.195 | F38: 0.195 | G38: 0.195 | H38: 0.1875 | I38: 0.1875 | J38: 0.1875 | K38: ct/kWh
A40: BC | B40: 5.0944468 | C40: 4.5421905 | D40: 2.3451036 | E40: 4.0195481 | F40: 3.9103357 | G40: 2.0092187 | H40: 3.0022965 | I40: 2.7698807 | J40: 1.3897171 | K40: ct/kWh
A41: WC | B41: 6.2445545 | C41: 5.9119403 | D41: 3.4038153 | E41: 4.7428356 | F41: 5.0150862 | G41: 2.5555799 | H41: 4.1084781 | I41: 4.0463644 | J41: 2.3824229 | K41: ct/kWh
A43: LCOH | B43: =SUM(B33:B38) -> 25.809184 | C43: =SUM(C33:C38) -> 20.984017 | D43: =SUM(D33:D38) -> 14.27212 | E43: =SUM(E33:E38) -> 15.536696 | F43: =SUM(F33:F38) -> 12.754304 | G43: =SUM(G33:G38) -> 10.357836 | H43: =SUM(H33:H38) -> 11.31258 | I43: =SUM(I33:I38) -> 9.7562986 | J43: =SUM(J33:J38) -> 8.4167496 | K43: ct/kWh
A45: Electricity consumption | B45: =B35/B19 -> 1.5576324 | C45: =C35/C19 -> 1.5576324 | D45: =D35/D19 -> 1.5576324 | E45: =E35/E19 -> 1.4925373 | F45: =F35/F19 -> 1.4925373 | G45: =G35/G19 -> 1.4925373 | H45: =H35/H19 -> 1.3850416 | I45: =I35/I19 -> 1.3850416 | J45: =J35/J19 -> 1.3850416 | K45: kWh_el/kWh_fuel | M45: LCOE
A47: Lifetime | B47: 25 | C47: 25 | D47: 25 | E47: 25 | F47: 25 | G47: 25 | H47: 25 | I47: 25 | J47: 25 | K47: years | M47: WACC
A48: UCRF | B48: =(B$1*(1+B$1)^B47)/((1+B$1)^B47-1) -> 0.078226718 | C48: =(C$1*(1+C$1)^C47)/((1+C$1)^C47-1) -> 0.078226718 | D48: =(D$1*(1+D$1)^D47)/((1+D$1)^D47-1) -> 0.078226718 | E48: =(E$1*(1+E$1)^E47)/((1+E$1)^E47-1) -> 0.078226718 | F48: =(F$1*(1+F$1)^F47)/((1+F$1)^F47-1) -> 0.078226718 | G48: =(G$1*(1+G$1)^G47)/((1+G$1)^G47-1) -> 0.078226718 | H48: =(H$1*(1+H$1)^H47)/((1+H$1)^H47-1) -> 0.078226718 | I48: =(I$1*(1+I$1)^I47)/((1+I$1)^I47-1) -> 0.078226718 | J48: =(J$1*(1+J$1)^J47)/((1+J$1)^J47-1) -> 0.078226718 | K48: - | M48: WACC
A50: UCRF_alternative | B50: =(B$2*(1+B$2)^B47)/((1+B$2)^B47-1) -> 0.078226718 | C50: =(C$2*(1+C$2)^C47)/((1+C$2)^C47-1) -> 0.078226718 | D50: =(D$2*(1+D$2)^D47)/((1+D$2)^D47-1) -> 0.078226718 | E50: =(E$2*(1+E$2)^E47)/((1+E$2)^E47-1) -> 0.078226718 | F50: =(F$2*(1+F$2)^F47)/((1+F$2)^F47-1) -> 0.078226718 | G50: =(G$2*(1+G$2)^G47)/((1+G$2)^G47-1) -> 0.078226718 | H50: =(H$2*(1+H$2)^H47)/((1+H$2)^H47-1) -> 0.078226718 | I50: =(I$2*(1+I$2)^I47)/((1+I$2)^I47-1) -> 0.078226718 | J50: =(J$2*(1+J$2)^J47)/((1+J$2)^J47-1) -> 0.078226718 | K50: - | M50: WACC
A51: Electricity cost_alternative | B51: =B45*B3 -> 14.596626 | C51: =C45*C3 -> 8.1910453 | D51: =D45*D3 -> 4.6249237 | E51: =E45*E3 -> 8.8946213 | F51: =F45*F3 -> 5.3894633 | G51: =G45*G3 -> 4.4316433 | H51: =H45*H3 -> 6.5907229 | I51: =I45*I3 -> 4.6128518 | J51: =J45*J3 -> 4.1124668 | K51: ct/kWh | M51: LCOE
...

Sheet LCOE Corrected LCOF
A1: WACC_source | B1: 0.06 | C1: 0.06 | D1: 0.06 | E1: 0.06 | F1: 0.06 | G1: 0.06 | H1: 0.06 | I1: 0.06 | J1: 0.06 | K1: -
A2: WACC_alternative | B2: 0.06 | C2: 0.06 | D2: 0.06 | E2: 0.06 | F2: 0.06 | G2: 0.06 | H2: 0.06 | I2: 0.06 | J2: 0.06 | K2: -
A3: LCOE_alternative | B3: =Inputs!$C$8*Inputs!$C$6 / 10 -> 5.76 | C3: =Inputs!$C$8*Inputs!$C$6 / 10 -> 5.76 | D3: =Inputs!$C$8*Inputs!$C$6 / 10 -> 5.76 | E3: 5.9593963 | F3: 3.6109404 | G3: 2.969201 | H3: =Inputs!$C$9*Inputs!$C$6 / 10 -> 0.99 | I3: =Inputs!$C$9*Inputs!$C$6 / 10 -> 0.99 | J3: =Inputs!$C$9*Inputs!$C$6 / 10 -> 0.99 | K3: ct/kWh
B4: 11.1 | C4: 11.1 | D4: 11.1 | E4: 7.5 | F4: 7.5 | G4: 7.5 | H4: 3.9 | I4: 3.9 | J4: 3.9 | L4: Note: this is the standard LCOE curve
A5: DAC_source | B5: 460 | C5: 460 | D5: 460 | E5: 135 | F5: 135 | G5: 135 | H5: 80 | I5: 80 | J5: 80 | K5: €/tCO2
A6: DAC_alternative | B6: 460 | C6: 460 | D6: 460 | E6: 135 | F6: 135 | G6: 135 | H6: 80 | I6: 80 | J6: 80 | K6: €/tCO2 | L6: Average between SS and LS DAC
B7: 731.19867 | C7: 731.19867 | D7: 731.19867 | E7: 449.5681 | F7: 449.5681 | G7: 449.5681 | H7: 298.29332 | I7: 298.29332 | J7: 298.29332 | L7: Note: this is modelled DAC cost
A8: Levelized cost of electricity [ct/kWh]
B10: 2020 | E10: 2035 | H10: 2050
B11: Offshore | C11: Onshore | D11: Hydro | E11: Offshore | F11: Onshore | G11: Hydro | H11: Offshore | I11: Onshore | J11: Hydro | N11: 2020 Offshore | O11: 2020 Onshore
A12: Capex generation | B12: 5.6892159 | C12: 4.0867761 | D12: 2.1299153 | E12: 3.5557599 | F12: 2.8062529 | G12: 2.1299153 | H12: 2.9335019 | I12: 2.5882915 | J12: 2.1299153 | K12: ct/kWh | M12: CAPEX | N12: 3200 | O12: 1500
A13: Opex generation | B13: 2.1818182 | C13: 1.171875 | D13: 0.83928571 | E13: 1.3636364 | F13: 0.8046875 | G13: 0.83928571 | H13: 1.125 | I13: 0.7421875 | J13: 0.83928571 | K13: ct/kWh | M13: Loadhours | N13: 4400 | O13: 3200
A14: Offshore grid fee | B14: 1.5 | C14: 0 | D14: 0 | E14: 1.04 | F14: 0 | G14: 0 | H14: 0.7 | I14: 0 | J14: 0 | K14: ct/kWh | M14: UCRF | N14: =B23 -> 0.078226718 | O14: =C23 -> 0.087184557
M15: Annualized CAPEX | N15: =N12*N14/N13 -> 0.056892159 | O15: =O12*O14/O13 -> 0.040867761 | P15: €/kWh
A16: BC | B16: 1.377431 | C16: 0.80426429 | D16: 0.37115013 | E16: 1.3238642 | F16: 1.1857743 | G16: 0.37115013 | H16: 1.292708 | I16: 1.020797 | J16: 0.37115013 | K16: ct/kWh | N16: =N15*100 -> 5.6892159 | O16: =O15*100 -> 4.0867761 | P16: ct/kWh
A17: WC | B17: 1.4414975 | C17: 0.91149953 | D17: 0.49486684 | E17: 1.3602703 | F17: 1.3812724 | G17: 0.49486684 | H17: 1.352834 | I17: 1.1569032 | J17: 0.49486684 | K17: ct/kWh
A19: LCOE | B19: =SUM(B12:B14) -> 9.3710341 | C19: =SUM(C12:C14) -> 5.2586511 | D19: =SUM(D12:D14) -> 2.969201 | E19: =SUM(E12:E14) -> 5.9593963 | F19: =SUM(F12:F14) -> 3.6109404 | G19: =SUM(G12:G14) -> 2.969201 | H19: =SUM(H12:H14) -> 4.7585019 | I19: =SUM(I12:I14) -> 3.330479 | J19: =SUM(J12:J14) -> 2.969201 | K19: ct/kWh
A20: LCOE | B20: =B19*10 -> 93.710341 | C20: =C19*10 -> 52.586511 | D20: =D19*10 -> 29.69201 | E20: =E19*10 -> 59.593963 | F20: =F19*10 -> 36.109404 | G20: =G19*10 -> 29.69201 | H20: =H19*10 -> 47.585019 | I20: =I19*10 -> 33.30479 | J20: =J19*10 -> 29.69201 | K20: €/MWh
A22: Lifetime | B22: 25 | C22: 20 | D22: 50 | E22: 25 | F22: 20 | G22: 50 | H22: 25 | I22: 20 | J22: 50 | K22: years | M22: WACC
A23: UCRF | B23: =(B$1*(1+B$1)^B22)/((1+B$1)^B22-1) -> 0.078226718 | C23: =(C$1*(1+C$1)^C22)/((1+C$1)^C22-1) -> 0.087184557 | D23: =(D$1*(1+D$1)^D22)/((1+D$1)^D22-1) -> 0.063444286 | E23: =(E$1*(1+E$1)^E22)/((1+E$1)^E22-1) -> 0.078226718 | F23: =(F$1*(1+F$1)^F22)/((1+F$1)^F22-1) -> 0.087184557 | G23: =(G$1*(1+G$1)^G22)/((1+G$1)^G22-1) -> 0.063444286 | H23: =(H$1*(1+H$1)^H22)/((1+H$1)^H22-1) -> 0.078226718 | I23: =(I$1*(1+I$1)^I22)/((1+I$1)^I22-1) -> 0.087184557 | J23: =(J$1*(1+J$1)^J22)/((1+J$1)^J22-1) -> 0.063444286 | K23: - | M23: WACC
A25: UCRF_alternative | B25: =(B$2*(1+B$2)^B22)/((1+B$2)^B22-1) -> 0.078226718 | C25: =(C$2*(1+C$2)^C22)/((1+C$2)^C22-1) -> 0.087184557 | D25: =(D$2*(1+D$2)^D22)/((1+D$2)^D22-1) -> 0.063444286 | E25: =(E$2*(1+E$2)^E22)/((1+E$2)^E22-1) -> 0.078226718 | F25: =(F$2*(1+F$2)^F22)/((1+F$2)^F22-1) -> 0.087184557 | G25: =(G$2*(1+G$2)^G22)/((1+G$2)^G22-1) -> 0.063444286 | H25: =(H$2*(1+H$2)^H22)/((1+H$2)^H22-1) -> 0.078226718 | I25: =(I$2*(1+I$2)^I22)/((1+I$2)^I22-1) -> 0.087184557 | J25: =(J$2*(1+J$2)^J22)/((1+J$2)^J22-1) -> 0.063444286 | K25: - | M25: WACC
A26: Capex generation_alternative | B26: =B12/B23*B25 -> 5.6892159 | C26: =C12/C23*C25 -> 4.0867761 | D26: =D12/D23*D25 -> 2.1299153 | E26: =E12/E23*E25 -> 3.5557599 | F26: =F12/F23*F25 -> 2.8062529 | G26: =G12/G23*G25 -> 2.1299153 | H26: =H12/H23*H25 -> 2.9335019 | I26: =I12/I23*I25 -> 2.5882915 | J26: =J12/J23*J25 -> 2.1299153 | K26: ct/kWh | M26: WACC
A27: LCOE_alternative | B27: =B19-B12+B26 -> 9.3710341 | C27: =C19-C12+C26 -> 5.2586511 | D27: =D19-D12+D26 -> 2.969201 | E27: =E19-E12+E26 -> 5.9593963 | F27: =F19-F12+F26 -> 3.6109404 | G27: =G19-G12+G26 -> 2.969201 | H27: =H19-H12+H26 -> 4.7585019 | I27: =I19-I12+I26 -> 3.330479 | J27: =J19-J12+J26 -> 2.969201 | K27: ct/kWh
A29: Levelized cost of hydrogen [ct/kWh]
B31: 2020 | E31: 2035 | H31: 2050
B32: Offshore | C32: Onshore | D32: Hydro | E32: Offshore | F32: Onshore | G32: Hydro | H32: Offshore | I32: Onshore | J32: Hydro
A33: Capex electrolysis | B33: 3.0462118 | C33: 4.1885412 | D33: 1.9147617 | E33: 1.3931149 | F33: 1.915533 | G33: 0.87567222 | H33: 0.81260441 | I33: 1.1173311 | J33: 0.51077992 | K33: ct/kWh
A34: Opex electrolysis | B34: 1.1682243 | C34: 1.6063084 | D34: 0.73431242 | E34: 0.53426052 | F34: 0.73460821 | G34: 0.3358209 | H34: 0.31163435 | I34: 0.42849723 | J34: 0.19588445 | K34: ct/kWh
A35: Electricity cost | B35: 14.596626 | C35: 8.1910453 | D35: 4.6249237 | E35: 8.8946213 | F35: 5.3894633 | G35: 4.4316433 | H35: 6.5907229 | I35: 4.6128518 | J35: 4.1124668 | K35: ct/kWh
A36: Storage cost | B36: 2.9792732 | C36: 2.9792732 | D36: 2.9792732 | E36: 2.3792732 | F36: 2.3792732 | G36: 2.3792732 | H36: 1.9792732 | I36: 1.9792732 | J36: 1.9792732 | K36: ct/kWh
A37: Liquefaction cost | B37: 3.7938486 | C37: 3.7938486 | D37: 3.7938486 | E37: 2.1404261 | F37: 2.1404261 | G37: 2.1404261 | H37: 1.4308452 | I37: 1.4308452 | J37: 1.4308452 | K37: ct/kWh
A38: Distribution cost | B38: 0.225 | C38: 0.225 | D38: 0.225 | E38: 0.195 | F38: 0.195 | G38: 0.195 | H38: 0.1875 | I38: 0.1875 | J38: 0.1875 | K38: ct/kWh
A40: BC | B40: 5.0944468 | C40: 4.5421905 | D40: 2.3451036 | E40: 4.0195481 | F40: 3.9103357 | G40: 2.0092187 | H40: 3.0022965 | I40: 2.7698807 | J40: 1.3897171 | K40: ct/kWh
A41: WC | B41: 6.2445545 | C41: 5.9119403 | D41: 3.4038153 | E41: 4.7428356 | F41: 5.0150862 | G41: 2.5555799 | H41: 4.1084781 | I41: 4.0463644 | J41: 2.3824229 | K41: ct/kWh
A43: LCOH | B43: =SUM(B33:B38) -> 25.809184 | C43: =SUM(C33:C38) -> 20.984017 | D43: =SUM(D33:D38) -> 14.27212 | E43: =SUM(E33:E38) -> 15.536696 | F43: =SUM(F33:F38) -> 12.754304 | G43: =SUM(G33:G38) -> 10.357836 | H43: =SUM(H33:H38) -> 11.31258 | I43: =SUM(I33:I38) -> 9.7562986 | J43: =SUM(J33:J38) -> 8.4167496 | K43: ct/kWh
A45: Electricity consumption | B45: =B35/B19 -> 1.5576324 | C45: =C35/C19 -> 1.5576324 | D45: =D35/D19 -> 1.5576324 | E45: =E35/E19 -> 1.4925373 | F45: =F35/F19 -> 1.4925373 | G45: =G35/G19 -> 1.4925373 | H45: =H35/H19 -> 1.3850416 | I45: =I35/I19 -> 1.3850416 | J45: =J35/J19 -> 1.3850416 | K45: kWh_el/kWh_fuel | M45: LCOE
A47: Lifetime | B47: 25 | C47: 25 | D47: 25 | E47: 25 | F47: 25 | G47: 25 | H47: 25 | I47: 25 | J47: 25 | K47: years | M47: WACC
A48: UCRF | B48: =(B$1*(1+B$1)^B47)/((1+B$1)^B47-1) -> 0.078226718 | C48: =(C$1*(1+C$1)^C47)/((1+C$1)^C47-1) -> 0.078226718 | D48: =(D$1*(1+D$1)^D47)/((1+D$1)^D47-1) -> 0.078226718 | E48: =(E$1*(1+E$1)^E47)/((1+E$1)^E47-1) -> 0.078226718 | F48: =(F$1*(1+F$1)^F47)/((1+F$1)^F47-1) -> 0.078226718 | G48: =(G$1*(1+G$1)^G47)/((1+G$1)^G47-1) -> 0.078226718 | H48: =(H$1*(1+H$1)^H47)/((1+H$1)^H47-1) -> 0.078226718 | I48: =(I$1*(1+I$1)^I47)/((1+I$1)^I47-1) -> 0.078226718 | J48: =(J$1*(1+J$1)^J47)/((1+J$1)^J47-1) -> 0.078226718 | K48: - | M48: WACC
A50: UCRF_alternative | B50: =(B$2*(1+B$2)^B47)/((1+B$2)^B47-1) -> 0.078226718 | C50: =(C$2*(1+C$2)^C47)/((1+C$2)^C47-1) -> 0.078226718 | D50: =(D$2*(1+D$2)^D47)/((1+D$2)^D47-1) -> 0.078226718 | E50: =(E$2*(1+E$2)^E47)/((1+E$2)^E47-1) -> 0.078226718 | F50: =(F$2*(1+F$2)^F47)/((1+F$2)^F47-1) -> 0.078226718 | G50: =(G$2*(1+G$2)^G47)/((1+G$2)^G47-1) -> 0.078226718 | H50: =(H$2*(1+H$2)^H47)/((1+H$2)^H47-1) -> 0.078226718 | I50: =(I$2*(1+I$2)^I47)/((1+I$2)^I47-1) -> 0.078226718 | J50: =(J$2*(1+J$2)^J47)/((1+J$2)^J47-1) -> 0.078226718 | K50: - | M50: WACC
A51: Electricity cost_alternative | B51: =B45*B3 -> 8.9719626 | C51: =C45*C3 -> 8.9719626 | D51: =D45*D3 -> 8.9719626 | E51: =E45*E3 -> 8.8946213 | F51: =F45*F3 -> 5.3894633 | G51: =G45*G3 -> 4.4316433 | H51: =H45*H3 -> 1.3711911 | I51: =I45*I3 -> 1.3711911 | J51: =J45*J3 -> 1.3711911 | K51: ct/kWh | M51: LCOE
...

Sheet CO2 Price Corrected LCOF
A1: WACC_source | B1: 0.06 | C1: 0.06 | D1: 0.06 | E1: 0.06 | F1: 0.06 | G1: 0.06 | H1: 0.06 | I1: 0.06 | J1: 0.06 | K1: -
A2: WACC_alternative | B2: 0.06 | C2: 0.06 | D2: 0.06 | E2: 0.06 | F2: 0.06 | G2: 0.06 | H2: 0.06 | I2: 0.06 | J2: 0.06 | K2: -
A3: LCOE_alternative | B3: =Inputs!$C$8*Inputs!$C$6 / 10 -> 5.76 | C3: =Inputs!$C$8*Inputs!$C$6 / 10 -> 5.76 | D3: =Inputs!$C$8*Inputs!$C$6 / 10 -> 5.76 | E3: 5.9593963 | F3: 3.6109404 | G3: 2.969201 | H3: =Inputs!$C$9*Inputs!$C$6 / 10 -> 0.99 | I3: =Inputs!$C$9*Inputs!$C$6 / 10 -> 0.99 | J3: =Inputs!$C$9*Inputs!$C$6 / 10 -> 0.99 | K3: ct/kWh
B4: 11.1 | C4: 11.1 | D4: 11.1 | E4: 7.5 | F4: 7.5 | G4: 7.5 | H4: 3.9 | I4: 3.9 | J4: 3.9 | L4: Note: this is the standard LCOE curve
A5: DAC_source | B5: 460 | C5: 460 | D5: 460 | E5: 135 | F5: 135 | G5: 135 | H5: 80 | I5: 80 | J5: 80 | K5: €/tCO2
A6: DAC_alternative | B6: =Inputs!$C$32*Inputs!$C$6 -> 1153.8 | C6: =Inputs!$C$32*Inputs!$C$6 -> 1153.8 | D6: =Inputs!$C$32*Inputs!$C$6 -> 1153.8 | E6: 135 | F6: 135 | G6: 135 | H6: =Inputs!$C$33*Inputs!$C$6 -> 432 | I6: =Inputs!$C$33*Inputs!$C$6 -> 432 | J6: =Inputs!$C$33*Inputs!$C$6 -> 432 | K6: €/tCO2 | L6: Average between SS and LS DAC
B7: 731.19867 | C7: 731.19867 | D7: 731.19867 | E7: 449.5681 | F7: 449.5681 | G7: 449.5681 | H7: 298.29332 | I7: 298.29332 | J7: 298.29332 | L7: Note: this is modelled DAC cost
A8: Levelized cost of electricity [ct/kWh]
B10: 2020 | E10: 2035 | H10: 2050
B11: Offshore | C11: Onshore | D11: Hydro | E11: Offshore | F11: Onshore | G11: Hydro | H11: Offshore | I11: Onshore | J11: Hydro | N11: 2020 Offshore | O11: 2020 Onshore
A12: Capex generation | B12: 5.6892159 | C12: 4.0867761 | D12: 2.1299153 | E12: 3.5557599 | F12: 2.8062529 | G12: 2.1299153 | H12: 2.9335019 | I12: 2.5882915 | J12: 2.1299153 | K12: ct/kWh | M12: CAPEX | N12: 3200 | O12: 1500
A13: Opex generation | B13: 2.1818182 | C13: 1.171875 | D13: 0.83928571 | E13: 1.3636364 | F13: 0.8046875 | G13: 0.83928571 | H13: 1.125 | I13: 0.7421875 | J13: 0.83928571 | K13: ct/kWh | M13: Loadhours | N13: 4400 | O13: 3200
A14: Offshore grid fee | B14: 1.5 | C14: 0 | D14: 0 | E14: 1.04 | F14: 0 | G14: 0 | H14: 0.7 | I14: 0 | J14: 0 | K14: ct/kWh | M14: UCRF | N14: =B23 -> 0.078226718 | O14: =C23 -> 0.087184557
M15: Annualized CAPEX | N15: =N12*N14/N13 -> 0.056892159 | O15: =O12*O14/O13 -> 0.040867761 | P15: €/kWh
A16: BC | B16: 1.377431 | C16: 0.80426429 | D16: 0.37115013 | E16: 1.3238642 | F16: 1.1857743 | G16: 0.37115013 | H16: 1.292708 | I16: 1.020797 | J16: 0.37115013 | K16: ct/kWh | N16: =N15*100 -> 5.6892159 | O16: =O15*100 -> 4.0867761 | P16: ct/kWh
A17: WC | B17: 1.4414975 | C17: 0.91149953 | D17: 0.49486684 | E17: 1.3602703 | F17: 1.3812724 | G17: 0.49486684 | H17: 1.352834 | I17: 1.1569032 | J17: 0.49486684 | K17: ct/kWh
A19: LCOE | B19: =SUM(B12:B14) -> 9.3710341 | C19: =SUM(C12:C14) -> 5.2586511 | D19: =SUM(D12:D14) -> 2.969201 | E19: =SUM(E12:E14) -> 5.9593963 | F19: =SUM(F12:F14) -> 3.6109404 | G19: =SUM(G12:G14) -> 2.969201 | H19: =SUM(H12:H14) -> 4.7585019 | I19: =SUM(I12:I14) -> 3.330479 | J19: =SUM(J12:J14) -> 2.969201 | K19: ct/kWh
A20: LCOE | B20: =B19*10 -> 93.710341 | C20: =C19*10 -> 52.586511 | D20: =D19*10 -> 29.69201 | E20: =E19*10 -> 59.593963 | F20: =F19*10 -> 36.109404 | G20: =G19*10 -> 29.69201 | H20: =H19*10 -> 47.585019 | I20: =I19*10 -> 33.30479 | J20: =J19*10 -> 29.69201 | K20: €/MWh
A22: Lifetime | B22: 25 | C22: 20 | D22: 50 | E22: 25 | F22: 20 | G22: 50 | H22: 25 | I22: 20 | J22: 50 | K22: years | M22: WACC
A23: UCRF | B23: =(B$1*(1+B$1)^B22)/((1+B$1)^B22-1) -> 0.078226718 | C23: =(C$1*(1+C$1)^C22)/((1+C$1)^C22-1) -> 0.087184557 | D23: =(D$1*(1+D$1)^D22)/((1+D$1)^D22-1) -> 0.063444286 | E23: =(E$1*(1+E$1)^E22)/((1+E$1)^E22-1) -> 0.078226718 | F23: =(F$1*(1+F$1)^F22)/((1+F$1)^F22-1) -> 0.087184557 | G23: =(G$1*(1+G$1)^G22)/((1+G$1)^G22-1) -> 0.063444286 | H23: =(H$1*(1+H$1)^H22)/((1+H$1)^H22-1) -> 0.078226718 | I23: =(I$1*(1+I$1)^I22)/((1+I$1)^I22-1) -> 0.087184557 | J23: =(J$1*(1+J$1)^J22)/((1+J$1)^J22-1) -> 0.063444286 | K23: - | M23: WACC
A25: UCRF_alternative | B25: =(B$2*(1+B$2)^B22)/((1+B$2)^B22-1) -> 0.078226718 | C25: =(C$2*(1+C$2)^C22)/((1+C$2)^C22-1) -> 0.087184557 | D25: =(D$2*(1+D$2)^D22)/((1+D$2)^D22-1) -> 0.063444286 | E25: =(E$2*(1+E$2)^E22)/((1+E$2)^E22-1) -> 0.078226718 | F25: =(F$2*(1+F$2)^F22)/((1+F$2)^F22-1) -> 0.087184557 | G25: =(G$2*(1+G$2)^G22)/((1+G$2)^G22-1) -> 0.063444286 | H25: =(H$2*(1+H$2)^H22)/((1+H$2)^H22-1) -> 0.078226718 | I25: =(I$2*(1+I$2)^I22)/((1+I$2)^I22-1) -> 0.087184557 | J25: =(J$2*(1+J$2)^J22)/((1+J$2)^J22-1) -> 0.063444286 | K25: - | M25: WACC
A26: Capex generation_alternative | B26: =B12/B23*B25 -> 5.6892159 | C26: =C12/C23*C25 -> 4.0867761 | D26: =D12/D23*D25 -> 2.1299153 | E26: =E12/E23*E25 -> 3.5557599 | F26: =F12/F23*F25 -> 2.8062529 | G26: =G12/G23*G25 -> 2.1299153 | H26: =H12/H23*H25 -> 2.9335019 | I26: =I12/I23*I25 -> 2.5882915 | J26: =J12/J23*J25 -> 2.1299153 | K26: ct/kWh | M26: WACC
A27: LCOE_alternative | B27: =B19-B12+B26 -> 9.3710341 | C27: =C19-C12+C26 -> 5.2586511 | D27: =D19-D12+D26 -> 2.969201 | E27: =E19-E12+E26 -> 5.9593963 | F27: =F19-F12+F26 -> 3.6109404 | G27: =G19-G12+G26 -> 2.969201 | H27: =H19-H12+H26 -> 4.7585019 | I27: =I19-I12+I26 -> 3.330479 | J27: =J19-J12+J26 -> 2.969201 | K27: ct/kWh
A29: Levelized cost of hydrogen [ct/kWh]
B31: 2020 | E31: 2035 | H31: 2050
B32: Offshore | C32: Onshore | D32: Hydro | E32: Offshore | F32: Onshore | G32: Hydro | H32: Offshore | I32: Onshore | J32: Hydro
A33: Capex electrolysis | B33: 3.0462118 | C33: 4.1885412 | D33: 1.9147617 | E33: 1.3931149 | F33: 1.915533 | G33: 0.87567222 | H33: 0.81260441 | I33: 1.1173311 | J33: 0.51077992 | K33: ct/kWh
A34: Opex electrolysis | B34: 1.1682243 | C34: 1.6063084 | D34: 0.73431242 | E34: 0.53426052 | F34: 0.73460821 | G34: 0.3358209 | H34: 0.31163435 | I34: 0.42849723 | J34: 0.19588445 | K34: ct/kWh
A35: Electricity cost | B35: 14.596626 | C35: 8.1910453 | D35: 4.6249237 | E35: 8.8946213 | F35: 5.3894633 | G35: 4.4316433 | H35: 6.5907229 | I35: 4.6128518 | J35: 4.1124668 | K35: ct/kWh
A36: Storage cost | B36: 2.9792732 | C36: 2.9792732 | D36: 2.9792732 | E36: 2.3792732 | F36: 2.3792732 | G36: 2.3792732 | H36: 1.9792732 | I36: 1.9792732 | J36: 1.9792732 | K36: ct/kWh
A37: Liquefaction cost | B37: 3.7938486 | C37: 3.7938486 | D37: 3.7938486 | E37: 2.1404261 | F37: 2.1404261 | G37: 2.1404261 | H37: 1.4308452 | I37: 1.4308452 | J37: 1.4308452 | K37: ct/kWh
A38: Distribution cost | B38: 0.225 | C38: 0.225 | D38: 0.225 | E38: 0.195 | F38: 0.195 | G38: 0.195 | H38: 0.1875 | I38: 0.1875 | J38: 0.1875 | K38: ct/kWh
A40: BC | B40: 5.0944468 | C40: 4.5421905 | D40: 2.3451036 | E40: 4.0195481 | F40: 3.9103357 | G40: 2.0092187 | H40: 3.0022965 | I40: 2.7698807 | J40: 1.3897171 | K40: ct/kWh
A41: WC | B41: 6.2445545 | C41: 5.9119403 | D41: 3.4038153 | E41: 4.7428356 | F41: 5.0150862 | G41: 2.5555799 | H41: 4.1084781 | I41: 4.0463644 | J41: 2.3824229 | K41: ct/kWh
A43: LCOH | B43: =SUM(B33:B38) -> 25.809184 | C43: =SUM(C33:C38) -> 20.984017 | D43: =SUM(D33:D38) -> 14.27212 | E43: =SUM(E33:E38) -> 15.536696 | F43: =SUM(F33:F38) -> 12.754304 | G43: =SUM(G33:G38) -> 10.357836 | H43: =SUM(H33:H38) -> 11.31258 | I43: =SUM(I33:I38) -> 9.7562986 | J43: =SUM(J33:J38) -> 8.4167496 | K43: ct/kWh
A45: Electricity consumption | B45: =B35/B19 -> 1.5576324 | C45: =C35/C19 -> 1.5576324 | D45: =D35/D19 -> 1.5576324 | E45: =E35/E19 -> 1.4925373 | F45: =F35/F19 -> 1.4925373 | G45: =G35/G19 -> 1.4925373 | H45: =H35/H19 -> 1.3850416 | I45: =I35/I19 -> 1.3850416 | J45: =J35/J19 -> 1.3850416 | K45: kWh_el/kWh_fuel | M45: LCOE
A47: Lifetime | B47: 25 | C47: 25 | D47: 25 | E47: 25 | F47: 25 | G47: 25 | H47: 25 | I47: 25 | J47: 25 | K47: years | M47: WACC
A48: UCRF | B48: =(B$1*(1+B$1)^B47)/((1+B$1)^B47-1) -> 0.078226718 | C48: =(C$1*(1+C$1)^C47)/((1+C$1)^C47-1) -> 0.078226718 | D48: =(D$1*(1+D$1)^D47)/((1+D$1)^D47-1) -> 0.078226718 | E48: =(E$1*(1+E$1)^E47)/((1+E$1)^E47-1) -> 0.078226718 | F48: =(F$1*(1+F$1)^F47)/((1+F$1)^F47-1) -> 0.078226718 | G48: =(G$1*(1+G$1)^G47)/((1+G$1)^G47-1) -> 0.078226718 | H48: =(H$1*(1+H$1)^H47)/((1+H$1)^H47-1) -> 0.078226718 | I48: =(I$1*(1+I$1)^I47)/((1+I$1)^I47-1) -> 0.078226718 | J48: =(J$1*(1+J$1)^J47)/((1+J$1)^J47-1) -> 0.078226718 | K48: - | M48: WACC
A50: UCRF_alternative | B50: =(B$2*(1+B$2)^B47)/((1+B$2)^B47-1) -> 0.078226718 | C50: =(C$2*(1+C$2)^C47)/((1+C$2)^C47-1) -> 0.078226718 | D50: =(D$2*(1+D$2)^D47)/((1+D$2)^D47-1) -> 0.078226718 | E50: =(E$2*(1+E$2)^E47)/((1+E$2)^E47-1) -> 0.078226718 | F50: =(F$2*(1+F$2)^F47)/((1+F$2)^F47-1) -> 0.078226718 | G50: =(G$2*(1+G$2)^G47)/((1+G$2)^G47-1) -> 0.078226718 | H50: =(H$2*(1+H$2)^H47)/((1+H$2)^H47-1) -> 0.078226718 | I50: =(I$2*(1+I$2)^I47)/((1+I$2)^I47-1) -> 0.078226718 | J50: =(J$2*(1+J$2)^J47)/((1+J$2)^J47-1) -> 0.078226718 | K50: - | M50: WACC
A51: Electricity cost_alternative | B51: =B45*B3 -> 8.9719626 | C51: =C45*C3 -> 8.9719626 | D51: =D45*D3 -> 8.9719626 | E51: =E45*E3 -> 8.8946213 | F51: =F45*F3 -> 5.3894633 | G51: =G45*G3 -> 4.4316433 | H51: =H45*H3 -> 1.3711911 | I51: =I45*I3 -> 1.3711911 | J51: =J45*J3 -> 1.3711911 | K51: ct/kWh | M51: LCOE
...

Sheet WACC Corrected LCOF
A1: WACC_source | B1: 0.06 | C1: 0.06 | D1: 0.06 | E1: 0.06 | F1: 0.06 | G1: 0.06 | H1: 0.06 | I1: 0.06 | J1: 0.06 | K1: -
A2: WACC_alternative | B2: =Inputs!$C$5 -> 0.07 | C2: =Inputs!$C$5 -> 0.07 | D2: =Inputs!$C$5 -> 0.07 | E2: =Inputs!$C$5 -> 0.07 | F2: =Inputs!$C$5 -> 0.07 | G2: =Inputs!$C$5 -> 0.07 | H2: =Inputs!$C$5 -> 0.07 | I2: =Inputs!$C$5 -> 0.07 | J2: =Inputs!$C$5 -> 0.07 | K2: -
A3: LCOE_alternative | B3: =Inputs!$C$8*Inputs!$C$6 / 10 -> 5.76 | C3: =Inputs!$C$8*Inputs!$C$6 / 10 -> 5.76 | D3: =Inputs!$C$8*Inputs!$C$6 / 10 -> 5.76 | E3: 5.9593963 | F3: 3.6109404 | G3: 2.969201 | H3: =Inputs!$C$9*Inputs!$C$6 / 10 -> 0.99 | I3: =Inputs!$C$9*Inputs!$C$6 / 10 -> 0.99 | J3: =Inputs!$C$9*Inputs!$C$6 / 10 -> 0.99 | K3: ct/kWh
B4: 11.1 | C4: 11.1 | D4: 11.1 | E4: 7.5 | F4: 7.5 | G4: 7.5 | H4: 3.9 | I4: 3.9 | J4: 3.9 | L4: Note: this is the standard LCOE curve
A5: DAC_source | B5: 460 | C5: 460 | D5: 460 | E5: 135 | F5: 135 | G5: 135 | H5: 80 | I5: 80 | J5: 80 | K5: €/tCO2
A6: DAC_alternative | B6: =Inputs!$C$32*Inputs!$C$6 -> 1153.8 | C6: =Inputs!$C$32*Inputs!$C$6 -> 1153.8 | D6: =Inputs!$C$32*Inputs!$C$6 -> 1153.8 | E6: 135 | F6: 135 | G6: 135 | H6: =Inputs!$C$33*Inputs!$C$6 -> 432 | I6: =Inputs!$C$33*Inputs!$C$6 -> 432 | J6: =Inputs!$C$33*Inputs!$C$6 -> 432 | K6: €/tCO2 | L6: Average between SS and LS DAC
B7: 731.19867 | C7: 731.19867 | D7: 731.19867 | E7: 449.5681 | F7: 449.5681 | G7: 449.5681 | H7: 298.29332 | I7: 298.29332 | J7: 298.29332 | L7: Note: this is modelled DAC cost
A8: Levelized cost of electricity [ct/kWh]
B10: 2020 | E10: 2035 | H10: 2050
B11: Offshore | C11: Onshore | D11: Hydro | E11: Offshore | F11: Onshore | G11: Hydro | H11: Offshore | I11: Onshore | J11: Hydro | N11: 2020 Offshore | O11: 2020 Onshore
A12: Capex generation | B12: 5.6892159 | C12: 4.0867761 | D12: 2.1299153 | E12: 3.5557599 | F12: 2.8062529 | G12: 2.1299153 | H12: 2.9335019 | I12: 2.5882915 | J12: 2.1299153 | K12: ct/kWh | M12: CAPEX | N12: 3200 | O12: 1500
A13: Opex generation | B13: 2.1818182 | C13: 1.171875 | D13: 0.83928571 | E13: 1.3636364 | F13: 0.8046875 | G13: 0.83928571 | H13: 1.125 | I13: 0.7421875 | J13: 0.83928571 | K13: ct/kWh | M13: Loadhours | N13: 4400 | O13: 3200
A14: Offshore grid fee | B14: 1.5 | C14: 0 | D14: 0 | E14: 1.04 | F14: 0 | G14: 0 | H14: 0.7 | I14: 0 | J14: 0 | K14: ct/kWh | M14: UCRF | N14: =B23 -> 0.078226718 | O14: =C23 -> 0.087184557
M15: Annualized CAPEX | N15: =N12*N14/N13 -> 0.056892159 | O15: =O12*O14/O13 -> 0.040867761 | P15: €/kWh
A16: BC | B16: 1.377431 | C16: 0.80426429 | D16: 0.37115013 | E16: 1.3238642 | F16: 1.1857743 | G16: 0.37115013 | H16: 1.292708 | I16: 1.020797 | J16: 0.37115013 | K16: ct/kWh | N16: =N15*100 -> 5.6892159 | O16: =O15*100 -> 4.0867761 | P16: ct/kWh
A17: WC | B17: 1.4414975 | C17: 0.91149953 | D17: 0.49486684 | E17: 1.3602703 | F17: 1.3812724 | G17: 0.49486684 | H17: 1.352834 | I17: 1.1569032 | J17: 0.49486684 | K17: ct/kWh
A19: LCOE | B19: =SUM(B12:B14) -> 9.3710341 | C19: =SUM(C12:C14) -> 5.2586511 | D19: =SUM(D12:D14) -> 2.969201 | E19: =SUM(E12:E14) -> 5.9593963 | F19: =SUM(F12:F14) -> 3.6109404 | G19: =SUM(G12:G14) -> 2.969201 | H19: =SUM(H12:H14) -> 4.7585019 | I19: =SUM(I12:I14) -> 3.330479 | J19: =SUM(J12:J14) -> 2.969201 | K19: ct/kWh
A20: LCOE | B20: =B19*10 -> 93.710341 | C20: =C19*10 -> 52.586511 | D20: =D19*10 -> 29.69201 | E20: =E19*10 -> 59.593963 | F20: =F19*10 -> 36.109404 | G20: =G19*10 -> 29.69201 | H20: =H19*10 -> 47.585019 | I20: =I19*10 -> 33.30479 | J20: =J19*10 -> 29.69201 | K20: €/MWh
A22: Lifetime | B22: 25 | C22: 20 | D22: 50 | E22: 25 | F22: 20 | G22: 50 | H22: 25 | I22: 20 | J22: 50 | K22: years | M22: WACC
A23: UCRF | B23: =(B$1*(1+B$1)^B22)/((1+B$1)^B22-1) -> 0.078226718 | C23: =(C$1*(1+C$1)^C22)/((1+C$1)^C22-1) -> 0.087184557 | D23: =(D$1*(1+D$1)^D22)/((1+D$1)^D22-1) -> 0.063444286 | E23: =(E$1*(1+E$1)^E22)/((1+E$1)^E22-1) -> 0.078226718 | F23: =(F$1*(1+F$1)^F22)/((1+F$1)^F22-1) -> 0.087184557 | G23: =(G$1*(1+G$1)^G22)/((1+G$1)^G22-1) -> 0.063444286 | H23: =(H$1*(1+H$1)^H22)/((1+H$1)^H22-1) -> 0.078226718 | I23: =(I$1*(1+I$1)^I22)/((1+I$1)^I22-1) -> 0.087184557 | J23: =(J$1*(1+J$1)^J22)/((1+J$1)^J22-1) -> 0.063444286 | K23: - | M23: WACC
A25: UCRF_alternative | B25: =(B$2*(1+B$2)^B22)/((1+B$2)^B22-1) -> 0.085810517 | C25: =(C$2*(1+C$2)^C22)/((1+C$2)^C22-1) -> 0.094392926 | D25: =(D$2*(1+D$2)^D22)/((1+D$2)^D22-1) -> 0.07245985 | E25: =(E$2*(1+E$2)^E22)/((1+E$2)^E22-1) -> 0.085810517 | F25: =(F$2*(1+F$2)^F22)/((1+F$2)^F22-1) -> 0.094392926 | G25: =(G$2*(1+G$2)^G22)/((1+G$2)^G22-1) -> 0.07245985 | H25: =(H$2*(1+H$2)^H22)/((1+H$2)^H22-1) -> 0.085810517 | I25: =(I$2*(1+I$2)^I22)/((1+I$2)^I22-1) -> 0.094392926 | J25: =(J$2*(1+J$2)^J22)/((1+J$2)^J22-1) -> 0.07245985 | K25: - | M25: WACC
A26: Capex generation_alternative | B26: =B12/B23*B25 -> 6.2407649 | C26: =C12/C23*C25 -> 4.4246684 | D26: =D12/D23*D25 -> 2.4325807 | E26: =E12/E23*E25 -> 3.9004781 | F26: =F12/F23*F25 -> 3.0382723 | G26: =G12/G23*G25 -> 2.4325807 | H26: =H12/H23*H25 -> 3.2178944 | I26: =I12/I23*I25 -> 2.80229 | J26: =J12/J23*J25 -> 2.4325807 | K26: ct/kWh | M26: WACC
A27: LCOE_alternative | B27: =B19-B12+B26 -> 9.9225831 | C27: =C19-C12+C26 -> 5.5965434 | D27: =D19-D12+D26 -> 3.2718664 | E27: =E19-E12+E26 -> 6.3041144 | F27: =F19-F12+F26 -> 3.8429598 | G27: =G19-G12+G26 -> 3.2718664 | H27: =H19-H12+H26 -> 5.0428944 | I27: =I19-I12+I26 -> 3.5444775 | J27: =J19-J12+J26 -> 3.2718664 | K27: ct/kWh
A29: Levelized cost of hydrogen [ct/kWh]
B31: 2020 | E31: 2035 | H31: 2050
B32: Offshore | C32: Onshore | D32: Hydro | E32: Offshore | F32: Onshore | G32: Hydro | H32: Offshore | I32: Onshore | J32: Hydro
A33: Capex electrolysis | B33: 3.0462118 | C33: 4.1885412 | D33: 1.9147617 | E33: 1.3931149 | F33: 1.915533 | G33: 0.87567222 | H33: 0.81260441 | I33: 1.1173311 | J33: 0.51077992 | K33: ct/kWh
A34: Opex electrolysis | B34: 1.1682243 | C34: 1.6063084 | D34: 0.73431242 | E34: 0.53426052 | F34: 0.73460821 | G34: 0.3358209 | H34: 0.31163435 | I34: 0.42849723 | J34: 0.19588445 | K34: ct/kWh
A35: Electricity cost | B35: 14.596626 | C35: 8.1910453 | D35: 4.6249237 | E35: 8.8946213 | F35: 5.3894633 | G35: 4.4316433 | H35: 6.5907229 | I35: 4.6128518 | J35: 4.1124668 | K35: ct/kWh
A36: Storage cost | B36: 2.9792732 | C36: 2.9792732 | D36: 2.9792732 | E36: 2.3792732 | F36: 2.3792732 | G36: 2.3792732 | H36: 1.9792732 | I36: 1.9792732 | J36: 1.9792732 | K36: ct/kWh
A37: Liquefaction cost | B37: 3.7938486 | C37: 3.7938486 | D37: 3.7938486 | E37: 2.1404261 | F37: 2.1404261 | G37: 2.1404261 | H37: 1.4308452 | I37: 1.4308452 | J37: 1.4308452 | K37: ct/kWh
A38: Distribution cost | B38: 0.225 | C38: 0.225 | D38: 0.225 | E38: 0.195 | F38: 0.195 | G38: 0.195 | H38: 0.1875 | I38: 0.1875 | J38: 0.1875 | K38: ct/kWh
A40: BC | B40: 5.0944468 | C40: 4.5421905 | D40: 2.3451036 | E40: 4.0195481 | F40: 3.9103357 | G40: 2.0092187 | H40: 3.0022965 | I40: 2.7698807 | J40: 1.3897171 | K40: ct/kWh
A41: WC | B41: 6.2445545 | C41: 5.9119403 | D41: 3.4038153 | E41: 4.7428356 | F41: 5.0150862 | G41: 2.5555799 | H41: 4.1084781 | I41: 4.0463644 | J41: 2.3824229 | K41: ct/kWh
A43: LCOH | B43: =SUM(B33:B38) -> 25.809184 | C43: =SUM(C33:C38) -> 20.984017 | D43: =SUM(D33:D38) -> 14.27212 | E43: =SUM(E33:E38) -> 15.536696 | F43: =SUM(F33:F38) -> 12.754304 | G43: =SUM(G33:G38) -> 10.357836 | H43: =SUM(H33:H38) -> 11.31258 | I43: =SUM(I33:I38) -> 9.7562986 | J43: =SUM(J33:J38) -> 8.4167496 | K43: ct/kWh
A45: Electricity consumption | B45: =B35/B19 -> 1.5576324 | C45: =C35/C19 -> 1.5576324 | D45: =D35/D19 -> 1.5576324 | E45: =E35/E19 -> 1.4925373 | F45: =F35/F19 -> 1.4925373 | G45: =G35/G19 -> 1.4925373 | H45: =H35/H19 -> 1.3850416 | I45: =I35/I19 -> 1.3850416 | J45: =J35/J19 -> 1.3850416 | K45: kWh_el/kWh_fuel | M45: LCOE
A47: Lifetime | B47: 25 | C47: 25 | D47: 25 | E47: 25 | F47: 25 | G47: 25 | H47: 25 | I47: 25 | J47: 25 | K47: years | M47: WACC
A48: UCRF | B48: =(B$1*(1+B$1)^B47)/((1+B$1)^B47-1) -> 0.078226718 | C48: =(C$1*(1+C$1)^C47)/((1+C$1)^C47-1) -> 0.078226718 | D48: =(D$1*(1+D$1)^D47)/((1+D$1)^D47-1) -> 0.078226718 | E48: =(E$1*(1+E$1)^E47)/((1+E$1)^E47-1) -> 0.078226718 | F48: =(F$1*(1+F$1)^F47)/((1+F$1)^F47-1) -> 0.078226718 | G48: =(G$1*(1+G$1)^G47)/((1+G$1)^G47-1) -> 0.078226718 | H48: =(H$1*(1+H$1)^H47)/((1+H$1)^H47-1) -> 0.078226718 | I48: =(I$1*(1+I$1)^I47)/((1+I$1)^I47-1) -> 0.078226718 | J48: =(J$1*(1+J$1)^J47)/((1+J$1)^J47-1) -> 0.078226718 | K48: - | M48: WACC
A50: UCRF_alternative | B50: =(B$2*(1+B$2)^B47)/((1+B$2)^B47-1) -> 0.085810517 | C50: =(C$2*(1+C$2)^C47)/((1+C$2)^C47-1) -> 0.085810517 | D50: =(D$2*(1+D$2)^D47)/((1+D$2)^D47-1) -> 0.085810517 | E50: =(E$2*(1+E$2)^E47)/((1+E$2)^E47-1) -> 0.085810517 | F50: =(F$2*(1+F$2)^F47)/((1+F$2)^F47-1) -> 0.085810517 | G50: =(G$2*(1+G$2)^G47)/((1+G$2)^G47-1) -> 0.085810517 | H50: =(H$2*(1+H$2)^H47)/((1+H$2)^H47-1) -> 0.085810517 | I50: =(I$2*(1+I$2)^I47)/((1+I$2)^I47-1) -> 0.085810517 | J50: =(J$2*(1+J$2)^J47)/((1+J$2)^J47-1) -> 0.085810517 | K50: - | M50: WACC
A51: Electricity cost_alternative | B51: =B45*B3 -> 8.9719626 | C51: =C45*C3 -> 8.9719626 | D51: =D45*D3 -> 8.9719626 | E51: =E45*E3 -> 8.8946213 | F51: =F45*F3 -> 5.3894633 | G51: =G45*G3 -> 4.4316433 | H51: =H45*H3 -> 1.3711911 | I51: =I45*I3 -> 1.3711911 | J51: =J45*J3 -> 1.3711911 | K51: ct/kWh | M51: LCOE
...

Sheet Outputs
A1: 2024 | H1: 2050
A2: Parameter | B2: Unit | C2: Base Case | D2: LCOE Corrected | E2: CO2 Cost Corrected | F2: WACC Corrected | H2: Parameter | I2: Unit | J2: Base Case | K2: LCOE Corrected | L2: CO2 Cost Corrected | M2: WACC Corrected
A3: Syn-Fuel cost | B3: €/l | C3: =AVERAGE('Base LCOF'!B113:D113) -> 3.3668222 | D3: ='LCOE Corrected LCOF'!B113 -> 3.3416801 | E3: =AVERAGE('CO2 Price Corrected LCOF'!B113:D113) -> 5.6292035 | F3: =AVERAGE('WACC Corrected LCOF'!B113:D113) -> 5.6365113 | H3: Syn-Fuel cost | I3: €/l | J3: =AVERAGE('Base LCOF'!H113:J113) -> 1.2028937 | K3: =AVERAGE('LCOE Corrected LCOF'!H113:J113) -> 0.74452389 | L3: =AVERAGE('CO2 Price Corrected LCOF'!H113:J113) -> 1.9011522 | M3: =AVERAGE('WACC Corrected LCOF'!H113:J113) -> 1.9048061
A4: Syn-Fuel cost | B4: $/l | C4: =C3/Inputs!$C$6 -> 3.7409136 | D4: =D3/Inputs!$C$6 -> 3.7129779 | E4: =E3/Inputs!$C$6 -> 6.2546706 | F4: =F3/Inputs!$C$6 -> 6.2627903 | H4: Syn-Fuel cost | I4: $/l | J4: =J3/Inputs!$C$6 -> 1.3365486 | K4: =K3/Inputs!$C$6 -> 0.82724876 | L4: =L3/Inputs!$C$6 -> 2.1123914 | M4: =M3/Inputs!$C$6 -> 2.1164512
A5: Fossil Fuel cost | B5: $/l | C5: =Inputs!$C$16 -> 0.8 | D5: =Inputs!$C$16 -> 0.8 | E5: =Inputs!$C$16 -> 0.8 | F5: =Inputs!$C$16 -> 0.8 | H5: Fossil Fuel cost | I5: $/l | J5: =Inputs!$C$18 -> 0.8 | K5: =Inputs!$C$18 -> 0.8 | L5: =Inputs!$C$18 -> 0.8 | M5: =Inputs!$C$18 -> 0.8
A6: Syn-Fuel emissions | B6: gCO2eq/MJ | C6: 13.4 | D6: 13.4 | E6: 13.4 | F6: 13.4 | H6: Syn-Fuel emissions | I6: gCO2eq/MJ | J6: 13.4 | K6: 13.4 | L6: 13.4 | M6: 13.4
A7: Fossil Fuel emissions | B7: gCO2eq/MJ | C7: =Inputs!$C$11 -> 88.7 | D7: =Inputs!$C$11 -> 88.7 | E7: =Inputs!$C$11 -> 88.7 | F7: =Inputs!$C$11 -> 88.7 | H7: Fossil Fuel emissions | I7: gCO2eq/MJ | J7: =Inputs!$C$11 -> 88.7 | K7: =Inputs!$C$11 -> 88.7 | L7: =Inputs!$C$11 -> 88.7 | M7: =Inputs!$C$11 -> 88.7
A8: CO2 Abated | B8: gCO2eq/MJ | C8: =C7-C6 -> 75.3 | D8: =D7-D6 -> 75.3 | E8: =E7-E6 -> 75.3 | F8: =F7-F6 -> 75.3 | H8: CO2 Abated | I8: gCO2eq/MJ | J8: =J7-J6 -> 75.3 | K8: =K7-K6 -> 75.3 | L8: =L7-L6 -> 75.3 | M8: =M7-M6 -> 75.3
A9: CO2 Abated | B9: gCO2eq/l | C9: =C8 * Inputs!$C$14 -> 2612.1269 | D9: =D8*Inputs!$C$14 -> 2612.1269 | E9: =E8*Inputs!$C$14 -> 2612.1269 | F9: =F8*Inputs!$C$14 -> 2612.1269 | H9: CO2 Abated | I9: gCO2eq/l | J9: =J8 * Inputs!$C$14 -> 2612.1269 | K9: =K8 * Inputs!$C$14 -> 2612.1269 | L9: =L8 * Inputs!$C$14 -> 2612.1269 | M9: =M8 * Inputs!$C$14 -> 2612.1269
A10: Abatement cost | B10: $/tCO2 | C10: =(C4-C5) / C9 * 10^6 -> 1125.8694 | D10: =(D4-D5) / D9 * 10^6 -> 1115.1747 | E10: =(E4-E5) / E9 * 10^6 -> 2088.2104 | F10: =(F4-F5) / F9 * 10^6 -> 2091.3189 | H10: Abatement cost | I10: $/tCO2 | J10: =(J4-J5) / J9 * 10^6 -> 205.40678 | K10: =(K4-K5) / K9 * 10^6 -> 10.431639 | L10: =(L4-L5) / L9 * 10^6 -> 502.42252 | M10: =(M4-M5) / M9 * 10^6 -> 503.97676
A12: Full Abatement | H12: Full Abatement
A13: Parameter | B13: Unit | C13: Value | H13: Parameter | I13: Unit | J13: Value
A14: Residual Emissions | B14: gCO2eq/l | C14: =C6*Inputs!$C$14 -> 464.84064 | H14: Residual Emissions | I14: gCO2eq/l | J14: =J6*Inputs!$C$14 -> 464.84064
A15: Emissions Reduction Cost | B15: $/l | C15: =C14*Inputs!$C$32 * 10^-6 -> 0.5959257 | H15: Emissions Reduction Cost | I15: $/l | J15: =J14*Inputs!$C$32 * 10^-6 -> 0.5959257
A16: Effective Synfuel Cost | B16: $/l | C16: =F4+C15 -> 6.858716 | H16: Effective Synfuel Cost | I16: $/l | J16: =M4+J15 -> 2.7123769
A17: Effective Abatement Cost | B17: $/tCO2 | C17: =(C16-C5) /C9 * 10^6 -> 2319.457 | H17: Effective Abatement Cost | I17: $/tCO2 | J17: =(J16-J5) /J9 * 10^6 -> 732.11487
