Workbook

Sheet Readme

Sheet Inputs
A1: Parameter | B1: Year | C1: Value | D1: Unit
A2: Standard Values
A3: Current Year | C3: =[1]Inputs!C4 -> 2024
A4: Inflation | C4: =[1]Inputs!C5 -> 0.02
A5: WACC | C5: =[1]Inputs!C6 -> 0.07
A6: USD to EUR | C6: =[1]Inputs!C7 -> 0.9
A7: Electricity
A8: LCOE | B8: 2024 | C8: =[1]Inputs!C9 -> 64 | D8: $/MWh
A9: LCOE | B9: 2050 | C9: =[1]Inputs!C10 -> 11 | D9: $/MWh
A10: Jet Fuel A-1 Characteristics
A11: Emissions Intensity | B11: 2024 | C11: =[1]Inputs!C12 -> 88.7 | D11: gCO2/MJ
A12: Emissions Intensity | B12: 2050 | C12: =[1]Inputs!C13 -> 88.7 | D12: gCO2/MJ
A13: Energy Density | C13: =[1]Inputs!C14 -> 43.2 | D13: MJ/kg
A14: Energy Density | C14: =[1]Inputs!C15 -> 34.6896 | D14: MJ/l
A15: Volumetric Density | C15: =[1]Inputs!C16 -> 0.803 | D15: kg/l
A16: Jet Fuel A-1 Price | B16: 2024 | C16: =[1]Inputs!C17 -> 0.8 | D16: $/l
A17: Scenario Specific Values
A18: Jet Fuel A-1 Price | B18: 2050 | C18: =[1]Inputs!C19 -> 0.8 | D18: $/l
A19: Reference
A20: Jet Fuel A-1 Price | B20: 2024 | C20: =[1]Inputs!C21 -> 0.32246154 | D20: $/l
A21: Jet Fuel A-1 Price | B21: 2050 | C21: =[1]Inputs!C22 -> 0.20923077 | D21: $/l
A22: EIA Reference
A23: Jet Fuel A-1 Price | B23: 2024 | C23: =[1]Inputs!C24 -> 1.0209014 | D23: $/l
A24: Jet Fuel A-1 Price | B24: 2050 | C24: =[1]Inputs!C25 -> 2.0095594 | D24: $/l
A25: EIA Low Oil Price Scenario
A26: Jet Fuel A-1 Price | B26: 2024 | C26: =[1]Inputs!C27 -> 0.48286833 | D26: $/l
A27: Jet Fuel A-1 Price | B27: 2050 | C27: =[1]Inputs!C28 -> 0.89646575 | D27: $/l
A28: EIA High Scenario
A29: Jet Fuel A-1 Price | B29: 2024 | C29: =[1]Inputs!C30 -> 1.8838713 | D29: $/l
A30: Jet Fuel A-1 Price | B30: 2050 | C30: =[1]Inputs!C31 -> 3.7893731 | D30: $/l
A31: Direct Air Capture
A32: LCOR | B32: 2024 | C32: =[1]Inputs!C33 -> 1282 | D32: $/tCO2
A33: LCOR | B33: 2050 | C33: =[1]Inputs!C34 -> 480 | D33: $/tCO2

Sheet Study Parameters
A1: Key Parameters
A2: Parameter | B2: Year | C2: Value | D2: Source | E2: Note
A3: Lifetime (years) | B3: Both | C3: 25
A4: Discount Rate | B4: 2024 | C4: 0.065
A5: Discount Rate (Baseline) | B5: 2050 | C5: 0.065
A6: Discount Rate (Optimistic) | B6: 2050 | C6: 0.05
A7: Full load (hours) | B7: Both | C7: 8000
A8: Debt-to-Equity Ratio | B8: 2024 | C8: 2
A9: Debt-to-Equity Ratio (Baseline) | B9: 2050 | C9: 2
A10: Debt-to-Equity Ratio (Optimistic) | B10: 2050 | C10: 1.5
A11: Debt Interest Rate | B11: Both | C11: 0.046 | D11: Moretti et. al. 2023 Supplementary Information Table A.1 | E11: Sierra Gorda site
A12: WACC | B12: 2024 | C12: =(C8*C11 + 1 *C4) / (1+C8) -> 0.052333333 | D12: Calculated
A13: WACC - Baseline | B13: 2050 | C13: =(C9*C11 + 1 *C5) /(1+C9) -> 0.052333333 | D13: Calculated
A14: WACC - Optimistic | B14: 2050 | C14: =(C10*C11+C5) / (1+C10) -> 0.0536 | D14: Calculated
A15: Process Parameters
A16: Parameter | B16: Year | C16: Value | D16: Unit | E16: Source | F16: Note
A17: CO2 Capture | B17: 2024 | C17: 61.9 | D17: kt/year | E17: Moretti et. al. 2023 Supplementary Information Table B.1 | F17: Sierra Gorda site
A18: CO2 Capture | B18: 2050 | C18: 116.9 | D18: kt/year | E18: Moretti et. al. 2023 Supplementary Information Table B.1 | F18: Sierra Gorda site
A19: Jet Fuel Output | B19: Both | C19: 24.3 | D19: kt/year | E19: Moretti et. al. 2023 Supplementary Information Table A.3
A20: Jet Fuel Output | B20: Both | C20: =C19*10^6 / C28 -> 31354839 | D20: l/year
A22: Electricity Output | B22: 2024 | C22: 176679 | D22: MWh/year | E22: Moretti et. al. 2023 Supplementary Information Table B.2
A23: Electricity Output | B23: 2050 | C23: 55 | D23: MWh/year | E23: Moretti et. al. 2023 Supplementary Information Table B.2
A25: Fuel Characteristics
A26: Parameter | B26: Year | C26: Value | D26: Unit | E26: Source | F26: Note
A27: Energy Density Jet Fuel | C27: 43.2 | D27: MJ/kg | E27: Moretti et. al. 2023 Supplementary Information Table A.8 | F27: LHV considered
A28: Volumetric Density Jet Fuel | C28: 0.775 | D28: kg/l | E28: Moretti et. al. 2023 Supplementary Information Table A.8
A29: Emissions Intensity | B29: 2024 | C29: 13.5 | D29: gCO/MJ | E29: Moretti et. al. 2023
A30: Emissions Intensity | B30: 2050 | C30: 9.7 | D30: gCO/MJ | E30: Moretti et. al. 2023
A31: Plant Scale
A32: Parameter | B32: Year | C32: Value | D32: Unit | E32: Source | F32: Note
A33: Heliostat Field | B33: Both | C33: 1 | D33: km2 | E33: Moretti et. al. 2023 Table 1
A35: External Costs
A36: Parameter | B36: Year | C36: Value | D36: Unit | E36: Source | F36: Note
A37: Electricity | B37: Both | C37: 50 | D37: €/MWh | E37: Moretti et. al. 2023
A38: DAC | B38: 2024 | C38: 730 | D38: €/tCO2 | E38: Moretti et. al. 2023
A39: DAC | B39: 2050 | C39: 237 | D39: €/tCO2 | E39: Moretti et. al. 2023
A40: Labour Costs | B40: 2024 | C40: =(C19* 10 * 1.2 * 21761) * (1+0.15) / 10^6 -> 7.2973337 | D40: M€/year | E40: Moretti et. al. 2023 Supplementary Information Labour Cost Equation
B41: 2050 | C41: =(C19* 10 * 1.2 * 21761 * 1.02 ^ 25) * (1+0.15) / 10^6 -> 11.972049 | D41: M€/year | E41: Moretti et. al. 2023 Supplementary Information Labour Cost Equation

Sheet Cost Components
A1: Economic Assumptions 2024 | G1: Economic Assumptions 2050 - Baseline | M1: Economic Assumptions 2050 - Optimistic
A2: CAPEX | G2: CAPEX | M2: CAPEX
A3: Component | B3: Value | C3: Unit | D3: Source | E3: Notes | G3: Component | H3: Value | I3: Unit | J3: Source | K3: Notes | M3: Component | N3: Value | O3: Unit | P3: Source | Q3: Notes
A4: Heliostat | B4: 120 | C4: €/m2 | D4: Moretti et. al. 2023 | G4: Heliostat | H4: 100 | I4: €/m2 | J4: Moretti et. al. 2023 | M4: Heliostat | N4: 100 | O4: €/m2 | P4: Moretti et. al. 2023
A5: Receiver | B5: 50 | C5: €/m2 | D5: Moretti et. al. 2023 | G5: Receiver | H5: 40 | I5: €/m2 | J5: Moretti et. al. 2023 | M5: Receiver | N5: 40 | O5: €/m2 | P5: Moretti et. al. 2023
A6: Power Block | B6: 14.4 | C6: M€ | D6: Moretti et. al. 2023 | G6: Power Block | H6: 14.4 | I6: M€ | J6: Moretti et. al. 2023 | M6: Power Block | N6: 11.2 | O6: M€ | P6: Moretti et. al. 2023
A7: Solar Redox | B7: 9 | C7: M€ | D7: Moretti et. al. 2023 | E7: Conversion factor applied according to Solar redox section in the paper | G7: Solar Redox | H7: 2.7 | I7: M€ | J7: Moretti et. al. 2023 | K7: Conversion factor applied according to Solar redox section in the paper | M7: Solar Redox | N7: 2.7 | O7: M€ | P7: Moretti et. al. 2023 | Q7: Conversion factor applied according to Solar redox section in the paper
A8: Heat Exchanger | B8: 0.76 | C8: M€ | D8: Moretti et. al. 2023 | G8: Heat Exchangers | H8: 0.44 | I8: M€ | J8: Moretti et. al. 2023 | M8: Heat Exchangers | N8: 0.44 | O8: M€ | P8: Moretti et. al. 2023
A9: Vacuum Pumps | B9: 0.46 | C9: M€ | D9: Moretti et. al. 2023 | G9: Vacuum Pumps | H9: 0.36 | I9: M€ | J9: Moretti et. al. 2023 | M9: Vacuum Pumps | N9: 0.36 | O9: M€ | P9: Moretti et. al. 2023
A10: Thermal Energy Storage | B10: 1.85 | C10: M€ | D10: Moretti et. al. 2023 | G10: Thermal Energy Storage | H10: 1.22 | I10: M€ | J10: Moretti et. al. 2023 | M10: Thermal Energy Storage | N10: 1.22 | O10: M€ | P10: Moretti et. al. 2023
A11: CO2 separator | B11: 16.9 | C11: M€ | D11: Moretti et. al. 2023 | G11: CO2 separator | H11: 16.9 | I11: M€ | J11: Moretti et. al. 2023 | M11: CO2 separator | N11: 12.2 | O11: M€ | P11: Moretti et. al. 2023
A12: FT Synthesis Unit | B12: 114.5 | C12: M€ | D12: Moretti et. al. 2023 | G12: FT Synthesis Unit | H12: 114.5 | I12: M€ | J12: Moretti et. al. 2023 | M12: FT Synthesis Unit | N12: 55.4 | O12: M€ | P12: Moretti et. al. 2023
A13: FT Distillation | B13: 34.8 | C13: M€ | D13: Moretti et. al. 2023 | G13: FT Distillation | H13: 34.8 | I13: M€ | J13: Moretti et. al. 2023 | M13: FT Distillation | N13: 34.8 | O13: M€ | P13: Moretti et. al. 2023
A14: Total Capex | B14: =SUM(B4:B13) -> 362.67 | C14: M€ | G14: Total Capex | H14: =SUM(H4:H13) -> 325.32 | I14: M€ | M14: Total Capex | N14: =SUM(N4:N13) -> 258.32 | O14: M€
A16: OPEX | G16: OPEX | M16: OPEX
A17: Component | B17: Value | C17: Unit | D17: Source | E17: Notes | G17: Component | H17: Value | I17: Unit | J17: Source | K17: Notes | M17: Component | N17: Value | O17: Unit | P17: Source | Q17: Notes
A18: Labour | B18: ='Study Parameters'!C40 -> 7.2973337 | C18: M€/year | D18: Moretti et. al. 2023 Supplementary Information Labour Cost Equation | G18: Labour | H18: ='Study Parameters'!C41 -> 11.972049 | I18: M€/year | J18: Moretti et. al. 2023 Supplementary Information Labour Cost Equation | M18: Labour | N18: ='Study Parameters'!C41 -> 11.972049
A19: Overhead | B19: =0.35 * B18 -> 2.5540668 | C19: M€/year | D19: Moretti et. al. 2023 Supplementary Information Table A.7 | G19: Overhead | H19: =0.35*H18 -> 4.1902173 | I19: M€/year | J19: Moretti et. al. 2023 Supplementary Information Table A.7 | M19: Overhead | N19: =0.35*N18 -> 4.1902173
A20: Maintenance and Repairs | B20: =0.025 * B14 -> 9.06675 | C20: M€/year | D20: Moretti et. al. 2023 Supplementary Information Table A.7 | G20: Maintenance and Repairs | H20: =0.01 * H14 -> 3.2532 | I20: M€/year | J20: Moretti et. al. 2023 Supplementary Information Table A.7 | M20: Maintenance and Repairs | N20: =0.01 * N14 -> 2.5832 | O20: M€/year | P20: Moretti et. al. 2023 Supplementary Information Table A.7
A21: Local Taxes | B21: =0.01 * B14 -> 3.6267 | C21: M€/year | D21: Moretti et. al. 2023 Supplementary Information Table A.7 | G21: Local Taxes | H21: =0.01 * H14 -> 3.2532 | I21: M€/year | J21: Moretti et. al. 2023 Supplementary Information Table A.7 | M21: Local Taxes | N21: =0.01 * N14 -> 2.5832 | O21: M€/year | P21: Moretti et. al. 2023 Supplementary Information Table A.7
A22: Insurance | B22: =0.01*B14 -> 3.6267 | C22: M€/year | D22: Moretti et. al. 2023 Supplementary Information Table A.7 | G22: Insurance | H22: =0.01 * H14 -> 3.2532 | I22: M€/year | J22: Moretti et. al. 2023 Supplementary Information Table A.7 | M22: Insurance | N22: =0.01 * N14 -> 2.5832 | O22: M€/year | P22: Moretti et. al. 2023 Supplementary Information Table A.7
D23: Moretti et. al. 2023 Supplementary Information Table A.7 | I23: M€/year | J23: Moretti et. al. 2023 Supplementary Information Table A.7 | O23: M€/year | P23: Moretti et. al. 2023 Supplementary Information Table A.7
D24: Moretti et. al. 2023 Supplementary Information Table A.7 | I24: M€/year | J24: Moretti et. al. 2023 Supplementary Information Table A.7 | O24: M€/year | P24: Moretti et. al. 2023 Supplementary Information Table A.7
A25: Administrative Cost | B25: =0.2*B18 -> 1.4594667 | C25: M€/year | D25: Moretti et. al. 2023 Supplementary Information Table A.7 | G25: Administrative Cost | H25: =0.02 * H18 -> 0.23944099 | I25: M€/year | J25: Moretti et. al. 2023 Supplementary Information Table A.7 | M25: Administrative Cost | N25: =0.02 * N18 -> 0.23944099 | O25: M€/year | P25: Moretti et. al. 2023 Supplementary Information Table A.7
A26: Laboratory Charges | B26: =0.15*B18 -> 1.0946001 | C26: M€/year | D26: Moretti et. al. 2023 Supplementary Information Table A.7 | G26: Laboratory Charges | H26: =0.15 *H18 -> 1.7958074 | I26: M€/year | J26: Moretti et. al. 2023 Supplementary Information Table A.7 | M26: Laboratory Charges | N26: =0.15 *N18 -> 1.7958074 | O26: M€/year | P26: Moretti et. al. 2023 Supplementary Information Table A.7
A27: Sales and Marketing | B27: =0.065 * SUM(B18:B26) -> 1.8671651 | C27: M€/year | G27: Sales and Marketing | H27: =0.065 * SUM(H18:H26) -> 1.8172125 | M27: Sales and Marketing | N27: =0.065 * SUM(N18:N26) -> 1.6865625
A28: CO2 Cost | B28: =('Study Parameters'!C38*'Study Parameters'!C17* 1000) / 10^6 -> 45.187 | C28: M€/year | D28: Moretti et. al. 2023 | G28: CO2 Cost | H28: =('Study Parameters'!$C$39*'Study Parameters'!$C$18 * 10^3) / 10^6 -> 27.7053 | I28: M€/year | J28: Moretti et. al. 2023 | M28: CO2 Cost | N28: =('Study Parameters'!$C$39*'Study Parameters'!$C$18 * 10^3) / 10^6 -> 27.7053 | O28: M€/year | P28: Moretti et. al. 2023
A29: Surplus Electricity | B29: =('Study Parameters'!C22* 'Study Parameters'!C37) * Inputs!C6 / 10^6 -> 7.950555 | C29: M€/year | D29: Moretti et. al. 2023 Supplementary Information Table A.7 | G29: Surplus Electricity | H29: =('Study Parameters'!$C$23*'Study Parameters'!$C$37) * Inputs!$C$6 / 10^6 -> 0.002475 | I29: M€/year | J29: Moretti et. al. 2023 Supplementary Information Table A.7 | M29: Surplus Electricity | N29: =('Study Parameters'!$C$23*'Study Parameters'!$C$37) * Inputs!$C$6 / 10^6 -> 0.002475 | O29: M€/year | P29: Moretti et. al. 2023 Supplementary Information Table A.7
A30: Total OPEX | B30: =SUM(B20:B28)-B29 -> 57.977827 | C30: M€/year | G30: Total OPEX | H30: =SUM(H20:H28) -> 41.317361 | I30: M€/year | M30: Total OPEX | N30: =SUM(N20:N28) -> 39.176711 | O30: M€/year
A32: Standardized Economic Assumptions 2024 | G32: Standardized Economic Assumptions 2050 (Baseline) | M32: Standardized Economic Assumptions 2050 (Optimistic)
A33: Component | B33: Value | C33: Unit | D33: Source | E33: Notes | G33: Component | H33: Value | I33: Unit | J33: Source | K33: Notes | M33: Component | N33: Value | O33: Unit | P33: Source | Q33: Notes
A34: Surplus Electricity | B34: =(Inputs!C8*'Study Parameters'!C22) / 10^6 -> 11.307456 | C34: M€/year | G34: Surplus Electricity | H34: =(Inputs!$C$9*'Study Parameters'!$C$23*Inputs!$C$6) / 10^6 -> 0.0005445 | I34: M€/year | M34: Surplus Electricity | N34: =(Inputs!$C$9*'Study Parameters'!$C$23*Inputs!$C$6) / 10^6 -> 0.0005445 | O34: M€/year
A35: LCOE Corrected OPEX | B35: =B30+B29-B34 -> 54.620926 | C35: M€/year | G35: LCOE Corrected OPEX | H35: =H30+H29-H34 -> 41.319291 | I35: M€/year | M35: LCOE Corrected OPEX | N35: =N30+N29-N34 -> 39.178641 | O35: M€/year
A36: CO2 Cost | B36: =(Inputs!C32*'Study Parameters'!C17* 1000) / 10^6 -> 79.3558 | C36: M€/year | G36: CO2 Cost | H36: =(Inputs!$C$33 * 'Study Parameters'!$C$18 * 1000) / 10 ^ 6 -> 56.112 | I36: M€/year | M36: CO2 Cost | N36: =(Inputs!$C$33 * 'Study Parameters'!$C$18 * 1000) / 10 ^ 6 -> 56.112 | O36: M€/year
A37: CO2 Corrected OPEX | B37: =B35-B28+B36 -> 88.789726 | C37: M€/year | G37: CO2 Corrected OPEX | H37: =H35-H28+H36 -> 69.725991 | I37: M€/year | M37: CO2 Corrected OPEX | N37: =N35-N28+N36 -> 67.585341 | O37: M€/year
A38: WACC | B38: =Inputs!C5 -> 0.07 | G38: WACC | H38: =Inputs!$C$5 -> 0.07 | M38: WACC | N38: =Inputs!$C$5 -> 0.07

Sheet MFSP Baseline
A1: Economic Model 2024
A2: Year | B2: 0 | C2: 1 | D2: 2 | E2: 3 | F2: 4 | G2: 5 | H2: 6 | I2: 7 | J2: 8 | K2: 9 | L2: 10 | M2: 11 | N2: 12 | O2: 13 | P2: 14 | Q2: 15 | R2: 16 | S2: 17 | T2: 18 | U2: 19 | V2: 20 | W2: 21 | X2: 22 | Y2: 23 | Z2: 24 | AA2: 25
A3: Cost (€) | B3: ='Cost Components'!B14 * 10^6 -> 362670000 | C3: ='Cost Components'!$B$30*10^6 -> 57977827 | D3: ='Cost Components'!$B$30*10^6 -> 57977827 | E3: ='Cost Components'!$B$30*10^6 -> 57977827 | F3: ='Cost Components'!$B$30*10^6 -> 57977827 | G3: ='Cost Components'!$B$30*10^6 -> 57977827 | H3: ='Cost Components'!$B$30*10^6 -> 57977827 | I3: ='Cost Components'!$B$30*10^6 -> 57977827 | J3: ='Cost Components'!$B$30*10^6 -> 57977827 | ... AA3: ='Cost Components'!$B$30*10^6 -> 57977827
A4: Discounted Cost (€) | B4: =B3 / (1+'Study Parameters'!$C$12) ^'MFSP Baseline'!B2 -> 362670000 | C4: =C3 / (1+'Study Parameters'!$C$12) ^'MFSP Baseline'!C2 -> 55094546 | D4: =D3 / (1+'Study Parameters'!$C$12) ^'MFSP Baseline'!D2 -> 52354652 | E4: =E3 / (1+'Study Parameters'!$C$12) ^'MFSP Baseline'!E2 -> 49751016 | F4: =F3 / (1+'Study Parameters'!$C$12) ^'MFSP Baseline'!F2 -> 47276860 | G4: =G3 / (1+'Study Parameters'!$C$12) ^'MFSP Baseline'!G2 -> 44925746 | H4: =H3 / (1+'Study Parameters'!$C$12) ^'MFSP Baseline'!H2 -> 42691555 | I4: =I3 / (1+'Study Parameters'!$C$12) ^'MFSP Baseline'!I2 -> 40568471 | ... AA4: =AA3 / (1+'Study Parameters'!$C$12) ^'MFSP Baseline'!AA2 -> 16196783
A5: Production (l) | B5: 0 | C5: ='Study Parameters'!$C$20 -> 31354839 | D5: ='Study Parameters'!$C$20 -> 31354839 | E5: ='Study Parameters'!$C$20 -> 31354839 | F5: ='Study Parameters'!$C$20 -> 31354839 | G5: ='Study Parameters'!$C$20 -> 31354839 | H5: ='Study Parameters'!$C$20 -> 31354839 | I5: ='Study Parameters'!$C$20 -> 31354839 | J5: ='Study Parameters'!$C$20 -> 31354839 | ... AA5: ='Study Parameters'!$C$20 -> 31354839
A6: Discounted Production (l) | B6: =B5 / (1+'Study Parameters'!$C$12) ^ 'MFSP Baseline'!B2 -> 0 | C6: =C5 / (1+'Study Parameters'!$C$12) ^ 'MFSP Baseline'!C2 -> 29795539 | D6: =D5 / (1+'Study Parameters'!$C$12) ^ 'MFSP Baseline'!D2 -> 28313784 | E6: =E5 / (1+'Study Parameters'!$C$12) ^ 'MFSP Baseline'!E2 -> 26905718 | F6: =F5 / (1+'Study Parameters'!$C$12) ^ 'MFSP Baseline'!F2 -> 25567676 | G6: =G5 / (1+'Study Parameters'!$C$12) ^ 'MFSP Baseline'!G2 -> 24296177 | H6: =H5 / (1+'Study Parameters'!$C$12) ^ 'MFSP Baseline'!H2 -> 23087909 | I6: =I5 / (1+'Study Parameters'!$C$12) ^ 'MFSP Baseline'!I2 -> 21939730 | ... AA6: =AA5 / (1+'Study Parameters'!$C$12) ^ 'MFSP Baseline'!AA2 -> 8759340.2
A8: Minimum Fuel Selling Price (€/l) | B8: =SUM(B4:AA4) / SUM(B6:AA6) -> 2.6890654
A10: Economic Model 2050 - Baseline
A11: Year | B11: 0 | C11: 1 | D11: 2 | E11: 3 | F11: 4 | G11: 5 | H11: 6 | I11: 7 | J11: 8 | K11: 9 | L11: 10 | M11: 11 | N11: 12 | O11: 13 | P11: 14 | Q11: 15 | R11: 16 | S11: 17 | T11: 18 | U11: 19 | V11: 20 | W11: 21 | X11: 22 | Y11: 23 | Z11: 24 | AA11: 25
A12: Cost (€) | B12: ='Cost Components'!H14 * 10 ^ 6 -> 325320000 | C12: ='Cost Components'!$H$30 * 10 ^ 6 -> 41317361 | D12: ='Cost Components'!$H$30 * 10 ^ 6 -> 41317361 | E12: ='Cost Components'!$H$30 * 10 ^ 6 -> 41317361 | F12: ='Cost Components'!$H$30 * 10 ^ 6 -> 41317361 | G12: ='Cost Components'!$H$30 * 10 ^ 6 -> 41317361 | H12: ='Cost Components'!$H$30 * 10 ^ 6 -> 41317361 | I12: ='Cost Components'!$H$30 * 10 ^ 6 -> 41317361 | J12: ='Cost Components'!$H$30 * 10 ^ 6 -> 41317361 | ... AA12: ='Cost Components'!$H$30 * 10 ^ 6 -> 41317361
A13: Discounted Cost (€) | B13: =B12 / (1+'Study Parameters'!$C$13) ^'MFSP Baseline'!B11 -> 325320000 | C13: =C12 / (1+'Study Parameters'!$C$13) ^'MFSP Baseline'!C11 -> 39262617 | D13: =D12 / (1+'Study Parameters'!$C$13) ^'MFSP Baseline'!D11 -> 37310058 | E13: =E12 / (1+'Study Parameters'!$C$13) ^'MFSP Baseline'!E11 -> 35454600 | F13: =F12 / (1+'Study Parameters'!$C$13) ^'MFSP Baseline'!F11 -> 33691416 | G13: =G12 / (1+'Study Parameters'!$C$13) ^'MFSP Baseline'!G11 -> 32015916 | H13: =H12 / (1+'Study Parameters'!$C$13) ^'MFSP Baseline'!H11 -> 30423741 | I13: =I12 / (1+'Study Parameters'!$C$13) ^'MFSP Baseline'!I11 -> 28910745 | ... AA13: =AA12 / (1+'Study Parameters'!$C$13) ^'MFSP Baseline'!AA11 -> 11542487
A14: Production (l) | B14: 0 | C14: ='Study Parameters'!$C$20 -> 31354839 | D14: ='Study Parameters'!$C$20 -> 31354839 | E14: ='Study Parameters'!$C$20 -> 31354839 | F14: ='Study Parameters'!$C$20 -> 31354839 | G14: ='Study Parameters'!$C$20 -> 31354839 | H14: ='Study Parameters'!$C$20 -> 31354839 | I14: ='Study Parameters'!$C$20 -> 31354839 | J14: ='Study Parameters'!$C$20 -> 31354839 | ... AA14: ='Study Parameters'!$C$20 -> 31354839
A15: Discounted Production (l) | B15: =B14 / (1+'Study Parameters'!$C$12) ^ 'MFSP Baseline'!B11 -> 0 | C15: =C14 / (1+'Study Parameters'!$C$13) ^ 'MFSP Baseline'!C11 -> 29795539 | D15: =D14 / (1+'Study Parameters'!$C$13) ^ 'MFSP Baseline'!D11 -> 28313784 | E15: =E14 / (1+'Study Parameters'!$C$13) ^ 'MFSP Baseline'!E11 -> 26905718 | F15: =F14 / (1+'Study Parameters'!$C$13) ^ 'MFSP Baseline'!F11 -> 25567676 | G15: =G14 / (1+'Study Parameters'!$C$13) ^ 'MFSP Baseline'!G11 -> 24296177 | H15: =H14 / (1+'Study Parameters'!$C$13) ^ 'MFSP Baseline'!H11 -> 23087909 | I15: =I14 / (1+'Study Parameters'!$C$13) ^ 'MFSP Baseline'!I11 -> 21939730 | J15: =J14 / (1+'Study Parameters'!$C$13) ^ 'MFSP Baseline'!J11 -> 20848651 | ... AA15: =AA14 / (1+'Study Parameters'!$C$13) ^ 'MFSP Baseline'!AA11 -> 8759340.2
A17: Minimum Fuel Selling Price (€/l) | B17: =SUM(B13:AA13) / SUM(B15:AA15) -> 2.071207
A20: Economic Model 2050 - Optimistic
A21: Year | B21: 0 | C21: 1 | D21: 2 | E21: 3 | F21: 4 | G21: 5 | H21: 6 | I21: 7 | J21: 8 | K21: 9 | L21: 10 | M21: 11 | N21: 12 | O21: 13 | P21: 14 | Q21: 15 | R21: 16 | S21: 17 | T21: 18 | U21: 19 | V21: 20 | W21: 21 | X21: 22 | Y21: 23 | Z21: 24 | AA21: 25
A22: Cost (€) | B22: ='Cost Components'!N14 * 10^6 -> 258320000 | C22: ='Cost Components'!$N$30 * 10^6 -> 39176711 | D22: ='Cost Components'!$N$30 * 10^6 -> 39176711 | E22: ='Cost Components'!$N$30 * 10^6 -> 39176711 | F22: ='Cost Components'!$N$30 * 10^6 -> 39176711 | G22: ='Cost Components'!$N$30 * 10^6 -> 39176711 | H22: ='Cost Components'!$N$30 * 10^6 -> 39176711 | I22: ='Cost Components'!$N$30 * 10^6 -> 39176711 | J22: ='Cost Components'!$N$30 * 10^6 -> 39176711 | ... AA22: ='Cost Components'!$N$30 * 10^6 -> 39176711
A23: Discounted Cost (€) | B23: =B22 / (1+'Study Parameters'!$C$14) ^'MFSP Baseline'!B21 -> 258320000 | C23: =C22 / (1+'Study Parameters'!$C$14) ^'MFSP Baseline'!C21 -> 37183666 | D23: =D22 / (1+'Study Parameters'!$C$14) ^'MFSP Baseline'!D21 -> 35292014 | E23: =E22 / (1+'Study Parameters'!$C$14) ^'MFSP Baseline'!E21 -> 33496597 | F23: =F22 / (1+'Study Parameters'!$C$14) ^'MFSP Baseline'!F21 -> 31792518 | G23: =G22 / (1+'Study Parameters'!$C$14) ^'MFSP Baseline'!G21 -> 30175131 | H23: =H22 / (1+'Study Parameters'!$C$14) ^'MFSP Baseline'!H21 -> 28640025 | I23: =I22 / (1+'Study Parameters'!$C$14) ^'MFSP Baseline'!I21 -> 27183016 | ... AA23: =AA22 / (1+'Study Parameters'!$C$14) ^'MFSP Baseline'!AA21 -> 10620230
A24: Production (l) | B24: 0 | C24: ='Study Parameters'!$C$20 -> 31354839 | D24: ='Study Parameters'!$C$20 -> 31354839 | E24: ='Study Parameters'!$C$20 -> 31354839 | F24: ='Study Parameters'!$C$20 -> 31354839 | G24: ='Study Parameters'!$C$20 -> 31354839 | H24: ='Study Parameters'!$C$20 -> 31354839 | I24: ='Study Parameters'!$C$20 -> 31354839 | J24: ='Study Parameters'!$C$20 -> 31354839 | ... AA24: ='Study Parameters'!$C$20 -> 31354839
A25: Discounted Production (l) | B25: 0 | C25: =C24 / (1+'Study Parameters'!$C$14) ^ 'MFSP Baseline'!C21 -> 29759718 | D25: =D24 / (1+'Study Parameters'!$C$14) ^ 'MFSP Baseline'!D21 -> 28245746 | E25: =E24 / (1+'Study Parameters'!$C$14) ^ 'MFSP Baseline'!E21 -> 26808794 | F25: =F24 / (1+'Study Parameters'!$C$14) ^ 'MFSP Baseline'!F21 -> 25444945 | G25: =G24 / (1+'Study Parameters'!$C$14) ^ 'MFSP Baseline'!G21 -> 24150480 | H25: =H24 / (1+'Study Parameters'!$C$14) ^ 'MFSP Baseline'!H21 -> 22921868 | I25: =I24 / (1+'Study Parameters'!$C$14) ^ 'MFSP Baseline'!I21 -> 21755759 | J25: =J24 / (1+'Study Parameters'!$C$14) ^ 'MFSP Baseline'!J21 -> 20648974 | ... AA25: =AA24 / (1+'Study Parameters'!$C$14) ^ 'MFSP Baseline'!AA21 -> 8499835.5
A27: Minimum Fuel Selling Price (€/l) | B27: =SUM(B23:AA23) / SUM(B25:AA25) -> 1.8552801

Sheet MFSP LCOE Corrected
A1: Economic Model 2024
A2: Year | B2: 0 | C2: 1 | D2: 2 | E2: 3 | F2: 4 | G2: 5 | H2: 6 | I2: 7 | J2: 8 | K2: 9 | L2: 10 | M2: 11 | N2: 12 | O2: 13 | P2: 14 | Q2: 15 | R2: 16 | S2: 17 | T2: 18 | U2: 19 | V2: 20 | W2: 21 | X2: 22 | Y2: 23 | Z2: 24 | AA2: 25
A3: Cost (€) | B3: ='Cost Components'!B14 * 10^6 -> 362670000 | C3: ='Cost Components'!$B$35*10^6 -> 54620926 | D3: ='Cost Components'!$B$35*10^6 -> 54620926 | E3: ='Cost Components'!$B$35*10^6 -> 54620926 | F3: ='Cost Components'!$B$35*10^6 -> 54620926 | G3: ='Cost Components'!$B$35*10^6 -> 54620926 | H3: ='Cost Components'!$B$35*10^6 -> 54620926 | I3: ='Cost Components'!$B$35*10^6 -> 54620926 | J3: ='Cost Components'!$B$35*10^6 -> 54620926 | ... AA3: ='Cost Components'!$B$35*10^6 -> 54620926
A4: Discounted Cost (€) | B4: =B3 / (1+'Study Parameters'!$C$12) ^'MFSP Baseline'!B2 -> 362670000 | C4: =C3 / (1+'Study Parameters'!$C$12) ^'MFSP Baseline'!C2 -> 51904586 | D4: =D3 / (1+'Study Parameters'!$C$12) ^'MFSP Baseline'!D2 -> 49323332 | E4: =E3 / (1+'Study Parameters'!$C$12) ^'MFSP Baseline'!E2 -> 46870445 | F4: =F3 / (1+'Study Parameters'!$C$12) ^'MFSP Baseline'!F2 -> 44539542 | G4: =G3 / (1+'Study Parameters'!$C$12) ^'MFSP Baseline'!G2 -> 42324557 | H4: =H3 / (1+'Study Parameters'!$C$12) ^'MFSP Baseline'!H2 -> 40219725 | I4: =I3 / (1+'Study Parameters'!$C$12) ^'MFSP Baseline'!I2 -> 38219567 | ... AA4: =AA3 / (1+'Study Parameters'!$C$12) ^'MFSP Baseline'!AA2 -> 15258993
A5: Production (l) | B5: 0 | C5: ='Study Parameters'!$C$20 -> 31354839 | D5: ='Study Parameters'!$C$20 -> 31354839 | E5: ='Study Parameters'!$C$20 -> 31354839 | F5: ='Study Parameters'!$C$20 -> 31354839 | G5: ='Study Parameters'!$C$20 -> 31354839 | H5: ='Study Parameters'!$C$20 -> 31354839 | I5: ='Study Parameters'!$C$20 -> 31354839 | J5: ='Study Parameters'!$C$20 -> 31354839 | ... AA5: ='Study Parameters'!$C$20 -> 31354839
A6: Discounted Production (l) | B6: =B5 / (1+'Study Parameters'!$C$12) ^ 'MFSP Baseline'!B2 -> 0 | C6: =C5 / (1+'Study Parameters'!$C$12) ^ 'MFSP Baseline'!C2 -> 29795539 | D6: =D5 / (1+'Study Parameters'!$C$12) ^ 'MFSP Baseline'!D2 -> 28313784 | E6: =E5 / (1+'Study Parameters'!$C$12) ^ 'MFSP Baseline'!E2 -> 26905718 | F6: =F5 / (1+'Study Parameters'!$C$12) ^ 'MFSP Baseline'!F2 -> 25567676 | G6: =G5 / (1+'Study Parameters'!$C$12) ^ 'MFSP Baseline'!G2 -> 24296177 | H6: =H5 / (1+'Study Parameters'!$C$12) ^ 'MFSP Baseline'!H2 -> 23087909 | I6: =I5 / (1+'Study Parameters'!$C$12) ^ 'MFSP Baseline'!I2 -> 21939730 | ... AA6: =AA5 / (1+'Study Parameters'!$C$12) ^ 'MFSP Baseline'!AA2 -> 8759340.2
A8: Minimum Fuel Selling Price (€/l) | B8: =SUM(B4:AA4) / SUM(B6:AA6) -> 2.5820038
A10: Economic Model 2050 - Baseline
A11: Year | B11: 0 | C11: 1 | D11: 2 | E11: 3 | F11: 4 | G11: 5 | H11: 6 | I11: 7 | J11: 8 | K11: 9 | L11: 10 | M11: 11 | N11: 12 | O11: 13 | P11: 14 | Q11: 15 | R11: 16 | S11: 17 | T11: 18 | U11: 19 | V11: 20 | W11: 21 | X11: 22 | Y11: 23 | Z11: 24 | AA11: 25
A12: Cost (€) | B12: ='Cost Components'!H14 * 10 ^ 6 -> 325320000 | C12: ='Cost Components'!$H$35 * 10 ^ 6 -> 41319291 | D12: ='Cost Components'!$H$35 * 10 ^ 6 -> 41319291 | E12: ='Cost Components'!$H$35 * 10 ^ 6 -> 41319291 | F12: ='Cost Components'!$H$35 * 10 ^ 6 -> 41319291 | G12: ='Cost Components'!$H$35 * 10 ^ 6 -> 41319291 | H12: ='Cost Components'!$H$35 * 10 ^ 6 -> 41319291 | I12: ='Cost Components'!$H$35 * 10 ^ 6 -> 41319291 | J12: ='Cost Components'!$H$35 * 10 ^ 6 -> 41319291 | ... AA12: ='Cost Components'!$H$35 * 10 ^ 6 -> 41319291
A13: Discounted Cost (€) | B13: =B12 / (1+'Study Parameters'!$C$12) ^'MFSP Baseline'!B11 -> 325320000 | C13: =C12 / (1+'Study Parameters'!$C$12) ^'MFSP Baseline'!C11 -> 39264452 | D13: =D12 / (1+'Study Parameters'!$C$12) ^'MFSP Baseline'!D11 -> 37311801 | E13: =E12 / (1+'Study Parameters'!$C$12) ^'MFSP Baseline'!E11 -> 35456257 | F13: =F12 / (1+'Study Parameters'!$C$12) ^'MFSP Baseline'!F11 -> 33692990 | G13: =G12 / (1+'Study Parameters'!$C$12) ^'MFSP Baseline'!G11 -> 32017412 | H13: =H12 / (1+'Study Parameters'!$C$12) ^'MFSP Baseline'!H11 -> 30425162 | I13: =I12 / (1+'Study Parameters'!$C$12) ^'MFSP Baseline'!I11 -> 28912096 | ... AA13: =AA12 / (1+'Study Parameters'!$C$12) ^'MFSP Baseline'!AA11 -> 11543026
A14: Production (l) | B14: 0 | C14: ='Study Parameters'!$C$20 -> 31354839 | D14: ='Study Parameters'!$C$20 -> 31354839 | E14: ='Study Parameters'!$C$20 -> 31354839 | F14: ='Study Parameters'!$C$20 -> 31354839 | G14: ='Study Parameters'!$C$20 -> 31354839 | H14: ='Study Parameters'!$C$20 -> 31354839 | I14: ='Study Parameters'!$C$20 -> 31354839 | J14: ='Study Parameters'!$C$20 -> 31354839 | ... AA14: ='Study Parameters'!$C$20 -> 31354839
A15: Discounted Production (l) | B15: =B14 / (1+'Study Parameters'!$C$12) ^ 'MFSP Baseline'!B11 -> 0 | C15: =C14 / ((1+'Study Parameters'!$C$12) ^ 'MFSP Baseline'!C11) -> 29795539 | D15: =D14 / ((1+'Study Parameters'!$C$12) ^ 'MFSP Baseline'!D11) -> 28313784 | E15: =E14 / ((1+'Study Parameters'!$C$12) ^ 'MFSP Baseline'!E11) -> 26905718 | F15: =F14 / ((1+'Study Parameters'!$C$12) ^ 'MFSP Baseline'!F11) -> 25567676 | G15: =G14 / ((1+'Study Parameters'!$C$12) ^ 'MFSP Baseline'!G11) -> 24296177 | H15: =H14 / ((1+'Study Parameters'!$C$12) ^ 'MFSP Baseline'!H11) -> 23087909 | I15: =I14 / ((1+'Study Parameters'!$C$12) ^ 'MFSP Baseline'!I11) -> 21939730 | J15: =J14 / ((1+'Study Parameters'!$C$12) ^ 'MFSP Baseline'!J11) -> 20848651 | ... AA15: =AA14 / ((1+'Study Parameters'!$C$12) ^ 'MFSP Baseline'!AA11) -> 8759340.2
A17: Minimum Fuel Selling Price (€/l) | B17: =SUM(B13:AA13) / SUM(B15:AA15) -> 2.0712685
A19: Economic Model 2050 - Optimistic
A20: Year | B20: 0 | C20: 1 | D20: 2 | E20: 3 | F20: 4 | G20: 5 | H20: 6 | I20: 7 | J20: 8 | K20: 9 | L20: 10 | M20: 11 | N20: 12 | O20: 13 | P20: 14 | Q20: 15 | R20: 16 | S20: 17 | T20: 18 | U20: 19 | V20: 20 | W20: 21 | X20: 22 | Y20: 23 | Z20: 24 | AA20: 25
A21: Cost (€) | B21: ='Cost Components'!N14 * 10^6 -> 258320000 | C21: ='Cost Components'!$N$35*10^6 -> 39178641 | D21: ='Cost Components'!$N$35*10^6 -> 39178641 | E21: ='Cost Components'!$N$35*10^6 -> 39178641 | F21: ='Cost Components'!$N$35*10^6 -> 39178641 | G21: ='Cost Components'!$N$35*10^6 -> 39178641 | H21: ='Cost Components'!$N$35*10^6 -> 39178641 | I21: ='Cost Components'!$N$35*10^6 -> 39178641 | J21: ='Cost Components'!$N$35*10^6 -> 39178641 | ... AA21: ='Cost Components'!$N$35*10^6 -> 39178641
A22: Discounted Cost (€) | B22: =B21 / (1+'Study Parameters'!$C$14) ^'MFSP Baseline'!B20 -> 258320000 | C22: =C21/((1+'Study Parameters'!$C$14) ^'MFSP LCOE Corrected'!C20) -> 37185499 | D22: =D21/((1+'Study Parameters'!$C$14) ^'MFSP LCOE Corrected'!D20) -> 35293753 | E22: =E21/((1+'Study Parameters'!$C$14) ^'MFSP LCOE Corrected'!E20) -> 33498247 | F22: =F21/((1+'Study Parameters'!$C$14) ^'MFSP LCOE Corrected'!F20) -> 31794084 | G22: =G21/((1+'Study Parameters'!$C$14) ^'MFSP LCOE Corrected'!G20) -> 30176618 | H22: =H21/((1+'Study Parameters'!$C$14) ^'MFSP LCOE Corrected'!H20) -> 28641437 | I22: =I21/((1+'Study Parameters'!$C$14) ^'MFSP LCOE Corrected'!I20) -> 27184355 | J22: =J21/((1+'Study Parameters'!$C$14) ^'MFSP LCOE Corrected'!J20) -> 25801400 | ... AA22: =AA21/((1+'Study Parameters'!$C$14) ^'MFSP LCOE Corrected'!AA20) -> 10620753
A23: Production (l) | B23: 0 | C23: ='Study Parameters'!$C$20 -> 31354839 | D23: ='Study Parameters'!$C$20 -> 31354839 | E23: ='Study Parameters'!$C$20 -> 31354839 | F23: ='Study Parameters'!$C$20 -> 31354839 | G23: ='Study Parameters'!$C$20 -> 31354839 | H23: ='Study Parameters'!$C$20 -> 31354839 | I23: ='Study Parameters'!$C$20 -> 31354839 | J23: ='Study Parameters'!$C$20 -> 31354839 | ... AA23: ='Study Parameters'!$C$20 -> 31354839
A24: Discounted Production (l) | B24: =B23 / (1+'Study Parameters'!$C$12) ^ 'MFSP Baseline'!B20 -> 0 | C24: =C23/((1+'Study Parameters'!$C$14) ^ ('MFSP LCOE Corrected'!C20)) -> 29759718 | D24: =D23/((1+'Study Parameters'!$C$14) ^ ('MFSP LCOE Corrected'!D20)) -> 28245746 | E24: =E23/((1+'Study Parameters'!$C$14) ^ ('MFSP LCOE Corrected'!E20)) -> 26808794 | F24: =F23/((1+'Study Parameters'!$C$14) ^ ('MFSP LCOE Corrected'!F20)) -> 25444945 | G24: =G23/((1+'Study Parameters'!$C$14) ^ ('MFSP LCOE Corrected'!G20)) -> 24150480 | H24: =H23/((1+'Study Parameters'!$C$14) ^ ('MFSP LCOE Corrected'!H20)) -> 22921868 | I24: =I23/((1+'Study Parameters'!$C$14) ^ ('MFSP LCOE Corrected'!I20)) -> 21755759 | J24: =J23/((1+'Study Parameters'!$C$14) ^ ('MFSP LCOE Corrected'!J20)) -> 20648974 | ... AA24: =AA23/((1+'Study Parameters'!$C$14) ^ ('MFSP LCOE Corrected'!AA20)) -> 8499835.5
A26: Minimum Fuel Selling Price (€/l) | B26: =SUM(B22:AA22) / SUM(B24:AA24) -> 1.8553417

Sheet MFSP CO2 Price Corrected
A1: Economic Model 2024
A2: Year | B2: 0 | C2: 1 | D2: 2 | E2: 3 | F2: 4 | G2: 5 | H2: 6 | I2: 7 | J2: 8 | K2: 9 | L2: 10 | M2: 11 | N2: 12 | O2: 13 | P2: 14 | Q2: 15 | R2: 16 | S2: 17 | T2: 18 | U2: 19 | V2: 20 | W2: 21 | X2: 22 | Y2: 23 | Z2: 24 | AA2: 25
A3: Cost (€) | B3: ='Cost Components'!B14 * 10^6 -> 362670000 | C3: ='Cost Components'!$B$37*10^6 -> 88789726 | D3: ='Cost Components'!$B$37*10^6 -> 88789726 | E3: ='Cost Components'!$B$37*10^6 -> 88789726 | F3: ='Cost Components'!$B$37*10^6 -> 88789726 | G3: ='Cost Components'!$B$37*10^6 -> 88789726 | H3: ='Cost Components'!$B$37*10^6 -> 88789726 | I3: ='Cost Components'!$B$37*10^6 -> 88789726 | J3: ='Cost Components'!$B$37*10^6 -> 88789726 | ... AA3: ='Cost Components'!$B$37*10^6 -> 88789726
A4: Discounted Cost (€) | B4: =B3 / (1+'Study Parameters'!$C$12) ^'MFSP Baseline'!B2 -> 362670000 | C4: =C3 / (1+'Study Parameters'!$C$12) ^'MFSP Baseline'!C2 -> 84374146 | D4: =D3 / (1+'Study Parameters'!$C$12) ^'MFSP Baseline'!D2 -> 80178156 | E4: =E3 / (1+'Study Parameters'!$C$12) ^'MFSP Baseline'!E2 -> 76190835 | F4: =F3 / (1+'Study Parameters'!$C$12) ^'MFSP Baseline'!F2 -> 72401807 | G4: =G3 / (1+'Study Parameters'!$C$12) ^'MFSP Baseline'!G2 -> 68801211 | H4: =H3 / (1+'Study Parameters'!$C$12) ^'MFSP Baseline'!H2 -> 65379674 | I4: =I3 / (1+'Study Parameters'!$C$12) ^'MFSP Baseline'!I2 -> 62128294 | ... AA4: =AA3 / (1+'Study Parameters'!$C$12) ^'MFSP Baseline'!AA2 -> 24804446
A5: Production (l) | B5: 0 | C5: ='Study Parameters'!$C$20 -> 31354839 | D5: ='Study Parameters'!$C$20 -> 31354839 | E5: ='Study Parameters'!$C$20 -> 31354839 | F5: ='Study Parameters'!$C$20 -> 31354839 | G5: ='Study Parameters'!$C$20 -> 31354839 | H5: ='Study Parameters'!$C$20 -> 31354839 | I5: ='Study Parameters'!$C$20 -> 31354839 | J5: ='Study Parameters'!$C$20 -> 31354839 | ... AA5: ='Study Parameters'!$C$20 -> 31354839
A6: Discounted Production (l) | B6: =B5 / (1+'Study Parameters'!$C$12) ^ 'MFSP Baseline'!B2 -> 0 | C6: =C5 / (1+'Study Parameters'!$C$12) ^ 'MFSP Baseline'!C2 -> 29795539 | D6: =D5 / (1+'Study Parameters'!$C$12) ^ 'MFSP Baseline'!D2 -> 28313784 | E6: =E5 / (1+'Study Parameters'!$C$12) ^ 'MFSP Baseline'!E2 -> 26905718 | F6: =F5 / (1+'Study Parameters'!$C$12) ^ 'MFSP Baseline'!F2 -> 25567676 | G6: =G5 / (1+'Study Parameters'!$C$12) ^ 'MFSP Baseline'!G2 -> 24296177 | H6: =H5 / (1+'Study Parameters'!$C$12) ^ 'MFSP Baseline'!H2 -> 23087909 | I6: =I5 / (1+'Study Parameters'!$C$12) ^ 'MFSP Baseline'!I2 -> 21939730 | ... AA6: =AA5 / (1+'Study Parameters'!$C$12) ^ 'MFSP Baseline'!AA2 -> 8759340.2
A8: Minimum Fuel Selling Price (€/l) | B8: =SUM(B4:AA4) / SUM(B6:AA6) -> 3.6717495
A10: Economic Model 2050 - Baseline
A11: Year | B11: 0 | C11: 1 | D11: 2 | E11: 3 | F11: 4 | G11: 5 | H11: 6 | I11: 7 | J11: 8 | K11: 9 | L11: 10 | M11: 11 | N11: 12 | O11: 13 | P11: 14 | Q11: 15 | R11: 16 | S11: 17 | T11: 18 | U11: 19 | V11: 20 | W11: 21 | X11: 22 | Y11: 23 | Z11: 24 | AA11: 25
A12: Cost (€) | B12: ='Cost Components'!H14 * 10 ^ 6 -> 325320000 | C12: ='Cost Components'!$H$37 * 10 ^ 6 -> 69725991 | D12: ='Cost Components'!$H$37 * 10 ^ 6 -> 69725991 | E12: ='Cost Components'!$H$37 * 10 ^ 6 -> 69725991 | F12: ='Cost Components'!$H$37 * 10 ^ 6 -> 69725991 | G12: ='Cost Components'!$H$37 * 10 ^ 6 -> 69725991 | H12: ='Cost Components'!$H$37 * 10 ^ 6 -> 69725991 | I12: ='Cost Components'!$H$37 * 10 ^ 6 -> 69725991 | J12: ='Cost Components'!$H$37 * 10 ^ 6 -> 69725991 | ... AA12: ='Cost Components'!$H$37 * 10 ^ 6 -> 69725991
A13: Discounted Cost (€) | B13: =B12 / (1+'Study Parameters'!$C$12) ^'MFSP Baseline'!B11 -> 325320000 | C13: =C12 / (1+'Study Parameters'!$C$12) ^'MFSP Baseline'!C11 -> 66258465 | D13: =D12 / (1+'Study Parameters'!$C$12) ^'MFSP Baseline'!D11 -> 62963381 | E13: =E12 / (1+'Study Parameters'!$C$12) ^'MFSP Baseline'!E11 -> 59832165 | F13: =F12 / (1+'Study Parameters'!$C$12) ^'MFSP Baseline'!F11 -> 56856666 | G13: =G12 / (1+'Study Parameters'!$C$12) ^'MFSP Baseline'!G11 -> 54029141 | H13: =H12 / (1+'Study Parameters'!$C$12) ^'MFSP Baseline'!H11 -> 51342231 | I13: =I12 / (1+'Study Parameters'!$C$12) ^'MFSP Baseline'!I11 -> 48788943 | ... AA13: =AA12 / (1+'Study Parameters'!$C$12) ^'MFSP Baseline'!AA11 -> 19478770
A14: Production (l) | B14: 0 | C14: ='Study Parameters'!$C$20 -> 31354839 | D14: ='Study Parameters'!$C$20 -> 31354839 | E14: ='Study Parameters'!$C$20 -> 31354839 | F14: ='Study Parameters'!$C$20 -> 31354839 | G14: ='Study Parameters'!$C$20 -> 31354839 | H14: ='Study Parameters'!$C$20 -> 31354839 | I14: ='Study Parameters'!$C$20 -> 31354839 | J14: ='Study Parameters'!$C$20 -> 31354839 | ... AA14: ='Study Parameters'!$C$20 -> 31354839
A15: Discounted Production (l) | B15: =B14 / (1+'Study Parameters'!$C$12) ^ 'MFSP Baseline'!B11 -> 0 | C15: =C14 / (1+'Study Parameters'!$C$12) ^ 'MFSP Baseline'!C11 -> 29795539 | D15: =D14 / (1+'Study Parameters'!$C$12) ^ 'MFSP Baseline'!D11 -> 28313784 | E15: =E14 / (1+'Study Parameters'!$C$12) ^ 'MFSP Baseline'!E11 -> 26905718 | F15: =F14 / (1+'Study Parameters'!$C$12) ^ 'MFSP Baseline'!F11 -> 25567676 | G15: =G14 / (1+'Study Parameters'!$C$12) ^ 'MFSP Baseline'!G11 -> 24296177 | H15: =H14 / (1+'Study Parameters'!$C$12) ^ 'MFSP Baseline'!H11 -> 23087909 | I15: =I14 / (1+'Study Parameters'!$C$12) ^ 'MFSP Baseline'!I11 -> 21939730 | ... AA15: =AA14 / (1+'Study Parameters'!$C$12) ^ 'MFSP Baseline'!AA11 -> 8759340.2
A17: Minimum Fuel Selling Price (€/l) | B17: =SUM(B13:AA13) / SUM(B15:AA15) -> 2.9772435
A19: Economic Model 2050 - Optimistic
A20: Year | B20: 0 | C20: 1 | D20: 2 | E20: 3 | F20: 4 | G20: 5 | H20: 6 | I20: 7 | J20: 8 | K20: 9 | L20: 10 | M20: 11 | N20: 12 | O20: 13 | P20: 14 | Q20: 15 | R20: 16 | S20: 17 | T20: 18 | U20: 19 | V20: 20 | W20: 21 | X20: 22 | Y20: 23 | Z20: 24 | AA20: 25
A21: Cost (€) | B21: ='Cost Components'!N14*10^6 -> 258320000 | C21: ='Cost Components'!$N$37 * 10^6 -> 67585341 | D21: ='Cost Components'!$N$37 * 10^6 -> 67585341 | E21: ='Cost Components'!$N$37 * 10^6 -> 67585341 | F21: ='Cost Components'!$N$37 * 10^6 -> 67585341 | G21: ='Cost Components'!$N$37 * 10^6 -> 67585341 | H21: ='Cost Components'!$N$37 * 10^6 -> 67585341 | I21: ='Cost Components'!$N$37 * 10^6 -> 67585341 | J21: ='Cost Components'!$N$37 * 10^6 -> 67585341 | ... AA21: ='Cost Components'!$N$37 * 10^6 -> 67585341
A22: Discounted Cost (€) | B22: =B21/((1+'Study Parameters'!$C$14) ^'MFSP CO2 Price Corrected'!B20) -> 258320000 | C22: =C21/((1+'Study Parameters'!$C$14) ^'MFSP CO2 Price Corrected'!C20) -> 64147059 | D22: =D21/((1+'Study Parameters'!$C$14) ^'MFSP CO2 Price Corrected'!D20) -> 60883693 | E22: =E21/((1+'Study Parameters'!$C$14) ^'MFSP CO2 Price Corrected'!E20) -> 57786345 | F22: =F21/((1+'Study Parameters'!$C$14) ^'MFSP CO2 Price Corrected'!F20) -> 54846569 | G22: =G21/((1+'Study Parameters'!$C$14) ^'MFSP CO2 Price Corrected'!G20) -> 52056349 | H22: =H21/((1+'Study Parameters'!$C$14) ^'MFSP CO2 Price Corrected'!H20) -> 49408076 | I22: =I21/((1+'Study Parameters'!$C$14) ^'MFSP CO2 Price Corrected'!I20) -> 46894529 | ... AA22: =AA21/((1+'Study Parameters'!$C$14) ^'MFSP CO2 Price Corrected'!AA20) -> 18321392
A23: Production (l) | B23: 0 | C23: ='Study Parameters'!$C$20 -> 31354839 | D23: ='Study Parameters'!$C$20 -> 31354839 | E23: ='Study Parameters'!$C$20 -> 31354839 | F23: ='Study Parameters'!$C$20 -> 31354839 | G23: ='Study Parameters'!$C$20 -> 31354839 | H23: ='Study Parameters'!$C$20 -> 31354839 | I23: ='Study Parameters'!$C$20 -> 31354839 | J23: ='Study Parameters'!$C$20 -> 31354839 | ... AA23: ='Study Parameters'!$C$20 -> 31354839
A24: Discounted Production (l) | B24: =B23 / (1+'Study Parameters'!$C$12) ^ 'MFSP Baseline'!B20 -> 0 | C24: =C23/((1+'Study Parameters'!$C$14) ^'MFSP CO2 Price Corrected'!C20) -> 29759718 | D24: =D23/((1+'Study Parameters'!$C$14) ^'MFSP CO2 Price Corrected'!D20) -> 28245746 | E24: =E23/((1+'Study Parameters'!$C$14) ^'MFSP CO2 Price Corrected'!E20) -> 26808794 | F24: =F23/((1+'Study Parameters'!$C$14) ^'MFSP CO2 Price Corrected'!F20) -> 25444945 | G24: =G23/((1+'Study Parameters'!$C$14) ^'MFSP CO2 Price Corrected'!G20) -> 24150480 | H24: =H23/((1+'Study Parameters'!$C$14) ^'MFSP CO2 Price Corrected'!H20) -> 22921868 | I24: =I23/((1+'Study Parameters'!$C$14) ^'MFSP CO2 Price Corrected'!I20) -> 21755759 | J24: =J23/((1+'Study Parameters'!$C$14) ^'MFSP CO2 Price Corrected'!J20) -> 20648974 | ... AA24: =AA23/((1+'Study Parameters'!$C$14) ^'MFSP CO2 Price Corrected'!AA20) -> 8499835.5
A26: Minimum Fuel Selling Price (€/l) | B26: =SUM(B22:AA22) / SUM(B24:AA24) -> 2.7613167

Sheet MFSP WACC Corrected
A1: Economic Model 2024
A2: Year | B2: 0 | C2: 1 | D2: 2 | E2: 3 | F2: 4 | G2: 5 | H2: 6 | I2: 7 | J2: 8 | K2: 9 | L2: 10 | M2: 11 | N2: 12 | O2: 13 | P2: 14 | Q2: 15 | R2: 16 | S2: 17 | T2: 18 | U2: 19 | V2: 20 | W2: 21 | X2: 22 | Y2: 23 | Z2: 24 | AA2: 25
A3: Cost (€) | B3: ='Cost Components'!B14 * 10^6 -> 362670000 | C3: ='Cost Components'!$B$37*10^6 -> 88789726 | D3: ='Cost Components'!$B$37*10^6 -> 88789726 | E3: ='Cost Components'!$B$37*10^6 -> 88789726 | F3: ='Cost Components'!$B$37*10^6 -> 88789726 | G3: ='Cost Components'!$B$37*10^6 -> 88789726 | H3: ='Cost Components'!$B$37*10^6 -> 88789726 | I3: ='Cost Components'!$B$37*10^6 -> 88789726 | J3: ='Cost Components'!$B$37*10^6 -> 88789726 | ... AA3: ='Cost Components'!$B$37*10^6 -> 88789726
A4: Discounted Cost (€) | B4: =B3 / (1+'Study Parameters'!$C$12) ^'MFSP Baseline'!B2 -> 362670000 | C4: =C3 / (1+'Cost Components'!$B$38) ^'MFSP Baseline'!C2 -> 82981052 | D4: =D3 / (1+'Cost Components'!$B$38) ^'MFSP Baseline'!D2 -> 77552385 | E4: =E3 / (1+'Cost Components'!$B$38) ^'MFSP Baseline'!E2 -> 72478865 | F4: =F3 / (1+'Cost Components'!$B$38) ^'MFSP Baseline'!F2 -> 67737257 | G4: =G3 / (1+'Cost Components'!$B$38) ^'MFSP Baseline'!G2 -> 63305847 | H4: =H3 / (1+'Cost Components'!$B$38) ^'MFSP Baseline'!H2 -> 59164343 | I4: =I3 / (1+'Cost Components'!$B$38) ^'MFSP Baseline'!I2 -> 55293779 | J4: =J3 / (1+'Cost Components'!$B$38) ^'MFSP Baseline'!J2 -> 51676429 | ... AA4: =AA3 / (1+'Cost Components'!$B$38) ^'MFSP Baseline'!AA2 -> 16359434
A5: Production (l) | B5: 0 | C5: ='Study Parameters'!$C$20 -> 31354839 | D5: ='Study Parameters'!$C$20 -> 31354839 | E5: ='Study Parameters'!$C$20 -> 31354839 | F5: ='Study Parameters'!$C$20 -> 31354839 | G5: ='Study Parameters'!$C$20 -> 31354839 | H5: ='Study Parameters'!$C$20 -> 31354839 | I5: ='Study Parameters'!$C$20 -> 31354839 | J5: ='Study Parameters'!$C$20 -> 31354839 | ... AA5: ='Study Parameters'!$C$20 -> 31354839
A6: Discounted Production (l) | B6: =B5 / (1+'Study Parameters'!$C$12) ^ 'MFSP Baseline'!B2 -> 0 | C6: =C5 / (1+'Cost Components'!$B$38) ^ 'MFSP Baseline'!C2 -> 29303588 | D6: =D5 / (1+'Cost Components'!$B$38) ^ 'MFSP Baseline'!D2 -> 27386530 | E6: =E5 / (1+'Cost Components'!$B$38) ^ 'MFSP Baseline'!E2 -> 25594888 | F6: =F5 / (1+'Cost Components'!$B$38) ^ 'MFSP Baseline'!F2 -> 23920456 | G6: =G5 / (1+'Cost Components'!$B$38) ^ 'MFSP Baseline'!G2 -> 22355567 | H6: =H5 / (1+'Cost Components'!$B$38) ^ 'MFSP Baseline'!H2 -> 20893053 | I6: =I5 / (1+'Cost Components'!$B$38) ^ 'MFSP Baseline'!I2 -> 19526218 | J6: =J5 / (1+'Cost Components'!$B$38) ^ 'MFSP Baseline'!J2 -> 18248802 | ... AA6: =AA5 / (1+'Cost Components'!$B$38) ^ 'MFSP Baseline'!AA2 -> 5777103.2
A8: Minimum Fuel Selling Price (€/l) | B8: =SUM(B4:AA4) / SUM(B6:AA6) -> 3.8243101
A10: Economic Model 2050 - Baseline
A11: Year | B11: 0 | C11: 1 | D11: 2 | E11: 3 | F11: 4 | G11: 5 | H11: 6 | I11: 7 | J11: 8 | K11: 9 | L11: 10 | M11: 11 | N11: 12 | O11: 13 | P11: 14 | Q11: 15 | R11: 16 | S11: 17 | T11: 18 | U11: 19 | V11: 20 | W11: 21 | X11: 22 | Y11: 23 | Z11: 24 | AA11: 25
A12: Cost (€) | B12: ='Cost Components'!H14 * 10 ^ 6 -> 325320000 | C12: ='Cost Components'!$H$37 * 10 ^ 6 -> 69725991 | D12: ='Cost Components'!$H$37 * 10 ^ 6 -> 69725991 | E12: ='Cost Components'!$H$37 * 10 ^ 6 -> 69725991 | F12: ='Cost Components'!$H$37 * 10 ^ 6 -> 69725991 | G12: ='Cost Components'!$H$37 * 10 ^ 6 -> 69725991 | H12: ='Cost Components'!$H$37 * 10 ^ 6 -> 69725991 | I12: ='Cost Components'!$H$37 * 10 ^ 6 -> 69725991 | J12: ='Cost Components'!$H$37 * 10 ^ 6 -> 69725991 | ... AA12: ='Cost Components'!$H$37 * 10 ^ 6 -> 69725991
A13: Discounted Cost (€) | B13: =B12 / (1+'Study Parameters'!$C$12) ^'MFSP Baseline'!B11 -> 325320000 | C13: =C12 / (1+'Cost Components'!$B$38) ^'MFSP Baseline'!C11 -> 65164478 | D13: =D12 / (1+'Cost Components'!$B$38) ^'MFSP Baseline'!D11 -> 60901381 | E13: =E12 / (1+'Cost Components'!$B$38) ^'MFSP Baseline'!E11 -> 56917179 | F13: =F12 / (1+'Cost Components'!$B$38) ^'MFSP Baseline'!F11 -> 53193625 | G13: =G12 / (1+'Cost Components'!$B$38) ^'MFSP Baseline'!G11 -> 49713668 | H13: =H12 / (1+'Cost Components'!$B$38) ^'MFSP Baseline'!H11 -> 46461372 | I13: =I12 / (1+'Cost Components'!$B$38) ^'MFSP Baseline'!I11 -> 43421843 | J13: =J12 / (1+'Cost Components'!$B$38) ^'MFSP Baseline'!J11 -> 40581162 | ... AA13: =AA12 / (1+'Cost Components'!$B$38) ^'MFSP Baseline'!AA11 -> 12846957
A14: Production (l) | B14: 0 | C14: ='Study Parameters'!$C$20 -> 31354839 | D14: ='Study Parameters'!$C$20 -> 31354839 | E14: ='Study Parameters'!$C$20 -> 31354839 | F14: ='Study Parameters'!$C$20 -> 31354839 | G14: ='Study Parameters'!$C$20 -> 31354839 | H14: ='Study Parameters'!$C$20 -> 31354839 | I14: ='Study Parameters'!$C$20 -> 31354839 | J14: ='Study Parameters'!$C$20 -> 31354839 | ... AA14: ='Study Parameters'!$C$20 -> 31354839
A15: Discounted Production (l) | B15: =B14 / (1+'Study Parameters'!$C$12) ^ 'MFSP Baseline'!B11 -> 0 | C15: =C14 / (1+'Cost Components'!$B$38) ^ 'MFSP Baseline'!C11 -> 29303588 | D15: =D14 / (1+'Cost Components'!$B$38) ^ 'MFSP Baseline'!D11 -> 27386530 | E15: =E14 / (1+'Cost Components'!$B$38) ^ 'MFSP Baseline'!E11 -> 25594888 | F15: =F14 / (1+'Cost Components'!$B$38) ^ 'MFSP Baseline'!F11 -> 23920456 | G15: =G14 / (1+'Cost Components'!$B$38) ^ 'MFSP Baseline'!G11 -> 22355567 | H15: =H14 / (1+'Cost Components'!$B$38) ^ 'MFSP Baseline'!H11 -> 20893053 | I15: =I14 / (1+'Cost Components'!$B$38) ^ 'MFSP Baseline'!I11 -> 19526218 | J15: =J14 / (1+'Cost Components'!$B$38) ^ 'MFSP Baseline'!J11 -> 18248802 | ... AA15: =AA14 / (1+'Cost Components'!$B$38) ^ 'MFSP Baseline'!AA11 -> 5777103.2
A17: Minimum Fuel Selling Price (€/l) | B17: =SUM(B13:AA13) / SUM(B15:AA15) -> 3.1140925
A19: Economic Model 2050 - Optimistic
A20: Year | B20: 0 | C20: 1 | D20: 2 | E20: 3 | F20: 4 | G20: 5 | H20: 6 | I20: 7 | J20: 8 | K20: 9 | L20: 10 | M20: 11 | N20: 12 | O20: 13 | P20: 14 | Q20: 15 | R20: 16 | S20: 17 | T20: 18 | U20: 19 | V20: 20 | W20: 21 | X20: 22 | Y20: 23 | Z20: 24 | AA20: 25
A21: Cost (€) | B21: ='Cost Components'!N14 * 10^6 -> 258320000 | C21: ='Cost Components'!$N$37 * 10^6 -> 67585341 | D21: ='Cost Components'!$N$37 * 10^6 -> 67585341 | E21: ='Cost Components'!$N$37 * 10^6 -> 67585341 | F21: ='Cost Components'!$N$37 * 10^6 -> 67585341 | G21: ='Cost Components'!$N$37 * 10^6 -> 67585341 | H21: ='Cost Components'!$N$37 * 10^6 -> 67585341 | I21: ='Cost Components'!$N$37 * 10^6 -> 67585341 | J21: ='Cost Components'!$N$37 * 10^6 -> 67585341 | ... AA21: ='Cost Components'!$N$37 * 10^6 -> 67585341
A22: Discounted Cost (€) | B22: =B21/((1+'Study Parameters'!$C$14) ^ 'MFSP WACC Corrected'!B20) -> 258320000 | C22: =C21/((1+Inputs!$C$5) ^ 'MFSP WACC Corrected'!C20) -> 63163870 | D22: =D21/((1+Inputs!$C$5) ^ 'MFSP WACC Corrected'!D20) -> 59031655 | E22: =E21/((1+Inputs!$C$5) ^ 'MFSP WACC Corrected'!E20) -> 55169771 | F22: =F21/((1+Inputs!$C$5) ^ 'MFSP WACC Corrected'!F20) -> 51560533 | G22: =G21/((1+Inputs!$C$5) ^ 'MFSP WACC Corrected'!G20) -> 48187414 | H22: =H21/((1+Inputs!$C$5) ^ 'MFSP WACC Corrected'!H20) -> 45034967 | I22: =I21/((1+Inputs!$C$5) ^ 'MFSP WACC Corrected'!I20) -> 42088754 | J22: =J21/((1+Inputs!$C$5) ^ 'MFSP WACC Corrected'!J20) -> 39335284 | ... AA22: =AA21/((1+Inputs!$C$5) ^ 'MFSP WACC Corrected'!AA20) -> 12452544
A23: Production (l) | B23: 0 | C23: ='Study Parameters'!$C$20 -> 31354839 | D23: ='Study Parameters'!$C$20 -> 31354839 | E23: ='Study Parameters'!$C$20 -> 31354839 | F23: ='Study Parameters'!$C$20 -> 31354839 | G23: ='Study Parameters'!$C$20 -> 31354839 | H23: ='Study Parameters'!$C$20 -> 31354839 | I23: ='Study Parameters'!$C$20 -> 31354839 | J23: ='Study Parameters'!$C$20 -> 31354839 | ... AA23: ='Study Parameters'!$C$20 -> 31354839
A24: Discounted Production (l) | B24: =B23 / (1+'Study Parameters'!$C$12) ^ 'MFSP Baseline'!B20 -> 0 | C24: =C23/((1+Inputs!$C$5) ^ 'MFSP WACC Corrected'!C20) -> 29303588 | D24: =D23/((1+Inputs!$C$5) ^ 'MFSP WACC Corrected'!D20) -> 27386530 | E24: =E23/((1+Inputs!$C$5) ^ 'MFSP WACC Corrected'!E20) -> 25594888 | F24: =F23/((1+Inputs!$C$5) ^ 'MFSP WACC Corrected'!F20) -> 23920456 | G24: =G23/((1+Inputs!$C$5) ^ 'MFSP WACC Corrected'!G20) -> 22355567 | H24: =H23/((1+Inputs!$C$5) ^ 'MFSP WACC Corrected'!H20) -> 20893053 | I24: =I23/((1+Inputs!$C$5) ^ 'MFSP WACC Corrected'!I20) -> 19526218 | J24: =J23/((1+Inputs!$C$5) ^ 'MFSP WACC Corrected'!J20) -> 18248802 | ... AA24: =AA23/((1+Inputs!$C$5) ^ 'MFSP WACC Corrected'!AA20) -> 5777103.2
A26: Minimum Fuel Selling Price (€/l) | B26: =SUM(B22:AA22) / SUM(B24:AA24) -> 2.8624582
A29: Contribution to Final Cost - 2024
A30: Year | B30: 0 | C30: 1 | D30: 2 | E30: 3 | F30: 4 | G30: 5 | H30: 6 | I30: 7 | J30: 8 | K30: 9 | L30: 10 | M30: 11 | N30: 12 | O30: 13 | P30: 14 | Q30: 15 | R30: 16 | S30: 17 | T30: 18 | U30: 19 | V30: 20 | W30: 21 | X30: 22 | Y30: 23 | Z30: 24 | AA30: 25
A31: CAPEX | B31: ='Cost Components'!B14 * 10^6 -> 362670000 | C31: 0 | D31: 0 | E31: 0 | F31: 0 | G31: 0 | H31: 0 | I31: 0 | J31: 0 | K31: 0 | L31: 0 | M31: 0 | N31: 0 | O31: 0 | P31: 0 | Q31: 0 | R31: 0 | S31: 0 | T31: 0 | U31: 0 | V31: 0 | W31: 0 | X31: 0 | Y31: 0 | Z31: 0 | AA31: 0
A32: Electricity Surplus (Discounted) | B32: 0 | C32: =(-'Cost Components'!$B$29 * 10^6) / (1+'Cost Components'!$B$38)^'MFSP WACC Corrected'!C30 -> -7430425.2 | D32: =(-'Cost Components'!$B$29 * 10^6) / (1+'Cost Components'!$B$38)^'MFSP WACC Corrected'!D30 -> -6944322.6 | E32: =(-'Cost Components'!$B$29 * 10^6) / (1+'Cost Components'!$B$38)^'MFSP WACC Corrected'!E30 -> -6490021.2 | F32: =(-'Cost Components'!$B$29 * 10^6) / (1+'Cost Components'!$B$38)^'MFSP WACC Corrected'!F30 -> -6065440.3 | G32: =(-'Cost Components'!$B$29 * 10^6) / (1+'Cost Components'!$B$38)^'MFSP WACC Corrected'!G30 -> -5668635.8 | H32: =(-'Cost Components'!$B$29 * 10^6) / (1+'Cost Components'!$B$38)^'MFSP WACC Corrected'!H30 -> -5297790.5 | I32: =(-'Cost Components'!$B$29 * 10^6) / (1+'Cost Components'!$B$38)^'MFSP WACC Corrected'!I30 -> -4951206.1 | J32: =(-'Cost Components'!$B$29 * 10^6) / (1+'Cost Components'!$B$38)^'MFSP WACC Corrected'!J30 -> -4627295.4 | ... AA32: =(-'Cost Components'!$B$29 * 10^6) / (1+'Cost Components'!$B$38)^'MFSP WACC Corrected'!AA30 -> -1464883.2
A33: CO2 Cost | B33: 0 | C33: =('Cost Components'!$B$36 * 10^6) / (1+'Cost Components'!$B$38) ^'MFSP WACC Corrected'!C30 -> 74164299 | D33: =('Cost Components'!$B$36 * 10^6) / (1+'Cost Components'!$B$38) ^'MFSP WACC Corrected'!D30 -> 69312429 | E33: =('Cost Components'!$B$36 * 10^6) / (1+'Cost Components'!$B$38) ^'MFSP WACC Corrected'!E30 -> 64777971 | F33: =('Cost Components'!$B$36 * 10^6) / (1+'Cost Components'!$B$38) ^'MFSP WACC Corrected'!F30 -> 60540160 | G33: =('Cost Components'!$B$36 * 10^6) / (1+'Cost Components'!$B$38) ^'MFSP WACC Corrected'!G30 -> 56579589 | H33: =('Cost Components'!$B$36 * 10^6) / (1+'Cost Components'!$B$38) ^'MFSP WACC Corrected'!H30 -> 52878120 | I33: =('Cost Components'!$B$36 * 10^6) / (1+'Cost Components'!$B$38) ^'MFSP WACC Corrected'!I30 -> 49418804 | J33: =('Cost Components'!$B$36 * 10^6) / (1+'Cost Components'!$B$38) ^'MFSP WACC Corrected'!J30 -> 46185798 | ... AA33: =('Cost Components'!$B$36 * 10^6) / (1+'Cost Components'!$B$38) ^'MFSP WACC Corrected'!AA30 -> 14621241
A34: OPEX | B34: 0 | C34: =((SUM('Cost Components'!$B$20:$B$26)*10^6)/(1+'Cost Components'!$B$38)^'MFSP WACC Corrected'!C30) -> 17639455 | D34: =((SUM('Cost Components'!$B$20:$B$26)*10^6)/(1+'Cost Components'!$B$38)^'MFSP WACC Corrected'!D30) -> 16485472 | E34: =((SUM('Cost Components'!$B$20:$B$26)*10^6)/(1+'Cost Components'!$B$38)^'MFSP WACC Corrected'!E30) -> 15406983 | F34: =((SUM('Cost Components'!$B$20:$B$26)*10^6)/(1+'Cost Components'!$B$38)^'MFSP WACC Corrected'!F30) -> 14399050 | G34: =((SUM('Cost Components'!$B$20:$B$26)*10^6)/(1+'Cost Components'!$B$38)^'MFSP WACC Corrected'!G30) -> 13457056 | H34: =((SUM('Cost Components'!$B$20:$B$26)*10^6)/(1+'Cost Components'!$B$38)^'MFSP WACC Corrected'!H30) -> 12576688 | I34: =((SUM('Cost Components'!$B$20:$B$26)*10^6)/(1+'Cost Components'!$B$38)^'MFSP WACC Corrected'!I30) -> 11753914 | J34: =((SUM('Cost Components'!$B$20:$B$26)*10^6)/(1+'Cost Components'!$B$38)^'MFSP WACC Corrected'!J30) -> 10984966 | ... AA34: =((SUM('Cost Components'!$B$20:$B$26)*10^6)/(1+'Cost Components'!$B$38)^'MFSP WACC Corrected'!AA30) -> 3477558.9
A35: Total | B35: =SUM(B31:B34) -> 362670000 | C35: =SUM(C31:C34) -> 84373329 | D35: =SUM(D31:D34) -> 78853578 | E35: =SUM(E31:E34) -> 73694933 | F35: =SUM(F31:F34) -> 68873769 | G35: =SUM(G31:G34) -> 64368009 | H35: =SUM(H31:H34) -> 60157017 | I35: =SUM(I31:I34) -> 56221512 | ... AA35: =SUM(AA31:AA34) -> 16633917
A37: Component
A38: CAPEX | B38: =SUM(B31:AA31) /SUM($B$35:$AA$35) -> 0.25634932
A39: Electricity | B39: =SUM(B32:AA32) /SUM($B$35:$AA$35) -> -0.065490373
A40: CO2 Cost | B40: =SUM(B33:AA33) /SUM($B$35:$AA$35) -> 0.65367021
A41: Other OPEX | B41: =SUM(B34:AA34) /SUM($B$35:$AA$35) -> 0.15547084
A43: Contribution to Final Cost - 2050
A44: Year | B44: 0 | C44: 1 | D44: 2 | E44: 3 | F44: 4 | G44: 5 | H44: 6 | I44: 7 | J44: 8 | K44: 9 | L44: 10 | M44: 11 | N44: 12 | O44: 13 | P44: 14 | Q44: 15 | R44: 16 | S44: 17 | T44: 18 | U44: 19 | V44: 20 | W44: 21 | X44: 22 | Y44: 23 | Z44: 24 | AA44: 25
A45: CAPEX | B45: ='Cost Components'!H14 * 10^6 -> 325320000 | C45: 0 | D45: 0 | E45: 0 | F45: 0 | G45: 0 | H45: 0 | I45: 0 | J45: 0 | K45: 0 | L45: 0 | M45: 0 | N45: 0 | O45: 0 | P45: 0 | Q45: 0 | R45: 0 | S45: 0 | T45: 0 | U45: 0 | V45: 0 | W45: 0 | X45: 0 | Y45: 0 | Z45: 0 | AA45: 0
A46: Electricity Surplus (Discounted) | B46: 0 | C46: =(-'Cost Components'!$H$29 * 10^6) / (1+'Cost Components'!$B$38)^'MFSP WACC Corrected'!C44 -> -2313.0841 | D46: =(-'Cost Components'!$H$29 * 10^6) / (1+'Cost Components'!$B$38)^'MFSP WACC Corrected'!D44 -> -2161.7609 | E46: =(-'Cost Components'!$H$29 * 10^6) / (1+'Cost Components'!$B$38)^'MFSP WACC Corrected'!E44 -> -2020.3372 | F46: =(-'Cost Components'!$H$29 * 10^6) / (1+'Cost Components'!$B$38)^'MFSP WACC Corrected'!F44 -> -1888.1656 | G46: =(-'Cost Components'!$H$29 * 10^6) / (1+'Cost Components'!$B$38)^'MFSP WACC Corrected'!G44 -> -1764.6408 | H46: =(-'Cost Components'!$H$29 * 10^6) / (1+'Cost Components'!$B$38)^'MFSP WACC Corrected'!H44 -> -1649.197 | I46: =(-'Cost Components'!$H$29 * 10^6) / (1+'Cost Components'!$B$38)^'MFSP WACC Corrected'!I44 -> -1541.3056 | J46: =(-'Cost Components'!$H$29 * 10^6) / (1+'Cost Components'!$B$38)^'MFSP WACC Corrected'!J44 -> -1440.4725 | ... AA46: =(-'Cost Components'!$H$29 * 10^6) / (1+'Cost Components'!$B$38)^'MFSP WACC Corrected'!AA44 -> -456.01671
A47: CO2 Cost | B47: 0 | C47: =('Cost Components'!$H$36 * 10^6) / (1+'Cost Components'!$B$38) ^'MFSP WACC Corrected'!C44 -> 52441121 | D47: =('Cost Components'!$H$36 * 10^6) / (1+'Cost Components'!$B$38) ^'MFSP WACC Corrected'!D44 -> 49010394 | E47: =('Cost Components'!$H$36 * 10^6) / (1+'Cost Components'!$B$38) ^'MFSP WACC Corrected'!E44 -> 45804106 | F47: =('Cost Components'!$H$36 * 10^6) / (1+'Cost Components'!$B$38) ^'MFSP WACC Corrected'!F44 -> 42807576 | G47: =('Cost Components'!$H$36 * 10^6) / (1+'Cost Components'!$B$38) ^'MFSP WACC Corrected'!G44 -> 40007081 | H47: =('Cost Components'!$H$36 * 10^6) / (1+'Cost Components'!$B$38) ^'MFSP WACC Corrected'!H44 -> 37389795 | I47: =('Cost Components'!$H$36 * 10^6) / (1+'Cost Components'!$B$38) ^'MFSP WACC Corrected'!I44 -> 34943734 | J47: =('Cost Components'!$H$36 * 10^6) / (1+'Cost Components'!$B$38) ^'MFSP WACC Corrected'!J44 -> 32657695 | ... AA47: =('Cost Components'!$H$36 * 10^6) / (1+'Cost Components'!$B$38) ^'MFSP WACC Corrected'!AA44 -> 10338590
A48: OPEX | B48: 0 | C48: =((SUM('Cost Components'!$H$20:$H$26)*10^6)/(1+'Cost Components'!$B$38)^'MFSP WACC Corrected'!C44) -> 11023223 | D48: =((SUM('Cost Components'!$H$20:$H$26)*10^6)/(1+'Cost Components'!$B$38)^'MFSP WACC Corrected'!D44) -> 10302077 | E48: =((SUM('Cost Components'!$H$20:$H$26)*10^6)/(1+'Cost Components'!$B$38)^'MFSP WACC Corrected'!E44) -> 9628109.7 | F48: =((SUM('Cost Components'!$H$20:$H$26)*10^6)/(1+'Cost Components'!$B$38)^'MFSP WACC Corrected'!F44) -> 8998233.4 | G48: =((SUM('Cost Components'!$H$20:$H$26)*10^6)/(1+'Cost Components'!$B$38)^'MFSP WACC Corrected'!G44) -> 8409563.9 | H48: =((SUM('Cost Components'!$H$20:$H$26)*10^6)/(1+'Cost Components'!$B$38)^'MFSP WACC Corrected'!H44) -> 7859405.5 | I48: =((SUM('Cost Components'!$H$20:$H$26)*10^6)/(1+'Cost Components'!$B$38)^'MFSP WACC Corrected'!I44) -> 7345238.8 | J48: =((SUM('Cost Components'!$H$20:$H$26)*10^6)/(1+'Cost Components'!$B$38)^'MFSP WACC Corrected'!J44) -> 6864709.2 | ... AA48: =((SUM('Cost Components'!$H$20:$H$26)*10^6)/(1+'Cost Components'!$B$38)^'MFSP WACC Corrected'!AA44) -> 2173191.1
A49: Total | B49: =SUM(B45:B48) -> 325320000 | C49: =SUM(C45:C48) -> 63462031 | D49: =SUM(D45:D48) -> 59310310 | E49: =SUM(E45:E48) -> 55430196 | F49: =SUM(F45:F48) -> 51803921 | G49: =SUM(G45:G48) -> 48414880 | H49: =SUM(H45:H48) -> 45247551 | I49: =SUM(I45:I48) -> 42287431 | ... AA49: =SUM(AA45:AA48) -> 12511325
...

Sheet Outputs
A1: 2024 | H1: 2050 - Baseline | O1: 2050 - Optimistic
A2: Parameter | B2: Unit | C2: Base case | D2: Electricity correction | E2: DAC correction | F2: WACC correction | H2: Parameter | I2: Unit | J2: Base case | K2: Electricity correction | L2: DAC correction | M2: WACC correction | O2: Parameter | P2: Unit | Q2: Base case | R2: Electricity correction | S2: DAC correction | T2: WACC correction
A3: Syn-Fuel cost | B3: €/l | C3: ='MFSP Baseline'!B8 -> 2.6890654 | D3: ='MFSP LCOE Corrected'!B8 -> 2.5820038 | E3: ='MFSP CO2 Price Corrected'!B8 -> 3.6717495 | F3: ='MFSP WACC Corrected'!B8 -> 3.8243101 | H3: Syn-Fuel cost | I3: €/l | J3: ='MFSP Baseline'!B17 -> 2.071207 | K3: ='MFSP LCOE Corrected'!B17 -> 2.0712685 | L3: ='MFSP CO2 Price Corrected'!B17 -> 2.9772435 | M3: ='MFSP WACC Corrected'!B17 -> 3.1140925 | O3: Syn-Fuel cost | P3: €/l | Q3: ='MFSP Baseline'!B27 -> 1.8552801 | R3: ='MFSP LCOE Corrected'!B26 -> 1.8553417 | S3: ='MFSP CO2 Price Corrected'!B26 -> 2.7613167 | T3: ='MFSP WACC Corrected'!B26 -> 2.8624582
A4: Syn-Fuel cost | B4: $/l | C4: =C3/Inputs!$C$6 -> 2.9878505 | D4: =D3/Inputs!$C$6 -> 2.8688931 | E4: =E3/Inputs!$C$6 -> 4.0797216 | F4: =F3/Inputs!$C$6 -> 4.2492334 | H4: Syn-Fuel cost | I4: $/l | J4: =J3/Inputs!$C$6 -> 2.3013411 | K4: =K3/Inputs!$C$6 -> 2.3014095 | L4: =L3/Inputs!$C$6 -> 3.3080484 | M4: =M3/Inputs!$C$6 -> 3.4601028 | O4: Syn-Fuel cost | P4: $/l | Q4: =Q3/Inputs!$C$6 -> 2.0614223 | R4: =R3/Inputs!$C$6 -> 2.0614908 | S4: =S3/Inputs!$C$6 -> 3.0681296 | T4: =T3/Inputs!$C$6 -> 3.1805091
A5: Fossil Fuel cost | B5: $/l | C5: =Inputs!$C$16 -> 0.8 | D5: =Inputs!$C$16 -> 0.8 | E5: =Inputs!$C$16 -> 0.8 | F5: =Inputs!$C$16 -> 0.8 | H5: Fossil Fuel cost | I5: $/l | J5: =Inputs!$C$18 -> 0.8 | K5: =Inputs!$C$18 -> 0.8 | L5: =Inputs!$C$18 -> 0.8 | M5: =Inputs!$C$18 -> 0.8 | O5: Fossil Fuel cost | P5: $/l | Q5: =Inputs!$C$18 -> 0.8 | R5: =Inputs!$C$18 -> 0.8 | S5: =Inputs!$C$18 -> 0.8 | T5: =Inputs!$C$18 -> 0.8
A6: Syn-Fuel emissions | B6: gCO2eq/MJ | C6: ='Study Parameters'!$C$29 -> 13.5 | D6: ='Study Parameters'!$C$29 -> 13.5 | E6: ='Study Parameters'!$C$29 -> 13.5 | F6: ='Study Parameters'!$C$29 -> 13.5 | H6: Syn-Fuel emissions | I6: gCO2eq/MJ | J6: ='Study Parameters'!$C$29 -> 13.5 | K6: ='Study Parameters'!$C$29 -> 13.5 | L6: ='Study Parameters'!$C$29 -> 13.5 | M6: ='Study Parameters'!$C$29 -> 13.5 | O6: Syn-Fuel emissions | P6: gCO2eq/MJ | Q6: ='Study Parameters'!$C$29 -> 13.5 | R6: ='Study Parameters'!$C$29 -> 13.5 | S6: ='Study Parameters'!$C$29 -> 13.5 | T6: ='Study Parameters'!$C$29 -> 13.5
A7: Fossil Fuel emissions | B7: gCO2eq/MJ | C7: =Inputs!$C$11 -> 88.7 | D7: =Inputs!$C$11 -> 88.7 | E7: =Inputs!$C$11 -> 88.7 | F7: =Inputs!$C$11 -> 88.7 | H7: Fossil Fuel emissions | I7: gCO2eq/MJ | J7: =Inputs!$C$11 -> 88.7 | K7: =Inputs!$C$11 -> 88.7 | L7: =Inputs!$C$11 -> 88.7 | M7: =Inputs!$C$11 -> 88.7 | O7: Fossil Fuel emissions | P7: gCO2eq/MJ | Q7: =Inputs!$C$11 -> 88.7 | R7: =Inputs!$C$11 -> 88.7 | S7: =Inputs!$C$11 -> 88.7 | T7: =Inputs!$C$11 -> 88.7
