Workbook

Sheet Legend
A1: Scenario Name | B1: Details | C1: Notes
A2: C-P-N | B2: Current - PEM - Nuclear
A3: C-P-R | B3: Current - PEM - Renewable | C3: Very high battery CAPEX, scenario is omitted
A4: C-P-N/R | B4: Current - PEM - Nuclear/Renewable
A5: C-S-N/R | B5: Current - SOEC- Nuclear/Renewable
A6: F-P-N | B6: 2050 - PEM - Nuclear
A7: F-P-R | B7: 2050 - PEM - Renewables
A8: F-P-N/R | B8: 2050 - PEM - Nuclear/Renewables
A9: F-S-N/R | B9: 2050 - SOEC - Nuclear/Renewables

Sheet Inputs
A1: Parameter | B1: Year | C1: Value | D1: Unit
A2: Standard Values
A3: Current Year | C3: 2024
A4: Inflation | C4: =[1]Inputs!C5 -> 0.02
A5: WACC | C5: =[1]Inputs!C6 -> 0.07
A6: USD to EUR | C6: =[1]Inputs!C7 -> 0.9
A7: Electricity
A8: LCOE | B8: 2024 | C8: =[1]Inputs!C9 -> 64 | D8: $/MWh
A9: LCOE | B9: 2050 | C9: =[1]Inputs!C10 -> 11 | D9: $/MWh
A10: Jet Fuel A-1 Characteristics
A11: Emissions Intensity | B11: 2024 | C11: =[1]Inputs!C12 -> 88.7 | D11: gCO2/MJ
A12: Emissions Intensity | B12: 2050 | C12: =[1]Inputs!C13 -> 88.7 | D12: gCO2/MJ
A13: Energy Density | C13: =[1]Inputs!C14 -> 43.2 | D13: MJ/kg
A14: Energy Density | C14: =[1]Inputs!C15 -> 34.6896 | D14: MJ/l
A15: Volumetric Density | C15: =[1]Inputs!C16 -> 0.803 | D15: kg/l
A16: Jet Fuel A-1 Price | B16: 2024 | C16: =[1]Inputs!C17 -> 0.8 | D16: $/l
A17: Scenario Specific Values
A18: Jet Fuel A-1 Price | B18: 2050 | C18: =[1]Inputs!C19 -> 1.7 | D18: $/l
A19: IEA Reference
A20: Jet Fuel A-1 Price | B20: 2024 | C20: =[1]Inputs!C21 -> 0.32246154 | D20: $/l
A21: Jet Fuel A-1 Price | B21: 2050 | C21: =[1]Inputs!C22 -> 0.20923077 | D21: $/l
A22: EIA Reference
A23: Jet Fuel A-1 Price | B23: 2024 | C23: =[1]Inputs!C24 -> 1.0209014 | D23: $/l
A24: Jet Fuel A-1 Price | B24: 2050 | C24: =[1]Inputs!C25 -> 2.0095594 | D24: $/l
A25: EIA Low Oil Price Scenario
A26: Jet Fuel A-1 Price | B26: 2024 | C26: =[1]Inputs!C27 -> 0.48286833 | D26: $/l
A27: Jet Fuel A-1 Price | B27: 2050 | C27: =[1]Inputs!C28 -> 0.89646575 | D27: $/l
A28: EIA High Scenario
A29: Jet Fuel A-1 Price | B29: 2024 | C29: =[1]Inputs!C30 -> 1.8838713 | D29: $/l
A30: Jet Fuel A-1 Price | B30: 2050 | C30: =[1]Inputs!C31 -> 3.7893731 | D30: $/l
A31: Direct Air Capture
A32: LCOR | B32: 2024 | C32: =[1]Inputs!C33 -> 1371 | D32: $/tCO2
A33: LCOR | B33: 2050 | C33: =[1]Inputs!C34 -> 523 | D33: $/tCO2

Sheet Study Parameters
A1: Key Parameters
A2: Parameter | B2: Year | C2: Value | D2: Source | E2: Note
A3: Discount Rate | B3: Both | C3: 0.08 | D3: Peacock et. al.
A4: Lifetime (years) | B4: Both | C4: 30 | D4: Peacock et. al.
A6: Process Parameters
A7: Parameter | B7: Year | C7: Value | D7: Unit | E7: Source | F7: Note
A8: Annual Jet Fuel Production | B8: Both | C8: 0.99 | D8: Mbbl | E8: Peacock et. al.
A9: Annual Jet Fuel Production | B9: Both | C9: =C8*159 * 10^6 -> 157410000 | D9: l | F9: Calculated (1 barrel = 159 litres)
A10: Annual CO2 Consumption | B10: Both | C10: 1 | D10: Mt | E10: Peacock et. al.
A11: Annual H2 consumption | B11: Both | C11: 94 | D11: kt | E11: Peacock et. al. | G11: =C10*10^9 / C9*0.8 -> 5.0822692
A12: Annual Diesel Production | B12: Both | C12: 0.66 | D12: Mbbl | E12: Peacock et. al.
A13: Annual Diesel Production | B13: Both | C13: =C12*159 * 10^6 -> 1.0494e+08 | D13: l | F13: Calculated (1 barrel = 159 litres)
A14: DAC Heat | B14: 2024 | C14: 1200 | D14: kWh/tCO2 | E14: Peacock et. al. Table 2
A15: DAC Heat | B15: 2050 | C15: 1100 | D15: kWh/tCO2 | E15: Peacock et. al. Table 2
A16: DAC Electricity | B16: 2024 | C16: 250 | D16: kWh/tCO2 | E16: Peacock et. al. Table 2
A17: DAC Electricity | B17: 2050 | C17: 182 | D17: kWh/tCO2 | E17: Peacock et. al. Table 2
A18: Electrolyzer Electricity Consumption | B18: 2024 | C18: 55.6 | D18: kWh/kg H2 | E18: Peacock et. al. Table 3
A19: Electrolyzer Electricity Consumption | B19: 2050 | C19: 47.5 | D19: kWh/kg H2 | E19: Peacock et. al. Table 3
A22: Plant Parameters
A23: Parameter | B23: Year | C23: Value | D23: Unit | E23: Source | F23: Note
A24: Installed Battery Capacity | B24: 2024 | C24: 18956 | D24: MWh | E24: Peacock et. al. Table 6
A25: Installed Battery Capacity | B25: 2050 | C25: 16474 | D25: MWh | E25: Peacock et. al. Table 6
A26: Number of cycles per day | B26: Both | C26: 2
A27: No. of cycles before replacement | B27: 2024 | C27: 2750
A28: No. of cycles before replacement | B28: 2050 | C28: 3500
A29: No. of replacements (Battery) | B29: 2024 | C29: =_xlfn.CEILING.MATH($C$4 / (($C$27/C26) / (365)),1) - 1 -> 7 | E29: Peacock et. al. Table 6
A30: No. of replacements (Battery) | B30: 2050 | C30: =_xlfn.CEILING.MATH($C$4 / (($C$28/C26) / (365)),1) - 1 -> 6 | E30: Peacock et. al. Table 6
A31: PEM Replacement period (years) | B31: 2024 | C31: 10 | E31: Peacock et. al. Table 3
A32: PEM Replacement period (years) | B32: 2050 | C32: 12 | E32: Peacock et. al. Table 3
A33: SOEC Replacement period (years) | B33: 2024 | C33: 6 | E33: Peacock et. al. Table 5
A34: SOEC Replacement period (years) | B34: 2050 | C34: 10 | E34: Peacock et. al. Table 5
A35: No. or replacements (PEM) | B35: 2024 | C35: =C4/C31 - 1 -> 2 | E35: Peacock et. al. Table 3
A36: No. or replacements (PEM) | B36: 2050 | C36: =_xlfn.CEILING.MATH(C4/C32 - 1,1) -> 2 | E36: Peacock et. al. Table 3
A37: No. or replacements (SOEC) | B37: 2024 | C37: =C4/C33 - 1 -> 4 | E37: Peacock et. al. Table 5
A38: No. or replacements (SOEC) | B38: 2050 | C38: =C4/C34 - 1 -> 2 | E38: Peacock et. al. Table 5
A40: Cost Parameters
A41: Parameter | B41: Year | C41: Value | D41: Unit | E41: Source | F41: Note
A42: Diesel Revenue | B42: Both | C42: 122 | D42: M€ | E42: Peacock et. al.
A43: Thermal Energy Cost (C-P-R Scenario) | B43: 2024 | C43: 28.5 | D43: $/MWh | E43: Peacock et. al. Table 1
A44: Thermal Energy Cost (F-P-R Scenario) | B44: 2050 | C44: 14.2 | D44: $/MWh | E44: Peacock et. al. Table 1
...

Sheet NPV DAC CAPEX
A1: Year | B1: 0 | C1: 1 | D1: 2 | E1: 3 | F1: 4 | G1: 5 | H1: 6 | I1: 7 | J1: 8 | K1: 9 | L1: 10 | M1: 11 | N1: 12 | O1: 13 | P1: 14 | Q1: 15 | R1: 16 | S1: 17 | T1: 18 | U1: 19 | V1: 20 | W1: 21 | X1: 22 | Y1: 23 | Z1: 24 | AA1: 25 | AB1: 26 | AC1: 27 | AD1: 28 | AE1: 29 | AF1: 30
A2: 2024
A3: Cost (€) | B3: 524 | C3: 524 | D3: 524 | E3: 524 | F3: 524 | G3: 524 | H3: 524 | I3: 524 | J3: 524 | K3: 524 | L3: 524 | M3: 524 | N3: 524 | O3: 524 | P3: 524 | Q3: 524 | R3: 524 | S3: 524 | T3: 524 | U3: 524 | V3: 524 | W3: 524 | X3: 524 | Y3: 524 | Z3: 524 | AA3: 524 | AB3: 524 | AC3: 524 | AD3: 524 | AE3: 524 | AF3: 524
A4: Discounted Cost (€) | B4: =B3/(1+'Study Parameters'!$C$3)^'NPV DAC CAPEX'!B1 -> 524 | C4: =C3/(1+'Study Parameters'!$C$3)^'NPV DAC CAPEX'!C1 -> 485.18519 | D4: =D3/(1+'Study Parameters'!$C$3)^'NPV DAC CAPEX'!D1 -> 449.24554 | E4: =E3/(1+'Study Parameters'!$C$3)^'NPV DAC CAPEX'!E1 -> 415.96809 | F4: =F3/(1+'Study Parameters'!$C$3)^'NPV DAC CAPEX'!F1 -> 385.15564 | G4: =G3/(1+'Study Parameters'!$C$3)^'NPV DAC CAPEX'!G1 -> 356.6256 | H4: =H3/(1+'Study Parameters'!$C$3)^'NPV DAC CAPEX'!H1 -> 330.20888 | I4: =I3/(1+'Study Parameters'!$C$3)^'NPV DAC CAPEX'!I1 -> 305.74897 | ... AF4: =AF3/(1+'Study Parameters'!$C$3)^'NPV DAC CAPEX'!AF1 -> 52.073722
A6: 2050
A7: Cost (€) | B7: 200 | C7: 200 | D7: 200 | E7: 200 | F7: 200 | G7: 200 | H7: 200 | I7: 200 | J7: 200 | K7: 200 | L7: 200 | M7: 200 | N7: 200 | O7: 200 | P7: 200 | Q7: 200 | R7: 200 | S7: 200 | T7: 200 | U7: 200 | V7: 200 | W7: 200 | X7: 200 | Y7: 200 | Z7: 200 | AA7: 200 | AB7: 200 | AC7: 200 | AD7: 200 | AE7: 200 | AF7: 200
A8: Discounted Cost (€) | B8: =B7/(1+'Study Parameters'!$C$3)^'NPV DAC CAPEX'!B1 -> 200 | C8: =C7/(1+'Study Parameters'!$C$3)^'NPV DAC CAPEX'!C1 -> 185.18519 | D8: =D7/(1+'Study Parameters'!$C$3)^'NPV DAC CAPEX'!D1 -> 171.46776 | E8: =E7/(1+'Study Parameters'!$C$3)^'NPV DAC CAPEX'!E1 -> 158.76645 | F8: =F7/(1+'Study Parameters'!$C$3)^'NPV DAC CAPEX'!F1 -> 147.00597 | G8: =G7/(1+'Study Parameters'!$C$3)^'NPV DAC CAPEX'!G1 -> 136.11664 | H8: =H7/(1+'Study Parameters'!$C$3)^'NPV DAC CAPEX'!H1 -> 126.03393 | I8: =I7/(1+'Study Parameters'!$C$3)^'NPV DAC CAPEX'!I1 -> 116.69808 | ... AF8: =AF7/(1+'Study Parameters'!$C$3)^'NPV DAC CAPEX'!AF1 -> 19.875467
A10: 2024
A11: CO2 Removed | B11: 0 | C11: =10^6 -> 1000000 | D11: =10^6 -> 1000000 | E11: =10^6 -> 1000000 | F11: =10^6 -> 1000000 | G11: =10^6 -> 1000000 | H11: =10^6 -> 1000000 | I11: =10^6 -> 1000000 | J11: =10^6 -> 1000000 | ... AF11: =10^6 -> 1000000
A12: CO2 Removed (Discounted) | B12: =B11/(1+'Study Parameters'!$C$3)^'NPV DAC CAPEX'!B1 -> 0 | C12: =C11/(1+'Study Parameters'!$C$3)^'NPV DAC CAPEX'!C1 -> 925925.93 | D12: =D11/(1+'Study Parameters'!$C$3)^'NPV DAC CAPEX'!D1 -> 857338.82 | E12: =E11/(1+'Study Parameters'!$C$3)^'NPV DAC CAPEX'!E1 -> 793832.24 | F12: =F11/(1+'Study Parameters'!$C$3)^'NPV DAC CAPEX'!F1 -> 735029.85 | G12: =G11/(1+'Study Parameters'!$C$3)^'NPV DAC CAPEX'!G1 -> 680583.2 | H12: =H11/(1+'Study Parameters'!$C$3)^'NPV DAC CAPEX'!H1 -> 630169.63 | I12: =I11/(1+'Study Parameters'!$C$3)^'NPV DAC CAPEX'!I1 -> 583490.4 | ... AF12: =AF11/(1+'Study Parameters'!$C$3)^'NPV DAC CAPEX'!AF1 -> 99377.333
A14: LCOR | B14: =(SUM(B4:AF4) * 10^6) / SUM(B12:AF12) -> 570.54558

Sheet Cost Components
A1: Economic Assumptions C-P-N | G1: Economic Assumptions C-P-N/R | M1: Economic Assumptions C-S-N/R | S1: Economic Assumptions F-P-N | Y1: Economic Assumptions F-P-N/R | AE1: Economic Assumptions F-S-N/R
A2: CAPEX | G2: CAPEX | M2: CAPEX | S2: CAPEX | Y2: CAPEX | AE2: CAPEX
A3: Component | B3: Value | C3: Unit | D3: Source | E3: Notes | G3: Component | H3: Value | I3: Unit | J3: Source | K3: Notes | M3: Component | N3: Value | O3: Unit | P3: Source | Q3: Notes | S3: Component | T3: Value | U3: Unit | V3: Source | W3: Notes | Y3: Component | Z3: Value | AA3: Unit | AB3: Source | AC3: Notes | AE3: Component | AF3: Value | AG3: Unit | AH3: Source | AI3: Notes
A4: PEM | B4: 480 | C4: M€ | D4: Peacock et. al. Figure 7 | G4: PEM | H4: 480 | I4: M€ | J4: Peacock et. al. Figure 7 | M4: SOE | N4: 750 | O4: M€ | P4: Peacock et. al. Figure 7 | S4: PEM | T4: 230 | U4: M€ | V4: Peacock et. al. Figure 7 | Y4: PEM | Z4: 230 | AA4: M€ | AB4: Peacock et. al. Figure 7 | AE4: SOEC | AF4: 175 | AG4: M€ | AH4: Peacock et. al. Figure 7
A5: DAC | B5: =SUM('NPV DAC CAPEX'!$B$4:$AF$4) -> 6423.0785 | C5: M€ | D5: Peacock et. al. Figure 7 | G5: DAC | H5: =SUM('NPV DAC CAPEX'!$B$4:$AF$4) -> 6423.0785 | I5: M€ | J5: Peacock et. al. Figure 7 | M5: DAC | N5: =SUM('NPV DAC CAPEX'!$B$4:$AF$4) -> 6423.0785 | O5: M€ | P5: Peacock et. al. Figure 7 | S5: DAC | T5: =SUM('NPV DAC CAPEX'!$B$8:$AF$8) -> 2451.5567 | U5: M€ | V5: Peacock et. al. Figure 7 | Y5: DAC | Z5: =SUM('NPV DAC CAPEX'!$B$8:$AF$8) -> 2451.5567 | AA5: M€ | AB5: Peacock et. al. Figure 7 | AE5: DAC | AF5: =SUM('NPV DAC CAPEX'!$B$8:$AF$8) -> 2451.5567 | AG5: M€ | AH5: Peacock et. al. Figure 7
A6: FT | B6: 620 | C6: M€ | D6: Peacock et. al. Figure 7 | G6: FT | H6: 620 | I6: M€ | J6: Peacock et. al. Figure 7 | M6: FT | N6: 620 | O6: M€ | P6: Peacock et. al. Figure 7 | S6: FT | T6: 620 | U6: M€ | V6: Peacock et. al. Figure 7 | Y6: FT | Z6: 620 | AA6: M€ | AB6: Peacock et. al. Figure 7 | AE6: FT | AF6: 620 | AG6: M€ | AH6: Peacock et. al. Figure 7
A7: PEM Stack Replacement | B7: 177 | C7: M€ | G7: PEM Stack Replacement | H7: 177 | I7: M€ | M7: SOE Stack Replacement | N7: ='Study Parameters'!C53*'Cost Components'!N4 -> 375 | O7: M€ | S7: PEM Stack Replacement | T7: ='Study Parameters'!$C$50*'Cost Components'!T4 -> 69 | U7: M€ | W7: Calculated | Y7: PEM Stack Replacement | Z7: ='Study Parameters'!$C$50*'Cost Components'!Z4 -> 69 | AA7: M€ | AC7: Calculated | AE7: SOEC Stack Replacement | AF7: ='Study Parameters'!C54*'Cost Components'!AF4 -> 70 | AG7: M€ | AI7: Calculated
A8: Total CAPEX | B8: =SUM(B4:B6) -> 7523.0785 | C8: M€ | G8: Total CAPEX | H8: =SUM(H4:H6) -> 7523.0785 | I8: M€ | M8: Total CAPEX | N8: =SUM(N4:N6) -> 7793.0785 | O8: M€ | S8: Total CAPEX | T8: =SUM(T4:T6) -> 3301.5567 | U8: M€ | Y8: Total CAPEX | Z8: =SUM(Z4:Z6) -> 3301.5567 | AA8: M€ | AE8: Total CAPEX | AF8: =SUM(AF4:AF6) -> 3246.5567 | AG8: M€
A10: OPEX | G10: OPEX | M10: OPEX | S10: OPEX | Y10: OPEX | AE10: OPEX
A11: Component | B11: Value | C11: Unit | D11: Source | E11: Notes | G11: Component | H11: Value | I11: Unit | J11: Source | K11: Notes | M11: Component | N11: Value | O11: Unit | P11: Source | Q11: Notes | S11: Component | T11: Value | U11: Unit | V11: Source | W11: Notes | Y11: Component | Z11: Value | AA11: Unit | AB11: Source | AC11: Notes | AE11: Component | AF11: Value | AG11: Unit | AH11: Source | AI11: Notes
A12: Electricity | B12: 700 | C12: M€/year | D12: Peacock et. al. Figure 9 | G12: Electricity | H12: 510 | I12: M€/year | J12: Peacock et. al. Figure 9 | M12: Electricity | N12: 380 | O12: M€/year | P12: Peacock et. al. Figure 9 | S12: Electricity | T12: 253 | U12: M€/year | V12: Peacock et. al. Figure 9 | Y12: Electricity | Z12: 184 | AA12: M€/year | AB12: Peacock et. al. Figure 9 | AE12: Electricity | AF12: 155 | AG12: M€/year | AH12: Peacock et. al. Figure 9
A13: Heat | B13: 44.2 | C13: M€/year | D13: Peacock et. al. Figure 9 | G13: Heat | H13: 44.2 | I13: M€/year | J13: Peacock et. al. Figure 9 | M13: Heat | N13: 55 | O13: M€/year | P13: Peacock et. al. Figure 9 | S13: Heat | T13: 25 | U13: M€/year | V13: Peacock et. al. Figure 9 | Y13: Heat | Z13: 25 | AA13: M€/year | AB13: Peacock et. al. Figure 9 | AE13: Heat | AF13: 27 | AG13: M€/year | AH13: Peacock et. al. Figure 9
A14: Water | B14: 14.7 | C14: M€/year | D14: Peacock et. al. Figure 9 | G14: Water | H14: 14.7 | I14: M€/year | J14: Peacock et. al. Figure 9 | M14: Water | N14: 9.8 | O14: M€/year | P14: Peacock et. al. Figure 9 | S14: Water | T14: 25 | U14: M€/year | V14: Peacock et. al. Figure 9 | Y14: Water | Z14: 26 | AA14: M€/year | AB14: Peacock et. al. Figure 9 | AE14: Water | AF14: 6 | AG14: M€/year | AH14: Peacock et. al. Figure 9
A15: Fixed Costs | B15: 121.6 | C15: M€/year | D15: Peacock et. al. Figure 9 | G15: Fixed Costs | H15: 121.6 | I15: M€/year | J15: Peacock et. al. Figure 9 | M15: Fixed Costs | N15: 141 | O15: M€/year | P15: Peacock et. al. Figure 9 | S15: Fixed Costs | T15: 90 | U15: M€/year | V15: Peacock et. al. Figure 9 | Y15: Fixed Costs | Z15: 90 | AA15: M€/year | AB15: Peacock et. al. Figure 9 | AE15: Fixed Costs | AF15: 90 | AG15: M€/year | AH15: Peacock et. al. Figure 9
A16: Total OPEX | B16: =SUM(B12:B15) -> 880.5 | G16: Total OPEX | H16: =SUM(H12:H15) -> 690.5 | M16: Total OPEX | N16: =SUM(N12:N15) -> 585.8 | S16: Total OPEX | T16: =SUM(T12:T15) -> 393 | Y16: Total OPEX | Z16: =SUM(Z12:Z15) -> 325 | AE16: Total OPEX | AF16: =SUM(AF12:AF15) -> 278
A18: Corrected Assumptions C-P-N | G18: Corrected Assumptions C-P-N/R | M18: Corrected Assumptions C-S-N/R | S18: Corrected Assumptions F-P-N | Y18: Corrected Assumptions F-P-N/R | AE18: Corrected Assumptions F-S-N/R
A19: OPEX | G19: OPEX | M19: OPEX | S19: OPEX | Y19: OPEX | AE19: OPEX
A20: Component | B20: Value | C20: Unit | D20: Source | E20: Notes | G20: Component | H20: Value | I20: Unit | J20: Source | K20: Notes | M20: Component | N20: Value | O20: Unit | P20: Source | Q20: Notes | S20: Component | T20: Value | U20: Unit | V20: Source | W20: Notes | Y20: Component | Z20: Value | AA20: Unit | AB20: Source | AC20: Notes | AE20: Component | AF20: Value | AG20: Unit | AH20: Source | AI20: Notes
A21: Electricity | B21: =Inputs!$C$8/'Study Parameters'!$C$59 * 'Cost Components'!B12 -> 379.66102 | C21: M€/year | E21: Grid Price considered | G21: Electricity | H21: =Inputs!$C$8/'Study Parameters'!$C$61 * 'Cost Components'!H12 -> 409.02256 | I21: M€/year | K21: Grid Price considered | M21: Electricity | N21: =Inputs!$C$8/'Study Parameters'!$C$61 * 'Cost Components'!N12 -> 304.7619 | O21: M€/year | Q21: Grid Price considered | S21: Electricity | T21: =Inputs!$C$9/'Study Parameters'!$C$60 * 'Cost Components'!T12 -> 55.66 | U21: M€/year | W21: Grid Price considered | Y21: Electricity | Z21: =Inputs!$C$9/'Study Parameters'!$C$62 * 'Cost Components'!Z12 -> 53.263158 | AA21: M€/year | AC21: Grid Price considered | AE21: Electricity | AF21: =Inputs!$C$9/'Study Parameters'!$C$62 * 'Cost Components'!AF12 -> 44.868421 | AG21: M€/year | AI21: Grid Price considered
A22: LCOE Corrected OPEX | B22: =B16-B12+B21 -> 560.16102 | C22: M€/year | G22: LCOE Corrected OPEX | H22: =H16-H12+H21 -> 589.52256 | I22: M€/year | M22: LCOE Corrected OPEX | N22: =N16-N12+N21 -> 510.5619 | O22: M€/year | S22: LCOE Corrected OPEX | T22: =T16-T12+T21 -> 195.66 | U22: M€/year | Y22: LCOE Corrected OPEX | Z22: =Z16-Z12+Z21 -> 194.26316 | AA22: M€/year | AE22: LCOE Corrected OPEX | AF22: =AF16-AF12+AF21 -> 167.86842 | AG22: M€/year
A23: CO2 Corrected CAPEX | B23: =B8-B5 -> 1100 | C23: M€ | E23: DAC CAPEX neglected | G23: CO2 Corrected CAPEX | H23: =H8-H5 -> 1100 | I23: M€ | K23: DAC CAPEX neglected | M23: CO2 Corrected CAPEX | N23: =N8-N5 -> 1370 | O23: M€ | Q23: DAC CAPEX neglected | S23: CO2 Corrected CAPEX | T23: =T8-T5 -> 850 | U23: M€ | W23: DAC CAPEX neglected | Y23: CO2 Corrected CAPEX | Z23: =Z8-Z5 -> 850 | AA23: M€ | AC23: DAC CAPEX neglected | AE23: CO2 Corrected CAPEX | AF23: =AF8-AF5 -> 795 | AG23: M€ | AI23: DAC CAPEX neglected
A24: CO2 Cost | B24: =(Inputs!$C$32*'Study Parameters'!$C$10*10^6) / 10^6 -> 1371 | C24: M€/year | G24: CO2 Cost | H24: =(Inputs!$C$32*'Study Parameters'!$C$10*10^6) / 10^6 -> 1371 | I24: M€/year | M24: CO2 Cost | N24: =(Inputs!$C$32*'Study Parameters'!$C$10*10^6) / 10^6 -> 1371 | O24: M€/year | S24: CO2 Cost | T24: =(Inputs!$C$33*'Study Parameters'!$C$10*10^6) / 10^6 -> 523 | U24: M€/year | Y24: CO2 Cost | Z24: =(Inputs!$C$33*'Study Parameters'!$C$10*10^6) / 10^6 -> 523 | AA24: M€/year | AE24: CO2 Cost | AF24: =(Inputs!$C$33*'Study Parameters'!$C$10*10^6) / 10^6 -> 523 | AG24: M€/year
A25: Electricity | B25: =(Inputs!$C$8*'Study Parameters'!D76) / 10^6 -> 363.66102 | C25: M€/year | E25: DAC Electricity requirements subtracted | G25: Electricity | H25: =(Inputs!$C$8*'Study Parameters'!D72) / 10^6 -> 409.02256 | I25: M€/year | K25: DAC Electricity requirements subtracted | M25: Electricity | N25: =(Inputs!$C$8*'Study Parameters'!D74) / 10^6 -> 304.7619 | O25: M€/year | Q25: DAC Electricity requirements subtracted | S25: Electricity | T25: =(Inputs!$C$8*'Study Parameters'!D71) / 10^6 -> 323.84 | U25: M€/year | W25: DAC Electricity requirements subtracted | Y25: Electricity | Z25: =(Inputs!$C$8*'Study Parameters'!D79) / 10^6 -> 298.24674 | AA25: M€/year | AC25: DAC Electricity requirements subtracted | AE25: Electricity | AF25: =(Inputs!$C$8*'Study Parameters'!D81) / 10^6 -> 249.40463 | AG25: M€/year | AI25: DAC Electricity requirements subtracted
A26: CO2 Corrected OPEX | B26: =B16-B12 - B13 - B14+B25+B24 -> 1856.261 | C26: M€/year | E26: DAC heat requirements subtracted | G26: CO2 Corrected OPEX | H26: =H16-H12 - H13 - H14+H25+H24 -> 1901.6226 | I26: M€/year | K26: DAC heat requirements subtracted | M26: CO2 Corrected OPEX | N26: =N16-N12 - N13 - N14+N25+N24 -> 1816.7619 | O26: M€/year | Q26: DAC heat requirements subtracted | S26: CO2 Corrected OPEX | T26: =T16-T12 - T13 - T14+T25+T24 -> 936.84 | U26: M€/year | W26: DAC heat requirements subtracted | Y26: CO2 Corrected OPEX | Z26: =Z16-Z12 - Z13 - Z14+Z25+Z24 -> 911.24674 | AA26: M€/year | AC26: DAC heat requirements subtracted | AE26: CO2 Corrected OPEX | AF26: =AF16-AF12 - AF13 - AF14+AF25+AF24 -> 862.40463 | AG26: M€/year | AI26: DAC heat requirements subtracted

Sheet LCOF Baseline
A1: C-P-N
A2: Year | B2: 0 | C2: 1 | D2: 2 | E2: 3 | F2: 4 | G2: 5 | H2: 6 | I2: 7 | J2: 8 | K2: 9 | L2: 10 | M2: 11 | N2: 12 | O2: 13 | P2: 14 | Q2: 15 | R2: 16 | S2: 17 | T2: 18 | U2: 19 | V2: 20 | W2: 21 | X2: 22 | Y2: 23 | Z2: 24 | AA2: 25 | AB2: 26 | AC2: 27 | AD2: 28 | AE2: 29 | AF2: 30
A3: Cost (€) | B3: ='Cost Components'!B8*10^6 -> 7.5230785e+09 | C3: ='Cost Components'!$B$16 * 10^6 -> 8.805e+08 | D3: ='Cost Components'!$B$16 * 10^6 -> 8.805e+08 | E3: ='Cost Components'!$B$16 * 10^6 -> 8.805e+08 | F3: ='Cost Components'!$B$16 * 10^6 -> 8.805e+08 | G3: ='Cost Components'!$B$16 * 10^6 -> 8.805e+08 | H3: ='Cost Components'!$B$16 * 10^6 -> 8.805e+08 | I3: ='Cost Components'!$B$16 * 10^6 -> 8.805e+08 | J3: ='Cost Components'!$B$16 * 10^6 -> 8.805e+08 | K3: ='Cost Components'!$B$16 * 10^6 -> 8.805e+08 | L3: ='Cost Components'!$B$16 * 10^6 + 'Cost Components'!$B$7*10^6 -> 1.0575e+09 | M3: ='Cost Components'!$B$16 * 10^6 -> 8.805e+08 | N3: ='Cost Components'!$B$16 * 10^6 -> 8.805e+08 | O3: ='Cost Components'!$B$16 * 10^6 -> 8.805e+08 | P3: ='Cost Components'!$B$16 * 10^6 -> 8.805e+08 | Q3: ='Cost Components'!$B$16 * 10^6 -> 8.805e+08 | R3: ='Cost Components'!$B$16 * 10^6 -> 8.805e+08 | S3: ='Cost Components'!$B$16 * 10^6 -> 8.805e+08 | T3: ='Cost Components'!$B$16 * 10^6 -> 8.805e+08 | U3: ='Cost Components'!$B$16 * 10^6 -> 8.805e+08 | V3: ='Cost Components'!$B$16 * 10^6 + 'Cost Components'!$B$7*10^6 -> 1.0575e+09 | W3: ='Cost Components'!$B$16 * 10^6 -> 8.805e+08 | X3: ='Cost Components'!$B$16 * 10^6 -> 8.805e+08 | Y3: ='Cost Components'!$B$16 * 10^6 -> 8.805e+08 | Z3: ='Cost Components'!$B$16 * 10^6 -> 8.805e+08 | AA3: ='Cost Components'!$B$16 * 10^6 -> 8.805e+08 | AB3: ='Cost Components'!$B$16 * 10^6 -> 8.805e+08 | AC3: ='Cost Components'!$B$16 * 10^6 -> 8.805e+08 | AD3: ='Cost Components'!$B$16 * 10^6 -> 8.805e+08 | ... AF3: ='Cost Components'!$B$16 * 10^6 -> 8.805e+08
A4: Discounted Cost (€) | B4: =B3/(1+'Study Parameters'!$C$3) ^ 'LCOF Baseline'!B2 -> 7.5230785e+09 | C4: =C3/(1+'Study Parameters'!$C$3) ^ 'LCOF Baseline'!C2 -> 8.1527778e+08 | D4: =D3/(1+'Study Parameters'!$C$3) ^ 'LCOF Baseline'!D2 -> 7.5488683e+08 | E4: =E3/(1+'Study Parameters'!$C$3) ^ 'LCOF Baseline'!E2 -> 6.9896929e+08 | F4: =F3/(1+'Study Parameters'!$C$3) ^ 'LCOF Baseline'!F2 -> 6.4719379e+08 | G4: =G3/(1+'Study Parameters'!$C$3) ^ 'LCOF Baseline'!G2 -> 5.992535e+08 | H4: =H3/(1+'Study Parameters'!$C$3) ^ 'LCOF Baseline'!H2 -> 5.5486436e+08 | I4: =I3/(1+'Study Parameters'!$C$3) ^ 'LCOF Baseline'!I2 -> 5.1376329e+08 | ... AF4: =AF3/(1+'Study Parameters'!$C$3) ^ 'LCOF Baseline'!AF2 -> 87501741
A5: Revenue (€) | B5: 0 | C5: ='Study Parameters'!$C$42*10^6 -> 122000000 | D5: ='Study Parameters'!$C$42*10^6 -> 122000000 | E5: ='Study Parameters'!$C$42*10^6 -> 122000000 | F5: ='Study Parameters'!$C$42*10^6 -> 122000000 | G5: ='Study Parameters'!$C$42*10^6 -> 122000000 | H5: ='Study Parameters'!$C$42*10^6 -> 122000000 | I5: ='Study Parameters'!$C$42*10^6 -> 122000000 | J5: ='Study Parameters'!$C$42*10^6 -> 122000000 | ... AF5: ='Study Parameters'!$C$42*10^6 -> 122000000
A6: Discounted Revenue (€) | B6: 0 | C6: =C5/(1+'Study Parameters'!$C$3) ^'LCOF Baseline'!C2 -> 1.1296296e+08 | D6: =D5/(1+'Study Parameters'!$C$3) ^'LCOF Baseline'!D2 -> 1.0459534e+08 | E6: =E5/(1+'Study Parameters'!$C$3) ^'LCOF Baseline'!E2 -> 96847533 | F6: =F5/(1+'Study Parameters'!$C$3) ^'LCOF Baseline'!F2 -> 89673642 | G6: =G5/(1+'Study Parameters'!$C$3) ^'LCOF Baseline'!G2 -> 83031150 | H6: =H5/(1+'Study Parameters'!$C$3) ^'LCOF Baseline'!H2 -> 76880694 | I6: =I5/(1+'Study Parameters'!$C$3) ^'LCOF Baseline'!I2 -> 71185828 | J6: =J5/(1+'Study Parameters'!$C$3) ^'LCOF Baseline'!J2 -> 65912804 | ... AF6: =AF5/(1+'Study Parameters'!$C$3) ^'LCOF Baseline'!AF2 -> 12124035
A7: Production (l) | B7: 0 | C7: ='Study Parameters'!$C$9 -> 157410000 | D7: ='Study Parameters'!$C$9 -> 157410000 | E7: ='Study Parameters'!$C$9 -> 157410000 | F7: ='Study Parameters'!$C$9 -> 157410000 | G7: ='Study Parameters'!$C$9 -> 157410000 | H7: ='Study Parameters'!$C$9 -> 157410000 | I7: ='Study Parameters'!$C$9 -> 157410000 | J7: ='Study Parameters'!$C$9 -> 157410000 | ... AF7: ='Study Parameters'!$C$9 -> 157410000
A8: Discounted Production (l) | B8: 0 | C8: =C7/(1+'Study Parameters'!$C$3) ^ 'LCOF Baseline'!C2 -> 145750000 | D8: =D7/(1+'Study Parameters'!$C$3) ^ 'LCOF Baseline'!D2 -> 1.349537e+08 | E8: =E7/(1+'Study Parameters'!$C$3) ^ 'LCOF Baseline'!E2 -> 1.2495713e+08 | F8: =F7/(1+'Study Parameters'!$C$3) ^ 'LCOF Baseline'!F2 -> 1.1570105e+08 | G8: =G7/(1+'Study Parameters'!$C$3) ^ 'LCOF Baseline'!G2 -> 1.071306e+08 | H8: =H7/(1+'Study Parameters'!$C$3) ^ 'LCOF Baseline'!H2 -> 99195001 | I8: =I7/(1+'Study Parameters'!$C$3) ^ 'LCOF Baseline'!I2 -> 91847223 | J8: =J7/(1+'Study Parameters'!$C$3) ^ 'LCOF Baseline'!J2 -> 85043725 | ... AF8: =AF7/(1+'Study Parameters'!$C$3) ^ 'LCOF Baseline'!AF2 -> 15642986
A10: Levelised Cost of Fuel (€/l) | B10: =(SUM(B4:AF4) - SUM(B6:AF6)) / SUM(B8:AF8) -> 9.1316404
A12: C-P-N/R
A13: Year | B13: 0 | C13: 1 | D13: 2 | E13: 3 | F13: 4 | G13: 5 | H13: 6 | I13: 7 | J13: 8 | K13: 9 | L13: 10 | M13: 11 | N13: 12 | O13: 13 | P13: 14 | Q13: 15 | R13: 16 | S13: 17 | T13: 18 | U13: 19 | V13: 20 | W13: 21 | X13: 22 | Y13: 23 | Z13: 24 | AA13: 25 | AB13: 26 | AC13: 27 | AD13: 28 | AE13: 29 | AF13: 30
A14: Cost (€) | B14: ='Cost Components'!H8*10^6 -> 7.5230785e+09 | C14: ='Cost Components'!$H$16*10^6 -> 6.905e+08 | D14: ='Cost Components'!$H$16*10^6 -> 6.905e+08 | E14: ='Cost Components'!$H$16*10^6 -> 6.905e+08 | F14: ='Cost Components'!$H$16*10^6 -> 6.905e+08 | G14: ='Cost Components'!$H$16*10^6 -> 6.905e+08 | H14: ='Cost Components'!$H$16*10^6 -> 6.905e+08 | I14: ='Cost Components'!$H$16*10^6 -> 6.905e+08 | J14: ='Cost Components'!$H$16*10^6 -> 6.905e+08 | K14: ='Cost Components'!$H$16*10^6 -> 6.905e+08 | L14: ='Cost Components'!$H$16*10^6 + 'Cost Components'!$H$7 * 10^6 -> 8.675e+08 | M14: ='Cost Components'!$H$16*10^6 -> 6.905e+08 | N14: ='Cost Components'!$H$16*10^6 -> 6.905e+08 | O14: ='Cost Components'!$H$16*10^6 -> 6.905e+08 | P14: ='Cost Components'!$H$16*10^6 -> 6.905e+08 | Q14: ='Cost Components'!$H$16*10^6 -> 6.905e+08 | R14: ='Cost Components'!$H$16*10^6 -> 6.905e+08 | S14: ='Cost Components'!$H$16*10^6 -> 6.905e+08 | T14: ='Cost Components'!$H$16*10^6 -> 6.905e+08 | U14: ='Cost Components'!$H$16*10^6 -> 6.905e+08 | V14: ='Cost Components'!$H$16*10^6 + 'Cost Components'!$H$7 * 10^6 -> 8.675e+08 | W14: ='Cost Components'!$H$16*10^6 -> 6.905e+08 | X14: ='Cost Components'!$H$16*10^6 -> 6.905e+08 | Y14: ='Cost Components'!$H$16*10^6 -> 6.905e+08 | Z14: ='Cost Components'!$H$16*10^6 -> 6.905e+08 | AA14: ='Cost Components'!$H$16*10^6 -> 6.905e+08 | AB14: ='Cost Components'!$H$16*10^6 -> 6.905e+08 | AC14: ='Cost Components'!$H$16*10^6 -> 6.905e+08 | AD14: ='Cost Components'!$H$16*10^6 -> 6.905e+08 | ... AF14: ='Cost Components'!$H$16*10^6 -> 6.905e+08
A15: Discounted Cost (€) | B15: =B14/(1+'Study Parameters'!$C$3) ^'LCOF Baseline'!B$13 -> 7.5230785e+09 | C15: =C14/(1+'Study Parameters'!$C$3) ^'LCOF Baseline'!C$13 -> 6.3935185e+08 | D15: =D14/(1+'Study Parameters'!$C$3) ^'LCOF Baseline'!D$13 -> 5.9199246e+08 | E15: =E14/(1+'Study Parameters'!$C$3) ^'LCOF Baseline'!E$13 -> 5.4814116e+08 | F15: =F14/(1+'Study Parameters'!$C$3) ^'LCOF Baseline'!F$13 -> 5.0753811e+08 | G15: =G14/(1+'Study Parameters'!$C$3) ^'LCOF Baseline'!G$13 -> 4.699427e+08 | H15: =H14/(1+'Study Parameters'!$C$3) ^'LCOF Baseline'!H$13 -> 4.3513213e+08 | I15: =I14/(1+'Study Parameters'!$C$3) ^'LCOF Baseline'!I$13 -> 4.0290012e+08 | ... AF15: =AF14/(1+'Study Parameters'!$C$3) ^'LCOF Baseline'!AF$13 -> 68620048
A16: Revenue (€) | B16: 0 | C16: ='Study Parameters'!$C$42 * 10^6 -> 122000000 | D16: ='Study Parameters'!$C$42 * 10^6 -> 122000000 | E16: ='Study Parameters'!$C$42 * 10^6 -> 122000000 | F16: ='Study Parameters'!$C$42 * 10^6 -> 122000000 | G16: ='Study Parameters'!$C$42 * 10^6 -> 122000000 | H16: ='Study Parameters'!$C$42 * 10^6 -> 122000000 | I16: ='Study Parameters'!$C$42 * 10^6 -> 122000000 | J16: ='Study Parameters'!$C$42 * 10^6 -> 122000000 | ... AF16: ='Study Parameters'!$C$42 * 10^6 -> 122000000
A17: Discounted Revenue (€) | B17: 0 | C17: =C16/(1+'Study Parameters'!$C$3) ^'LCOF Baseline'!C$13 -> 1.1296296e+08 | D17: =D16/(1+'Study Parameters'!$C$3) ^'LCOF Baseline'!D$13 -> 1.0459534e+08 | E17: =E16/(1+'Study Parameters'!$C$3) ^'LCOF Baseline'!E$13 -> 96847533 | F17: =F16/(1+'Study Parameters'!$C$3) ^'LCOF Baseline'!F$13 -> 89673642 | G17: =G16/(1+'Study Parameters'!$C$3) ^'LCOF Baseline'!G$13 -> 83031150 | H17: =H16/(1+'Study Parameters'!$C$3) ^'LCOF Baseline'!H$13 -> 76880694 | I17: =I16/(1+'Study Parameters'!$C$3) ^'LCOF Baseline'!I$13 -> 71185828 | J17: =J16/(1+'Study Parameters'!$C$3) ^'LCOF Baseline'!J$13 -> 65912804 | ... AF17: =AF16/(1+'Study Parameters'!$C$3) ^'LCOF Baseline'!AF$13 -> 12124035
A18: Production (l) | B18: 0 | C18: ='Study Parameters'!$C$9 -> 157410000 | D18: ='Study Parameters'!$C$9 -> 157410000 | E18: ='Study Parameters'!$C$9 -> 157410000 | F18: ='Study Parameters'!$C$9 -> 157410000 | G18: ='Study Parameters'!$C$9 -> 157410000 | H18: ='Study Parameters'!$C$9 -> 157410000 | I18: ='Study Parameters'!$C$9 -> 157410000 | J18: ='Study Parameters'!$C$9 -> 157410000 | ... AF18: ='Study Parameters'!$C$9 -> 157410000
A19: Discounted Production (l) | B19: 0 | C19: =C18/(1+'Study Parameters'!$C$3) ^'LCOF Baseline'!C$13 -> 145750000 | D19: =D18/(1+'Study Parameters'!$C$3) ^'LCOF Baseline'!D$13 -> 1.349537e+08 | E19: =E18/(1+'Study Parameters'!$C$3) ^'LCOF Baseline'!E$13 -> 1.2495713e+08 | F19: =F18/(1+'Study Parameters'!$C$3) ^'LCOF Baseline'!F$13 -> 1.1570105e+08 | G19: =G18/(1+'Study Parameters'!$C$3) ^'LCOF Baseline'!G$13 -> 1.071306e+08 | H19: =H18/(1+'Study Parameters'!$C$3) ^'LCOF Baseline'!H$13 -> 99195001 | I19: =I18/(1+'Study Parameters'!$C$3) ^'LCOF Baseline'!I$13 -> 91847223 | J19: =J18/(1+'Study Parameters'!$C$3) ^'LCOF Baseline'!J$13 -> 85043725 | ... AF19: =AF18/(1+'Study Parameters'!$C$3) ^'LCOF Baseline'!AF$13 -> 15642986
A21: Levelised Cost of Fuel (€/l) | B21: =(SUM(B15:AF15) - SUM(B17:AF17)) / SUM(B19:AF19) -> 7.9246015
A23: C-S-N/R
A24: Year | B24: 0 | C24: 1 | D24: 2 | E24: 3 | F24: 4 | G24: 5 | H24: 6 | I24: 7 | J24: 8 | K24: 9 | L24: 10 | M24: 11 | N24: 12 | O24: 13 | P24: 14 | Q24: 15 | R24: 16 | S24: 17 | T24: 18 | U24: 19 | V24: 20 | W24: 21 | X24: 22 | Y24: 23 | Z24: 24 | AA24: 25 | AB24: 26 | AC24: 27 | AD24: 28 | AE24: 29 | AF24: 30
A25: Cost (€) | B25: ='Cost Components'!N8 * 10^6 -> 7.7930785e+09 | C25: ='Cost Components'!$N$16 * 10^6 -> 585800000 | D25: ='Cost Components'!$N$16 * 10^6 -> 585800000 | E25: ='Cost Components'!$N$16 * 10^6 -> 585800000 | F25: ='Cost Components'!$N$16 * 10^6 -> 585800000 | G25: ='Cost Components'!$N$16 * 10^6 -> 585800000 | H25: ='Cost Components'!$N$16 * 10^6 -> 585800000 | I25: ='Cost Components'!$N$16 * 10^6 + 'Cost Components'!$N$7 * 10^6 -> 960800000 | J25: ='Cost Components'!$N$16 * 10^6 -> 585800000 | K25: ='Cost Components'!$N$16 * 10^6 -> 585800000 | L25: ='Cost Components'!$N$16 * 10^6 -> 585800000 | M25: ='Cost Components'!$N$16 * 10^6 -> 585800000 | N25: ='Cost Components'!$N$16 * 10^6 -> 585800000 | O25: ='Cost Components'!$N$16 * 10^6 + 'Cost Components'!$N$7 * 10^6 -> 960800000 | P25: ='Cost Components'!$N$16 * 10^6 -> 585800000 | Q25: ='Cost Components'!$N$16 * 10^6 -> 585800000 | R25: ='Cost Components'!$N$16 * 10^6 -> 585800000 | S25: ='Cost Components'!$N$16 * 10^6 -> 585800000 | T25: ='Cost Components'!$N$16 * 10^6 -> 585800000 | U25: ='Cost Components'!$N$16 * 10^6 + 'Cost Components'!$N$7 * 10^6 -> 960800000 | V25: ='Cost Components'!$N$16 * 10^6 -> 585800000 | W25: ='Cost Components'!$N$16 * 10^6 -> 585800000 | X25: ='Cost Components'!$N$16 * 10^6 -> 585800000 | Y25: ='Cost Components'!$N$16 * 10^6 -> 585800000 | Z25: ='Cost Components'!$N$16 * 10^6 -> 585800000 | AA25: ='Cost Components'!$N$16 * 10^6 + 'Cost Components'!$N$7 * 10^6 -> 960800000 | AB25: ='Cost Components'!$N$16 * 10^6 -> 585800000 | AC25: ='Cost Components'!$N$16 * 10^6 -> 585800000 | AD25: ='Cost Components'!$N$16 * 10^6 -> 585800000 | AE25: ='Cost Components'!$N$16 * 10^6 -> 585800000 | AF25: ='Cost Components'!$N$16 * 10^6 -> 585800000
A26: Discounted Cost (€) | B26: =B25/(1+'Study Parameters'!$C$3)^'LCOF Baseline'!B$24 -> 7.7930785e+09 | C26: =C25/(1+'Study Parameters'!$C$3)^'LCOF Baseline'!C$24 -> 5.4240741e+08 | D26: =D25/(1+'Study Parameters'!$C$3)^'LCOF Baseline'!D$24 -> 5.0222908e+08 | E26: =E25/(1+'Study Parameters'!$C$3)^'LCOF Baseline'!E$24 -> 4.6502693e+08 | F26: =F25/(1+'Study Parameters'!$C$3)^'LCOF Baseline'!F$24 -> 4.3058049e+08 | G26: =G25/(1+'Study Parameters'!$C$3)^'LCOF Baseline'!G$24 -> 3.9868564e+08 | H26: =H25/(1+'Study Parameters'!$C$3)^'LCOF Baseline'!H$24 -> 3.6915337e+08 | I26: =I25/(1+'Study Parameters'!$C$3)^'LCOF Baseline'!I$24 -> 5.6061757e+08 | ... AF26: =AF25/(1+'Study Parameters'!$C$3)^'LCOF Baseline'!AF$24 -> 58215241
A27: Revenue (€) | B27: 0 | C27: ='Study Parameters'!$C$42 * 10^6 -> 122000000 | D27: ='Study Parameters'!$C$42 * 10^6 -> 122000000 | E27: ='Study Parameters'!$C$42 * 10^6 -> 122000000 | F27: ='Study Parameters'!$C$42 * 10^6 -> 122000000 | G27: ='Study Parameters'!$C$42 * 10^6 -> 122000000 | H27: ='Study Parameters'!$C$42 * 10^6 -> 122000000 | I27: ='Study Parameters'!$C$42 * 10^6 -> 122000000 | J27: ='Study Parameters'!$C$42 * 10^6 -> 122000000 | ... AF27: ='Study Parameters'!$C$42 * 10^6 -> 122000000
A28: Discounted Revenue (€) | B28: 0 | C28: =C27/(1+'Study Parameters'!$C$3)^'LCOF Baseline'!C$24 -> 1.1296296e+08 | D28: =D27/(1+'Study Parameters'!$C$3)^'LCOF Baseline'!D$24 -> 1.0459534e+08 | E28: =E27/(1+'Study Parameters'!$C$3)^'LCOF Baseline'!E$24 -> 96847533 | F28: =F27/(1+'Study Parameters'!$C$3)^'LCOF Baseline'!F$24 -> 89673642 | G28: =G27/(1+'Study Parameters'!$C$3)^'LCOF Baseline'!G$24 -> 83031150 | H28: =H27/(1+'Study Parameters'!$C$3)^'LCOF Baseline'!H$24 -> 76880694 | I28: =I27/(1+'Study Parameters'!$C$3)^'LCOF Baseline'!I$24 -> 71185828 | J28: =J27/(1+'Study Parameters'!$C$3)^'LCOF Baseline'!J$24 -> 65912804 | ... AF28: =AF27/(1+'Study Parameters'!$C$3)^'LCOF Baseline'!AF$24 -> 12124035
A29: Production (l) | B29: 0 | C29: ='Study Parameters'!$C$9 -> 157410000 | D29: ='Study Parameters'!$C$9 -> 157410000 | E29: ='Study Parameters'!$C$9 -> 157410000 | F29: ='Study Parameters'!$C$9 -> 157410000 | G29: ='Study Parameters'!$C$9 -> 157410000 | H29: ='Study Parameters'!$C$9 -> 157410000 | I29: ='Study Parameters'!$C$9 -> 157410000 | J29: ='Study Parameters'!$C$9 -> 157410000 | ... AF29: ='Study Parameters'!$C$9 -> 157410000
A30: Discounted Production (l) | B30: 0 | C30: =C29/(1+'Study Parameters'!$C$3)^'LCOF Baseline'!C$24 -> 145750000 | D30: =D29/(1+'Study Parameters'!$C$3)^'LCOF Baseline'!D$24 -> 1.349537e+08 | E30: =E29/(1+'Study Parameters'!$C$3)^'LCOF Baseline'!E$24 -> 1.2495713e+08 | F30: =F29/(1+'Study Parameters'!$C$3)^'LCOF Baseline'!F$24 -> 1.1570105e+08 | G30: =G29/(1+'Study Parameters'!$C$3)^'LCOF Baseline'!G$24 -> 1.071306e+08 | H30: =H29/(1+'Study Parameters'!$C$3)^'LCOF Baseline'!H$24 -> 99195001 | I30: =I29/(1+'Study Parameters'!$C$3)^'LCOF Baseline'!I$24 -> 91847223 | J30: =J29/(1+'Study Parameters'!$C$3)^'LCOF Baseline'!J$24 -> 85043725 | ... AF30: =AF29/(1+'Study Parameters'!$C$3)^'LCOF Baseline'!AF$24 -> 15642986
A32: Levelised Cost of Fuel (€/l) | B32: =(SUM(B26:AF26) - SUM(B28:AF28)) / SUM(B30:AF30) -> 7.6253466
A34: F-P-N
A35: Year | B35: 0 | C35: 1 | D35: 2 | E35: 3 | F35: 4 | G35: 5 | H35: 6 | I35: 7 | J35: 8 | K35: 9 | L35: 10 | M35: 11 | N35: 12 | O35: 13 | P35: 14 | Q35: 15 | R35: 16 | S35: 17 | T35: 18 | U35: 19 | V35: 20 | W35: 21 | X35: 22 | Y35: 23 | Z35: 24 | AA35: 25 | AB35: 26 | AC35: 27 | AD35: 28 | AE35: 29 | AF35: 30
A36: Cost (€) | B36: ='Cost Components'!T8 * 10^6 -> 3.3015567e+09 | C36: ='Cost Components'!$T$16 * 10^6 -> 393000000 | D36: ='Cost Components'!$T$16 * 10^6 -> 393000000 | E36: ='Cost Components'!$T$16 * 10^6 -> 393000000 | F36: ='Cost Components'!$T$16 * 10^6 -> 393000000 | G36: ='Cost Components'!$T$16 * 10^6 -> 393000000 | H36: ='Cost Components'!$T$16 * 10^6 -> 393000000 | I36: ='Cost Components'!$T$16 * 10^6 -> 393000000 | J36: ='Cost Components'!$T$16 * 10^6 -> 393000000 | ... M36: ='Cost Components'!$T$16 * 10^6 -> 393000000 | N36: ='Cost Components'!$T$16 * 10^6 + 'Cost Components'!$T$7 * 10^6 -> 462000000 | O36: ='Cost Components'!$T$16 * 10^6 -> 393000000 | P36: ='Cost Components'!$T$16 * 10^6 -> 393000000 | Q36: ='Cost Components'!$T$16 * 10^6 -> 393000000 | R36: ='Cost Components'!$T$16 * 10^6 -> 393000000 | S36: ='Cost Components'!$T$16 * 10^6 -> 393000000 | T36: ='Cost Components'!$T$16 * 10^6 -> 393000000 | U36: ='Cost Components'!$T$16 * 10^6 -> 393000000 | V36: ='Cost Components'!$T$16 * 10^6 -> 393000000 | ... Y36: ='Cost Components'!$T$16 * 10^6 -> 393000000 | Z36: ='Cost Components'!$T$16 * 10^6 + 'Cost Components'!$T$7 * 10^6 -> 462000000 | AA36: ='Cost Components'!$T$16 * 10^6 -> 393000000 | AB36: ='Cost Components'!$T$16 * 10^6 -> 393000000 | AC36: ='Cost Components'!$T$16 * 10^6 -> 393000000 | AD36: ='Cost Components'!$T$16 * 10^6 -> 393000000 | AE36: ='Cost Components'!$T$16 * 10^6 -> 393000000 | AF36: ='Cost Components'!$T$16 * 10^6 -> 393000000
A37: Discounted Cost (€) | B37: =B36/(1+'Study Parameters'!$C$3)^'LCOF Baseline'!B$35 -> 3.3015567e+09 | C37: =C36/(1+'Study Parameters'!$C$3)^'LCOF Baseline'!C$35 -> 3.6388889e+08 | D37: =D36/(1+'Study Parameters'!$C$3)^'LCOF Baseline'!D$35 -> 3.3693416e+08 | E37: =E36/(1+'Study Parameters'!$C$3)^'LCOF Baseline'!E$35 -> 3.1197607e+08 | F37: =F36/(1+'Study Parameters'!$C$3)^'LCOF Baseline'!F$35 -> 2.8886673e+08 | G37: =G36/(1+'Study Parameters'!$C$3)^'LCOF Baseline'!G$35 -> 2.674692e+08 | H37: =H36/(1+'Study Parameters'!$C$3)^'LCOF Baseline'!H$35 -> 2.4765666e+08 | I37: =I36/(1+'Study Parameters'!$C$3)^'LCOF Baseline'!I$35 -> 2.2931173e+08 | ... AF37: =AF36/(1+'Study Parameters'!$C$3)^'LCOF Baseline'!AF$35 -> 39055292
A38: Revenue (€) | B38: 0 | C38: ='Study Parameters'!$C$42 * 10^6 -> 122000000 | D38: ='Study Parameters'!$C$42 * 10^6 -> 122000000 | E38: ='Study Parameters'!$C$42 * 10^6 -> 122000000 | F38: ='Study Parameters'!$C$42 * 10^6 -> 122000000 | G38: ='Study Parameters'!$C$42 * 10^6 -> 122000000 | H38: ='Study Parameters'!$C$42 * 10^6 -> 122000000 | I38: ='Study Parameters'!$C$42 * 10^6 -> 122000000 | J38: ='Study Parameters'!$C$42 * 10^6 -> 122000000 | ... AF38: ='Study Parameters'!$C$42 * 10^6 -> 122000000
A39: Discounted Revenue (€) | B39: 0 | C39: =C38/(1+'Study Parameters'!$C$3)^'LCOF Baseline'!C$35 -> 1.1296296e+08 | D39: =D38/(1+'Study Parameters'!$C$3)^'LCOF Baseline'!D$35 -> 1.0459534e+08 | E39: =E38/(1+'Study Parameters'!$C$3)^'LCOF Baseline'!E$35 -> 96847533 | F39: =F38/(1+'Study Parameters'!$C$3)^'LCOF Baseline'!F$35 -> 89673642 | G39: =G38/(1+'Study Parameters'!$C$3)^'LCOF Baseline'!G$35 -> 83031150 | H39: =H38/(1+'Study Parameters'!$C$3)^'LCOF Baseline'!H$35 -> 76880694 | I39: =I38/(1+'Study Parameters'!$C$3)^'LCOF Baseline'!I$35 -> 71185828 | J39: =J38/(1+'Study Parameters'!$C$3)^'LCOF Baseline'!J$35 -> 65912804 | ... AF39: =AF38/(1+'Study Parameters'!$C$3)^'LCOF Baseline'!AF$35 -> 12124035
A40: Production (l) | B40: 0 | C40: ='Study Parameters'!$C$9 -> 157410000 | D40: ='Study Parameters'!$C$9 -> 157410000 | E40: ='Study Parameters'!$C$9 -> 157410000 | F40: ='Study Parameters'!$C$9 -> 157410000 | G40: ='Study Parameters'!$C$9 -> 157410000 | H40: ='Study Parameters'!$C$9 -> 157410000 | I40: ='Study Parameters'!$C$9 -> 157410000 | J40: ='Study Parameters'!$C$9 -> 157410000 | ... AF40: ='Study Parameters'!$C$9 -> 157410000
A41: Discounted Production (l) | B41: 0 | C41: =C40/(1+'Study Parameters'!$C$3)^'LCOF Baseline'!C$35 -> 145750000 | D41: =D40/(1+'Study Parameters'!$C$3)^'LCOF Baseline'!D$35 -> 1.349537e+08 | E41: =E40/(1+'Study Parameters'!$C$3)^'LCOF Baseline'!E$35 -> 1.2495713e+08 | F41: =F40/(1+'Study Parameters'!$C$3)^'LCOF Baseline'!F$35 -> 1.1570105e+08 | G41: =G40/(1+'Study Parameters'!$C$3)^'LCOF Baseline'!G$35 -> 1.071306e+08 | H41: =H40/(1+'Study Parameters'!$C$3)^'LCOF Baseline'!H$35 -> 99195001 | I41: =I40/(1+'Study Parameters'!$C$3)^'LCOF Baseline'!I$35 -> 91847223 | J41: =J40/(1+'Study Parameters'!$C$3)^'LCOF Baseline'!J$35 -> 85043725 | ... AF41: =AF40/(1+'Study Parameters'!$C$3)^'LCOF Baseline'!AF$35 -> 15642986
A43: Levelised Cost of Fuel (€/l) | B43: =(SUM(B37:AF37) - SUM(B39:AF39)) / SUM(B41:AF41) -> 3.6063103
A45: F-P-N/R
A46: Year | B46: 0 | C46: 1 | D46: 2 | E46: 3 | F46: 4 | G46: 5 | H46: 6 | I46: 7 | J46: 8 | K46: 9 | L46: 10 | M46: 11 | N46: 12 | O46: 13 | P46: 14 | Q46: 15 | R46: 16 | S46: 17 | T46: 18 | U46: 19 | V46: 20 | W46: 21 | X46: 22 | Y46: 23 | Z46: 24 | AA46: 25 | AB46: 26 | AC46: 27 | AD46: 28 | AE46: 29 | AF46: 30
A47: Cost (€) | B47: ='Cost Components'!T8 * 10^6 -> 3.3015567e+09 | C47: ='Cost Components'!$Z$16 * 10^6 -> 325000000 | D47: ='Cost Components'!$Z$16 * 10^6 -> 325000000 | E47: ='Cost Components'!$Z$16 * 10^6 -> 325000000 | F47: ='Cost Components'!$Z$16 * 10^6 -> 325000000 | G47: ='Cost Components'!$Z$16 * 10^6 -> 325000000 | H47: ='Cost Components'!$Z$16 * 10^6 -> 325000000 | I47: ='Cost Components'!$Z$16 * 10^6 -> 325000000 | J47: ='Cost Components'!$Z$16 * 10^6 -> 325000000 | ... M47: ='Cost Components'!$Z$16 * 10^6 -> 325000000 | N47: ='Cost Components'!$Z$16 * 10^6 + 'Cost Components'!$Z$7 * 10^6 -> 394000000 | O47: ='Cost Components'!$Z$16 * 10^6 -> 325000000 | P47: ='Cost Components'!$Z$16 * 10^6 -> 325000000 | Q47: ='Cost Components'!$Z$16 * 10^6 -> 325000000 | R47: ='Cost Components'!$Z$16 * 10^6 -> 325000000 | S47: ='Cost Components'!$Z$16 * 10^6 -> 325000000 | T47: ='Cost Components'!$Z$16 * 10^6 -> 325000000 | U47: ='Cost Components'!$Z$16 * 10^6 -> 325000000 | V47: ='Cost Components'!$Z$16 * 10^6 -> 325000000 | ... Y47: ='Cost Components'!$Z$16 * 10^6 -> 325000000 | Z47: ='Cost Components'!$Z$16 * 10^6 + 'Cost Components'!$Z$7 * 10^6 -> 394000000 | AA47: ='Cost Components'!$Z$16 * 10^6 -> 325000000 | AB47: ='Cost Components'!$Z$16 * 10^6 -> 325000000 | AC47: ='Cost Components'!$Z$16 * 10^6 -> 325000000 | AD47: ='Cost Components'!$Z$16 * 10^6 -> 325000000 | AE47: ='Cost Components'!$Z$16 * 10^6 -> 325000000 | AF47: ='Cost Components'!$Z$16 * 10^6 -> 325000000
A48: Discounted Cost (€) | B48: =B47/(1+'Study Parameters'!$C$3)^'LCOF Baseline'!B$46 -> 3.3015567e+09 | C48: =C47/(1+'Study Parameters'!$C$3)^'LCOF Baseline'!C$46 -> 3.0092593e+08 | D48: =D47/(1+'Study Parameters'!$C$3)^'LCOF Baseline'!D$46 -> 2.7863512e+08 | E48: =E47/(1+'Study Parameters'!$C$3)^'LCOF Baseline'!E$46 -> 2.5799548e+08 | F48: =F47/(1+'Study Parameters'!$C$3)^'LCOF Baseline'!F$46 -> 2.388847e+08 | G48: =G47/(1+'Study Parameters'!$C$3)^'LCOF Baseline'!G$46 -> 2.2118954e+08 | H48: =H47/(1+'Study Parameters'!$C$3)^'LCOF Baseline'!H$46 -> 2.0480513e+08 | I48: =I47/(1+'Study Parameters'!$C$3)^'LCOF Baseline'!I$46 -> 1.8963438e+08 | ... AF48: =AF47/(1+'Study Parameters'!$C$3)^'LCOF Baseline'!AF$46 -> 32297633
...

Sheet LCOF LCOE Corrected
A1: C-P-N
A2: Year | B2: 0 | C2: 1 | D2: 2 | E2: 3 | F2: 4 | G2: 5 | H2: 6 | I2: 7 | J2: 8 | K2: 9 | L2: 10 | M2: 11 | N2: 12 | O2: 13 | P2: 14 | Q2: 15 | R2: 16 | S2: 17 | T2: 18 | U2: 19 | V2: 20 | W2: 21 | X2: 22 | Y2: 23 | Z2: 24 | AA2: 25 | AB2: 26 | AC2: 27 | AD2: 28 | AE2: 29 | AF2: 30
A3: Cost (€) | B3: ='Cost Components'!B8*10^6 -> 7.5230785e+09 | C3: ='Cost Components'!$B$22 * 10^6 -> 5.6016102e+08 | D3: ='Cost Components'!$B$22 * 10^6 -> 5.6016102e+08 | E3: ='Cost Components'!$B$22 * 10^6 -> 5.6016102e+08 | F3: ='Cost Components'!$B$22 * 10^6 -> 5.6016102e+08 | G3: ='Cost Components'!$B$22 * 10^6 -> 5.6016102e+08 | H3: ='Cost Components'!$B$22 * 10^6 -> 5.6016102e+08 | I3: ='Cost Components'!$B$22 * 10^6 -> 5.6016102e+08 | J3: ='Cost Components'!$B$22 * 10^6 -> 5.6016102e+08 | K3: ='Cost Components'!$B$22 * 10^6 -> 5.6016102e+08 | L3: ='Cost Components'!$B$22 * 10^6 + 'Cost Components'!$B$7*10^6 -> 7.3716102e+08 | M3: ='Cost Components'!$B$22 * 10^6 -> 5.6016102e+08 | N3: ='Cost Components'!$B$22 * 10^6 -> 5.6016102e+08 | O3: ='Cost Components'!$B$22 * 10^6 -> 5.6016102e+08 | P3: ='Cost Components'!$B$22 * 10^6 -> 5.6016102e+08 | Q3: ='Cost Components'!$B$22 * 10^6 -> 5.6016102e+08 | R3: ='Cost Components'!$B$22 * 10^6 -> 5.6016102e+08 | S3: ='Cost Components'!$B$22 * 10^6 -> 5.6016102e+08 | T3: ='Cost Components'!$B$22 * 10^6 -> 5.6016102e+08 | U3: ='Cost Components'!$B$22 * 10^6 -> 5.6016102e+08 | V3: ='Cost Components'!$B$22 * 10^6 + 'Cost Components'!$B$7*10^6 -> 7.3716102e+08 | W3: ='Cost Components'!$B$16 * 10^6 -> 8.805e+08 | X3: ='Cost Components'!$B$16 * 10^6 -> 8.805e+08 | Y3: ='Cost Components'!$B$16 * 10^6 -> 8.805e+08 | Z3: ='Cost Components'!$B$16 * 10^6 -> 8.805e+08 | AA3: ='Cost Components'!$B$16 * 10^6 -> 8.805e+08 | AB3: ='Cost Components'!$B$16 * 10^6 -> 8.805e+08 | AC3: ='Cost Components'!$B$16 * 10^6 -> 8.805e+08 | AD3: ='Cost Components'!$B$16 * 10^6 -> 8.805e+08 | ... AF3: ='Cost Components'!$B$16 * 10^6 -> 8.805e+08
A4: Discounted Cost (€) | B4: =B3/(1+'Study Parameters'!$C$3) ^ 'LCOF Baseline'!B2 -> 7.5230785e+09 | C4: =C3/(1+'Study Parameters'!$C$3) ^ 'LCOF Baseline'!C2 -> 5.1866761e+08 | D4: =D3/(1+'Study Parameters'!$C$3) ^ 'LCOF Baseline'!D2 -> 4.8024779e+08 | E4: =E3/(1+'Study Parameters'!$C$3) ^ 'LCOF Baseline'!E2 -> 4.4467388e+08 | F4: =F3/(1+'Study Parameters'!$C$3) ^ 'LCOF Baseline'!F2 -> 4.1173507e+08 | G4: =G3/(1+'Study Parameters'!$C$3) ^ 'LCOF Baseline'!G2 -> 3.8123618e+08 | H4: =H3/(1+'Study Parameters'!$C$3) ^ 'LCOF Baseline'!H2 -> 3.5299646e+08 | I4: =I3/(1+'Study Parameters'!$C$3) ^ 'LCOF Baseline'!I2 -> 3.2684857e+08 | ... AF4: =AF3/(1+'Study Parameters'!$C$3) ^ 'LCOF Baseline'!AF2 -> 87501741
A5: Revenue (€) | B5: 0 | C5: ='Study Parameters'!$C$42*10^6 -> 122000000 | D5: ='Study Parameters'!$C$42*10^6 -> 122000000 | E5: ='Study Parameters'!$C$42*10^6 -> 122000000 | F5: ='Study Parameters'!$C$42*10^6 -> 122000000 | G5: ='Study Parameters'!$C$42*10^6 -> 122000000 | H5: ='Study Parameters'!$C$42*10^6 -> 122000000 | I5: ='Study Parameters'!$C$42*10^6 -> 122000000 | J5: ='Study Parameters'!$C$42*10^6 -> 122000000 | ... AF5: ='Study Parameters'!$C$42*10^6 -> 122000000
A6: Discounted Revenue (€) | B6: 0 | C6: =C5/(1+'Study Parameters'!$C$3) ^'LCOF Baseline'!C2 -> 1.1296296e+08 | D6: =D5/(1+'Study Parameters'!$C$3) ^'LCOF Baseline'!D2 -> 1.0459534e+08 | E6: =E5/(1+'Study Parameters'!$C$3) ^'LCOF Baseline'!E2 -> 96847533 | F6: =F5/(1+'Study Parameters'!$C$3) ^'LCOF Baseline'!F2 -> 89673642 | G6: =G5/(1+'Study Parameters'!$C$3) ^'LCOF Baseline'!G2 -> 83031150 | H6: =H5/(1+'Study Parameters'!$C$3) ^'LCOF Baseline'!H2 -> 76880694 | I6: =I5/(1+'Study Parameters'!$C$3) ^'LCOF Baseline'!I2 -> 71185828 | J6: =J5/(1+'Study Parameters'!$C$3) ^'LCOF Baseline'!J2 -> 65912804 | ... AF6: =AF5/(1+'Study Parameters'!$C$3) ^'LCOF Baseline'!AF2 -> 12124035
A7: Production (l) | B7: 0 | C7: ='Study Parameters'!$C$9 -> 157410000 | D7: ='Study Parameters'!$C$9 -> 157410000 | E7: ='Study Parameters'!$C$9 -> 157410000 | F7: ='Study Parameters'!$C$9 -> 157410000 | G7: ='Study Parameters'!$C$9 -> 157410000 | H7: ='Study Parameters'!$C$9 -> 157410000 | I7: ='Study Parameters'!$C$9 -> 157410000 | J7: ='Study Parameters'!$C$9 -> 157410000 | ... AF7: ='Study Parameters'!$C$9 -> 157410000
A8: Discounted Production (l) | B8: 0 | C8: =C7/(1+'Study Parameters'!$C$3) ^ 'LCOF Baseline'!C2 -> 145750000 | D8: =D7/(1+'Study Parameters'!$C$3) ^ 'LCOF Baseline'!D2 -> 1.349537e+08 | E8: =E7/(1+'Study Parameters'!$C$3) ^ 'LCOF Baseline'!E2 -> 1.2495713e+08 | F8: =F7/(1+'Study Parameters'!$C$3) ^ 'LCOF Baseline'!F2 -> 1.1570105e+08 | G8: =G7/(1+'Study Parameters'!$C$3) ^ 'LCOF Baseline'!G2 -> 1.071306e+08 | H8: =H7/(1+'Study Parameters'!$C$3) ^ 'LCOF Baseline'!H2 -> 99195001 | I8: =I7/(1+'Study Parameters'!$C$3) ^ 'LCOF Baseline'!I2 -> 91847223 | J8: =J7/(1+'Study Parameters'!$C$3) ^ 'LCOF Baseline'!J2 -> 85043725 | ... AF8: =AF7/(1+'Study Parameters'!$C$3) ^ 'LCOF Baseline'!AF2 -> 15642986
A10: Levelised Cost of Fuel (€/l) | B10: =(SUM(B4:AF4) - SUM(B6:AF6)) / SUM(B8:AF8) -> 7.3568211
A12: C-P-N/R
A13: Year | B13: 0 | C13: 1 | D13: 2 | E13: 3 | F13: 4 | G13: 5 | H13: 6 | I13: 7 | J13: 8 | K13: 9 | L13: 10 | M13: 11 | N13: 12 | O13: 13 | P13: 14 | Q13: 15 | R13: 16 | S13: 17 | T13: 18 | U13: 19 | V13: 20 | W13: 21 | X13: 22 | Y13: 23 | Z13: 24 | AA13: 25 | AB13: 26 | AC13: 27 | AD13: 28 | AE13: 29 | AF13: 30
A14: Cost (€) | B14: ='Cost Components'!H8*10^6 -> 7.5230785e+09 | C14: ='Cost Components'!$H$22*10^6 -> 5.8952256e+08 | D14: ='Cost Components'!$H$22*10^6 -> 5.8952256e+08 | E14: ='Cost Components'!$H$22*10^6 -> 5.8952256e+08 | F14: ='Cost Components'!$H$22*10^6 -> 5.8952256e+08 | G14: ='Cost Components'!$H$22*10^6 -> 5.8952256e+08 | H14: ='Cost Components'!$H$22*10^6 -> 5.8952256e+08 | I14: ='Cost Components'!$H$22*10^6 -> 5.8952256e+08 | J14: ='Cost Components'!$H$22*10^6 -> 5.8952256e+08 | K14: ='Cost Components'!$H$22*10^6 -> 5.8952256e+08 | L14: ='Cost Components'!$H$22*10^6 + 'Cost Components'!$H$7 * 10^6 -> 7.6652256e+08 | M14: ='Cost Components'!$H$22*10^6 -> 5.8952256e+08 | N14: ='Cost Components'!$H$22*10^6 -> 5.8952256e+08 | O14: ='Cost Components'!$H$22*10^6 -> 5.8952256e+08 | P14: ='Cost Components'!$H$22*10^6 -> 5.8952256e+08 | Q14: ='Cost Components'!$H$22*10^6 -> 5.8952256e+08 | R14: ='Cost Components'!$H$22*10^6 -> 5.8952256e+08 | S14: ='Cost Components'!$H$22*10^6 -> 5.8952256e+08 | T14: ='Cost Components'!$H$22*10^6 -> 5.8952256e+08 | U14: ='Cost Components'!$H$22*10^6 -> 5.8952256e+08 | V14: ='Cost Components'!$H$22*10^6 + 'Cost Components'!$H$7 * 10^6 -> 7.6652256e+08 | W14: ='Cost Components'!$H$22*10^6 -> 5.8952256e+08 | X14: ='Cost Components'!$H$22*10^6 -> 5.8952256e+08 | Y14: ='Cost Components'!$H$22*10^6 -> 5.8952256e+08 | Z14: ='Cost Components'!$H$22*10^6 -> 5.8952256e+08 | AA14: ='Cost Components'!$H$22*10^6 -> 5.8952256e+08 | AB14: ='Cost Components'!$H$22*10^6 -> 5.8952256e+08 | AC14: ='Cost Components'!$H$22*10^6 -> 5.8952256e+08 | AD14: ='Cost Components'!$H$22*10^6 -> 5.8952256e+08 | ... AF14: ='Cost Components'!$H$22*10^6 -> 5.8952256e+08
A15: Discounted Cost (€) | B15: =B14/(1+'Study Parameters'!$C$3) ^'LCOF Baseline'!B$13 -> 7.5230785e+09 | C15: =C14/(1+'Study Parameters'!$C$3) ^'LCOF Baseline'!C$13 -> 5.4585422e+08 | D15: =D14/(1+'Study Parameters'!$C$3) ^'LCOF Baseline'!D$13 -> 5.0542057e+08 | E15: =E14/(1+'Study Parameters'!$C$3) ^'LCOF Baseline'!E$13 -> 4.6798201e+08 | F15: =F14/(1+'Study Parameters'!$C$3) ^'LCOF Baseline'!F$13 -> 4.3331668e+08 | G15: =G14/(1+'Study Parameters'!$C$3) ^'LCOF Baseline'!G$13 -> 4.0121915e+08 | H15: =H14/(1+'Study Parameters'!$C$3) ^'LCOF Baseline'!H$13 -> 3.7149921e+08 | I15: =I14/(1+'Study Parameters'!$C$3) ^'LCOF Baseline'!I$13 -> 3.4398075e+08 | ... AF15: =AF14/(1+'Study Parameters'!$C$3) ^'LCOF Baseline'!AF$13 -> 58585179
A16: Revenue (€) | B16: 0 | C16: ='Study Parameters'!$C$42 * 10^6 -> 122000000 | D16: ='Study Parameters'!$C$42 * 10^6 -> 122000000 | E16: ='Study Parameters'!$C$42 * 10^6 -> 122000000 | F16: ='Study Parameters'!$C$42 * 10^6 -> 122000000 | G16: ='Study Parameters'!$C$42 * 10^6 -> 122000000 | H16: ='Study Parameters'!$C$42 * 10^6 -> 122000000 | I16: ='Study Parameters'!$C$42 * 10^6 -> 122000000 | J16: ='Study Parameters'!$C$42 * 10^6 -> 122000000 | ... AF16: ='Study Parameters'!$C$42 * 10^6 -> 122000000
A17: Discounted Revenue (€) | B17: 0 | C17: =C16/(1+'Study Parameters'!$C$3) ^'LCOF Baseline'!C$13 -> 1.1296296e+08 | D17: =D16/(1+'Study Parameters'!$C$3) ^'LCOF Baseline'!D$13 -> 1.0459534e+08 | E17: =E16/(1+'Study Parameters'!$C$3) ^'LCOF Baseline'!E$13 -> 96847533 | F17: =F16/(1+'Study Parameters'!$C$3) ^'LCOF Baseline'!F$13 -> 89673642 | G17: =G16/(1+'Study Parameters'!$C$3) ^'LCOF Baseline'!G$13 -> 83031150 | H17: =H16/(1+'Study Parameters'!$C$3) ^'LCOF Baseline'!H$13 -> 76880694 | I17: =I16/(1+'Study Parameters'!$C$3) ^'LCOF Baseline'!I$13 -> 71185828 | J17: =J16/(1+'Study Parameters'!$C$3) ^'LCOF Baseline'!J$13 -> 65912804 | ... AF17: =AF16/(1+'Study Parameters'!$C$3) ^'LCOF Baseline'!AF$13 -> 12124035
A18: Production (l) | B18: 0 | C18: ='Study Parameters'!$C$9 -> 157410000 | D18: ='Study Parameters'!$C$9 -> 157410000 | E18: ='Study Parameters'!$C$9 -> 157410000 | F18: ='Study Parameters'!$C$9 -> 157410000 | G18: ='Study Parameters'!$C$9 -> 157410000 | H18: ='Study Parameters'!$C$9 -> 157410000 | I18: ='Study Parameters'!$C$9 -> 157410000 | J18: ='Study Parameters'!$C$9 -> 157410000 | ... AF18: ='Study Parameters'!$C$9 -> 157410000
A19: Discounted Production (l) | B19: 0 | C19: =C18/(1+'Study Parameters'!$C$3) ^'LCOF Baseline'!C$13 -> 145750000 | D19: =D18/(1+'Study Parameters'!$C$3) ^'LCOF Baseline'!D$13 -> 1.349537e+08 | E19: =E18/(1+'Study Parameters'!$C$3) ^'LCOF Baseline'!E$13 -> 1.2495713e+08 | F19: =F18/(1+'Study Parameters'!$C$3) ^'LCOF Baseline'!F$13 -> 1.1570105e+08 | G19: =G18/(1+'Study Parameters'!$C$3) ^'LCOF Baseline'!G$13 -> 1.071306e+08 | H19: =H18/(1+'Study Parameters'!$C$3) ^'LCOF Baseline'!H$13 -> 99195001 | I19: =I18/(1+'Study Parameters'!$C$3) ^'LCOF Baseline'!I$13 -> 91847223 | J19: =J18/(1+'Study Parameters'!$C$3) ^'LCOF Baseline'!J$13 -> 85043725 | ... AF19: =AF18/(1+'Study Parameters'!$C$3) ^'LCOF Baseline'!AF$13 -> 15642986
A21: Levelised Cost of Fuel (€/l) | B21: =(SUM(B15:AF15) - SUM(B17:AF17)) / SUM(B19:AF19) -> 7.2831083
A23: C-S-N/R
A24: Year | B24: 0 | C24: 1 | D24: 2 | E24: 3 | F24: 4 | G24: 5 | H24: 6 | I24: 7 | J24: 8 | K24: 9 | L24: 10 | M24: 11 | N24: 12 | O24: 13 | P24: 14 | Q24: 15 | R24: 16 | S24: 17 | T24: 18 | U24: 19 | V24: 20 | W24: 21 | X24: 22 | Y24: 23 | Z24: 24 | AA24: 25 | AB24: 26 | AC24: 27 | AD24: 28 | AE24: 29 | AF24: 30
A25: Cost (€) | B25: ='Cost Components'!N8 * 10^6 -> 7.7930785e+09 | C25: ='Cost Components'!$N$22 * 10^6 -> 5.105619e+08 | D25: ='Cost Components'!$N$22 * 10^6 -> 5.105619e+08 | E25: ='Cost Components'!$N$22 * 10^6 -> 5.105619e+08 | F25: ='Cost Components'!$N$22 * 10^6 -> 5.105619e+08 | G25: ='Cost Components'!$N$22 * 10^6 -> 5.105619e+08 | H25: ='Cost Components'!$N$22 * 10^6 -> 5.105619e+08 | I25: ='Cost Components'!$N$22 * 10^6 + 'Cost Components'!$N$7 * 10^6 -> 8.855619e+08 | J25: ='Cost Components'!$N$22 * 10^6 -> 5.105619e+08 | K25: ='Cost Components'!$N$22 * 10^6 -> 5.105619e+08 | L25: ='Cost Components'!$N$22 * 10^6 -> 5.105619e+08 | M25: ='Cost Components'!$N$22 * 10^6 -> 5.105619e+08 | N25: ='Cost Components'!$N$22 * 10^6 -> 5.105619e+08 | O25: ='Cost Components'!$N$22 * 10^6 + 'Cost Components'!$N$7 * 10^6 -> 8.855619e+08 | P25: ='Cost Components'!$N$22 * 10^6 -> 5.105619e+08 | Q25: ='Cost Components'!$N$22 * 10^6 -> 5.105619e+08 | R25: ='Cost Components'!$N$22 * 10^6 -> 5.105619e+08 | S25: ='Cost Components'!$N$22 * 10^6 -> 5.105619e+08 | T25: ='Cost Components'!$N$22 * 10^6 -> 5.105619e+08 | U25: ='Cost Components'!$N$22 * 10^6 + 'Cost Components'!$N$7 * 10^6 -> 8.855619e+08 | V25: ='Cost Components'!$N$22 * 10^6 -> 5.105619e+08 | W25: ='Cost Components'!$N$22 * 10^6 -> 5.105619e+08 | X25: ='Cost Components'!$N$22 * 10^6 -> 5.105619e+08 | Y25: ='Cost Components'!$N$22 * 10^6 -> 5.105619e+08 | Z25: ='Cost Components'!$N$22 * 10^6 -> 5.105619e+08 | AA25: ='Cost Components'!$N$22 * 10^6 + 'Cost Components'!$N$7 * 10^6 -> 8.855619e+08 | AB25: ='Cost Components'!$N$22 * 10^6 -> 5.105619e+08 | AC25: ='Cost Components'!$N$22 * 10^6 -> 5.105619e+08 | AD25: ='Cost Components'!$N$22 * 10^6 -> 5.105619e+08 | AE25: ='Cost Components'!$N$22 * 10^6 -> 5.105619e+08 | AF25: ='Cost Components'!$N$22 * 10^6 -> 5.105619e+08
A26: Discounted Cost (€) | B26: =B25/(1+'Study Parameters'!$C$3)^'LCOF Baseline'!B$24 -> 7.7930785e+09 | C26: =C25/(1+'Study Parameters'!$C$3)^'LCOF Baseline'!C$24 -> 4.727425e+08 | D26: =D25/(1+'Study Parameters'!$C$3)^'LCOF Baseline'!D$24 -> 4.3772454e+08 | E26: =E25/(1+'Study Parameters'!$C$3)^'LCOF Baseline'!E$24 -> 4.053005e+08 | F26: =F25/(1+'Study Parameters'!$C$3)^'LCOF Baseline'!F$24 -> 3.7527824e+08 | G26: =G25/(1+'Study Parameters'!$C$3)^'LCOF Baseline'!G$24 -> 3.4747985e+08 | H26: =H25/(1+'Study Parameters'!$C$3)^'LCOF Baseline'!H$24 -> 3.2174061e+08 | I26: =I25/(1+'Study Parameters'!$C$3)^'LCOF Baseline'!I$24 -> 5.1671687e+08 | ... AF26: =AF25/(1+'Study Parameters'!$C$3)^'LCOF Baseline'!AF$24 -> 50738280
A27: Revenue (€) | B27: 0 | C27: ='Study Parameters'!$C$42 * 10^6 -> 122000000 | D27: ='Study Parameters'!$C$42 * 10^6 -> 122000000 | E27: ='Study Parameters'!$C$42 * 10^6 -> 122000000 | F27: ='Study Parameters'!$C$42 * 10^6 -> 122000000 | G27: ='Study Parameters'!$C$42 * 10^6 -> 122000000 | H27: ='Study Parameters'!$C$42 * 10^6 -> 122000000 | I27: ='Study Parameters'!$C$42 * 10^6 -> 122000000 | J27: ='Study Parameters'!$C$42 * 10^6 -> 122000000 | ... AF27: ='Study Parameters'!$C$42 * 10^6 -> 122000000
A28: Discounted Revenue (€) | B28: 0 | C28: =C27/(1+'Study Parameters'!$C$3)^'LCOF Baseline'!C$24 -> 1.1296296e+08 | D28: =D27/(1+'Study Parameters'!$C$3)^'LCOF Baseline'!D$24 -> 1.0459534e+08 | E28: =E27/(1+'Study Parameters'!$C$3)^'LCOF Baseline'!E$24 -> 96847533 | F28: =F27/(1+'Study Parameters'!$C$3)^'LCOF Baseline'!F$24 -> 89673642 | G28: =G27/(1+'Study Parameters'!$C$3)^'LCOF Baseline'!G$24 -> 83031150 | H28: =H27/(1+'Study Parameters'!$C$3)^'LCOF Baseline'!H$24 -> 76880694 | I28: =I27/(1+'Study Parameters'!$C$3)^'LCOF Baseline'!I$24 -> 71185828 | J28: =J27/(1+'Study Parameters'!$C$3)^'LCOF Baseline'!J$24 -> 65912804 | ... AF28: =AF27/(1+'Study Parameters'!$C$3)^'LCOF Baseline'!AF$24 -> 12124035
A29: Production (l) | B29: 0 | C29: ='Study Parameters'!$C$9 -> 157410000 | D29: ='Study Parameters'!$C$9 -> 157410000 | E29: ='Study Parameters'!$C$9 -> 157410000 | F29: ='Study Parameters'!$C$9 -> 157410000 | G29: ='Study Parameters'!$C$9 -> 157410000 | H29: ='Study Parameters'!$C$9 -> 157410000 | I29: ='Study Parameters'!$C$9 -> 157410000 | J29: ='Study Parameters'!$C$9 -> 157410000 | ... AF29: ='Study Parameters'!$C$9 -> 157410000
A30: Discounted Production (l) | B30: 0 | C30: =C29/(1+'Study Parameters'!$C$3)^'LCOF Baseline'!C$24 -> 145750000 | D30: =D29/(1+'Study Parameters'!$C$3)^'LCOF Baseline'!D$24 -> 1.349537e+08 | E30: =E29/(1+'Study Parameters'!$C$3)^'LCOF Baseline'!E$24 -> 1.2495713e+08 | F30: =F29/(1+'Study Parameters'!$C$3)^'LCOF Baseline'!F$24 -> 1.1570105e+08 | G30: =G29/(1+'Study Parameters'!$C$3)^'LCOF Baseline'!G$24 -> 1.071306e+08 | H30: =H29/(1+'Study Parameters'!$C$3)^'LCOF Baseline'!H$24 -> 99195001 | I30: =I29/(1+'Study Parameters'!$C$3)^'LCOF Baseline'!I$24 -> 91847223 | J30: =J29/(1+'Study Parameters'!$C$3)^'LCOF Baseline'!J$24 -> 85043725 | ... AF30: =AF29/(1+'Study Parameters'!$C$3)^'LCOF Baseline'!AF$24 -> 15642986
A32: Levelised Cost of Fuel (€/l) | B32: =(SUM(B26:AF26) - SUM(B28:AF28)) / SUM(B30:AF30) -> 7.1473713
A34: F-P-N
A35: Year | B35: 0 | C35: 1 | D35: 2 | E35: 3 | F35: 4 | G35: 5 | H35: 6 | I35: 7 | J35: 8 | K35: 9 | L35: 10 | M35: 11 | N35: 12 | O35: 13 | P35: 14 | Q35: 15 | R35: 16 | S35: 17 | T35: 18 | U35: 19 | V35: 20 | W35: 21 | X35: 22 | Y35: 23 | Z35: 24 | AA35: 25 | AB35: 26 | AC35: 27 | AD35: 28 | AE35: 29 | AF35: 30
